Workbook

Sheet aufgeräumt
A1: FAME (µg/sample) | B1: FAME (µg/sample) | C1: NC25.D | D1: NC26.D | E1: NC27.D | F1: NC28.D | G1: NC3.D | H1: NC4.D | I1: NC7.D | J1: NC8.D | K1: NC10.D | L1: NC15.D | M1: Pro2.D | N1: Pro7.D
A2: Octansäure | B2: C08:0 | C2: 6.9195217 | D2: 6.7014393 | E2: 6.6946287 | F2: 6.7367412 | G2: 6.6951332 | H2: 6.6676724 | I2: 6.6992855 | J2: 6.7397358 | K2: 6.6895515 | L2: 6.6836143 | M2: 6.8369263 | N2: 6.6635893
A3: Decansäure | B3: C10:0 | C3: 0 | D3: 0 | E3: 0 | F3: 0.2717704 | G3: 0 | H3: 0 | I3: 0 | J3: 0 | K3: 0 | L3: 0 | M3: 0 | N3: 0
A4: Undecansäure | B4: C11:0 | C4: 0 | D4: 0 | E4: 0 | F4: 0 | G4: 0 | H4: 0 | I4: 0 | J4: 0 | K4: 0 | L4: 0 | M4: 0 | N4: 0
A5: Dodecansäure | B5: C12:0 | C5: 3.9083869 | D5: 8.8682996 | E5: 13.852462 | F5: 11.917392 | G5: 14.65145 | H5: 0 | I5: 0 | J5: 0 | K5: 0 | L5: 0 | M5: 0 | N5: 0
A6: Tridecansäure | B6: C13:0 | C6: 89.102143 | D6: 96.253499 | E6: 97.207645 | F6: 96.611987 | G6: 95.48406 | H6: 0 | I6: 0.8001623 | J6: 0 | K6: 0 | L6: 0 | M6: 0 | N6: 0
A7: Tetradecansäure | B7: C14:0 | C7: 82.495747 | D7: 91.746003 | E7: 137.17156 | F7: 106.61916 | G7: 134.51254 | H7: 46.715863 | I7: 83.530886 | J7: 42.469701 | K7: 33.764052 | L7: 38.385557 | M7: 49.80879 | N7: 7.0520523
A8: 9-Tetradecensäure | B8: C14:1 | C8: 0 | D8: 0 | E8: 0 | F8: 0 | G8: 0 | H8: 0 | I8: 0 | J8: 0 | K8: 0 | L8: 0 | M8: 0 | N8: 0
A9: Pentadecansäure | B9: C15:0 | C9: 12.380672 | D9: 14.86793 | E9: 21.296026 | F9: 17.70647 | G9: 18.688696 | H9: 12.195388 | I9: 12.503864 | J9: 6.2557918 | K9: 9.4287721 | L9: 6.9455379 | M9: 9.6523759 | N9: 4.64437
A10: Cis-10-Pentadecensäure | B10: C15:1 | C10: 0 | D10: 0 | E10: 0 | F10: 0 | G10: 0 | H10: 0 | I10: 0 | J10: 0 | K10: 0 | L10: 0 | M10: 0 | N10: 0
A11: Hexadecansäure | B11: C16:0 | C11: 2493.7801 | D11: 2296.9465 | E11: 3158.6579 | F11: 2735.375 | G11: 3052.9329 | H11: 3033.5847 | I11: 2678.0562 | J11: 2174.1626 | K11: 2199.1592 | L11: 1975.0772 | M11: 2609.5016 | N11: 1428.1466
A12: Cis-9-Hexadecensäure | B12: C16:1 | C12: 349.68088 | D12: 321.00219 | E12: 538.04847 | F12: 487.11089 | G12: 632.97792 | H12: 434.55811 | I12: 496.55875 | J12: 395.71086 | K12: 369.00012 | L12: 327.46316 | M12: 532.5441 | N12: 40.549058
A13: Heptadecansäure | B13: C17:0 | C13: 19.372227 | D13: 18.381928 | E13: 34.052666 | F13: 24.171529 | G13: 22.566353 | H13: 25.937929 | I13: 24.492535 | J13: 13.986285 | K13: 19.590826 | L13: 14.960301 | M13: 20.573109 | N13: 10.73173
... A26: Cis-5,8,11,14-Eicosatetraensäure | B26: C20:4(n-6) | C26: 214.76229 | D26: 143.37697 | E26: 367.99145 | F26: 235.72993 | G26: 233.85097 | H26: 337.94537 | I26: 284.34847 | J26: 206.1788 | K26: 258.32174 | L26: 167.85773 | M26: 187.97657 | N26: 154.59918
A27: Cis-11,14,17-Eicosatriensäure | B27: C20:3(n-3) | C27: ND | D27: ND | E27: 17.386777 | F27: ND | G27: ND | H27: 16.655207 | I27: 6.0526282 | J27: 12.949457 | K27: 12.677769 | L27: 10.570114 | M27: ND | N27: ND
A28: Heneicosansäure | B28: C21:0 | C28: 0 | D28: 0 | E28: 0.0708758 | F28: 0.4644721 | G28: 0 | H28: 0 | I28: 0 | J28: 0 | K28: 0 | L28: 0 | M28: 0 | N28: 0
A29: Cis-5,8,11,14,17-Eicosapentaensäure | B29: C20:5(n-3) | C29: 187.38594 | D29: 173.11516 | E29: 287.80609 | F29: 213.30576 | G29: 199.1393 | H29: 253.1281 | I29: 236.64177 | J29: 217.11987 | K29: 221.29606 | L29: 164.65718 | M29: 186.53659 | N29: 106.37485
A30: Docosansäure | B30: C22:0 | C30: 0 | D30: 0 | E30: 0 | F30: 0 | G30: 0 | H30: 0 | I30: 0 | J30: 0 | K30: 0 | L30: 0 | M30: 0 | N30: 0
A31: 13-Docosensäure | B31: C22:1 | C31: 94.303771 | D31: 51.987947 | E31: 85.83048 | F31: 66.71807 | G31: 62.498384 | H31: 89.688234 | I31: 49.572101 | J31: 53.032529 | K31: 52.252935 | L31: 57.276931 | M31: 54.794601 | N31: 58.359669
A32: Cis-13,16-Docosadiensäure | B32: C22:2 | C32: 1.9159594 | D32: 1.8645901 | E32: 1.9092201 | F32: 1.898734 | G32: 9.9632521 | H32: 2.0221628 | I32: 1.9170098 | J32: 9.3506858 | K32: 1.9415489 | L32: 1.9027576 | M32: 1.806976 | N32: 1.9237338
A33: Cis-7,10,13,16,19-Docosapentaensäure | B33: C22:5(n-3) | C33: 5.5423441 | D33: 4.2312013 | E33: 14.592968 | F33: 7.7797768 | G33: 7.5219358 | H33: 11.610083 | I33: 7.7788684 | J33: 6.3701761 | K33: 9.3293405 | L33: 5.3429677 | M33: 5.724796 | N33: 3.6180725
A34: Cis-4,7,10,13,16,19-Docosahexaensäure | B34: C22:6(n-3) | C34: 6.4709817 | D34: 4.0687561 | E34: 19.883378 | F34: 8.5064085 | G34: 6.9483413 | H34: 13.991179 | I34: 10.848844 | J34: 4.2916133 | K34: 10.419841 | L34: 6.3393358 | M34: 4.3243431 | N34: 1.3568966
A35: Tetracosansäure | B35: C24:0 | C35: 6.612612 | D35: 12.190144 | E35: 21.478908 | F35: 22.515429 | G35: 25.124685 | H35: 16.382639 | I35: 9.6472345 | J35: 0 | K35: 16.10157 | L35: 0 | M35: 12.948116 | N35: 9.4936729
A36: Cis-15-Tetracosensäure | B36: C24:1 | C36: 0 | D36: 0 | E36: 0 | F36: 0 | G36: 0 | H36: 0 | I36: 0 | J36: 0 | K36: 0 | L36: 0 | M36: 0 | N36: 0

Sheet µg statt ng
A1: FAME | B1: Data File | C1: MEGA-Mix_230628.D | D1: NC25.D | E1: NC26.D | F1: NC27.D | G1: NC28.D | H1: NC3.D | I1: NC4.D | J1: NC7.D | K1: NC8.D | L1: NC10.D | M1: NC15.D | N1: Pro2.D | O1: Pro7.D | P1: blank230628b.D | R1: ISD( µ/ml)
A2: Octansäure | B2: Final Conc. | C2: ='data processing'!D2/1000 -> 396.84743 | D2: ='data processing'!E2/1000 -> 6.9195217 | E2: ='data processing'!F2/1000 -> 6.7014393 | F2: ='data processing'!G2/1000 -> 6.6946287 | G2: ='data processing'!H2/1000 -> 6.7367412 | H2: ='data processing'!I2/1000 -> 6.6951332 | I2: ='data processing'!J2/1000 -> 6.6676724 | J2: ='data processing'!K2/1000 -> 6.6992855 | ... P2: ='data processing'!Q2/1000 -> 1634.0094 | R2: 400
A3: Decansäure | B3: Final Conc. | C3: ='data processing'!D3/1000 -> 391.7786 | D3: ='data processing'!E3/1000 -> 0 | E3: ='data processing'!F3/1000 -> 0 | F3: ='data processing'!G3/1000 -> 0 | G3: ='data processing'!H3/1000 -> 0.2717704 | H3: ='data processing'!I3/1000 -> 0 | I3: ='data processing'!J3/1000 -> 0 | J3: ='data processing'!K3/1000 -> 0 | ... P3: ='data processing'!Q3/1000 -> 4113.9979 | R3: 400
A4: Undecansäure | B4: Final Conc. | C4: ='data processing'!D4/1000 -> 190.53502 | D4: ='data processing'!E4/1000 -> 0 | E4: ='data processing'!F4/1000 -> 0 | F4: ='data processing'!G4/1000 -> 0 | G4: ='data processing'!H4/1000 -> 0 | H4: ='data processing'!I4/1000 -> 0 | I4: ='data processing'!J4/1000 -> 0 | J4: ='data processing'!K4/1000 -> 0 | ... P4: ='data processing'!Q4/1000 -> 927.21527 | R4: 200
A5: Dodecansäure | B5: Final Conc. | C5: ='data processing'!D5/1000 -> 258.52885 | D5: ='data processing'!E5/1000 -> 3.9083869 | E5: ='data processing'!F5/1000 -> 8.8682996 | F5: ='data processing'!G5/1000 -> 13.852462 | G5: ='data processing'!H5/1000 -> 11.917392 | H5: ='data processing'!I5/1000 -> 14.65145 | I5: ='data processing'!J5/1000 -> 0 | J5: ='data processing'!K5/1000 -> 0 | ... P5: ='data processing'!Q5/1000 -> 64.40791 | R5: 400
A6: Tridecansäure | B6: Final Conc. | C6: ='data processing'!D6/1000 -> 109.48459 | D6: ='data processing'!E6/1000 -> 89.102143 | E6: ='data processing'!F6/1000 -> 96.253499 | F6: ='data processing'!G6/1000 -> 97.207645 | G6: ='data processing'!H6/1000 -> 96.611987 | H6: ='data processing'!I6/1000 -> 95.48406 | I6: ='data processing'!J6/1000 -> 0 | J6: ='data processing'!K6/1000 -> 0.8001623 | ... P6: ='data processing'!Q6/1000 -> 1943.7305 | R6: 200
A7: Tetradecansäure | B7: Final Conc. | C7: ='data processing'!D7/1000 -> 288.28134 | D7: ='data processing'!E7/1000 -> 82.495747 | E7: ='data processing'!F7/1000 -> 91.746003 | F7: ='data processing'!G7/1000 -> 137.17156 | G7: ='data processing'!H7/1000 -> 106.61916 | H7: ='data processing'!I7/1000 -> 134.51254 | I7: ='data processing'!J7/1000 -> 46.715863 | J7: ='data processing'!K7/1000 -> 83.530886 | ... P7: ='data processing'!Q7/1000 -> 360.72214 | R7: 400
A8: 9-Tetradecensäure | B8: Final Conc. | C8: ='data processing'!D8/1000 -> 162.1922 | D8: ='data processing'!E8/1000 -> 0 | E8: ='data processing'!F8/1000 -> 0 | F8: ='data processing'!G8/1000 -> 0 | G8: ='data processing'!H8/1000 -> 0 | H8: ='data processing'!I8/1000 -> 0 | I8: ='data processing'!J8/1000 -> 0 | J8: ='data processing'!K8/1000 -> 0 | ... P8: ='data processing'!Q8/1000 -> 745.54101 | R8: 200
A9: Pentadecansäure | B9: Final Conc. | C9: ='data processing'!D9/1000 -> 121.97621 | D9: ='data processing'!E9/1000 -> 12.380672 | E9: ='data processing'!F9/1000 -> 14.86793 | F9: ='data processing'!G9/1000 -> 21.296026 | G9: ='data processing'!H9/1000 -> 17.70647 | H9: ='data processing'!I9/1000 -> 18.688696 | I9: ='data processing'!J9/1000 -> 12.195388 | J9: ='data processing'!K9/1000 -> 12.503864 | ... P9: ='data processing'!Q9/1000 -> 387.17308 | R9: 200
A10: Cis-10-Pentadecensäure | B10: Final Conc. | C10: ='data processing'!D10/1000 -> 157.63121 | D10: ='data processing'!E10/1000 -> 0 | E10: ='data processing'!F10/1000 -> 0 | F10: ='data processing'!G10/1000 -> 0 | G10: ='data processing'!H10/1000 -> 0 | H10: ='data processing'!I10/1000 -> 0 | I10: ='data processing'!J10/1000 -> 0 | J10: ='data processing'!K10/1000 -> 0 | ... P10: ='data processing'!Q10/1000 -> 196.23319 | R10: 200
A11: Hexadecansäure | B11: Final Conc. | C11: ='data processing'!D11/1000 -> 1812.9395 | D11: ='data processing'!E11/1000 -> 2493.7801 | E11: ='data processing'!F11/1000 -> 2296.9465 | F11: ='data processing'!G11/1000 -> 3158.6579 | G11: ='data processing'!H11/1000 -> 2735.375 | H11: ='data processing'!I11/1000 -> 3052.9329 | I11: ='data processing'!J11/1000 -> 3033.5847 | J11: ='data processing'!K11/1000 -> 2678.0562 | ... P11: ='data processing'!Q11/1000 -> 102087.99 | R11: 600
A12: Cis-9-Hexadecensäure | B12: Final Conc. | C12: ='data processing'!D12/1000 -> 160.40755 | D12: ='data processing'!E12/1000 -> 349.68088 | E12: ='data processing'!F12/1000 -> 321.00219 | F12: ='data processing'!G12/1000 -> 538.04847 | G12: ='data processing'!H12/1000 -> 487.11089 | H12: ='data processing'!I12/1000 -> 632.97792 | I12: ='data processing'!J12/1000 -> 434.55811 | J12: ='data processing'!K12/1000 -> 496.55875 | ... P12: ='data processing'!Q12/1000 -> 972.11868 | R12: 200
A13: Heptadecansäure | B13: Final Conc. | C13: ='data processing'!D13/1000 -> 149.7384 | D13: ='data processing'!E13/1000 -> 19.372227 | E13: ='data processing'!F13/1000 -> 18.381928 | F13: ='data processing'!G13/1000 -> 34.052666 | G13: ='data processing'!H13/1000 -> 24.171529 | H13: ='data processing'!I13/1000 -> 22.566353 | I13: ='data processing'!J13/1000 -> 25.937929 | J13: ='data processing'!K13/1000 -> 24.492535 | ... P13: ='data processing'!Q13/1000 -> 81.92907 | R13: 200
... A20: Alpha-Octadecatriensäure | B20: Final Conc. | C20: ='data processing'!D20/1000 -> 568.23009 | D20: ='data processing'!E20/1000 -> 181.89141 | E20: ='data processing'!F20/1000 -> 175.06268 | F20: ='data processing'!G20/1000 -> 517.86098 | G20: ='data processing'!H20/1000 -> 216.44536 | H20: ='data processing'!I20/1000 -> 226.71888 | I20: ='data processing'!J20/1000 -> 488.27724 | J20: ='data processing'!K20/1000 -> 286.32961 | ... P20: ='data processing'!Q20/1000 -> 1561.3923 | R20: 200
A21: 6,9,12,15-Octadecatetraensäure | B21: Final Conc. | C21: ='data processing'!D21/1000 -> 111.91174 | D21: ='data processing'!E21/1000 -> 8.8877941 | E21: ='data processing'!F21/1000 -> 9.4875166 | F21: ='data processing'!G21/1000 -> 33.008861 | G21: ='data processing'!H21/1000 -> 12.446491 | H21: ='data processing'!I21/1000 -> 11.34546 | I21: ='data processing'!J21/1000 -> 21.513762 | J21: ='data processing'!K21/1000 -> 14.834082 | ... P21: ='data processing'!Q21/1000 -> 945.24588
A22: Eicosansäure | B22: Final Conc. | C22: ='data processing'!D22/1000 -> 275.44388 | D22: ='data processing'!E22/1000 -> 4.7820946 | E22: ='data processing'!F22/1000 -> 1.5077561 | F22: ='data processing'!G22/1000 -> 1.5606182 | G22: ='data processing'!H22/1000 -> 1.8122145 | H22: ='data processing'!I22/1000 -> 1.5999242 | I22: ='data processing'!J22/1000 -> 1.7797164 | J22: ='data processing'!K22/1000 -> 1.5552858 | ... P22: ='data processing'!Q22/1000 -> 1052.7063 | R22: 400
A23: Cis-11-Eicosensäure | B23: Final Conc. | C23: ='data processing'!D23/1000 -> 49.023988 | D23: ='data processing'!E23/1000 -> 9.3887077 | E23: ='data processing'!F23/1000 -> 9.4481436 | F23: ='data processing'!G23/1000 -> 51.819646 | G23: ='data processing'!H23/1000 -> 17.964521 | H23: ='data processing'!I23/1000 -> 26.919016 | I23: ='data processing'!J23/1000 -> 46.561836 | J23: ='data processing'!K23/1000 -> 0 | ... P23: ='data processing'!Q23/1000 -> 138.96061 | R23: 200
A24: Cis-11,14-Eicosadiensäure | B24: Final Conc. | C24: ='data processing'!D24/1000 -> 108.22961 | D24: ='data processing'!E24/1000 -> 22.894911 | E24: ='data processing'!F24/1000 -> 25.386587 | F24: ='data processing'!G24/1000 -> 86.324219 | G24: ='data processing'!H24/1000 -> 41.860368 | H24: ='data processing'!I24/1000 -> 50.078904 | I24: ='data processing'!J24/1000 -> 71.859141 | J24: ='data processing'!K24/1000 -> 49.490551 | ... P24: ='data processing'!Q24/1000 -> 146.77572 | R24: 200
A25: Cis-8,11,14-Eisocatriensäure | B25: Final Conc. | C25: ='data processing'!D25/1000 -> 71.399479 | D25: ='data processing'!E25/1000 -> 0.4021034 | E25: ='data processing'!F25/1000 -> 0.3949214 | F25: ='data processing'!G25/1000 -> 19.824876 | G25: ='data processing'!H25/1000 -> 5.0889846 | H25: ='data processing'!I25/1000 -> 0.4216065 | I25: ='data processing'!J25/1000 -> 12.968693 | J25: ='data processing'!K25/1000 -> 8.8423252 | ... P25: ='data processing'!Q25/1000 -> 232.25564 | R25: 200
A26: Cis-5,8,11,14-Eicosatetraensäure | B26: Final Conc. | C26: ='data processing'!D26/1000 -> 257.49216 | D26: ='data processing'!E26/1000 -> 214.76229 | E26: ='data processing'!F26/1000 -> 143.37697 | F26: ='data processing'!G26/1000 -> 367.99145 | G26: ='data processing'!H26/1000 -> 235.72993 | H26: ='data processing'!I26/1000 -> 233.85097 | I26: ='data processing'!J26/1000 -> 337.94537 | J26: ='data processing'!K26/1000 -> 284.34847 | ... P26: ='data processing'!Q26/1000 -> 637.33304 | R26: 200
A27: Cis-11,14,17-Eicosatriensäure | B27: Final Conc. | C27: ='data processing'!D27/1000 -> 79.427843 | D27: ='data processing'!E27/1000 -> #VALUE! | E27: ='data processing'!F27/1000 -> #VALUE! | F27: ='data processing'!G27/1000 -> 17.386777 | G27: ='data processing'!H27/1000 -> #VALUE! | H27: ='data processing'!I27/1000 -> #VALUE! | I27: ='data processing'!J27/1000 -> 16.655207 | J27: ='data processing'!K27/1000 -> 6.0526282 | ... P27: ='data processing'!Q27/1000 -> 175.2885 | R27: 200
A28: Heneicosansäure | B28: Final Conc. | C28: ='data processing'!D28/1000 -> 119.92238 | D28: ='data processing'!E28/1000 -> 0 | E28: ='data processing'!F28/1000 -> 0 | F28: ='data processing'!G28/1000 -> 0.0708758 | G28: ='data processing'!H28/1000 -> 0.4644721 | H28: ='data processing'!I28/1000 -> 0 | I28: ='data processing'!J28/1000 -> 0 | J28: ='data processing'!K28/1000 -> 0 | ... P28: ='data processing'!Q28/1000 -> 51.732789 | R28: 200
A29: Cis-5,8,11,14,17-Eicosapentaensäure | B29: Final Conc. | C29: ='data processing'!D29/1000 -> 173.12247 | D29: ='data processing'!E29/1000 -> 187.38594 | E29: ='data processing'!F29/1000 -> 173.11516 | F29: ='data processing'!G29/1000 -> 287.80609 | G29: ='data processing'!H29/1000 -> 213.30576 | H29: ='data processing'!I29/1000 -> 199.1393 | I29: ='data processing'!J29/1000 -> 253.1281 | J29: ='data processing'!K29/1000 -> 236.64177 | ... P29: ='data processing'!Q29/1000 -> 763.44892 | R29: 200
A30: Docosansäure | B30: Final Conc. | C30: ='data processing'!D30/1000 -> 162.54339 | D30: ='data processing'!E30/1000 -> 0 | E30: ='data processing'!F30/1000 -> 0 | F30: ='data processing'!G30/1000 -> 0 | G30: ='data processing'!H30/1000 -> 0 | H30: ='data processing'!I30/1000 -> 0 | I30: ='data processing'!J30/1000 -> 0 | J30: ='data processing'!K30/1000 -> 0 | ... P30: ='data processing'!Q30/1000 -> 788.58374 | R30: 200
A31: 13-Docosensäure | B31: Final Conc. | C31: ='data processing'!D31/1000 -> 105.56625 | D31: ='data processing'!E31/1000 -> 94.303771 | E31: ='data processing'!F31/1000 -> 51.987947 | F31: ='data processing'!G31/1000 -> 85.83048 | G31: ='data processing'!H31/1000 -> 66.71807 | H31: ='data processing'!I31/1000 -> 62.498384 | I31: ='data processing'!J31/1000 -> 89.688234 | J31: ='data processing'!K31/1000 -> 49.572101 | ... P31: ='data processing'!Q31/1000 -> 319.80246 | R31: 400
A32: Cis-13,16-Docosadiensäure | B32: Final Conc. | C32: ='data processing'!D32/1000 -> 94.335022 | D32: ='data processing'!E32/1000 -> 1.9159594 | E32: ='data processing'!F32/1000 -> 1.8645901 | F32: ='data processing'!G32/1000 -> 1.9092201 | G32: ='data processing'!H32/1000 -> 1.898734 | H32: ='data processing'!I32/1000 -> 9.9632521 | I32: ='data processing'!J32/1000 -> 2.0221628 | J32: ='data processing'!K32/1000 -> 1.9170098 | ... P32: ='data processing'!Q32/1000 -> 471.39392 | R32: 200
A33: Cis-7,10,13,16,19-Docosapentaensäure | B33: Final Conc. | C33: ='data processing'!D33/1000 -> 31.265686 | D33: ='data processing'!E33/1000 -> 5.5423441 | E33: ='data processing'!F33/1000 -> 4.2312013 | F33: ='data processing'!G33/1000 -> 14.592968 | G33: ='data processing'!H33/1000 -> 7.7797768 | H33: ='data processing'!I33/1000 -> 7.5219358 | I33: ='data processing'!J33/1000 -> 11.610083 | J33: ='data processing'!K33/1000 -> 7.7788684 | ... P33: ='data processing'!Q33/1000 -> 497.17422
A34: Cis-4,7,10,13,16,19-Docosahexaensäure | B34: Final Conc. | C34: ='data processing'!D34/1000 -> 82.502099 | D34: ='data processing'!E34/1000 -> 6.4709817 | E34: ='data processing'!F34/1000 -> 4.0687561 | F34: ='data processing'!G34/1000 -> 19.883378 | G34: ='data processing'!H34/1000 -> 8.5064085 | H34: ='data processing'!I34/1000 -> 6.9483413 | I34: ='data processing'!J34/1000 -> 13.991179 | J34: ='data processing'!K34/1000 -> 10.848844 | ... P34: ='data processing'!Q34/1000 -> 517.7258 | R34: 200
A35: Tetracosansäure | B35: Final Conc. | C35: ='data processing'!D35/1000 -> 614.95968 | D35: ='data processing'!E35/1000 -> 6.612612 | E35: ='data processing'!F35/1000 -> 12.190144 | F35: ='data processing'!G35/1000 -> 21.478908 | G35: ='data processing'!H35/1000 -> 22.515429 | H35: ='data processing'!I35/1000 -> 25.124685 | I35: ='data processing'!J35/1000 -> 16.382639 | J35: ='data processing'!K35/1000 -> 9.6472345 | ... P35: ='data processing'!Q35/1000 -> 1787.7852 | R35: 400
A36: Cis-15-Tetracosensäure | B36: Final Conc. | C36: ='data processing'!D36/1000 -> 11.717464 | D36: ='data processing'!E36/1000 -> 0 | E36: ='data processing'!F36/1000 -> 0 | F36: ='data processing'!G36/1000 -> 0 | G36: ='data processing'!H36/1000 -> 0 | H36: ='data processing'!I36/1000 -> 0 | I36: ='data processing'!J36/1000 -> 0 | J36: ='data processing'!K36/1000 -> 0 | ... P36: ='data processing'!Q36/1000 -> 263.01412 | R36: 200

Sheet data processing
A1: FAME | B1: Data File | C1: blank230628.D | D1: MEGA-Mix_230628.D | E1: NC25.D | F1: NC26.D | G1: NC27.D | H1: NC28.D | I1: NC3.D | J1: NC4.D | K1: NC7.D | L1: NC8.D | M1: NC10.D | N1: NC15.D | O1: Pro2.D | P1: Pro7.D | Q1: blank230628b.D | S1: ISD( µ/ml)
A2: Octansäure | B2: Final Conc. | C2: 469764.07 | D2: 396847.43 | E2: 6919.5217 | F2: 6701.4393 | G2: 6694.6287 | H2: 6736.7412 | I2: 6695.1332 | J2: 6667.6724 | K2: 6699.2855 | L2: 6739.7358 | M2: 6689.5515 | N2: 6683.6143 | O2: 6836.9263 | P2: 6663.5893 | Q2: 1634009.4 | S2: 400
A3: Decansäure | B3: Final Conc. | C3: 293879.56 | D3: 391778.6 | E3: 0 | F3: 0 | G3: 0 | H3: 271.7704 | I3: 0 | J3: 0 | K3: 0 | L3: 0 | M3: 0 | N3: 0 | O3: 0 | P3: 0 | Q3: 4113997.9 | S3: 400
A4: Undecansäure | B4: Final Conc. | C4: 156810.32 | D4: 190535.02 | E4: 0 | F4: 0 | G4: 0 | H4: 0 | I4: 0 | J4: 0 | K4: 0 | L4: 0 | M4: 0 | N4: 0 | O4: 0 | P4: 0 | Q4: 927215.27 | S4: 200
A5: Dodecansäure | B5: Final Conc. | C5: 6429.3685 | D5: 258528.85 | E5: 3908.3869 | F5: 8868.2996 | G5: 13852.462 | H5: 11917.392 | I5: 14651.45 | J5: 0 | K5: 0 | L5: 0 | M5: 0 | N5: 0 | O5: 0 | P5: 0 | Q5: 64407.91 | S5: 400
A6: Tridecansäure | B6: Final Conc. | C6: 104030.93 | D6: 109484.59 | E6: 89102.143 | F6: 96253.499 | G6: 97207.645 | H6: 96611.987 | I6: 95484.06 | J6: 0 | K6: 800.1623 | L6: 0 | M6: 0 | N6: 0 | O6: 0 | P6: 0 | Q6: 1943730.5 | S6: 200
A7: Tetradecansäure | B7: Final Conc. | C7: 14576.394 | D7: 288281.34 | E7: 82495.747 | F7: 91746.003 | G7: 137171.56 | H7: 106619.16 | I7: 134512.54 | J7: 46715.863 | K7: 83530.886 | L7: 42469.701 | M7: 33764.052 | N7: 38385.557 | O7: 49808.79 | P7: 7052.0523 | Q7: 360722.14 | S7: 400
A8: 9-Tetradecensäure | B8: Final Conc. | C8: 255322.1 | D8: 162192.2 | E8: 0 | F8: 0 | G8: 0 | H8: 0 | I8: 0 | J8: 0 | K8: 0 | L8: 0 | M8: 0 | N8: 0 | O8: 0 | P8: 0 | Q8: 745541.01 | S8: 200
A9: Pentadecansäure | B9: Final Conc. | C9: 144466.88 | D9: 121976.21 | E9: 12380.672 | F9: 14867.93 | G9: 21296.026 | H9: 17706.47 | I9: 18688.696 | J9: 12195.388 | K9: 12503.864 | L9: 6255.7918 | M9: 9428.7721 | N9: 6945.5379 | O9: 9652.3759 | P9: 4644.37 | Q9: 387173.08 | S9: 200
A10: Cis-10-Pentadecensäure | B10: Final Conc. | C10: 37236.192 | D10: 157631.21 | E10: 0 | F10: 0 | G10: 0 | H10: 0 | I10: 0 | J10: 0 | K10: 0 | L10: 0 | M10: 0 | N10: 0 | O10: 0 | P10: 0 | Q10: 196233.19 | S10: 200
A11: Hexadecansäure | B11: Final Conc. | C11: 81652.239 | D11: 1812939.5 | E11: 2493780.1 | F11: 2296946.5 | G11: 3158657.9 | H11: 2735375 | I11: 3052932.9 | J11: 3033584.7 | K11: 2678056.2 | L11: 2174162.6 | M11: 2199159.2 | N11: 1975077.2 | O11: 2609501.6 | P11: 1428146.6 | Q11: 1.0208799e+08 | S11: 600
A12: Cis-9-Hexadecensäure | B12: Final Conc. | C12: 58989.511 | D12: 160407.55 | E12: 349680.88 | F12: 321002.19 | G12: 538048.47 | H12: 487110.89 | I12: 632977.92 | J12: 434558.11 | K12: 496558.75 | L12: 395710.86 | M12: 369000.12 | N12: 327463.16 | O12: 532544.1 | P12: 40549.058 | Q12: 972118.68 | S12: 200
A13: Heptadecansäure | B13: Final Conc. | C13: 9365.2058 | D13: 149738.4 | E13: 19372.227 | F13: 18381.928 | G13: 34052.666 | H13: 24171.529 | I13: 22566.353 | J13: 25937.929 | K13: 24492.535 | L13: 13986.285 | M13: 19590.826 | N13: 14960.301 | O13: 20573.109 | P13: 10731.73 | Q13: 81929.07 | S13: 200
... A20: Alpha-Octadecatriensäure | B20: Final Conc. | C20: 331064.87 | D20: 568230.09 | E20: 181891.41 | F20: 175062.68 | G20: 517860.98 | H20: 216445.36 | I20: 226718.88 | J20: 488277.24 | K20: 286329.61 | L20: 319693.33 | M20: 225711.78 | N20: 215718.51 | O20: 190102.66 | P20: 84144.925 | Q20: 1561392.3 | S20: 200
A21: 6,9,12,15-Octadecatetraensäure | B21: Final Conc. | C21: 202595.28 | D21: 111911.74 | E21: 8887.7941 | F21: 9487.5166 | G21: 33008.861 | H21: 12446.491 | I21: 11345.46 | J21: 21513.762 | K21: 14834.082 | L21: 17437.924 | M21: 12062.197 | N21: 8358.2134 | O21: 13824.566 | P21: 4171.1581 | Q21: 945245.88
A22: Eicosansäure | B22: Final Conc. | C22: 260462.69 | D22: 275443.88 | E22: 4782.0946 | F22: 1507.7561 | G22: 1560.6182 | H22: 1812.2145 | I22: 1599.9242 | J22: 1779.7164 | K22: 1555.2858 | L22: 1449.5451 | M22: 4960.0798 | N22: 1657.6354 | O22: 1649.1342 | P22: 1548.8088 | Q22: 1052706.3 | S22: 400
A23: Cis-11-Eicosensäure | B23: Final Conc. | C23: 60710.919 | D23: 49023.988 | E23: 9388.7077 | F23: 9448.1436 | G23: 51819.646 | H23: 17964.521 | I23: 26919.016 | J23: 46561.836 | K23: 0 | L23: 22870.71 | M23: 19860.391 | N23: 23761.468 | O23: 20722.165 | P23: 24433.72 | Q23: 138960.61 | S23: 200
A24: Cis-11,14-Eicosadiensäure | B24: Final Conc. | C24: 62244.818 | D24: 108229.61 | E24: 22894.911 | F24: 25386.587 | G24: 86324.219 | H24: 41860.368 | I24: 50078.904 | J24: 71859.141 | K24: 49490.551 | L24: 43932.387 | M24: 40090.425 | N24: 42134.904 | O24: 42873.952 | P24: 16347.606 | Q24: 146775.72 | S24: 200
A25: Cis-8,11,14-Eisocatriensäure | B25: Final Conc. | C25: 26429.983 | D25: 71399.48 | E25: 402.1034 | F25: 394.9214 | G25: 19824.876 | H25: 5088.9846 | I25: 421.6065 | J25: 12968.693 | K25: 8842.3252 | L25: 7252.3596 | M25: 421.0307 | N25: 418.7612 | O25: 420.6048 | P25: 23291.743 | Q25: 232255.64 | S25: 200
A26: Cis-5,8,11,14-Eicosatetraensäure | B26: Final Conc. | C26: 80590.52 | D26: 257492.16 | E26: 214762.29 | F26: 143376.97 | G26: 367991.45 | H26: 235729.93 | I26: 233850.97 | J26: 337945.37 | K26: 284348.47 | L26: 206178.8 | M26: 258321.74 | N26: 167857.73 | O26: 187976.57 | P26: 154599.18 | Q26: 637333.04 | S26: 200
A27: Cis-11,14,17-Eicosatriensäure | B27: Final Conc. | C27: 62957.707 | D27: 79427.843 | E27: ND | F27: ND | G27: 17386.777 | H27: ND | I27: ND | J27: 16655.207 | K27: 6052.6282 | L27: 12949.457 | M27: 12677.769 | N27: 10570.114 | O27: ND | P27: ND | Q27: 175288.5 | S27: 200
A28: Heneicosansäure | B28: Final Conc. | C28: 6426.2581 | D28: 119922.38 | E28: 0 | F28: 0 | G28: 70.8758 | H28: 464.4721 | I28: 0 | J28: 0 | K28: 0 | L28: 0 | M28: 0 | N28: 0 | O28: 0 | P28: 0 | Q28: 51732.789 | S28: 200
A29: Cis-5,8,11,14,17-Eicosapentaensäure | B29: Final Conc. | C29: 166444.06 | D29: 173122.47 | E29: 187385.94 | F29: 173115.16 | G29: 287806.09 | H29: 213305.76 | I29: 199139.3 | J29: 253128.1 | K29: 236641.77 | L29: 217119.87 | M29: 221296.06 | N29: 164657.18 | O29: 186536.59 | P29: 106374.85 | Q29: 763448.92 | S29: 200
A30: Docosansäure | B30: Final Conc. | C30: 427118.51 | D30: 162543.39 | E30: 0 | F30: 0 | G30: 0 | H30: 0 | I30: 0 | J30: 0 | K30: 0 | L30: 0 | M30: 0 | N30: 0 | O30: 0 | P30: 0 | Q30: 788583.74 | S30: 200
A31: 13-Docosensäure | B31: Final Conc. | C31: 91514.27 | D31: 105566.25 | E31: 94303.771 | F31: 51987.947 | G31: 85830.48 | H31: 66718.07 | I31: 62498.384 | J31: 89688.234 | K31: 49572.101 | L31: 53032.529 | M31: 52252.935 | N31: 57276.931 | O31: 54794.601 | P31: 58359.669 | Q31: 319802.46 | S31: 400
A32: Cis-13,16-Docosadiensäure | B32: Final Conc. | C32: 112012.4 | D32: 94335.022 | E32: 1915.9594 | F32: 1864.5901 | G32: 1909.2201 | H32: 1898.734 | I32: 9963.2521 | J32: 2022.1628 | K32: 1917.0098 | L32: 9350.6858 | M32: 1941.5489 | N32: 1902.7576 | O32: 1806.976 | P32: 1923.7338 | Q32: 471393.92 | S32: 200
A33: Cis-7,10,13,16,19-Docosapentaensäure | B33: Final Conc. | C33: 116254.87 | D33: 31265.685 | E33: 5542.3441 | F33: 4231.2013 | G33: 14592.968 | H33: 7779.7768 | I33: 7521.9358 | J33: 11610.083 | K33: 7778.8684 | L33: 6370.1761 | M33: 9329.3405 | N33: 5342.9677 | O33: 5724.796 | P33: 3618.0725 | Q33: 497174.22
A34: Cis-4,7,10,13,16,19-Docosahexaensäure | B34: Final Conc. | C34: 143116.23 | D34: 82502.099 | E34: 6470.9817 | F34: 4068.7561 | G34: 19883.378 | H34: 8506.4085 | I34: 6948.3413 | J34: 13991.179 | K34: 10848.844 | L34: 4291.6133 | M34: 10419.841 | N34: 6339.3358 | O34: 4324.3431 | P34: 1356.8966 | Q34: 517725.8 | S34: 200
A35: Tetracosansäure | B35: Final Conc. | C35: 125142.77 | D35: 614959.68 | E35: 6612.612 | F35: 12190.144 | G35: 21478.908 | H35: 22515.429 | I35: 25124.685 | J35: 16382.639 | K35: 9647.2345 | L35: 0 | M35: 16101.57 | N35: 0 | O35: 12948.116 | P35: 9493.6729 | Q35: 1787785.2 | S35: 400
A36: Cis-15-Tetracosensäure | B36: Final Conc. | C36: 30263.648 | D36: 11717.464 | E36: 0 | F36: 0 | G36: 0 | H36: 0 | I36: 0 | J36: 0 | K36: 0 | L36: 0 | M36: 0 | N36: 0 | O36: 0 | P36: 0 | Q36: 263014.12 | S36: 200

Sheet raw data
A2: Octansäure | B2: Data File | C2: blank230628.D | D2: MEGA-Mix_230628.D | E2: NC25.D | F2: NC26.D | G2: NC27.D | H2: NC28.D | I2: NC3.D | J2: NC4.D | K2: NC7.D | L2: NC8.D | M2: NC10.D | N2: NC15.D | O2: Pro2.D | P2: Pro7.D | Q2: blank230628b.D
B3: Type | C3: Blank | D3: Sample | E3: Sample | F3: Sample | G3: Sample | H3: Sample | I3: Sample | J3: Sample | K3: Sample | L3: Sample | M3: Sample | N3: Sample | O3: Sample | P3: Sample | Q3: Blank
B4: ISTD | C4: Nonadecansäure | D4: Nonadecansäure | E4: Nonadecansäure | F4: Nonadecansäure | G4: Nonadecansäure | H4: Nonadecansäure | I4: Nonadecansäure | J4: Nonadecansäure | K4: Nonadecansäure | L4: Nonadecansäure | M4: Nonadecansäure | N4: Nonadecansäure | O4: Nonadecansäure | P4: Nonadecansäure | Q4: Nonadecansäure
B5: RT | C5: 4.224 | D5: 4.185 | E5: 4.167 | F5: 4.2 | G5: 4.174 | H5: 4.196 | I5: 4.2 | J5: 4.192 | K5: 4.17 | L5: 4.182 | M5: 4.185 | N5: 4.203 | O5: 4.171 | P5: 4.176 | Q5: 4.168
B6: Resp. | C6: 3859 | D6: 34299665 | E6: 15960 | F6: 3826 | G6: 4531 | H6: 5566 | I6: 3504 | J6: 1822 | K6: 4263 | L6: 5924 | M6: 3592 | N6: 3767 | O6: 11176 | P6: 1778 | Q6: 2382
B7: ISTD Resp | C7: 4375 | D7: 46147435 | E7: 29303512 | F7: 29605111 | G7: 38972507 | H7: 28325627 | I7: 29885889 | J7: 28058058 | K7: 34068209 | L7: 29299387 | M7: 33694913 | N7: 39534888 | O7: 28855855 | P7: 31116840 | Q7: 768
B8: RR | C8: 0.8822 | D8: 0.7433 | E8: 0.0005 | F8: 0.0001 | G8: 0.0001 | H8: 0.0002 | I8: 0.0001 | J8: 0.0001 | K8: 0.0001 | L8: 0.0002 | M8: 0.0001 | N8: 0.0001 | O8: 0.0004 | P8: 0.0001 | Q8: 3.0998
B9: Final Conc. | C9: 469764.07 | D9: 396847.43 | E9: 6919.5217 | F9: 6701.4393 | G9: 6694.6287 | H9: 6736.7412 | I9: 6695.1332 | J9: 6667.6724 | K9: 6699.2855 | L9: 6739.7358 | M9: 6689.5515 | N9: 6683.6143 | O9: 6836.9263 | P9: 6663.5893 | Q9: 1634009.4
A10: Decansäure | B10: Data File | C10: blank230628.D | D10: MEGA-Mix_230628.D | E10: NC25.D | F10: NC26.D | G10: NC27.D | H10: NC28.D | I10: NC3.D | J10: NC4.D | K10: NC7.D | L10: NC8.D | M10: NC10.D | N10: NC15.D | O10: Pro2.D | P10: Pro7.D | Q10: blank230628b.D
B11: Type | C11: Blank | D11: Sample | E11: Sample | F11: Sample | G11: Sample | H11: Sample | I11: Sample | J11: Sample | K11: Sample | L11: Sample | M11: Sample | N11: Sample | O11: Sample | P11: Sample | Q11: Blank
B12: ISTD | C12: Nonadecansäure | D12: Nonadecansäure | E12: Nonadecansäure | F12: Nonadecansäure | G12: Nonadecansäure | H12: Nonadecansäure | I12: Nonadecansäure | J12: Nonadecansäure | K12: Nonadecansäure | L12: Nonadecansäure | M12: Nonadecansäure | N12: Nonadecansäure | O12: Nonadecansäure | P12: Nonadecansäure | Q12: Nonadecansäure
B13: RT | C13: 5.312 | D13: 5.35 | E13: 5.352 | F13: 5.339 | G13: 5.36 | H13: 5.333 | I13: 5.338 | J13: 5.352 | K13: 5.295 | L13: 5.35 | M13: 5.341 | N13: 5.342 | O13: 5.328 | P13: 4.787 | Q13: 5.375
B14: Resp. | C14: 1889 | D14: 26526355 | E14: 8098 | F14: 25206 | G14: 6369 | H14: 71921 | I14: 27673 | J14: 3029 | K14: 16050 | L14: 4775 | M14: 5431 | N14: 9974 | O14: 6458 | P14: 11535 | Q14: 4623
B15: ISTD Resp | C15: 4375 | D15: 46147435 | E15: 29303512 | F15: 29605111 | G15: 38972507 | H15: 28325627 | I15: 29885889 | J15: 28058058 | K15: 34068209 | L15: 29299387 | M15: 33694913 | N15: 39534888 | O15: 28855855 | P15: 31116840 | Q15: 768
B16: RR | C16: 0.4317 | D16: 0.5748 | E16: 0.0003 | F16: 0.0009 | G16: 0.0002 | H16: 0.0025 | I16: 0.0009 | J16: 0.0001 | K16: 0.0005 | L16: 0.0002 | M16: 0.0002 | N16: 0.0003 | O16: 0.0002 | P16: 0.0004 | Q16: 6.0157
B17: Final Conc. | C17: 293879.56 | D17: 391778.6 | E17: 0 | F17: 0 | G17: 0 | H17: 271.7704 | I17: 0 | J17: 0 | K17: 0 | L17: 0 | M17: 0 | N17: 0 | O17: 0 | P17: 0 | Q17: 4113997.9
A18: Undecansäure | B18: Data File | C18: blank230628.D | D18: MEGA-Mix_230628.D | E18: NC25.D | F18: NC26.D | G18: NC27.D | H18: NC28.D | I18: NC3.D | J18: NC4.D | K18: NC7.D | L18: NC8.D | M18: NC10.D | N18: NC15.D | O18: Pro2.D | P18: Pro7.D | Q18: blank230628b.D
B19: Type | C19: Blank | D19: Sample | E19: Sample | F19: Sample | G19: Sample | H19: Sample | I19: Sample | J19: Sample | K19: Sample | L19: Sample | M19: Sample | N19: Sample | O19: Sample | P19: Sample | Q19: Blank
B20: ISTD | C20: Nonadecansäure | D20: Nonadecansäure | E20: Nonadecansäure | F20: Nonadecansäure | G20: Nonadecansäure | H20: Nonadecansäure | I20: Nonadecansäure | J20: Nonadecansäure | K20: Nonadecansäure | L20: Nonadecansäure | M20: Nonadecansäure | N20: Nonadecansäure | O20: Nonadecansäure | P20: Nonadecansäure | Q20: Nonadecansäure
B21: RT | C21: 6.164 | D21: 6.16 | E21: 6.145 | F21: 6.15 | G21: 6.151 | H21: 6.154 | I21: 6.184 | J21: 6.153 | K21: 6.142 | L21: 6.175 | M21: 6.179 | N21: 6.137 | O21: 6.167 | P21: 6.158 | Q21: 6.176
B22: Resp. | C22: 2008 | D22: 25696663 | E22: 39806 | F22: 60144 | G22: 100105 | H22: 78001 | I22: 6826 | J22: 1370 | K22: 1777 | L22: 1698 | M22: 3826 | N22: 1829 | O22: 5393 | P22: 13413 | Q22: 2070
B23: ISTD Resp | C23: 4375 | D23: 46147435 | E23: 29303512 | F23: 29605111 | G23: 38972507 | H23: 28325627 | I23: 29885889 | J23: 28058058 | K23: 34068209 | L23: 29299387 | M23: 33694913 | N23: 39534888 | O23: 28855855 | P23: 31116840 | Q23: 768
B24: RR | C24: 0.459 | D24: 0.5568 | E24: 0.0014 | F24: 0.002 | G24: 0.0026 | H24: 0.0028 | I24: 0.0002 | J24: 0 | K24: 0.0001 | L24: 0.0001 | M24: 0.0001 | N24: 0 | O24: 0.0002 | P24: 0.0004 | Q24: 2.6938
B25: Final Conc. | C25: 156810.32 | D25: 190535.02 | E25: 0 | F25: 0 | G25: 0 | H25: 0 | I25: 0 | J25: 0 | K25: 0 | L25: 0 | M25: 0 | N25: 0 | O25: 0 | P25: 0 | Q25: 927215.27
A27: Dodecansäure | B27: Data File | C27: blank230628.D | D27: MEGA-Mix_230628.D | E27: NC25.D | F27: NC26.D | G27: NC27.D | H27: NC28.D | I27: NC3.D | J27: NC4.D | K27: NC7.D | L27: NC8.D | M27: NC10.D | N27: NC15.D | O27: Pro2.D | P27: Pro7.D | Q27: blank230628b.D
B28: Type | C28: Blank | D28: Sample | E28: Sample | F28: Sample | G28: Sample | H28: Sample | I28: Sample | J28: Sample | K28: Sample | L28: Sample | M28: Sample | N28: Sample | O28: Sample | P28: Sample | Q28: Blank
B29: ISTD | C29: Nonadecansäure | D29: Nonadecansäure | E29: Nonadecansäure | F29: Nonadecansäure | G29: Nonadecansäure | H29: Nonadecansäure | I29: Nonadecansäure | J29: Nonadecansäure | K29: Nonadecansäure | L29: Nonadecansäure | M29: Nonadecansäure | N29: Nonadecansäure | O29: Nonadecansäure | P29: Nonadecansäure | Q29: Nonadecansäure
B30: RT | C30: 7.475 | D30: 7.273 | E30: 7.244 | F30: 7.244 | G30: 7.244 | H30: 7.243 | I30: 7.244 | J30: 7.481 | K30: 7.241 | L30: 7.244 | M30: 7.354 | N30: 7.293 | O30: 7.559 | P30: 7.482 | Q30: 7.473
B31: Resp. | C31: 1049 | D31: 202541766 | E31: 5807602 | F31: 8284211 | G31: 14102536 | H31: 9347712 | I31: 11207483 | J31: 4201 | K31: 2235360 | L31: 224277 | M31: 6422 | N31: 18035 | O31: 2166 | P31: 1002 | Q31: 917
B32: ISTD Resp | C32: 4375 | D32: 46147435 | E32: 29303512 | F32: 29605111 | G32: 38972507 | H32: 28325627 | I32: 29885889 | J32: 28058058 | K32: 34068209 | L32: 29299387 | M32: 33694913 | N32: 39534888 | O32: 28855855 | P32: 31116840 | Q32: 768
B33: RR | C33: 0.2397 | D33: 4.389 | E33: 0.1982 | F33: 0.2798 | G33: 0.3619 | H33: 0.33 | I33: 0.375 | J33: 0.0001 | K33: 0.0656 | L33: 0.0077 | M33: 0.0002 | N33: 0.0005 | O33: 0.0001 | P33: 0 | Q33: 1.194
B34: Final Conc. | C34: 6429.3685 | D34: 258528.85 | E34: 3908.3869 | F34: 8868.2996 | G34: 13852.462 | H34: 11917.392 | I34: 14651.45 | J34: 0 | K34: 0 | L34: 0 | M34: 0 | N34: 0 | O34: 0 | P34: 0 | Q34: 64407.91
A36: Tridecansäure | B36: Data File | C36: blank230628.D | D36: MEGA-Mix_230628.D | E36: NC25.D | F36: NC26.D | G36: NC27.D | H36: NC28.D | I36: NC3.D | J36: NC4.D | K36: NC7.D | L36: NC8.D | M36: NC10.D | N36: NC15.D | O36: Pro2.D | P36: Pro7.D | Q36: blank230628b.D
B37: Type | C37: Blank | D37: Sample | E37: Sample | F37: Sample | G37: Sample | H37: Sample | I37: Sample | J37: Sample | K37: Sample | L37: Sample | M37: Sample | N37: Sample | O37: Sample | P37: Sample | Q37: Blank
B38: ISTD | C38: Nonadecansäure | D38: Nonadecansäure | E38: Nonadecansäure | F38: Nonadecansäure | G38: Nonadecansäure | H38: Nonadecansäure | I38: Nonadecansäure | J38: Nonadecansäure | K38: Nonadecansäure | L38: Nonadecansäure | M38: Nonadecansäure | N38: Nonadecansäure | O38: Nonadecansäure | P38: Nonadecansäure | Q38: Nonadecansäure
B39: RT | C39: 9.072 | D39: 8.774 | E39: 8.744 | F39: 8.744 | G39: 8.745 | H39: 8.746 | I39: 8.747 | J39: 9.171 | K39: 8.735 | L39: 9.072 | M39: 9.032 | N39: 8.882 | O39: 9.08 | P39: 8.918 | Q39: 9.048
B40: Resp. | C40: 2688 | D40: 29828537 | E40: 15454181 | F40: 16849228 | G40: 22397604 | H40: 16180313 | I40: 16874783 | J40: 8742 | K40: 404780 | L40: 8021 | M40: 7362 | N40: 6668 | O40: 6270 | P40: 3523 | Q40: 8725
B41: ISTD Resp | C41: 4375 | D41: 46147435 | E41: 29303512 | F41: 29605111 | G41: 38972507 | H41: 28325627 | I41: 29885889 | J41: 28058058 | K41: 34068209 | L41: 29299387 | M41: 33694913 | N41: 39534888 | O41: 28855855 | P41: 31116840 | Q41: 768
B42: RR | C42: 0.6145 | D42: 0.6464 | E42: 0.5274 | F42: 0.5691 | G42: 0.5747 | H42: 0.5712 | I42: 0.5646 | J42: 0.0003 | K42: 0.0119 | L42: 0.0003 | M42: 0.0002 | N42: 0.0002 | O42: 0.0002 | P42: 0.0001 | Q42: 11.3546
B43: Final Conc. | C43: 104030.93 | D43: 109484.59 | E43: 89102.143 | F43: 96253.499 | G43: 97207.645 | H43: 96611.987 | I43: 95484.06 | J43: 0 | K43: 800.1623 | L43: 0 | M43: 0 | N43: 0 | O43: 0 | P43: 0 | Q43: 1943730.5
...

Sheet 230628_FA-Quant-Report_ISTD
A1: Batch Data Path | B1: D:\MassHunter\GCMS\1\data\Sophie_Landau\230628\QuantResults\230628.batch.bin
A2: Analysis Time | B2: 45161.461 | C2: Analyst Name | D2: FLOEK026\install | E2: Report Generator Name | F2: FLOEK026\install
A3: Calibration Last Update | B3: 45154.569 | C3: Analyze Quant Version | D3: 10.1 | E3: Report Quant Version | F3: 10.2
A4: Sequence Table
A5: Data File | B5: Name | C5: Type | D5: Vial | E5: Vol. | F5: Level | G5: Acq. Method File
A6: blank230628.D | B6: blank | C6: Blank | D6: 1 | E6: 1 | G6: FAME_02_Insert
A8: MEGA-Mix_230628.D | B8: MEGA-Mix | C8: Sample | D8: 2 | E8: 1 | G8: FAME_02_Insert
A10: NC25.D | B10: NC25 | C10: Sample | D10: 3 | E10: 1 | G10: FAME_02_Insert
A12: NC26.D | B12: NC26 | C12: Sample | D12: 4 | E12: 1 | G12: FAME_02_Insert
A14: NC27.D | B14: NC27 | C14: Sample | D14: 5 | E14: 1 | G14: FAME_02_Insert
A16: NC28.D | B16: NC28 | C16: Sample | D16: 6 | E16: 1 | G16: FAME_02_Insert
A18: NC3.D | B18: NC3 | C18: Sample | D18: 7 | E18: 1 | G18: FAME_02_Insert
A20: NC4.D | B20: NC4 | C20: Sample | D20: 8 | E20: 1 | G20: FAME_02_Insert
A22: NC7.D | B22: NC7 | C22: Sample | D22: 9 | E22: 1 | G22: FAME_02_Insert
A24: NC8.D | B24: NC8 | C24: Sample | D24: 10 | E24: 1 | G24: FAME_02_Insert
A26: NC10.D | B26: NC10 | C26: Sample | D26: 11 | E26: 1 | G26: FAME_02_Insert
A28: NC15.D | B28: NC15 | C28: Sample | D28: 12 | E28: 1 | G28: FAME_02_Insert
... A34: blank230628b.D | B34: blank | C34: Blank | D34: 1 | E34: 1 | G34: FAME_02_Insert
A36: Octansäure
A37: Data File | B37: Type | C37: ISTD | D37: RT | E37: Resp. | F37: ISTD Resp | G37: RR | H37: Final Conc. | I37: Exp. Conc. | J37: Accuracy
A38: blank230628.D | B38: Blank | C38: Nonadecansäure | D38: 4.224 | E38: 3859 | F38: 4375 | G38: 0.8822 | H38: 469764.07
A39: MEGA-Mix_230628.D | B39: Sample | C39: Nonadecansäure | D39: 4.185 | E39: 34299665 | F39: 46147435 | G39: 0.7433 | H39: 396847.43
A40: NC25.D | B40: Sample | C40: Nonadecansäure | D40: 4.167 | E40: 15960 | F40: 29303512 | G40: 0.0005 | H40: 6919.5217
A41: NC26.D | B41: Sample | C41: Nonadecansäure | D41: 4.2 | E41: 3826 | F41: 29605111 | G41: 0.0001 | H41: 6701.4393
A42: NC27.D | B42: Sample | C42: Nonadecansäure | D42: 4.174 | E42: 4531 | F42: 38972507 | G42: 0.0001 | H42: 6694.6287
A43: NC28.D | B43: Sample | C43: Nonadecansäure | D43: 4.196 | E43: 5566 | F43: 28325627 | G43: 0.0002 | H43: 6736.7412
A44: NC3.D | B44: Sample | C44: Nonadecansäure | D44: 4.2 | E44: 3504 | F44: 29885889 | G44: 0.0001 | H44: 6695.1332
A45: NC4.D | B45: Sample | C45: Nonadecansäure | D45: 4.192 | E45: 1822 | F45: 28058058 | G45: 0.0001 | H45: 6667.6724
A46: NC7.D | B46: Sample | C46: Nonadecansäure | D46: 4.17 | E46: 4263 | F46: 34068209 | G46: 0.0001 | H46: 6699.2855
A47: NC8.D | B47: Sample | C47: Nonadecansäure | D47: 4.182 | E47: 5924 | F47: 29299387 | G47: 0.0002 | H47: 6739.7358
A48: NC10.D | B48: Sample | C48: Nonadecansäure | D48: 4.185 | E48: 3592 | F48: 33694913 | G48: 0.0001 | H48: 6689.5515
A49: NC15.D | B49: Sample | C49: Nonadecansäure | D49: 4.203 | E49: 3767 | F49: 39534888 | G49: 0.0001 | H49: 6683.6143
... A52: blank230628b.D | B52: Blank | C52: Nonadecansäure | D52: 4.168 | E52: 2382 | F52: 768 | G52: 3.0998 | H52: 1634009.4
A53: Decansäure
A54: Data File | B54: Type | C54: ISTD | D54: RT | E54: Resp. | F54: ISTD Resp | G54: RR | H54: Final Conc. | I54: Exp. Conc. | J54: Accuracy
A55: blank230628.D | B55: Blank | C55: Nonadecansäure | D55: 5.312 | E55: 1889 | F55: 4375 | G55: 0.4317 | H55: 293879.56
A56: MEGA-Mix_230628.D | B56: Sample | C56: Nonadecansäure | D56: 5.35 | E56: 26526355 | F56: 46147435 | G56: 0.5748 | H56: 391778.6
A57: NC25.D | B57: Sample | C57: Nonadecansäure | D57: 5.352 | E57: 8098 | F57: 29303512 | G57: 0.0003 | H57: 0
A58: NC26.D | B58: Sample | C58: Nonadecansäure | D58: 5.339 | E58: 25206 | F58: 29605111 | G58: 0.0009 | H58: 0
A59: NC27.D | B59: Sample | C59: Nonadecansäure | D59: 5.36 | E59: 6369 | F59: 38972507 | G59: 0.0002 | H59: 0
...
