Workbook

Sheet aufgeräumt
A1: FAME (µg/sample) | B1: FAME (µg/sample) | C1: W1NC.D | D1: W1Cip.D | E1: W1Pro.D | F1: W1Mix.D | G1: W2NC.D | H1: W2Cip.D | I1: W2Pro.D | J1: W2Mix.D | K1: W3NC.D
A2: Octansäure | B2: C08:0 | C2: 8.4897928 | D2: 6.7110905 | E2: 6.4875883 | F2: 6.7419952 | G2: 6.8420343 | H2: 6.9187815 | I2: 6.8520785 | J2: 6.7748372 | K2: 6.8264772
A3: Decansäure | B3: C10:0 | C3: 3.5278461 | D3: 0 | E3: 10.972772 | F3: 0 | G3: 1.3022846 | H3: 0 | I3: 0.903363 | J3: 0 | K3: 3.2359822
A4: Undecansäure | B4: C11:0 | C4: 0.2621582 | D4: 0 | E4: 1.0574169 | F4: 0 | G4: 0 | H4: 0 | I4: 0 | J4: 0 | K4: 0.144809
A5: Dodecansäure | B5: C12:0 | C5: 17.347754 | D5: 3.4789967 | E5: 24.59341 | F5: 8.9879605 | G5: 28.672792 | H5: 5.647691 | I5: 15.16002 | J5: 14.250568 | K5: 17.236231
A6: Tridecansäure | B6: C13:0 | C6: 89.994023 | D6: 76.516699 | E6: 92.250923 | F6: 108.34571 | G6: 111.37774 | H6: 95.54063 | I6: 86.806049 | J6: 85.757244 | K6: 124.8379
A7: Tetradecansäure | B7: C14:0 | C7: 260.69208 | D7: 268.58298 | E7: 280.7981 | F7: 327.58339 | G7: 226.38105 | H7: 140.64858 | I7: 186.4842 | J7: 125.94264 | K7: 285.18065
A8: 9-Tetradecensäure | B8: C14:1 | C8: 0 | D8: 0 | E8: 0 | F8: 0 | G8: 0 | H8: 6.4803132 | I8: 0 | J8: 0 | K8: 0
A9: Pentadecansäure | B9: C15:0 | C9: 11.053502 | D9: 11.52557 | E9: 16.017327 | F9: 11.593805 | G9: 13.430845 | H9: 8.8437347 | I9: 9.422083 | J9: 6.5394794 | K9: 16.945877
A10: Cis-10-Pentadecensäure | B10: C15:1 | C10: 0 | D10: 0 | E10: 0 | F10: 0 | G10: 0 | H10: 0 | I10: 0 | J10: 0 | K10: 0
A11: Hexadecansäure | B11: C16:0 | C11: 3439.147 | D11: 2916.7312 | E11: 3781.7041 | F11: 3321.8463 | G11: 5445.5674 | H11: 3886.0665 | I11: 3560.4577 | J11: 2713.1369 | K11: 6027.6313
A12: Cis-9-Hexadecensäure | B12: C16:1 | C12: 412.95174 | D12: 522.45979 | E12: 399.96856 | F12: 303.93006 | G12: 866.93063 | H12: 492.4923 | I12: 685.87132 | J12: 386.46815 | K12: 145.67465
A13: Heptadecansäure | B13: C17:0 | C13: 12.402884 | D13: 8.0118439 | E13: 20.891149 | F13: 11.767879 | G13: 18.850768 | H13: 16.350447 | I13: 10.118476 | J13: 8.0055298 | K13: 23.823893
... A36: Cis-15-Tetracosensäure | B36: C24:1 | C36: 0 | D36: 0 | E36: 0 | F36: 0 | G36: 0 | H36: 0 | I36: 0 | J36: 0 | K36: 0

Sheet µg statt ng
A1: FAME | B1: Data File | C1: blank230626.D | D1: MEGA-Mix_230626.D | E1: W1NC.D | F1: W1Cip.D | G1: W1Pro.D | H1: W1Mix.D | I1: W2NC.D | J1: W2Cip.D | K1: W2Pro.D | L1: W2Mix.D | M1: W3NC.D | O1: ISD( µ/ml)
A2: Octansäure | B2: Final Conc. | C2: ='data processing'!C2/1000 -> 1799.6362 | D2: ='data processing'!D2/1000 -> 388.32338 | E2: ='data processing'!E2/1000 -> 8.4897928 | F2: ='data processing'!F2/1000 -> 6.7110905 | G2: ='data processing'!G2/1000 -> 6.4875883 | H2: ='data processing'!H2/1000 -> 6.7419952 | I2: ='data processing'!I2/1000 -> 6.8420343 | J2: ='data processing'!J2/1000 -> 6.9187815 | ... M2: ='data processing'!M2/1000 -> 6.8264772 | O2: 400
A3: Decansäure | B3: Final Conc. | C3: ='data processing'!C3/1000 -> 1028.5854 | D3: ='data processing'!D3/1000 -> 397.35066 | E3: ='data processing'!E3/1000 -> 3.5278461 | F3: ='data processing'!F3/1000 -> 0 | G3: ='data processing'!G3/1000 -> 10.972772 | H3: ='data processing'!H3/1000 -> 0 | I3: ='data processing'!I3/1000 -> 1.3022846 | J3: ='data processing'!J3/1000 -> 0 | ... M3: ='data processing'!M3/1000 -> 3.2359822 | O3: 400
A4: Undecansäure | B4: Final Conc. | C4: ='data processing'!C4/1000 -> 529.32226 | D4: ='data processing'!D4/1000 -> 189.07934 | E4: ='data processing'!E4/1000 -> 0.2621582 | F4: ='data processing'!F4/1000 -> 0 | G4: ='data processing'!G4/1000 -> 1.0574169 | H4: ='data processing'!H4/1000 -> 0 | I4: ='data processing'!I4/1000 -> 0 | J4: ='data processing'!J4/1000 -> 0 | ... M4: ='data processing'!M4/1000 -> 0.144809 | O4: 200
A5: Dodecansäure | B5: Final Conc. | C5: ='data processing'!C5/1000 -> 4990.9473 | D5: ='data processing'!D5/1000 -> 239.17144 | E5: ='data processing'!E5/1000 -> 17.347754 | F5: ='data processing'!F5/1000 -> 3.4789967 | G5: ='data processing'!G5/1000 -> 24.59341 | H5: ='data processing'!H5/1000 -> 8.9879605 | I5: ='data processing'!I5/1000 -> 28.672792 | J5: ='data processing'!J5/1000 -> 5.647691 | ... M5: ='data processing'!M5/1000 -> 17.236231 | O5: 400
A6: Tridecansäure | B6: Final Conc. | C6: ='data processing'!C6/1000 -> 511.30821 | D6: ='data processing'!D6/1000 -> 114.85208 | E6: ='data processing'!E6/1000 -> 89.994023 | F6: ='data processing'!F6/1000 -> 76.516699 | G6: ='data processing'!G6/1000 -> 92.250923 | H6: ='data processing'!H6/1000 -> 108.34571 | I6: ='data processing'!I6/1000 -> 111.37774 | J6: ='data processing'!J6/1000 -> 95.54063 | ... M6: ='data processing'!M6/1000 -> 124.8379 | O6: 200
A7: Tetradecansäure | B7: Final Conc. | C7: ='data processing'!C7/1000 -> 402.36448 | D7: ='data processing'!D7/1000 -> 278.43026 | E7: ='data processing'!E7/1000 -> 260.69208 | F7: ='data processing'!F7/1000 -> 268.58298 | G7: ='data processing'!G7/1000 -> 280.7981 | H7: ='data processing'!H7/1000 -> 327.58339 | I7: ='data processing'!I7/1000 -> 226.38105 | J7: ='data processing'!J7/1000 -> 140.64858 | ... M7: ='data processing'!M7/1000 -> 285.18065 | O7: 400
A8: 9-Tetradecensäure | B8: Final Conc. | C8: ='data processing'!C8/1000 -> 676.61502 | D8: ='data processing'!D8/1000 -> 160.80868 | E8: ='data processing'!E8/1000 -> 0 | F8: ='data processing'!F8/1000 -> 0 | G8: ='data processing'!G8/1000 -> 0 | H8: ='data processing'!H8/1000 -> 0 | I8: ='data processing'!I8/1000 -> 0 | J8: ='data processing'!J8/1000 -> 6.4803132 | ... M8: ='data processing'!M8/1000 -> 0 | O8: 200
A9: Pentadecansäure | B9: Final Conc. | C9: ='data processing'!C9/1000 -> 209.59923 | D9: ='data processing'!D9/1000 -> 120.91005 | E9: ='data processing'!E9/1000 -> 11.053502 | F9: ='data processing'!F9/1000 -> 11.52557 | G9: ='data processing'!G9/1000 -> 16.017327 | H9: ='data processing'!H9/1000 -> 11.593805 | I9: ='data processing'!I9/1000 -> 13.430845 | J9: ='data processing'!J9/1000 -> 8.8437347 | ... M9: ='data processing'!M9/1000 -> 16.945877 | O9: 200
A10: Cis-10-Pentadecensäure | B10: Final Conc. | C10: ='data processing'!C10/1000 -> 221.2193 | D10: ='data processing'!D10/1000 -> 154.26159 | E10: ='data processing'!E10/1000 -> 0 | F10: ='data processing'!F10/1000 -> 0 | G10: ='data processing'!G10/1000 -> 0 | H10: ='data processing'!H10/1000 -> 0 | I10: ='data processing'!I10/1000 -> 0 | J10: ='data processing'!J10/1000 -> 0 | ... M10: ='data processing'!M10/1000 -> 0 | O10: 200
A11: Hexadecansäure | B11: Final Conc. | C11: ='data processing'!C11/1000 -> 22987.378 | D11: ='data processing'!D11/1000 -> 1729.0034 | E11: ='data processing'!E11/1000 -> 3439.147 | F11: ='data processing'!F11/1000 -> 2916.7312 | G11: ='data processing'!G11/1000 -> 3781.7041 | H11: ='data processing'!H11/1000 -> 3321.8463 | I11: ='data processing'!I11/1000 -> 5445.5674 | J11: ='data processing'!J11/1000 -> 3886.0665 | ... M11: ='data processing'!M11/1000 -> 6027.6313 | O11: 600
A12: Cis-9-Hexadecensäure | B12: Final Conc. | C12: ='data processing'!C12/1000 -> 385.87263 | D12: ='data processing'!D12/1000 -> 159.14418 | E12: ='data processing'!E12/1000 -> 412.95174 | F12: ='data processing'!F12/1000 -> 522.45979 | G12: ='data processing'!G12/1000 -> 399.96856 | H12: ='data processing'!H12/1000 -> 303.93006 | I12: ='data processing'!I12/1000 -> 866.93063 | J12: ='data processing'!J12/1000 -> 492.4923 | ... M12: ='data processing'!M12/1000 -> 145.67465 | O12: 200
A13: Heptadecansäure | B13: Final Conc. | C13: ='data processing'!C13/1000 -> 57.922397 | D13: ='data processing'!D13/1000 -> 151.11312 | E13: ='data processing'!E13/1000 -> 12.402884 | F13: ='data processing'!F13/1000 -> 8.0118439 | G13: ='data processing'!G13/1000 -> 20.891149 | H13: ='data processing'!H13/1000 -> 11.767879 | I13: ='data processing'!I13/1000 -> 18.850768 | J13: ='data processing'!J13/1000 -> 16.350447 | ... M13: ='data processing'!M13/1000 -> 23.823893 | O13: 200
... A20: Alpha-Octadecatriensäure | B20: Final Conc. | C20: ='data processing'!C20/1000 -> 933.22488 | D20: ='data processing'!D20/1000 -> 561.72557 | E20: ='data processing'!E20/1000 -> 1589.8427 | F20: ='data processing'!F20/1000 -> 1271.6817 | G20: ='data processing'!G20/1000 -> 1884.9026 | H20: ='data processing'!H20/1000 -> 1838.9375 | I20: ='data processing'!I20/1000 -> 3097.0301 | J20: ='data processing'!J20/1000 -> 2284.7086 | ... M20: ='data processing'!M20/1000 -> 3770.3103 | O20: 200
A21: 6,9,12,15-Octadecatetraensäure | B21: Final Conc. | C21: ='data processing'!C21/1000 -> 88.191463 | D21: ='data processing'!D21/1000 -> 108.98908 | E21: ='data processing'!E21/1000 -> 119.44329 | F21: ='data processing'!F21/1000 -> 132.03142 | G21: ='data processing'!G21/1000 -> 150.35204 | H21: ='data processing'!H21/1000 -> 172.99176 | I21: ='data processing'!I21/1000 -> 202.40559 | J21: ='data processing'!J21/1000 -> 138.10811 | ... M21: ='data processing'!M21/1000 -> 346.01261
A22: Eicosansäure | B22: Final Conc. | C22: ='data processing'!C22/1000 -> 279.63178 | D22: ='data processing'!D22/1000 -> 277.85521 | E22: ='data processing'!E22/1000 -> 38.12247 | F22: ='data processing'!F22/1000 -> 33.025972 | G22: ='data processing'!G22/1000 -> 54.27093 | H22: ='data processing'!H22/1000 -> 49.371424 | I22: ='data processing'!I22/1000 -> 21.568108 | J22: ='data processing'!J22/1000 -> 14.882105 | ... M22: ='data processing'!M22/1000 -> 22.211565 | O22: 400
A23: Cis-11-Eicosensäure | B23: Final Conc. | C23: ='data processing'!C23/1000 -> 277.5603 | D23: ='data processing'!D23/1000 -> 49.463998 | E23: ='data processing'!E23/1000 -> 25.829834 | F23: ='data processing'!F23/1000 -> 12.245436 | G23: ='data processing'!G23/1000 -> 0 | H23: ='data processing'!H23/1000 -> 15.057482 | I23: ='data processing'!I23/1000 -> 39.595628 | J23: ='data processing'!J23/1000 -> 0.1341609 | ... M23: ='data processing'!M23/1000 -> 35.43422 | O23: 200
A24: Cis-11,14-Eicosadiensäure | B24: Final Conc. | C24: ='data processing'!C24/1000 -> 99.710073 | D24: ='data processing'!D24/1000 -> 107.13391 | E24: ='data processing'!E24/1000 -> 17.306898 | F24: ='data processing'!F24/1000 -> 51.282989 | G24: ='data processing'!G24/1000 -> 19.658987 | H24: ='data processing'!H24/1000 -> 29.563606 | I24: ='data processing'!I24/1000 -> 15.15045 | J24: ='data processing'!J24/1000 -> 1.3623094 | ... M24: ='data processing'!M24/1000 -> 17.177085 | O24: 200
A25: Cis-8,11,14-Eisocatriensäure | B25: Final Conc. | C25: ='data processing'!C25/1000 -> 119.59318 | D25: ='data processing'!D25/1000 -> 70.996889 | E25: ='data processing'!E25/1000 -> 4.9322325 | F25: ='data processing'!F25/1000 -> 10.875138 | G25: ='data processing'!G25/1000 -> 5.191386 | H25: ='data processing'!H25/1000 -> 10.995605 | I25: ='data processing'!I25/1000 -> 0.4173301 | J25: ='data processing'!J25/1000 -> 0.4018824 | ... M25: ='data processing'!M25/1000 -> 0.4224136 | O25: 200
A26: Cis-5,8,11,14-Eicosatetraensäure | B26: Final Conc. | C26: ='data processing'!C26/1000 -> 1719.4467 | D26: ='data processing'!D26/1000 -> 248.02657 | E26: ='data processing'!E26/1000 -> 34.410478 | F26: ='data processing'!F26/1000 -> 55.359025 | G26: ='data processing'!G26/1000 -> 40.570802 | H26: ='data processing'!H26/1000 -> 27.035758 | I26: ='data processing'!I26/1000 -> 129.15607 | J26: ='data processing'!J26/1000 -> 54.570461 | ... M26: ='data processing'!M26/1000 -> 158.72422 | O26: 200
A27: Cis-11,14,17-Eicosatriensäure | B27: Final Conc. | C27: ='data processing'!C27/1000 -> 63.535416 | D27: ='data processing'!D27/1000 -> 78.221578 | E27: ='data processing'!E27/1000 -> 0 | F27: ='data processing'!F27/1000 -> 9.1917089 | G27: ='data processing'!G27/1000 -> 7.5946672 | H27: ='data processing'!H27/1000 -> 0 | I27: ='data processing'!I27/1000 -> 0 | J27: ='data processing'!J27/1000 -> 3.1999224 | ... M27: ='data processing'!M27/1000 -> 0 | O27: 200
A28: Heneicosansäure | B28: Final Conc. | C28: ='data processing'!C28/1000 -> 31.759214 | D28: ='data processing'!D28/1000 -> 116.40255 | E28: ='data processing'!E28/1000 -> 0 | F28: ='data processing'!F28/1000 -> 0 | G28: ='data processing'!G28/1000 -> 0 | H28: ='data processing'!H28/1000 -> 0 | I28: ='data processing'!I28/1000 -> 0 | J28: ='data processing'!J28/1000 -> 0 | ... M28: ='data processing'!M28/1000 -> 0 | O28: 200
A29: Cis-5,8,11,14,17-Eicosapentaensäure | B29: Final Conc. | C29: ='data processing'!C29/1000 -> 331.76114 | D29: ='data processing'!D29/1000 -> 164.28836 | E29: ='data processing'!E29/1000 -> 93.22772 | F29: ='data processing'!F29/1000 -> 133.89221 | G29: ='data processing'!G29/1000 -> 140.17136 | H29: ='data processing'!H29/1000 -> 65.407775 | I29: ='data processing'!I29/1000 -> 274.82376 | J29: ='data processing'!J29/1000 -> 144.10381 | ... M29: ='data processing'!M29/1000 -> 329.72 | O29: 200
A30: Docosansäure | B30: Final Conc. | C30: ='data processing'!C30/1000 -> 3724.4277 | D30: ='data processing'!D30/1000 -> 151.52676 | E30: ='data processing'!E30/1000 -> 7.7498568 | F30: ='data processing'!F30/1000 -> 9.4802548 | G30: ='data processing'!G30/1000 -> 11.673013 | H30: ='data processing'!H30/1000 -> 13.934636 | I30: ='data processing'!I30/1000 -> 0 | J30: ='data processing'!J30/1000 -> 3.0235838 | ... M30: ='data processing'!M30/1000 -> 6.7582188 | O30: 200
A31: 13-Docosensäure | B31: Final Conc. | C31: ='data processing'!C31/1000 -> 175.74326 | D31: ='data processing'!D31/1000 -> 101.37639 | E31: ='data processing'!E31/1000 -> 72.88725 | F31: ='data processing'!F31/1000 -> 61.976931 | G31: ='data processing'!G31/1000 -> 76.183231 | H31: ='data processing'!H31/1000 -> 77.338679 | I31: ='data processing'!I31/1000 -> 97.342965 | J31: ='data processing'!J31/1000 -> 82.943793 | ... M31: ='data processing'!M31/1000 -> 99.869837 | O31: 400
A32: Cis-13,16-Docosadiensäure | B32: Final Conc. | C32: ='data processing'!C32/1000 -> 48.476785 | D32: ='data processing'!D32/1000 -> 89.817474 | E32: ='data processing'!E32/1000 -> 1.9283764 | F32: ='data processing'!F32/1000 -> 1.9349927 | G32: ='data processing'!G32/1000 -> 1.9660056 | H32: ='data processing'!H32/1000 -> 1.9230614 | I32: ='data processing'!I32/1000 -> 1.9268451 | J32: ='data processing'!J32/1000 -> 1.9346868 | ... M32: ='data processing'!M32/1000 -> 1.9364283 | O32: 200
A33: Cis-7,10,13,16,19-Docosapentaensäure | B33: Final Conc. | C33: ='data processing'!C33/1000 -> 104.58953 | D33: ='data processing'!D33/1000 -> 29.652205 | E33: ='data processing'!E33/1000 -> 0 | F33: ='data processing'!F33/1000 -> 0.4411186 | G33: ='data processing'!G33/1000 -> 0.1649234 | H33: ='data processing'!H33/1000 -> 0.3133081 | I33: ='data processing'!I33/1000 -> 0.3713167 | J33: ='data processing'!J33/1000 -> 0 | ... M33: ='data processing'!M33/1000 -> 1.5613624
A34: Cis-4,7,10,13,16,19-Docosahexaensäure | B34: Final Conc. | C34: ='data processing'!C34/1000 -> 614.54491 | D34: ='data processing'!D34/1000 -> 76.023778 | E34: ='data processing'!E34/1000 -> 5.6614434 | F34: ='data processing'!F34/1000 -> 14.584281 | G34: ='data processing'!G34/1000 -> 12.290981 | H34: ='data processing'!H34/1000 -> 13.697815 | I34: ='data processing'!I34/1000 -> 10.348816 | J34: ='data processing'!J34/1000 -> 7.3355317 | ... M34: ='data processing'!M34/1000 -> 26.125284 | O34: 200
A35: Tetracosansäure | B35: Final Conc. | C35: ='data processing'!C35/1000 -> 1297.1528 | D35: ='data processing'!D35/1000 -> 524.26718 | E35: ='data processing'!E35/1000 -> 64.036196 | F35: ='data processing'!F35/1000 -> 98.077004 | G35: ='data processing'!G35/1000 -> 83.230082 | H35: ='data processing'!H35/1000 -> 102.85915 | I35: ='data processing'!I35/1000 -> 45.14622 | J35: ='data processing'!J35/1000 -> 0 | ... M35: ='data processing'!M35/1000 -> 98.012855 | O35: 400
A36: Cis-15-Tetracosensäure | B36: Final Conc. | C36: ='data processing'!C36/1000 -> 55.30179 | D36: ='data processing'!D36/1000 -> 9.5518737 | E36: ='data processing'!E36/1000 -> 0 | F36: ='data processing'!F36/1000 -> 0 | G36: ='data processing'!G36/1000 -> 0 | H36: ='data processing'!H36/1000 -> 0 | I36: ='data processing'!I36/1000 -> 0 | J36: ='data processing'!J36/1000 -> 0 | ... M36: ='data processing'!M36/1000 -> 0 | O36: 200

Sheet data processing
A1: FAME | B1: Data File | C1: blank230626.D | D1: MEGA-Mix_230626.D | E1: W1NC.D | F1: W1Cip.D | G1: W1Pro.D | H1: W1Mix.D | I1: W2NC.D | J1: W2Cip.D | K1: W2Pro.D | L1: W2Mix.D | M1: W3NC.D | O1: ISD( µ/ml)
A2: Octansäure | B2: Final Conc. | C2: 1799636.2 | D2: 388323.38 | E2: 8489.7928 | F2: 6711.0905 | G2: 6487.5883 | H2: 6741.9952 | I2: 6842.0343 | J2: 6918.7815 | K2: 6852.0785 | L2: 6774.8372 | M2: 6826.4772 | O2: 400
A3: Decansäure | B3: Final Conc. | C3: 1028585.4 | D3: 397350.66 | E3: 3527.8461 | F3: 0 | G3: 10972.772 | H3: 0 | I3: 1302.2846 | J3: 0 | K3: 903.363 | L3: 0 | M3: 3235.9822 | O3: 400
A4: Undecansäure | B4: Final Conc. | C4: 529322.26 | D4: 189079.34 | E4: 262.1582 | F4: 0 | G4: 1057.4169 | H4: 0 | I4: 0 | J4: 0 | K4: 0 | L4: 0 | M4: 144.809 | O4: 200
A5: Dodecansäure | B5: Final Conc. | C5: 4990947.3 | D5: 239171.44 | E5: 17347.754 | F5: 3478.9967 | G5: 24593.41 | H5: 8987.9605 | I5: 28672.792 | J5: 5647.691 | K5: 15160.02 | L5: 14250.568 | M5: 17236.231 | O5: 400
A6: Tridecansäure | B6: Final Conc. | C6: 511308.21 | D6: 114852.08 | E6: 89994.023 | F6: 76516.699 | G6: 92250.923 | H6: 108345.71 | I6: 111377.74 | J6: 95540.63 | K6: 86806.049 | L6: 85757.244 | M6: 124837.9 | O6: 200
A7: Tetradecansäure | B7: Final Conc. | C7: 402364.48 | D7: 278430.26 | E7: 260692.08 | F7: 268582.98 | G7: 280798.1 | H7: 327583.39 | I7: 226381.05 | J7: 140648.58 | K7: 186484.2 | L7: 125942.64 | M7: 285180.65 | O7: 400
A8: 9-Tetradecensäure | B8: Final Conc. | C8: 676615.02 | D8: 160808.68 | E8: 0 | F8: 0 | G8: 0 | H8: 0 | I8: 0 | J8: 6480.3132 | K8: 0 | L8: 0 | M8: 0 | O8: 200
A9: Pentadecansäure | B9: Final Conc. | C9: 209599.23 | D9: 120910.05 | E9: 11053.502 | F9: 11525.57 | G9: 16017.327 | H9: 11593.805 | I9: 13430.845 | J9: 8843.7347 | K9: 9422.083 | L9: 6539.4794 | M9: 16945.877 | O9: 200
A10: Cis-10-Pentadecensäure | B10: Final Conc. | C10: 221219.3 | D10: 154261.59 | E10: 0 | F10: 0 | G10: 0 | H10: 0 | I10: 0 | J10: 0 | K10: 0 | L10: 0 | M10: 0 | O10: 200
A11: Hexadecansäure | B11: Final Conc. | C11: 22987378 | D11: 1729003.4 | E11: 3439147 | F11: 2916731.2 | G11: 3781704.1 | H11: 3321846.3 | I11: 5445567.4 | J11: 3886066.5 | K11: 3560457.7 | L11: 2713136.9 | M11: 6027631.3 | O11: 600
A12: Cis-9-Hexadecensäure | B12: Final Conc. | C12: 385872.63 | D12: 159144.18 | E12: 412951.74 | F12: 522459.79 | G12: 399968.56 | H12: 303930.06 | I12: 866930.63 | J12: 492492.3 | K12: 685871.32 | L12: 386468.15 | M12: 145674.65 | O12: 200
A13: Heptadecansäure | B13: Final Conc. | C13: 57922.397 | D13: 151113.12 | E13: 12402.884 | F13: 8011.8439 | G13: 20891.149 | H13: 11767.879 | I13: 18850.768 | J13: 16350.447 | K13: 10118.476 | L13: 8005.5298 | M13: 23823.893 | O13: 200
... A20: Alpha-Octadecatriensäure | B20: Final Conc. | C20: 933224.88 | D20: 561725.57 | E20: 1589842.7 | F20: 1271681.7 | G20: 1884902.6 | H20: 1838937.5 | I20: 3097030.1 | J20: 2284708.6 | K20: 1489178.3 | L20: 1155060.5 | M20: 3770310.3 | O20: 200
A21: 6,9,12,15-Octadecatetraensäure | B21: Final Conc. | C21: 88191.463 | D21: 108989.08 | E21: 119443.29 | F21: 132031.42 | G21: 150352.04 | H21: 172991.76 | I21: 202405.59 | J21: 138108.11 | K21: 105359.44 | L21: 76254.628 | M21: 346012.61
A22: Eicosansäure | B22: Final Conc. | C22: 279631.78 | D22: 277855.21 | E22: 38122.47 | F22: 33025.972 | G22: 54270.93 | H22: 49371.424 | I22: 21568.108 | J22: 14882.105 | K22: 12602.02 | L22: 8772.3797 | M22: 22211.565 | O22: 400
A23: Cis-11-Eicosensäure | B23: Final Conc. | C23: 277560.3 | D23: 49463.998 | E23: 25829.834 | F23: 12245.436 | G23: 0 | H23: 15057.482 | I23: 39595.628 | J23: 134.1609 | K23: 16545.328 | L23: 13933.102 | M23: 35434.22 | O23: 200
A24: Cis-11,14-Eicosadiensäure | B24: Final Conc. | C24: 99710.073 | D24: 107133.91 | E24: 17306.898 | F24: 51282.988 | G24: 19658.987 | H24: 29563.606 | I24: 15150.45 | J24: 1362.3094 | K24: 4858.6785 | L24: 3379.4102 | M24: 17177.085 | O24: 200
A25: Cis-8,11,14-Eisocatriensäure | B25: Final Conc. | C25: 119593.18 | D25: 70996.889 | E25: 4932.2325 | F25: 10875.138 | G25: 5191.386 | H25: 10995.605 | I25: 417.3301 | J25: 401.8824 | K25: 2494.3208 | L25: 2754.7326 | M25: 422.4136 | O25: 200
A26: Cis-5,8,11,14-Eicosatetraensäure | B26: Final Conc. | C26: 1719446.7 | D26: 248026.57 | E26: 34410.478 | F26: 55359.025 | G26: 40570.802 | H26: 27035.758 | I26: 129156.07 | J26: 54570.461 | K26: 74977.004 | L26: 48937.47 | M26: 158724.22 | O26: 200
A27: Cis-11,14,17-Eicosatriensäure | B27: Final Conc. | C27: 63535.416 | D27: 78221.578 | E27: 0 | F27: 9191.7089 | G27: 7594.6672 | H27: 0 | I27: 0 | J27: 3199.9224 | K27: 5872.6006 | L27: 0 | M27: 0 | O27: 200
A28: Heneicosansäure | B28: Final Conc. | C28: 31759.214 | D28: 116402.55 | E28: 0 | F28: 0 | G28: 0 | H28: 0 | I28: 0 | J28: 0 | K28: 0 | L28: 0 | M28: 0 | O28: 200
A29: Cis-5,8,11,14,17-Eicosapentaensäure | B29: Final Conc. | C29: 331761.14 | D29: 164288.36 | E29: 93227.72 | F29: 133892.21 | G29: 140171.36 | H29: 65407.776 | I29: 274823.76 | J29: 144103.81 | K29: 188447.6 | L29: 104481.88 | M29: 329720 | O29: 200
A30: Docosansäure | B30: Final Conc. | C30: 3724427.7 | D30: 151526.76 | E30: 7749.8568 | F30: 9480.2548 | G30: 11673.013 | H30: 13934.636 | I30: 0 | J30: 3023.5838 | K30: 1256.232 | L30: 0 | M30: 6758.2188 | O30: 200
A31: 13-Docosensäure | B31: Final Conc. | C31: 175743.26 | D31: 101376.39 | E31: 72887.25 | F31: 61976.931 | G31: 76183.231 | H31: 77338.679 | I31: 97342.965 | J31: 82943.793 | K31: 60894.14 | L31: 66563.472 | M31: 99869.837 | O31: 400
A32: Cis-13,16-Docosadiensäure | B32: Final Conc. | C32: 48476.785 | D32: 89817.474 | E32: 1928.3764 | F32: 1934.9927 | G32: 1966.0056 | H32: 1923.0614 | I32: 1926.8451 | J32: 1934.6868 | K32: 1920.9329 | L32: 1933.1859 | M32: 1936.4283 | O32: 200
A33: Cis-7,10,13,16,19-Docosapentaensäure | B33: Final Conc. | C33: 104589.53 | D33: 29652.205 | E33: 0 | F33: 441.1186 | G33: 164.9234 | H33: 313.3081 | I33: 371.3167 | J33: 0 | K33: 0 | L33: 2014.5051 | M33: 1561.3624
A34: Cis-4,7,10,13,16,19-Docosahexaensäure | B34: Final Conc. | C34: 614544.91 | D34: 76023.778 | E34: 5661.4434 | F34: 14584.281 | G34: 12290.981 | H34: 13697.815 | I34: 10348.816 | J34: 7335.5317 | K34: 4445.2569 | L34: 5069.6614 | M34: 26125.284 | O34: 200
A35: Tetracosansäure | B35: Final Conc. | C35: 1297152.8 | D35: 524267.18 | E35: 64036.196 | F35: 98077.004 | G35: 83230.082 | H35: 102859.15 | I35: 45146.22 | J35: 0 | K35: 34981.727 | L35: 18754.355 | M35: 98012.855 | O35: 400
A36: Cis-15-Tetracosensäure | B36: Final Conc. | C36: 55301.79 | D36: 9551.8737 | E36: 0 | F36: 0 | G36: 0 | H36: 0 | I36: 0 | J36: 0 | K36: 0 | L36: 0 | M36: 0 | O36: 200

Sheet raw data
A5: Octansäure | B5: Data File | C5: blank230626.D | D5: MEGA-Mix_230626.D | E5: W1NC.D | F5: W1Cip.D | G5: W1Pro.D | H5: W1Mix.D | I5: W2NC.D | J5: W2Cip.D | K5: W2Pro.D | L5: W2Mix.D | M5: W3NC.D
B6: Type | C6: Blank | D6: Sample | E6: Sample | F6: Sample | G6: Sample | H6: Sample | I6: Sample | J6: Sample | K6: Sample | L6: Sample | M6: Sample
B7: ISTD | C7: Nonadecansäure | D7: Nonadecansäure | E7: Nonadecansäure | F7: Nonadecansäure | G7: Nonadecansäure | H7: Nonadecansäure | I7: Nonadecansäure | J7: Nonadecansäure | K7: Nonadecansäure | L7: Nonadecansäure | M7: Nonadecansäure
B8: RT | C8: 4.177 | D8: 4.189 | E8: 4.168 | F8: 4.185 | G8: 3.985 | H8: 4.193 | I8: 4.178 | J8: 4.196 | K8: 4.278 | L8: 4.229 | M8: 4.098
B9: Resp. | C9: 10858 | D9: 54437443 | E9: 167926 | F9: 8907 | G9: -17810 | H9: 9565 | I9: 16449 | J9: 21337 | K9: 23172 | L9: 15084 | M9: 14119
B10: ISTD Resp | C10: 3179 | D10: 74876841 | E10: 47495554 | F10: 60332207 | G10: 64043225 | H10: 46322280 | I10: 41429518 | J10: 39278730 | K10: 55678321 | L10: 56064453 | M10: 38428120
B11: RR | C11: 3.4152 | D11: 0.727 | E11: 0.0035 | F11: 0.0001 | G11: -0.0003 | H11: 0.0002 | I11: 0.0004 | J11: 0.0005 | K11: 0.0004 | L11: 0.0003 | M11: 0.0004
B12: Final Conc. | C12: 1799636.2 | D12: 388323.38 | E12: 8489.7928 | F12: 6711.0905 | G12: 6487.5883 | H12: 6741.9952 | I12: 6842.0343 | J12: 6918.7815 | K12: 6852.0785 | L12: 6774.8372 | M12: 6826.4772
A14: Decansäure | B14: Data File | C14: blank230626.D | D14: MEGA-Mix_230626.D | E14: W1NC.D | F14: W1Cip.D | G14: W1Pro.D | H14: W1Mix.D | I14: W2NC.D | J14: W2Cip.D | K14: W2Pro.D | L14: W2Mix.D | M14: W3NC.D
B15: Type | C15: Blank | D15: Sample | E15: Sample | F15: Sample | G15: Sample | H15: Sample | I15: Sample | J15: Sample | K15: Sample | L15: Sample | M15: Sample
B16: ISTD | C16: Nonadecansäure | D16: Nonadecansäure | E16: Nonadecansäure | F16: Nonadecansäure | G16: Nonadecansäure | H16: Nonadecansäure | I16: Nonadecansäure | J16: Nonadecansäure | K16: Nonadecansäure | L16: Nonadecansäure | M16: Nonadecansäure
B17: RT | C17: 5.343 | D17: 5.355 | E17: 5.339 | F17: 5.338 | G17: 5.339 | H17: 5.338 | I17: 5.331 | J17: 5.335 | K17: 5.338 | L17: 5.361 | M17: 5.338
B18: Resp. | C18: 4787 | D18: 43650384 | E18: 346651 | F18: 25578 | G18: 1164376 | H18: 93688 | I18: 167600 | J18: 25194 | K18: 192776 | L18: 28506 | M18: 264077
B19: ISTD Resp | C19: 3179 | D19: 74876841 | E19: 47495554 | F19: 60332207 | G19: 64043225 | H19: 46322280 | I19: 41429518 | J19: 39278730 | K19: 55678321 | L19: 56064453 | M19: 38428120
B20: RR | C20: 1.5057 | D20: 0.583 | E20: 0.0073 | F20: 0.0004 | G20: 0.0182 | H20: 0.002 | I20: 0.004 | J20: 0.0006 | K20: 0.0035 | L20: 0.0005 | M20: 0.0069
B21: Final Conc. | C21: 1028585.4 | D21: 397350.66 | E21: 3527.8461 | F21: 0 | G21: 10972.772 | H21: 0 | I21: 1302.2846 | J21: 0 | K21: 903.363 | L21: 0 | M21: 3235.9822
A23: Undecansäure | B23: Data File | C23: blank230626.D | D23: MEGA-Mix_230626.D | E23: W1NC.D | F23: W1Cip.D | G23: W1Pro.D | H23: W1Mix.D | I23: W2NC.D | J23: W2Cip.D | K23: W2Pro.D | L23: W2Mix.D | M23: W3NC.D
B24: Type | C24: Blank | D24: Sample | E24: Sample | F24: Sample | G24: Sample | H24: Sample | I24: Sample | J24: Sample | K24: Sample | L24: Sample | M24: Sample
B25: ISTD | C25: Nonadecansäure | D25: Nonadecansäure | E25: Nonadecansäure | F25: Nonadecansäure | G25: Nonadecansäure | H25: Nonadecansäure | I25: Nonadecansäure | J25: Nonadecansäure | K25: Nonadecansäure | L25: Nonadecansäure | M25: Nonadecansäure
B26: RT | C26: 6.157 | D26: 6.167 | E26: 6.153 | F26: 6.158 | G26: 6.154 | H26: 6.151 | I26: 6.156 | J26: 6.165 | K26: 6.151 | L26: 6.153 | M26: 6.151
B27: Resp. | C27: 4895 | D27: 41378126 | E27: 232795 | F27: 32537 | G27: 461640 | H27: 97613 | I27: 110744 | J27: 14613 | K27: 144423 | L27: 180784 | M27: 175271
B28: ISTD Resp | C28: 3179 | D28: 74876841 | E28: 47495554 | F28: 60332207 | G28: 64043225 | H28: 46322280 | I28: 41429518 | J28: 39278730 | K28: 55678321 | L28: 56064453 | M28: 38428120
B29: RR | C29: 1.5396 | D29: 0.5526 | E29: 0.0049 | F29: 0.0005 | G29: 0.0072 | H29: 0.0021 | I29: 0.0027 | J29: 0.0004 | K29: 0.0026 | L29: 0.0032 | M29: 0.0046
B30: Final Conc. | C30: 529322.26 | D30: 189079.34 | E30: 262.1582 | F30: 0 | G30: 1057.4169 | H30: 0 | I30: 0 | J30: 0 | K30: 0 | L30: 0 | M30: 144.809
A32: Dodecansäure | B32: Data File | C32: blank230626.D | D32: MEGA-Mix_230626.D | E32: W1NC.D | F32: W1Cip.D | G32: W1Pro.D | H32: W1Mix.D | I32: W2NC.D | J32: W2Cip.D | K32: W2Pro.D | L32: W2Mix.D | M32: W3NC.D
B33: Type | C33: Blank | D33: Sample | E33: Sample | F33: Sample | G33: Sample | H33: Sample | I33: Sample | J33: Sample | K33: Sample | L33: Sample | M33: Sample
B34: ISTD | C34: Nonadecansäure | D34: Nonadecansäure | E34: Nonadecansäure | F34: Nonadecansäure | G34: Nonadecansäure | H34: Nonadecansäure | I34: Nonadecansäure | J34: Nonadecansäure | K34: Nonadecansäure | L34: Nonadecansäure | M34: Nonadecansäure
B35: RT | C35: 7.257 | D35: 7.281 | E35: 7.252 | F35: 7.254 | G35: 7.252 | H35: 7.25 | I35: 7.251 | J35: 7.25 | K35: 7.251 | L35: 7.25 | M35: 7.249
B36: Resp. | C36: 261594 | D36: 304779351 | E36: 19919063 | F36: 11530723 | G36: 34496564 | H36: 13053303 | I36: 25097506 | J36: 8909017 | K36: 21345944 | L36: 20654763 | M36: 16045753
B37: ISTD Resp | C37: 3179 | D37: 74876841 | E37: 47495554 | F37: 60332207 | G37: 64043225 | H37: 46322280 | I37: 41429518 | J37: 39278730 | K37: 55678321 | L37: 56064453 | M37: 38428120
B38: RR | C38: 82.2804 | D38: 4.0704 | E38: 0.4194 | F38: 0.1911 | G38: 0.5386 | H38: 0.2818 | I38: 0.6058 | J38: 0.2268 | K38: 0.3834 | L38: 0.3684 | M38: 0.4176
B39: Final Conc. | C39: 4990947.3 | D39: 239171.44 | E39: 17347.754 | F39: 3478.9967 | G39: 24593.41 | H39: 8987.9605 | I39: 28672.792 | J39: 5647.691 | K39: 15160.02 | L39: 14250.568 | M39: 17236.231
A41: Tridecansäure | B41: Data File | C41: blank230626.D | D41: MEGA-Mix_230626.D | E41: W1NC.D | F41: W1Cip.D | G41: W1Pro.D | H41: W1Mix.D | I41: W2NC.D | J41: W2Cip.D | K41: W2Pro.D | L41: W2Mix.D | M41: W3NC.D
B42: Type | C42: Blank | D42: Sample | E42: Sample | F42: Sample | G42: Sample | H42: Sample | I42: Sample | J42: Sample | K42: Sample | L42: Sample | M42: Sample
B43: ISTD | C43: Nonadecansäure | D43: Nonadecansäure | E43: Nonadecansäure | F43: Nonadecansäure | G43: Nonadecansäure | H43: Nonadecansäure | I43: Nonadecansäure | J43: Nonadecansäure | K43: Nonadecansäure | L43: Nonadecansäure | M43: Nonadecansäure
B44: RT | C44: 9.054 | D44: 8.786 | E44: 8.755 | F44: 8.759 | G44: 8.759 | H44: 8.755 | I44: 8.754 | J44: 8.754 | K44: 8.756 | L44: 8.754 | M44: 8.754
B45: Resp. | C45: 9513 | D45: 50744773 | E45: 25295655 | F45: 27385400 | G45: 34952590 | H45: 29633569 | I45: 27236876 | J45: 22191333 | K45: 28617475 | L45: 28472663 | M45: 28283346
B46: ISTD Resp | C46: 3179 | D46: 74876841 | E46: 47495554 | F46: 60332207 | G46: 64043225 | H46: 46322280 | I46: 41429518 | J46: 39278730 | K46: 55678321 | L46: 56064453 | M46: 38428120
B47: RR | C47: 2.9922 | D47: 0.6777 | E47: 0.5326 | F47: 0.4539 | G47: 0.5458 | H47: 0.6397 | I47: 0.6574 | J47: 0.565 | K47: 0.514 | L47: 0.5079 | M47: 0.736
B48: Final Conc. | C48: 511308.21 | D48: 114852.08 | E48: 89994.023 | F48: 76516.699 | G48: 92250.923 | H48: 108345.71 | I48: 111377.74 | J48: 95540.63 | K48: 86806.049 | L48: 85757.244 | M48: 124837.9
...

Sheet 230626_FA-Quant-Report_ISTD
A1: Batch Data Path | B1: D:\MassHunter\GCMS\1\data\Sophie_Landau\230626\QuantResults\230626.batch.bin
A2: Analysis Time | B2: 45275.61 | C2: Analyst Name | D2: FLOEK026\install | E2: Report Generator Name | F2: FLOEK026\install
A3: Calibration Last Update | B3: 45154.569 | C3: Analyze Quant Version | D3: 10.1 | E3: Report Quant Version | F3: 10.2
A4: Sequence Table
A5: Data File | B5: Name | C5: Type | D5: Vial | E5: Vol. | F5: Level | G5: Acq. Method File
A6: blank230626.D | B6: blank | C6: Blank | D6: 1 | E6: 1 | G6: FAME_02_Insert
A8: MEGA-Mix_230626.D | B8: MEGA-Mix | C8: Sample | D8: 2 | E8: 1 | G8: FAME_02_Insert
A10: W1NC.D | B10: W1NC | C10: Sample | D10: 3 | E10: 1 | G10: FAME_02_Insert
A12: W1Cip.D | B12: W1Cip | C12: Sample | D12: 4 | E12: 1 | G12: FAME_02_Insert
A14: W1Pro.D | B14: W1Pro | C14: Sample | D14: 5 | E14: 1 | G14: FAME_02_Insert
A16: W1Mix.D | B16: W1Mix | C16: Sample | D16: 6 | E16: 1 | G16: FAME_02_Insert
A18: W2NC.D | B18: W2NC | C18: Sample | D18: 7 | E18: 1 | G18: FAME_02_Insert
A20: W2Cip.D | B20: W2Cip | C20: Sample | D20: 8 | E20: 1 | G20: FAME_02_Insert
A22: W2Pro.D | B22: W2Pro | C22: Sample | D22: 9 | E22: 1 | G22: FAME_02_Insert
A24: W2Mix.D | B24: W2Mix | C24: Sample | D24: 10 | E24: 1 | G24: FAME_02_Insert
A26: W3NC.D | B26: N3NC | C26: Sample | D26: 11 | E26: 1 | G26: FAME_02_Insert
A28: Octansäure
A29: Data File | B29: Type | C29: ISTD | D29: RT | E29: Resp. | F29: ISTD Resp | G29: RR | H29: Final Conc. | I29: Exp. Conc. | J29: Accuracy
A30: blank230626.D | B30: Blank | C30: Nonadecansäure | D30: 4.177 | E30: 10858 | F30: 3179 | G30: 3.4152 | H30: 1799636.2
A31: MEGA-Mix_230626.D | B31: Sample | C31: Nonadecansäure | D31: 4.189 | E31: 54437443 | F31: 74876841 | G31: 0.727 | H31: 388323.38
A32: W1NC.D | B32: Sample | C32: Nonadecansäure | D32: 4.168 | E32: 167926 | F32: 47495554 | G32: 0.0035 | H32: 8489.7928
A33: W1Cip.D | B33: Sample | C33: Nonadecansäure | D33: 4.185 | E33: 8907 | F33: 60332207 | G33: 0.0001 | H33: 6711.0905
A34: W1Pro.D | B34: Sample | C34: Nonadecansäure | D34: 3.985 | E34: -17810 | F34: 64043225 | G34: -0.0003 | H34: 6487.5883
A35: W1Mix.D | B35: Sample | C35: Nonadecansäure | D35: 4.193 | E35: 9565 | F35: 46322280 | G35: 0.0002 | H35: 6741.9952
A36: W2NC.D | B36: Sample | C36: Nonadecansäure | D36: 4.178 | E36: 16449 | F36: 41429518 | G36: 0.0004 | H36: 6842.0343
A37: W2Cip.D | B37: Sample | C37: Nonadecansäure | D37: 4.196 | E37: 21337 | F37: 39278730 | G37: 0.0005 | H37: 6918.7815
A38: W2Pro.D | B38: Sample | C38: Nonadecansäure | D38: 4.278 | E38: 23172 | F38: 55678321 | G38: 0.0004 | H38: 6852.0785
A39: W2Mix.D | B39: Sample | C39: Nonadecansäure | D39: 4.229 | E39: 15084 | F39: 56064453 | G39: 0.0003 | H39: 6774.8372
A40: W3NC.D | B40: Sample | C40: Nonadecansäure | D40: 4.098 | E40: 14119 | F40: 38428120 | G40: 0.0004 | H40: 6826.4772
A41: Decansäure
A42: Data File | B42: Type | C42: ISTD | D42: RT | E42: Resp. | F42: ISTD Resp | G42: RR | H42: Final Conc. | I42: Exp. Conc. | J42: Accuracy
A43: blank230626.D | B43: Blank | C43: Nonadecansäure | D43: 5.343 | E43: 4787 | F43: 3179 | G43: 1.5057 | H43: 1028585.4
A44: MEGA-Mix_230626.D | B44: Sample | C44: Nonadecansäure | D44: 5.355 | E44: 43650384 | F44: 74876841 | G44: 0.583 | H44: 397350.66
A45: W1NC.D | B45: Sample | C45: Nonadecansäure | D45: 5.339 | E45: 346651 | F45: 47495554 | G45: 0.0073 | H45: 3527.8461
A46: W1Cip.D | B46: Sample | C46: Nonadecansäure | D46: 5.338 | E46: 25578 | F46: 60332207 | G46: 0.0004 | H46: 0
A47: W1Pro.D | B47: Sample | C47: Nonadecansäure | D47: 5.339 | E47: 1164376 | F47: 64043225 | G47: 0.0182 | H47: 10972.772
A48: W1Mix.D | B48: Sample | C48: Nonadecansäure | D48: 5.338 | E48: 93688 | F48: 46322280 | G48: 0.002 | H48: 0
A49: W2NC.D | B49: Sample | C49: Nonadecansäure | D49: 5.331 | E49: 167600 | F49: 41429518 | G49: 0.004 | H49: 1302.2846
A50: W2Cip.D | B50: Sample | C50: Nonadecansäure | D50: 5.335 | E50: 25194 | F50: 39278730 | G50: 0.0006 | H50: 0
A51: W2Pro.D | B51: Sample | C51: Nonadecansäure | D51: 5.338 | E51: 192776 | F51: 55678321 | G51: 0.0035 | H51: 903.363
...
