Workbook

Sheet aufgeräumt
A1: FAME (µg/sample) | B1: FAME (µg/sample) | C1: W3Cip.D | D1: W3Mix.D | E1: Cip2.D | F1: Cip3.D | G1: Cip4.D | H1: Cip18.D | I1: Cip6.D | J1: Cip7.D | K1: Cip16.D | L1: Cip19.D | M1: Cip11.D | N1: Cip14.D | O1: Blank1.D
A2: Octansäure | B2: C08:0 | C2: 6.884514 | D2: 7.0170779 | E2: 6.6740167 | F2: 6.7009608 | G2: 6.9302637 | H2: 7.0599457 | I2: 6.701084 | J2: 6.7255191 | K2: 6.7232432 | L2: 6.8768636 | M2: 6.7338295 | N2: 6.8677396 | O2: 6.7065411
A3: Decansäure | B3: C10:0 | C3: 4.1247162 | D3: 0 | E3: 0 | F3: 0 | G3: 0 | H3: 0 | I3: 0 | J3: 0 | K3: 0 | L3: 0 | M3: 1.5662897 | N3: 1.0888094 | O3: 4.5137455
A4: Undecansäure | B4: C11:0 | C4: ND | D4: ND | E4: ND | F4: ND | G4: ND | H4: ND | I4: ND | J4: ND | K4: ND | L4: ND | M4: ND | N4: ND | O4: 0.5605737
A5: Dodecansäure | B5: C12:0 | C5: 14.241061 | D5: 14.062033 | E5: 3.9211512 | F5: 1.8041423 | G5: 0 | H5: 2.4583841 | I5: 1.1361461 | J5: 16.954508 | K5: 7.192426 | L5: 5.7644689 | M5: 15.172462 | N5: 16.68453 | O5: 16.079607
A6: Tridecansäure | B6: C13:0 | C6: 116.72914 | D6: 104.66005 | E6: 76.050123 | F6: 71.632268 | G6: 58.130237 | H6: 74.712325 | I6: 71.046942 | J6: 98.337983 | K6: 89.01608 | L6: 80.76472 | M6: 96.950538 | N6: 100.95884 | O6: 104.06352
A7: Tetradecansäure | B7: C14:0 | C7: 307.14897 | D7: 228.45541 | E7: 79.314416 | F7: 44.227004 | G7: 66.694819 | H7: 54.893558 | I7: 66.590007 | J7: 111.37035 | K7: 56.979878 | L7: 76.653051 | M7: 90.80816 | N7: 84.719422 | O7: 28.730075
A8: 9-Tetradecensäure | B8: C14:1 | C8: 0 | D8: 0 | E8: 0 | F8: 0 | G8: 0 | H8: 0 | I8: 1.2378943 | J8: 0 | K8: 0 | L8: 0 | M8: 0 | N8: 0 | O8: 0
A9: Pentadecansäure | B9: C15:0 | C9: 15.876937 | D9: 18.218657 | E9: 14.399843 | F9: 11.750371 | G9: 12.735333 | H9: 6.449668 | I9: 10.521298 | J9: 19.481495 | K9: 9.3105071 | L9: 13.141642 | M9: 11.251206 | N9: 14.583758 | O9: 6.547856
A10: Cis-10-Pentadecensäure | B10: C15:1 | C10: 0 | D10: 3.6164395 | E10: 0 | F10: 0 | G10: 0 | H10: 0 | I10: 0 | J10: 0 | K10: 0 | L10: 0 | M10: 0 | N10: 0 | O10: 0
A11: Hexadecansäure | B11: C16:0 | C11: 5408.4227 | D11: 7135.8009 | E11: 2314.9184 | F11: 1889.5194 | G11: 2400.2797 | H11: 2264.3087 | I11: 2176.9347 | J11: 2738.568 | K11: 1936.7175 | L11: 2267.1542 | M11: 2681.835 | N11: 2450.7074 | O11: 1489.3189
A12: Cis-9-Hexadecensäure | B12: C16:1 | C12: 949.72925 | D12: 672.07827 | E12: 267.76593 | F12: 76.218546 | G12: 235.98604 | H12: 264.58079 | I12: 206.18112 | J12: 347.50974 | K12: 159.33959 | L12: 292.75304 | M12: 418.1409 | N12: 323.61404 | O12: 0
A13: Heptadecansäure | B13: C17:0 | C13: 17.226616 | D13: 34.639677 | E13: 20.27114 | F13: 14.551685 | G13: 19.930199 | H13: 15.71155 | I13: 16.219138 | J13: 25.551999 | K13: 12.34731 | L13: 15.849215 | M13: 16.984159 | N13: 18.090706 | O13: 3.3850266
A14: Cis-10-Heptadecensäure | B14: C17:1 | C14: 20.971489 | D14: 35.866235 | E14: 0 | F14: 0 | G14: 0 | H14: 0 | I14: ND | J14: 0 | K14: 0 | L14: 0.539097 | M14: 0 | N14: ND | O14: ND
A15: Octadecansäure | B15: C18:0 | C15: 543.79472 | D15: 645.73957 | E15: 479.3803 | F15: 426.28469 | G15: 508.78927 | H15: 466.2344 | I15: 464.62921 | J15: 549.42977 | K15: 442.89498 | L15: 466.5122 | M15: 510.02375 | N15: 501.55448 | O15: 448.63464
A16: Cis-9-Octadecensäure | B16: C18:1 | C16: 1955.7333 | D16: 2472.5267 | E16: 410.53134 | F16: 285.97257 | G16: 398.91752 | H16: 323.44557 | I16: 393.18045 | J16: 477.99272 | K16: 335.34007 | L16: 336.10576 | M16: 433.00921 | N16: 484.74814 | O16: 16.423912
A17: Octadeca-9,12-diensäure (trans) | B17: C18:2(n-6t) | C17: 0 | D17: 3.7790925 | E17: 1.4892816 | F17: 0.3485468 | G17: 0.3485753 | H17: 0.2441129 | I17: 0.5552832 | J17: 1.9112914 | K17: 0.3407386 | L17: 0.2944635 | M17: 2.2944055 | N17: 0.1108309 | O17: 0.3319534
A18: Octadeca-9,12-diensäure (cis) | B18: C18:2(n-6c) | C18: 1913.5384 | D18: 2318.1243 | E18: 196.64122 | F18: 112.63554 | G18: 201.41717 | H18: 174.77679 | I18: 147.41456 | J18: 286.14592 | K18: 117.20801 | L18: 153.96691 | M18: 231.05648 | N18: 258.65551 | O18: 6.0034596
A19: Gamma-Octadecatriensäure | B19: C18:3(n-6) | C19: 157.53268 | D19: 0 | E19: 0.4872043 | F19: 0.2493268 | G19: ND | H19: 0.2375764 | I19: 0.1009045 | J19: 0 | K19: 0.1309809 | L19: 0 | M19: 22.888522 | N19: 0 | O19: 0
A20: Alpha-Octadecatriensäure | B20: C18:3(n-3) | C20: 3321.1106 | D20: 4662.239 | E20: 171.92456 | F20: 81.385994 | G20: 177.07674 | H20: 108.25915 | I20: 108.1641 | J20: 274.66328 | K20: 88.699407 | L20: 117.57209 | M20: 225.5953 | N20: 264.73479 | O20: 1.9379754
A21: 6,9,12,15-Octadecatetraensäure | B21: C18:4(n-3) | C21: 322.1213 | D21: 435.78198 | E21: 7.9447387 | F21: 0.4786554 | G21: 9.7597838 | H21: 0.2971872 | I21: 0.6644373 | J21: 16.514242 | K21: 0.7501133 | L21: 10.186508 | M21: 18.420323 | N21: 12.528589 | O21: 0.2145091
A22: Eicosansäure | B22: C20:0 | C22: 28.789515 | D22: 27.809502 | E22: 1.3960406 | F22: 1.8113054 | G22: 6.3919607 | H22: 1.6299003 | I22: 1.6217752 | J22: 1.69143 | K22: 1.6099726 | L22: 2.4318781 | M22: 1.6016769 | N22: 1.7239437 | O22: 8.752849
A23: Cis-11-Eicosensäure | B23: C20:1 | C23: 29.800345 | D23: 40.924457 | E23: 10.101382 | F23: 7.4938227 | G23: 8.7549446 | H23: 0.0940871 | I23: 10.371822 | J23: 16.010991 | K23: 8.6810986 | L23: 0.2565368 | M23: 7.7440866 | N23: 15.196998 | O23: 0.1493779
A24: Cis-11,14-Eicosadiensäure | B24: C20:2(n-6) | C24: 19.851863 | D24: 11.014298 | E24: 29.199633 | F24: 14.909966 | G24: 26.735095 | H24: 33.724539 | I24: 13.381612 | J24: 38.918844 | K24: 13.280418 | L24: 16.474373 | M24: 29.200895 | N24: 36.381874 | O24: 0.2437476
A25: Cis-8,11,14-Eisocatriensäure | B25: C20:3(n-6) | C25: 4.6745024 | D25: 0.4264854 | E25: 0.6535427 | F25: 0.4315314 | G25: ND | H25: 0.4193009 | I25: 0.4120068 | J25: 0.915577 | K25: 14.096273 | L25: 0.4255577 | M25: 1.2008975 | N25: 0.2907852 | O25: 0.4401581
A26: Cis-5,8,11,14-Eicosatetraensäure | B26: C20:4(n-6) | C26: 112.97919 | D26: 70.75697 | E26: 205.33235 | F26: 114.39899 | G26: 201.34779 | H26: 210.16844 | I26: 101.86173 | J26: 263.19871 | K26: 91.994642 | L26: 140.12785 | M26: 252.48779 | N26: 216.86235 | O26: 0.5801763
A27: Cis-11,14,17-Eicosatriensäure | B27: C20:3(n-3) | C27: ND | D27: 3.9305622 | E27: ND | F27: ND | G27: ND | H27: ND | I27: ND | J27: 9.8058728 | K27: ND | L27: ND | M27: 8.6348212 | N27: ND | O27: ND
A28: Heneicosansäure | B28: C21:0 | C28: 0 | D28: 0 | E28: 0 | F28: 0 | G28: 0 | H28: 0 | I28: 0 | J28: 0 | K28: 0 | L28: 0 | M28: 0 | N28: 0 | O28: 0.0007524
A29: Cis-5,8,11,14,17-Eicosapentaensäure | B29: C20:5(n-3) | C29: 294.62663 | D29: 245.77713 | E29: 176.33223 | F29: 102.39941 | G29: 178.77904 | H29: 175.02228 | I29: 109.08123 | J29: 213.88311 | K29: 98.28417 | L29: 155.76381 | M29: 240.54605 | N29: 190.06238 | O29: 0.535825
A30: Docosansäure | B30: C22:0 | C30: 1.5882031 | D30: 8.0548824 | E30: 0 | F30: 0 | G30: 0 | H30: 0 | I30: 0 | J30: 0 | K30: 0 | L30: 0 | M30: 0 | N30: 0 | O30: 0
A31: 13-Docosensäure | B31: C22:1 | C31: 94.49607 | D31: 156.7944 | E31: 121.65281 | F31: 109.03916 | G31: 122.68979 | H31: 99.914846 | I31: 117.46671 | J31: 116.80064 | K31: 119.90831 | L31: 118.86794 | M31: 107.96056 | N31: 120.52015 | O31: 165.91263
A32: Cis-13,16-Docosadiensäure | B32: C22:2 | C32: 1.9322348 | D32: 1.9360178 | E32: 1.9353707 | F32: 1.9337981 | G32: 1.9588975 | H32: 1.9156862 | I32: 1.875428 | J32: 1.9571567 | K32: 1.972998 | L32: 1.9537872 | M32: 7.4573211 | N32: 1.9489389 | O32: 1.9244387
A33: Cis-7,10,13,16,19-Docosapentaensäure | B33: C22:5(n-3) | C33: 0.7963374 | D33: 0.1548988 | E33: 6.9613173 | F33: 2.340826 | G33: 5.0671295 | H33: 5.3807233 | I33: 2.654284 | J33: 7.7411357 | K33: 2.6072953 | L33: 4.3420641 | M33: 7.6749007 | N33: 6.7048836 | O33: 0
A34: Cis-4,7,10,13,16,19-Docosahexaensäure | B34: C22:6(n-3) | C34: 17.029595 | D34: 12.651214 | E34: 6.4502671 | F34: 1.0731942 | G34: 4.9528833 | H34: 5.8417789 | I34: 1.7200402 | J34: 8.2331139 | K34: 0.4985818 | L34: 2.4813516 | M34: 6.7180199 | N34: 4.7687079 | O34: 0
A35: Tetracosansäure | B35: C24:0 | C35: 108.88773 | D35: 151.09801 | E35: 12.646934 | F35: 9.0722939 | G35: 13.239547 | H35: 0 | I35: 0 | J35: 0 | K35: 0 | L35: 14.399121 | M35: 10.869473 | N35: 13.146673 | O35: 6.9332251
A36: Cis-15-Tetracosensäure | B36: C24:1 | C36: 0 | D36: 0 | E36: 0 | F36: 0 | G36: 0 | H36: 0 | I36: 0 | J36: 0 | K36: 0 | L36: 0 | M36: 0 | N36: 0 | O36: 0

Sheet µg statt ng
A1: FAME | B1: Data File | C1: blank230627.D | D1: MEGA-Mix_230627.D | E1: W3Cip.D | F1: W3Mix.D | G1: Cip2.D | H1: Cip3.D | I1: Cip4.D | J1: Cip18.D | K1: Cip6.D | L1: Cip7.D | M1: Cip16.D | N1: Cip19.D | O1: Cip11.D | P1: Cip14.D | Q1: Blank1.D | S1: ISD( µ/ml)
A2: Octansäure | B2: Final Conc. | C2: ='data processing'!C2/1000 -> 3702.0867 | D2: ='data processing'!D2/1000 -> 392.86468 | E2: ='data processing'!E2/1000 -> 6.884514 | F2: ='data processing'!F2/1000 -> 7.0170779 | G2: ='data processing'!G2/1000 -> 6.6740167 | H2: ='data processing'!H2/1000 -> 6.7009608 | I2: ='data processing'!I2/1000 -> 6.9302637 | J2: ='data processing'!J2/1000 -> 7.0599457 | ... Q2: ='data processing'!Q2/1000 -> 6.7065411 | S2: 400
A3: Decansäure | B3: Final Conc. | C3: ='data processing'!C3/1000 -> 1723.2191 | D3: ='data processing'!D3/1000 -> 391.47517 | E3: ='data processing'!E3/1000 -> 4.1247162 | F3: ='data processing'!F3/1000 -> 0 | G3: ='data processing'!G3/1000 -> 0 | H3: ='data processing'!H3/1000 -> 0 | I3: ='data processing'!I3/1000 -> 0 | J3: ='data processing'!J3/1000 -> 0 | ... Q3: ='data processing'!Q3/1000 -> 4.5137455 | S3: 400
A4: Undecansäure | B4: Final Conc. | C4: ='data processing'!C4/1000 -> 620.35487 | D4: ='data processing'!D4/1000 -> 190.40695 | E4: ='data processing'!E4/1000 -> 0 | F4: ='data processing'!F4/1000 -> 0 | G4: ='data processing'!G4/1000 -> 0 | H4: ='data processing'!H4/1000 -> 0 | I4: ='data processing'!I4/1000 -> 0 | J4: ='data processing'!J4/1000 -> 0 | ... Q4: ='data processing'!Q4/1000 -> 0.5605737 | S4: 200
A5: Dodecansäure | B5: Final Conc. | C5: ='data processing'!C5/1000 -> 147.51713 | D5: ='data processing'!D5/1000 -> 251.07344 | E5: ='data processing'!E5/1000 -> 14.241061 | F5: ='data processing'!F5/1000 -> 14.062033 | G5: ='data processing'!G5/1000 -> 3.9211512 | H5: ='data processing'!H5/1000 -> 1.8041423 | I5: ='data processing'!I5/1000 -> 0 | J5: ='data processing'!J5/1000 -> 2.4583841 | ... Q5: ='data processing'!Q5/1000 -> 16.079607 | S5: 400
A6: Tridecansäure | B6: Final Conc. | C6: ='data processing'!C6/1000 -> 957.53869 | D6: ='data processing'!D6/1000 -> 110.37287 | E6: ='data processing'!E6/1000 -> 116.72914 | F6: ='data processing'!F6/1000 -> 104.66005 | G6: ='data processing'!G6/1000 -> 76.050123 | H6: ='data processing'!H6/1000 -> 71.632268 | I6: ='data processing'!I6/1000 -> 58.130237 | J6: ='data processing'!J6/1000 -> 74.712325 | ... Q6: ='data processing'!Q6/1000 -> 104.06352 | S6: 200
A7: Tetradecansäure | B7: Final Conc. | C7: ='data processing'!C7/1000 -> 167.71359 | D7: ='data processing'!D7/1000 -> 282.21616 | E7: ='data processing'!E7/1000 -> 307.14897 | F7: ='data processing'!F7/1000 -> 228.45541 | G7: ='data processing'!G7/1000 -> 79.314416 | H7: ='data processing'!H7/1000 -> 44.227004 | I7: ='data processing'!I7/1000 -> 66.694819 | J7: ='data processing'!J7/1000 -> 54.893558 | ... Q7: ='data processing'!Q7/1000 -> 28.730075 | S7: 400
A8: 9-Tetradecensäure | B8: Final Conc. | C8: ='data processing'!C8/1000 -> 982.32716 | D8: ='data processing'!D8/1000 -> 159.97267 | E8: ='data processing'!E8/1000 -> 0 | F8: ='data processing'!F8/1000 -> 0 | G8: ='data processing'!G8/1000 -> 0 | H8: ='data processing'!H8/1000 -> 0 | I8: ='data processing'!I8/1000 -> 0 | J8: ='data processing'!J8/1000 -> 0 | ... Q8: ='data processing'!Q8/1000 -> 0 | S8: 200
A9: Pentadecansäure | B9: Final Conc. | C9: ='data processing'!C9/1000 -> 1251.1856 | D9: ='data processing'!D9/1000 -> 121.3352 | E9: ='data processing'!E9/1000 -> 15.876937 | F9: ='data processing'!F9/1000 -> 18.218657 | G9: ='data processing'!G9/1000 -> 14.399843 | H9: ='data processing'!H9/1000 -> 11.750371 | I9: ='data processing'!I9/1000 -> 12.735333 | J9: ='data processing'!J9/1000 -> 6.449668 | ... Q9: ='data processing'!Q9/1000 -> 6.547856 | S9: 200
A10: Cis-10-Pentadecensäure | B10: Final Conc. | C10: ='data processing'!C10/1000 -> 1379.2556 | D10: ='data processing'!D10/1000 -> 155.66184 | E10: ='data processing'!E10/1000 -> 0 | F10: ='data processing'!F10/1000 -> 3.6164395 | G10: ='data processing'!G10/1000 -> 0 | H10: ='data processing'!H10/1000 -> 0 | I10: ='data processing'!I10/1000 -> 0 | J10: ='data processing'!J10/1000 -> 0 | ... Q10: ='data processing'!Q10/1000 -> 0 | S10: 200
A11: Hexadecansäure | B11: Final Conc. | C11: ='data processing'!C11/1000 -> 642.5558 | D11: ='data processing'!D11/1000 -> 1770.645 | E11: ='data processing'!E11/1000 -> 5408.4227 | F11: ='data processing'!F11/1000 -> 7135.8009 | G11: ='data processing'!G11/1000 -> 2314.9184 | H11: ='data processing'!H11/1000 -> 1889.5194 | I11: ='data processing'!I11/1000 -> 2400.2797 | J11: ='data processing'!J11/1000 -> 2264.3087 | ... Q11: ='data processing'!Q11/1000 -> 1489.3189 | S11: 600
A12: Cis-9-Hexadecensäure | B12: Final Conc. | C12: ='data processing'!C12/1000 -> 138.85238 | D12: ='data processing'!D12/1000 -> 158.57154 | E12: ='data processing'!E12/1000 -> 949.72925 | F12: ='data processing'!F12/1000 -> 672.07827 | G12: ='data processing'!G12/1000 -> 267.76593 | H12: ='data processing'!H12/1000 -> 76.218546 | I12: ='data processing'!I12/1000 -> 235.98604 | J12: ='data processing'!J12/1000 -> 264.58079 | ... Q12: ='data processing'!Q12/1000 -> 0 | S12: 200
A13: Heptadecansäure | B13: Final Conc. | C13: ='data processing'!C13/1000 -> 127.41549 | D13: ='data processing'!D13/1000 -> 149.9415 | E13: ='data processing'!E13/1000 -> 17.226616 | F13: ='data processing'!F13/1000 -> 34.639677 | G13: ='data processing'!G13/1000 -> 20.27114 | H13: ='data processing'!H13/1000 -> 14.551685 | I13: ='data processing'!I13/1000 -> 19.930199 | J13: ='data processing'!J13/1000 -> 15.71155 | ... Q13: ='data processing'!Q13/1000 -> 3.3850266 | S13: 200
... A20: Alpha-Octadecatriensäure | B20: Final Conc. | C20: ='data processing'!C20/1000 -> 4244.4321 | D20: ='data processing'!D20/1000 -> 566.87598 | E20: ='data processing'!E20/1000 -> 3321.1106 | F20: ='data processing'!F20/1000 -> 4662.239 | G20: ='data processing'!G20/1000 -> 171.92456 | H20: ='data processing'!H20/1000 -> 81.385994 | I20: ='data processing'!I20/1000 -> 177.07674 | J20: ='data processing'!J20/1000 -> 108.25915 | ... Q20: ='data processing'!Q20/1000 -> 1.9379754 | S20: 200
A21: 6,9,12,15-Octadecatetraensäure | B21: Final Conc. | C21: ='data processing'!C21/1000 -> 2149.8474 | D21: ='data processing'!D21/1000 -> 111.99468 | E21: ='data processing'!E21/1000 -> 322.1213 | F21: ='data processing'!F21/1000 -> 435.78198 | G21: ='data processing'!G21/1000 -> 7.9447387 | H21: ='data processing'!H21/1000 -> 0.4786554 | I21: ='data processing'!I21/1000 -> 9.7597838 | J21: ='data processing'!J21/1000 -> 0.2971872 | ... Q21: ='data processing'!Q21/1000 -> 0.2145091
A22: Eicosansäure | B22: Final Conc. | C22: ='data processing'!C22/1000 -> 3796.9198 | D22: ='data processing'!D22/1000 -> 284.98399 | E22: ='data processing'!E22/1000 -> 28.789515 | F22: ='data processing'!F22/1000 -> 27.809502 | G22: ='data processing'!G22/1000 -> 1.3960406 | H22: ='data processing'!H22/1000 -> 1.8113054 | I22: ='data processing'!I22/1000 -> 6.3919607 | J22: ='data processing'!J22/1000 -> 1.6299003 | ... Q22: ='data processing'!Q22/1000 -> 8.752849 | S22: 400
A23: Cis-11-Eicosensäure | B23: Final Conc. | C23: ='data processing'!C23/1000 -> 721.18045 | D23: ='data processing'!D23/1000 -> 51.192596 | E23: ='data processing'!E23/1000 -> 29.800345 | F23: ='data processing'!F23/1000 -> 40.924457 | G23: ='data processing'!G23/1000 -> 10.101382 | H23: ='data processing'!H23/1000 -> 7.4938227 | I23: ='data processing'!I23/1000 -> 8.7549446 | J23: ='data processing'!J23/1000 -> 0.0940871 | ... Q23: ='data processing'!Q23/1000 -> 0.1493779 | S23: 200
A24: Cis-11,14-Eicosadiensäure | B24: Final Conc. | C24: ='data processing'!C24/1000 -> 125.44738 | D24: ='data processing'!D24/1000 -> 107.08246 | E24: ='data processing'!E24/1000 -> 19.851863 | F24: ='data processing'!F24/1000 -> 11.014298 | G24: ='data processing'!G24/1000 -> 29.199633 | H24: ='data processing'!H24/1000 -> 14.909966 | I24: ='data processing'!I24/1000 -> 26.735095 | J24: ='data processing'!J24/1000 -> 33.724539 | ... Q24: ='data processing'!Q24/1000 -> 0.2437476 | S24: 200
A25: Cis-8,11,14-Eisocatriensäure | B25: Final Conc. | C25: ='data processing'!C25/1000 -> 223.91128 | D25: ='data processing'!D25/1000 -> 73.358256 | E25: ='data processing'!E25/1000 -> 4.6745024 | F25: ='data processing'!F25/1000 -> 0.4264854 | G25: ='data processing'!G25/1000 -> 0.6535427 | H25: ='data processing'!H25/1000 -> 0.4315314 | I25: ='data processing'!I25/1000 -> #VALUE! | J25: ='data processing'!J25/1000 -> 0.4193009 | ... Q25: ='data processing'!Q25/1000 -> 0.4401581 | S25: 200
A26: Cis-5,8,11,14-Eicosatetraensäure | B26: Final Conc. | C26: ='data processing'!C26/1000 -> 981.53201 | D26: ='data processing'!D26/1000 -> 259.31243 | E26: ='data processing'!E26/1000 -> 112.97919 | F26: ='data processing'!F26/1000 -> 70.75697 | G26: ='data processing'!G26/1000 -> 205.33235 | H26: ='data processing'!H26/1000 -> 114.39899 | I26: ='data processing'!I26/1000 -> 201.34779 | J26: ='data processing'!J26/1000 -> 210.16844 | ... Q26: ='data processing'!Q26/1000 -> 0.5801763 | S26: 200
A27: Cis-11,14,17-Eicosatriensäure | B27: Final Conc. | C27: ='data processing'!C27/1000 -> 132.59332 | D27: ='data processing'!D27/1000 -> 80.45391 | E27: ='data processing'!E27/1000 -> #VALUE! | F27: ='data processing'!F27/1000 -> 3.9305622 | G27: ='data processing'!G27/1000 -> #VALUE! | H27: ='data processing'!H27/1000 -> #VALUE! | I27: ='data processing'!I27/1000 -> #VALUE! | J27: ='data processing'!J27/1000 -> #VALUE! | ... Q27: ='data processing'!Q27/1000 -> #VALUE! | S27: 200
A28: Heneicosansäure | B28: Final Conc. | C28: ='data processing'!C28/1000 -> 48.157496 | D28: ='data processing'!D28/1000 -> 121.96037 | E28: ='data processing'!E28/1000 -> 0 | F28: ='data processing'!F28/1000 -> 0 | G28: ='data processing'!G28/1000 -> 0 | H28: ='data processing'!H28/1000 -> 0 | I28: ='data processing'!I28/1000 -> 0 | J28: ='data processing'!J28/1000 -> 0 | ... Q28: ='data processing'!Q28/1000 -> 0.0007524 | S28: 200
A29: Cis-5,8,11,14,17-Eicosapentaensäure | B29: Final Conc. | C29: ='data processing'!C29/1000 -> 273.9628 | D29: ='data processing'!D29/1000 -> 175.722 | E29: ='data processing'!E29/1000 -> 294.62663 | F29: ='data processing'!F29/1000 -> 245.77713 | G29: ='data processing'!G29/1000 -> 176.33223 | H29: ='data processing'!H29/1000 -> 102.39941 | I29: ='data processing'!I29/1000 -> 178.77904 | J29: ='data processing'!J29/1000 -> 175.02228 | ... Q29: ='data processing'!Q29/1000 -> 0.535825 | S29: 200
A30: Docosansäure | B30: Final Conc. | C30: ='data processing'!C30/1000 -> 1129.657 | D30: ='data processing'!D30/1000 -> 163.69427 | E30: ='data processing'!E30/1000 -> 1.5882031 | F30: ='data processing'!F30/1000 -> 8.0548824 | G30: ='data processing'!G30/1000 -> 0 | H30: ='data processing'!H30/1000 -> 0 | I30: ='data processing'!I30/1000 -> 0 | J30: ='data processing'!J30/1000 -> 0 | ... Q30: ='data processing'!Q30/1000 -> 0 | S30: 200
A31: 13-Docosensäure | B31: Final Conc. | C31: ='data processing'!C31/1000 -> 225.40664 | D31: ='data processing'!D31/1000 -> 111.21599 | E31: ='data processing'!E31/1000 -> 94.49607 | F31: ='data processing'!F31/1000 -> 156.7944 | G31: ='data processing'!G31/1000 -> 121.65281 | H31: ='data processing'!H31/1000 -> 109.03916 | I31: ='data processing'!I31/1000 -> 122.68979 | J31: ='data processing'!J31/1000 -> 99.914846 | ... Q31: ='data processing'!Q31/1000 -> 165.91263 | S31: 400
A32: Cis-13,16-Docosadiensäure | B32: Final Conc. | C32: ='data processing'!C32/1000 -> 168.18516 | D32: ='data processing'!D32/1000 -> 98.278121 | E32: ='data processing'!E32/1000 -> 1.9322348 | F32: ='data processing'!F32/1000 -> 1.9360178 | G32: ='data processing'!G32/1000 -> 1.9353707 | H32: ='data processing'!H32/1000 -> 1.9337981 | I32: ='data processing'!I32/1000 -> 1.9588975 | J32: ='data processing'!J32/1000 -> 1.9156862 | ... Q32: ='data processing'!Q32/1000 -> 1.9244387 | S32: 200
A33: Cis-7,10,13,16,19-Docosapentaensäure | B33: Final Conc. | C33: ='data processing'!C33/1000 -> 1254.4492 | D33: ='data processing'!D33/1000 -> 33.783535 | E33: ='data processing'!E33/1000 -> 0.7963374 | F33: ='data processing'!F33/1000 -> 0.1548988 | G33: ='data processing'!G33/1000 -> 6.9613173 | H33: ='data processing'!H33/1000 -> 2.340826 | I33: ='data processing'!I33/1000 -> 5.0671295 | J33: ='data processing'!J33/1000 -> 5.3807233 | ... Q33: ='data processing'!Q33/1000 -> 0
A34: Cis-4,7,10,13,16,19-Docosahexaensäure | B34: Final Conc. | C34: ='data processing'!C34/1000 -> 1363.9878 | D34: ='data processing'!D34/1000 -> 85.385164 | E34: ='data processing'!E34/1000 -> 17.029595 | F34: ='data processing'!F34/1000 -> 12.651214 | G34: ='data processing'!G34/1000 -> 6.4502671 | H34: ='data processing'!H34/1000 -> 1.0731942 | I34: ='data processing'!I34/1000 -> 4.9528833 | J34: ='data processing'!J34/1000 -> 5.8417789 | ... Q34: ='data processing'!Q34/1000 -> 0 | S34: 200
A35: Tetracosansäure | B35: Final Conc. | C35: ='data processing'!C35/1000 -> 1498.0662 | D35: ='data processing'!D35/1000 -> 594.69358 | E35: ='data processing'!E35/1000 -> 108.88773 | F35: ='data processing'!F35/1000 -> 151.09801 | G35: ='data processing'!G35/1000 -> 12.646934 | H35: ='data processing'!H35/1000 -> 9.0722939 | I35: ='data processing'!I35/1000 -> 13.239547 | J35: ='data processing'!J35/1000 -> 0 | ... Q35: ='data processing'!Q35/1000 -> 6.9332251 | S35: 400
A36: Cis-15-Tetracosensäure | B36: Final Conc. | C36: ='data processing'!C36/1000 -> 1934.8481 | D36: ='data processing'!D36/1000 -> 11.287789 | E36: ='data processing'!E36/1000 -> 0 | F36: ='data processing'!F36/1000 -> 0 | G36: ='data processing'!G36/1000 -> 0 | H36: ='data processing'!H36/1000 -> 0 | I36: ='data processing'!I36/1000 -> 0 | J36: ='data processing'!J36/1000 -> 0 | ... Q36: ='data processing'!Q36/1000 -> 0 | S36: 200

Sheet data processing
A1: FAME | B1: Data File | C1: blank230627.D | D1: MEGA-Mix_230627.D | E1: W3Cip.D | F1: W3Mix.D | G1: Cip2.D | H1: Cip3.D | I1: Cip4.D | J1: Cip18.D | K1: Cip6.D | L1: Cip7.D | M1: Cip16.D | N1: Cip19.D | O1: Cip11.D | P1: Cip14.D | Q1: Blank1.D | S1: ISD( µ/ml)
A2: Octansäure | B2: Final Conc. | C2: 3702086.7 | D2: 392864.68 | E2: 6884.514 | F2: 7017.0779 | G2: 6674.0167 | H2: 6700.9608 | I2: 6930.2637 | J2: 7059.9457 | K2: 6701.084 | L2: 6725.5191 | M2: 6723.2432 | N2: 6876.8636 | O2: 6733.8295 | P2: 6867.7396 | Q2: 6706.5411 | S2: 400
A3: Decansäure | B3: Final Conc. | C3: 1723219.1 | D3: 391475.17 | E3: 4124.7162 | F3: 0 | G3: 0 | H3: 0 | I3: 0 | J3: 0 | K3: 0 | L3: 0 | M3: 0 | N3: 0 | O3: 1566.2897 | P3: 1088.8094 | Q3: 4513.7455 | S3: 400
A4: Undecansäure | B4: Final Conc. | C4: 620354.87 | D4: 190406.95 | E4: 0 | F4: 0 | G4: 0 | H4: 0 | I4: 0 | J4: 0 | K4: 0 | L4: 0 | M4: 0 | N4: 0 | O4: 0 | P4: 0 | Q4: 560.5737 | S4: 200
A5: Dodecansäure | B5: Final Conc. | C5: 147517.13 | D5: 251073.44 | E5: 14241.061 | F5: 14062.033 | G5: 3921.1512 | H5: 1804.1423 | I5: 0 | J5: 2458.3841 | K5: 1136.1461 | L5: 16954.508 | M5: 7192.426 | N5: 5764.4689 | O5: 15172.462 | P5: 16684.53 | Q5: 16079.607 | S5: 400
A6: Tridecansäure | B6: Final Conc. | C6: 957538.69 | D6: 110372.87 | E6: 116729.14 | F6: 104660.05 | G6: 76050.123 | H6: 71632.268 | I6: 58130.237 | J6: 74712.325 | K6: 71046.942 | L6: 98337.983 | M6: 89016.08 | N6: 80764.72 | O6: 96950.538 | P6: 100958.84 | Q6: 104063.52 | S6: 200
A7: Tetradecansäure | B7: Final Conc. | C7: 167713.59 | D7: 282216.16 | E7: 307148.97 | F7: 228455.41 | G7: 79314.416 | H7: 44227.004 | I7: 66694.819 | J7: 54893.558 | K7: 66590.007 | L7: 111370.35 | M7: 56979.878 | N7: 76653.051 | O7: 90808.16 | P7: 84719.422 | Q7: 28730.075 | S7: 400
A8: 9-Tetradecensäure | B8: Final Conc. | C8: 982327.16 | D8: 159972.67 | E8: 0 | F8: 0 | G8: 0 | H8: 0 | I8: 0 | J8: 0 | K8: 1237.8943 | L8: 0 | M8: 0 | N8: 0 | O8: 0 | P8: 0 | Q8: 0 | S8: 200
A9: Pentadecansäure | B9: Final Conc. | C9: 1251185.6 | D9: 121335.2 | E9: 15876.937 | F9: 18218.657 | G9: 14399.843 | H9: 11750.371 | I9: 12735.333 | J9: 6449.668 | K9: 10521.298 | L9: 19481.495 | M9: 9310.5071 | N9: 13141.642 | O9: 11251.206 | P9: 14583.758 | Q9: 6547.856 | S9: 200
A10: Cis-10-Pentadecensäure | B10: Final Conc. | C10: 1379255.6 | D10: 155661.84 | E10: 0 | F10: 3616.4395 | G10: 0 | H10: 0 | I10: 0 | J10: 0 | K10: 0 | L10: 0 | M10: 0 | N10: 0 | O10: 0 | P10: 0 | Q10: 0 | S10: 200
A11: Hexadecansäure | B11: Final Conc. | C11: 642555.8 | D11: 1770645 | E11: 5408422.7 | F11: 7135800.9 | G11: 2314918.4 | H11: 1889519.4 | I11: 2400279.7 | J11: 2264308.7 | K11: 2176934.7 | L11: 2738568 | M11: 1936717.5 | N11: 2267154.2 | O11: 2681835 | P11: 2450707.4 | Q11: 1489318.9 | S11: 600
A12: Cis-9-Hexadecensäure | B12: Final Conc. | C12: 138852.38 | D12: 158571.54 | E12: 949729.25 | F12: 672078.27 | G12: 267765.93 | H12: 76218.546 | I12: 235986.04 | J12: 264580.79 | K12: 206181.12 | L12: 347509.74 | M12: 159339.59 | N12: 292753.04 | O12: 418140.9 | P12: 323614.04 | Q12: 0 | S12: 200
A13: Heptadecansäure | B13: Final Conc. | C13: 127415.49 | D13: 149941.5 | E13: 17226.616 | F13: 34639.677 | G13: 20271.14 | H13: 14551.685 | I13: 19930.199 | J13: 15711.55 | K13: 16219.138 | L13: 25551.999 | M13: 12347.31 | N13: 15849.215 | O13: 16984.159 | P13: 18090.706 | Q13: 3385.0266 | S13: 200
A14: Cis-10-Heptadecensäure | B14: Final Conc. | C14: 3346789.2 | D14: 215302.6 | E14: 20971.489 | F14: 35866.235 | G14: 0 | H14: 0 | I14: 0 | J14: 0 | K14: ND | L14: 0 | M14: 0 | N14: 539.097 | O14: 0 | P14: ND | Q14: 0 | S14: 200
A15: Octadecansäure | B15: Final Conc. | C15: 205999.62 | D15: 397736.83 | E15: 543794.72 | F15: 645739.57 | G15: 479380.3 | H15: 426284.69 | I15: 508789.27 | J15: 466234.4 | K15: 464629.21 | L15: 549429.77 | M15: 442894.98 | N15: 466512.2 | O15: 510023.75 | P15: 501554.48 | Q15: 448634.64 | S15: 400
A16: Cis-9-Octadecensäure | B16: Final Conc. | C16: 658678.2 | D16: 460168.1 | E16: 1955733.3 | F16: 2472526.7 | G16: 410531.34 | H16: 285972.57 | I16: 398917.52 | J16: 323445.57 | K16: 393180.45 | L16: 477992.72 | M16: 335340.07 | N16: 336105.76 | O16: 433009.21 | P16: 484748.14 | Q16: 16423.912 | S16: 400
A17: Octadeca-9,12-diensäure (trans) | B17: Final Conc. | C17: 825905.86 | D17: 40924.061 | E17: 0 | F17: 3779.0925 | G17: 1489.2816 | H17: 348.5468 | I17: 348.5753 | J17: 244.1129 | K17: 555.2832 | L17: 1911.2914 | M17: 340.7386 | N17: 294.4635 | O17: 2294.4055 | P17: 110.8309 | Q17: 331.9534 | S17: 200
A18: Octadeca-9,12-diensäure (cis) | B18: Final Conc. | C18: 861831.52 | D18: 184257.95 | E18: 1913538.4 | F18: 2318124.3 | G18: 196641.22 | H18: 112635.54 | I18: 201417.17 | J18: 174776.79 | K18: 147414.56 | L18: 286145.92 | M18: 117208.01 | N18: 153966.91 | O18: 231056.48 | P18: 258655.51 | Q18: 6003.4596 | S18: 200
A19: Gamma-Octadecatriensäure | B19: Final Conc. | C19: 962477.5 | D19: 188654.93 | E19: 157532.68 | F19: 0 | G19: 487.2043 | H19: 249.3268 | I19: ND | J19: 237.5764 | K19: 100.9045 | L19: 0 | M19: 130.9809 | N19: 0 | O19: 22888.522 | P19: 0 | Q19: 0 | S19: 200
A20: Alpha-Octadecatriensäure | B20: Final Conc. | C20: 4244432.1 | D20: 566875.98 | E20: 3321110.6 | F20: 4662239 | G20: 171924.56 | H20: 81385.995 | I20: 177076.74 | J20: 108259.15 | K20: 108164.1 | L20: 274663.28 | M20: 88699.407 | N20: 117572.09 | O20: 225595.3 | P20: 264734.79 | Q20: 1937.9754 | S20: 200
A21: 6,9,12,15-Octadecatetraensäure | B21: Final Conc. | C21: 2149847.4 | D21: 111994.68 | E21: 322121.3 | F21: 435781.98 | G21: 7944.7387 | H21: 478.6554 | I21: 9759.7838 | J21: 297.1872 | K21: 664.4373 | L21: 16514.242 | M21: 750.1133 | N21: 10186.508 | O21: 18420.323 | P21: 12528.589 | Q21: 214.5091
A22: Eicosansäure | B22: Final Conc. | C22: 3796919.8 | D22: 284983.99 | E22: 28789.515 | F22: 27809.502 | G22: 1396.0406 | H22: 1811.3054 | I22: 6391.9607 | J22: 1629.9003 | K22: 1621.7752 | L22: 1691.43 | M22: 1609.9726 | N22: 2431.8781 | O22: 1601.6769 | P22: 1723.9437 | Q22: 8752.849 | S22: 400
A23: Cis-11-Eicosensäure | B23: Final Conc. | C23: 721180.45 | D23: 51192.596 | E23: 29800.345 | F23: 40924.457 | G23: 10101.382 | H23: 7493.8227 | I23: 8754.9446 | J23: 94.0871 | K23: 10371.822 | L23: 16010.991 | M23: 8681.0986 | N23: 256.5368 | O23: 7744.0866 | P23: 15196.998 | Q23: 149.3779 | S23: 200
A24: Cis-11,14-Eicosadiensäure | B24: Final Conc. | C24: 125447.38 | D24: 107082.46 | E24: 19851.863 | F24: 11014.298 | G24: 29199.633 | H24: 14909.966 | I24: 26735.095 | J24: 33724.539 | K24: 13381.612 | L24: 38918.844 | M24: 13280.418 | N24: 16474.373 | O24: 29200.895 | P24: 36381.874 | Q24: 243.7476 | S24: 200
A25: Cis-8,11,14-Eisocatriensäure | B25: Final Conc. | C25: 223911.28 | D25: 73358.256 | E25: 4674.5024 | F25: 426.4854 | G25: 653.5427 | H25: 431.5314 | I25: ND | J25: 419.3009 | K25: 412.0068 | L25: 915.577 | M25: 14096.273 | N25: 425.5577 | O25: 1200.8975 | P25: 290.7852 | Q25: 440.1581 | S25: 200
A26: Cis-5,8,11,14-Eicosatetraensäure | B26: Final Conc. | C26: 981532.01 | D26: 259312.43 | E26: 112979.19 | F26: 70756.97 | G26: 205332.35 | H26: 114398.99 | I26: 201347.79 | J26: 210168.44 | K26: 101861.73 | L26: 263198.71 | M26: 91994.642 | N26: 140127.85 | O26: 252487.79 | P26: 216862.35 | Q26: 580.1763 | S26: 200
A27: Cis-11,14,17-Eicosatriensäure | B27: Final Conc. | C27: 132593.32 | D27: 80453.91 | E27: ND | F27: 3930.5622 | G27: ND | H27: ND | I27: ND | J27: ND | K27: ND | L27: 9805.8728 | M27: ND | N27: ND | O27: 8634.8212 | P27: ND | Q27: ND | S27: 200
A28: Heneicosansäure | B28: Final Conc. | C28: 48157.496 | D28: 121960.37 | E28: 0 | F28: 0 | G28: 0 | H28: 0 | I28: 0 | J28: 0 | K28: 0 | L28: 0 | M28: 0 | N28: 0 | O28: 0 | P28: 0 | Q28: 0.7524 | S28: 200
A29: Cis-5,8,11,14,17-Eicosapentaensäure | B29: Final Conc. | C29: 273962.8 | D29: 175722 | E29: 294626.63 | F29: 245777.13 | G29: 176332.23 | H29: 102399.41 | I29: 178779.04 | J29: 175022.28 | K29: 109081.23 | L29: 213883.11 | M29: 98284.17 | N29: 155763.81 | O29: 240546.05 | P29: 190062.38 | Q29: 535.825 | S29: 200
A30: Docosansäure | B30: Final Conc. | C30: 1129657 | D30: 163694.27 | E30: 1588.2031 | F30: 8054.8824 | G30: 0 | H30: 0 | I30: 0 | J30: 0 | K30: 0 | L30: 0 | M30: 0 | N30: 0 | O30: 0 | P30: 0 | Q30: 0 | S30: 200
A31: 13-Docosensäure | B31: Final Conc. | C31: 225406.64 | D31: 111215.99 | E31: 94496.069 | F31: 156794.4 | G31: 121652.81 | H31: 109039.16 | I31: 122689.79 | J31: 99914.846 | K31: 117466.71 | L31: 116800.64 | M31: 119908.31 | N31: 118867.94 | O31: 107960.56 | P31: 120520.15 | Q31: 165912.63 | S31: 400
A32: Cis-13,16-Docosadiensäure | B32: Final Conc. | C32: 168185.16 | D32: 98278.121 | E32: 1932.2348 | F32: 1936.0178 | G32: 1935.3707 | H32: 1933.7981 | I32: 1958.8975 | J32: 1915.6862 | K32: 1875.428 | L32: 1957.1567 | M32: 1972.998 | N32: 1953.7872 | O32: 7457.3211 | P32: 1948.9389 | Q32: 1924.4387 | S32: 200
A33: Cis-7,10,13,16,19-Docosapentaensäure | B33: Final Conc. | C33: 1254449.2 | D33: 33783.535 | E33: 796.3374 | F33: 154.8988 | G33: 6961.3173 | H33: 2340.826 | I33: 5067.1295 | J33: 5380.7233 | K33: 2654.284 | L33: 7741.1357 | M33: 2607.2953 | N33: 4342.0641 | O33: 7674.9007 | P33: 6704.8836 | Q33: 0
A34: Cis-4,7,10,13,16,19-Docosahexaensäure | B34: Final Conc. | C34: 1363987.8 | D34: 85385.164 | E34: 17029.595 | F34: 12651.214 | G34: 6450.2671 | H34: 1073.1942 | I34: 4952.8833 | J34: 5841.7789 | K34: 1720.0402 | L34: 8233.1139 | M34: 498.5818 | N34: 2481.3516 | O34: 6718.0199 | P34: 4768.7079 | Q34: 0 | S34: 200
A35: Tetracosansäure | B35: Final Conc. | C35: 1498066.2 | D35: 594693.58 | E35: 108887.73 | F35: 151098.01 | G35: 12646.934 | H35: 9072.2939 | I35: 13239.547 | J35: 0 | K35: 0 | L35: 0 | M35: 0 | N35: 14399.121 | O35: 10869.473 | P35: 13146.673 | Q35: 6933.2251 | S35: 400
A36: Cis-15-Tetracosensäure | B36: Final Conc. | C36: 1934848.1 | D36: 11287.789 | E36: 0 | F36: 0 | G36: 0 | H36: 0 | I36: 0 | J36: 0 | K36: 0 | L36: 0 | M36: 0 | N36: 0 | O36: 0 | P36: 0 | Q36: 0 | S36: 200

Sheet raw data
A5: Octansäure | B5: Data File | C5: blank230627.D | D5: MEGA-Mix_230627.D | E5: W3Cip.D | F5: W3Mix.D | G5: Cip2.D | H5: Cip3.D | I5: Cip4.D | J5: Cip18.D | K5: Cip6.D | L5: Cip7.D | M5: Cip16.D | N5: Cip19.D | O5: Cip11.D | P5: Cip14.D | Q5: Blank1.D
B6: Type | C6: Blank | D6: Sample | E6: Sample | F6: Sample | G6: Sample | H6: Sample | I6: Sample | J6: Sample | K6: Sample | L6: Sample | M6: Sample | N6: Sample | O6: Sample | P6: Sample | Q6: Sample
B7: ISTD | C7: Nonadecansäure | D7: Nonadecansäure | E7: Nonadecansäure | F7: Nonadecansäure | G7: Nonadecansäure | H7: Nonadecansäure | I7: Nonadecansäure | J7: Nonadecansäure | K7: Nonadecansäure | L7: Nonadecansäure | M7: Nonadecansäure | N7: Nonadecansäure | O7: Nonadecansäure | P7: Nonadecansäure | Q7: Nonadecansäure
B8: RT | C8: 4.168 | D8: 4.188 | E8: 4.276 | F8: 4.165 | G8: 4.193 | H8: 4.185 | I8: 4.178 | J8: 4.178 | K8: 4.19 | L8: 4.173 | M8: 4.165 | N8: 4.209 | O8: 4.174 | P8: 4.163 | Q8: 4.163
B9: Resp. | C9: 5835 | D9: 44306017 | E9: 17642 | F9: 27942 | G9: 3058 | H9: 4349 | I9: 18489 | J9: 24311 | K9: 4321 | L9: 5865 | M9: 6076 | N9: 14702 | O9: 4567 | P9: 14068 | Q9: 4373
B10: ISTD Resp | C10: 829 | D10: 60224864 | E10: 36911952 | F10: 38252679 | G10: 39706672 | H10: 33890606 | I10: 32717868 | J10: 29935446 | K10: 33606591 | L10: 33491506 | M10: 35580632 | N10: 31727925 | O10: 23917418 | P10: 31543279 | Q10: 31466182
B11: RR | C11: 7.0389 | D11: 0.7357 | E11: 0.0005 | F11: 0.0007 | G11: 0.0001 | H11: 0.0001 | I11: 0.0006 | J11: 0.0008 | K11: 0.0001 | L11: 0.0002 | M11: 0.0002 | N11: 0.0005 | O11: 0.0002 | P11: 0.0004 | Q11: 0.0001
B12: Final Conc. | C12: 3702086.7 | D12: 392864.68 | E12: 6884.514 | F12: 7017.0779 | G12: 6674.0167 | H12: 6700.9608 | I12: 6930.2637 | J12: 7059.9457 | K12: 6701.084 | L12: 6725.5191 | M12: 6723.2432 | N12: 6876.8636 | O12: 6733.8295 | P12: 6867.7396 | Q12: 6706.5411
A14: Decansäure | B14: Data File | C14: blank230627.D | D14: MEGA-Mix_230627.D | E14: W3Cip.D | F14: W3Mix.D | G14: Cip2.D | H14: Cip3.D | I14: Cip4.D | J14: Cip18.D | K14: Cip6.D | L14: Cip7.D | M14: Cip16.D | N14: Cip19.D | O14: Cip11.D | P14: Cip14.D | Q14: Blank1.D
B15: Type | C15: Blank | D15: Sample | E15: Sample | F15: Sample | G15: Sample | H15: Sample | I15: Sample | J15: Sample | K15: Sample | L15: Sample | M15: Sample | N15: Sample | O15: Sample | P15: Sample | Q15: Sample
B16: ISTD | C16: Nonadecansäure | D16: Nonadecansäure | E16: Nonadecansäure | F16: Nonadecansäure | G16: Nonadecansäure | H16: Nonadecansäure | I16: Nonadecansäure | J16: Nonadecansäure | K16: Nonadecansäure | L16: Nonadecansäure | M16: Nonadecansäure | N16: Nonadecansäure | O16: Nonadecansäure | P16: Nonadecansäure | Q16: Nonadecansäure
B17: RT | C17: 5.409 | D17: 5.353 | E17: 5.339 | F17: 5.338 | G17: 5.333 | H17: 5.344 | I17: 5.389 | J17: 5.341 | K17: 5.402 | L17: 5.35 | M17: 5.335 | N17: 5.361 | O17: 5.335 | P17: 5.336 | Q17: 5.336
B18: Resp. | C18: 2090 | D18: 34591597 | E18: 301610 | F18: 45291 | G18: 23719 | H18: 4747 | I18: 6097 | J18: 24247 | K18: 7051 | L18: 20737 | M18: 34205 | N18: 5030 | O18: 105986 | P18: 117763 | Q18: 275006
B19: ISTD Resp | C19: 829 | D19: 60224864 | E19: 36911952 | F19: 38252679 | G19: 39706672 | H19: 33890606 | I19: 32717868 | J19: 29935446 | K19: 33606591 | L19: 33491506 | M19: 35580632 | N19: 31727925 | O19: 23917418 | P19: 31543279 | Q19: 31466182
B20: RR | C20: 2.521 | D20: 0.5744 | E20: 0.0082 | F20: 0.0012 | G20: 0.0006 | H20: 0.0001 | I20: 0.0002 | J20: 0.0008 | K20: 0.0002 | L20: 0.0006 | M20: 0.001 | N20: 0.0002 | O20: 0.0044 | P20: 0.0037 | Q20: 0.0087
B21: Final Conc. | C21: 1723219.1 | D21: 391475.17 | E21: 4124.7162 | F21: 0 | G21: 0 | H21: 0 | I21: 0 | J21: 0 | K21: 0 | L21: 0 | M21: 0 | N21: 0 | O21: 1566.2897 | P21: 1088.8094 | Q21: 4513.7455
A23: Undecansäure | B23: Data File | C23: blank230627.D | D23: MEGA-Mix_230627.D | E23: W3Cip.D | F23: W3Mix.D | G23: Cip2.D | H23: Cip3.D | I23: Cip4.D | J23: Cip18.D | K23: Cip6.D | L23: Cip7.D | M23: Cip16.D | N23: Cip19.D | O23: Cip11.D | P23: Cip14.D | Q23: Blank1.D
B24: Type | C24: Blank | D24: Sample | E24: Sample | F24: Sample | G24: Sample | H24: Sample | I24: Sample | J24: Sample | K24: Sample | L24: Sample | M24: Sample | N24: Sample | O24: Sample | P24: Sample | Q24: Sample
B25: ISTD | C25: Nonadecansäure | D25: Nonadecansäure | E25: Nonadecansäure | F25: Nonadecansäure | G25: Nonadecansäure | H25: Nonadecansäure | I25: Nonadecansäure | J25: Nonadecansäure | K25: Nonadecansäure | L25: Nonadecansäure | M25: Nonadecansäure | N25: Nonadecansäure | O25: Nonadecansäure | P25: Nonadecansäure | Q25: Nonadecansäure
B26: RT | C26: 6.164 | D26: 6.165 | E26: 6.15 | F26: 6.222 | G26: 6.176 | H26: 6.195 | I26: 6.167 | J26: 6.142 | K26: 6.156 | L26: 6.173 | M26: 6.148 | N26: 6.15 | O26: 6.151 | P26: 6.153 | Q26: 6.15
B27: Resp. | C27: 1495 | D27: 33513142 | E27: 132234 | F27: 37506 | G27: 18591 | H27: 2027 | I27: 3925 | J27: 62681 | K27: 5886 | L27: 5244 | M27: 90827 | N27: 25723 | O27: 76977 | P27: 94138 | Q27: 181466
B28: ISTD Resp | C28: 829 | D28: 60224864 | E28: 36911952 | F28: 38252679 | G28: 39706672 | H28: 33890606 | I28: 32717868 | J28: 29935446 | K28: 33606591 | L28: 33491506 | M28: 35580632 | N28: 31727925 | O28: 23917418 | P28: 31543279 | Q28: 31466182
B29: RR | C29: 1.8036 | D29: 0.5565 | E29: 0.0036 | F29: 0.001 | G29: 0.0005 | H29: 0.0001 | I29: 0.0001 | J29: 0.0021 | K29: 0.0002 | L29: 0.0002 | M29: 0.0026 | N29: 0.0008 | O29: 0.0032 | P29: 0.003 | Q29: 0.0058
B30: Final Conc. | C30: 620354.87 | D30: 190406.95 | E30: 0 | F30: 0 | G30: 0 | H30: 0 | I30: 0 | J30: 0 | K30: 0 | L30: 0 | M30: 0 | N30: 0 | O30: 0 | P30: 0 | Q30: 560.5737
A32: Dodecansäure | B32: Data File | C32: blank230627.D | D32: MEGA-Mix_230627.D | E32: W3Cip.D | F32: W3Mix.D | G32: Cip2.D | H32: Cip3.D | I32: Cip4.D | J32: Cip18.D | K32: Cip6.D | L32: Cip7.D | M32: Cip16.D | N32: Cip19.D | O32: Cip11.D | P32: Cip14.D | Q32: Blank1.D
B33: Type | C33: Blank | D33: Sample | E33: Sample | F33: Sample | G33: Sample | H33: Sample | I33: Sample | J33: Sample | K33: Sample | L33: Sample | M33: Sample | N33: Sample | O33: Sample | P33: Sample | Q33: Sample
B34: ISTD | C34: Nonadecansäure | D34: Nonadecansäure | E34: Nonadecansäure | F34: Nonadecansäure | G34: Nonadecansäure | H34: Nonadecansäure | I34: Nonadecansäure | J34: Nonadecansäure | K34: Nonadecansäure | L34: Nonadecansäure | M34: Nonadecansäure | N34: Nonadecansäure | O34: Nonadecansäure | P34: Nonadecansäure | Q34: Nonadecansäure
B35: RT | C35: 7.493 | D35: 7.278 | E35: 7.248 | F35: 7.25 | G35: 7.247 | H35: 7.247 | I35: 7.246 | J35: 7.246 | K35: 7.246 | L35: 7.247 | M35: 7.247 | N35: 7.246 | O35: 7.246 | P35: 7.245 | Q35: 7.246
B36: Resp. | C36: 2124 | D36: 256937649 | E36: 13592995 | F36: 13974006 | G36: 7877724 | H36: 5542941 | I36: 3238690 | J36: 5218411 | K36: 5126998 | L36: 13829161 | M36: 8974868 | N36: 7257362 | O36: 9174353 | P36: 12884542 | Q36: 12539758
B37: ISTD Resp | C37: 829 | D37: 60224864 | E37: 36911952 | F37: 38252679 | G37: 39706672 | H37: 33890606 | I37: 32717868 | J37: 29935446 | K37: 33606591 | L37: 33491506 | M37: 35580632 | N37: 31727925 | O37: 23917418 | P37: 31543279 | Q37: 31466182
B38: RR | C38: 2.5619 | D38: 4.2663 | E38: 0.3683 | F38: 0.3653 | G38: 0.1984 | H38: 0.1636 | I38: 0.099 | J38: 0.1743 | K38: 0.1526 | L38: 0.4129 | M38: 0.2522 | N38: 0.2287 | O38: 0.3836 | P38: 0.4085 | Q38: 0.3985
B39: Final Conc. | C39: 147517.13 | D39: 251073.44 | E39: 14241.061 | F39: 14062.033 | G39: 3921.1512 | H39: 1804.1423 | I39: 0 | J39: 2458.3841 | K39: 1136.1461 | L39: 16954.508 | M39: 7192.426 | N39: 5764.4689 | O39: 15172.462 | P39: 16684.53 | Q39: 16079.607
A41: Tridecansäure | B41: Data File | C41: blank230627.D | D41: MEGA-Mix_230627.D | E41: W3Cip.D | F41: W3Mix.D | G41: Cip2.D | H41: Cip3.D | I41: Cip4.D | J41: Cip18.D | K41: Cip6.D | L41: Cip7.D | M41: Cip16.D | N41: Cip19.D | O41: Cip11.D | P41: Cip14.D | Q41: Blank1.D
B42: Type | C42: Blank | D42: Sample | E42: Sample | F42: Sample | G42: Sample | H42: Sample | I42: Sample | J42: Sample | K42: Sample | L42: Sample | M42: Sample | N42: Sample | O42: Sample | P42: Sample | Q42: Sample
B43: ISTD | C43: Nonadecansäure | D43: Nonadecansäure | E43: Nonadecansäure | F43: Nonadecansäure | G43: Nonadecansäure | H43: Nonadecansäure | I43: Nonadecansäure | J43: Nonadecansäure | K43: Nonadecansäure | L43: Nonadecansäure | M43: Nonadecansäure | N43: Nonadecansäure | O43: Nonadecansäure | P43: Nonadecansäure | Q43: Nonadecansäure
B44: RT | C44: 9.054 | D44: 8.781 | E44: 8.752 | F44: 8.754 | G44: 8.748 | H44: 8.748 | I44: 8.748 | J44: 8.748 | K44: 8.748 | L44: 8.747 | M44: 8.747 | N44: 8.746 | O44: 8.746 | P44: 8.746 | Q44: 8.747
B45: Resp. | C45: 4640 | D45: 39240141 | E45: 25420081 | F45: 23648164 | G45: 17915106 | H45: 14416898 | I45: 11339066 | J45: 13272668 | K45: 14181243 | L45: 19468663 | M45: 18746751 | N45: 15188470 | O45: 13709504 | P45: 18818781 | Q45: 19343106
B46: ISTD Resp | C46: 829 | D46: 60224864 | E46: 36911952 | F46: 38252679 | G46: 39706672 | H46: 33890606 | I46: 32717868 | J46: 29935446 | K46: 33606591 | L46: 33491506 | M46: 35580632 | N46: 31727925 | O46: 23917418 | P46: 31543279 | Q46: 31466182
B47: RR | C47: 5.5973 | D47: 0.6516 | E47: 0.6887 | F47: 0.6182 | G47: 0.4512 | H47: 0.4254 | I47: 0.3466 | J47: 0.4434 | K47: 0.422 | L47: 0.5813 | M47: 0.5269 | N47: 0.4787 | O47: 0.5732 | P47: 0.5966 | Q47: 0.6147
B48: Final Conc. | C48: 957538.69 | D48: 110372.87 | E48: 116729.14 | F48: 104660.05 | G48: 76050.123 | H48: 71632.268 | I48: 58130.237 | J48: 74712.325 | K48: 71046.942 | L48: 98337.983 | M48: 89016.08 | N48: 80764.72 | O48: 96950.538 | P48: 100958.84 | Q48: 104063.52
...

Sheet 230627_FA-Quant-Report_ISTD
A1: Batch Data Path | B1: D:\MassHunter\GCMS\1\data\Sophie_Landau\230627\QuantResults\230627.batch.bin
A2: Analysis Time | B2: 45160.674 | C2: Analyst Name | D2: FLOEK026\install | E2: Report Generator Name | F2: FLOEK026\install
A3: Calibration Last Update | B3: 45154.569 | C3: Analyze Quant Version | D3: 10.1 | E3: Report Quant Version | F3: 10.2
A4: Sequence Table
A5: Data File | B5: Name | C5: Type | D5: Vial | E5: Vol. | F5: Level | G5: Acq. Method File
A6: blank230627.D | B6: blank | C6: Blank | D6: 1 | E6: 1 | G6: FAME_02_Insert
A8: MEGA-Mix_230627.D | B8: MEGA-Mix | C8: Sample | D8: 2 | E8: 1 | G8: FAME_02_Insert
A10: W3Cip.D | B10: W3Cip | C10: Sample | D10: 3 | E10: 1 | G10: FAME_02_Insert
A12: W3Mix.D | B12: W3Mix | C12: Sample | D12: 4 | E12: 1 | G12: FAME_02_Insert
A14: Cip2.D | B14: Cip2 | C14: Sample | D14: 5 | E14: 1 | G14: FAME_02_Insert
A16: Cip3.D | B16: Cip3 | C16: Sample | D16: 6 | E16: 1 | G16: FAME_02_Insert
A18: Cip4.D | B18: Cip4 | C18: Sample | D18: 7 | E18: 1 | G18: FAME_02_Insert
A20: Cip18.D | B20: Cip18 | C20: Sample | D20: 8 | E20: 1 | G20: FAME_02_Insert
A22: Cip6.D | B22: Cip6 | C22: Sample | D22: 9 | E22: 1 | G22: FAME_02_Insert
A24: Cip7.D | B24: Cip7 | C24: Sample | D24: 10 | E24: 1 | G24: FAME_02_Insert
A26: Cip16.D | B26: Cip16 | C26: Sample | D26: 11 | E26: 1 | G26: FAME_02_Insert
A28: Cip19.D | B28: Cip19 | C28: Sample | D28: 12 | E28: 1 | G28: FAME_02_Insert
... A34: Blank1.D | B34: Blank1 | C34: Sample | D34: 15 | E34: 1 | G34: FAME_02_Insert
A36: Octansäure
A37: Data File | B37: Type | C37: ISTD | D37: RT | E37: Resp. | F37: ISTD Resp | G37: RR | H37: Final Conc. | I37: Exp. Conc. | J37: Accuracy
A38: blank230627.D | B38: Blank | C38: Nonadecansäure | D38: 4.168 | E38: 5835 | F38: 829 | G38: 7.0389 | H38: 3702086.7
A39: MEGA-Mix_230627.D | B39: Sample | C39: Nonadecansäure | D39: 4.188 | E39: 44306017 | F39: 60224864 | G39: 0.7357 | H39: 392864.68
A40: W3Cip.D | B40: Sample | C40: Nonadecansäure | D40: 4.276 | E40: 17642 | F40: 36911952 | G40: 0.0005 | H40: 6884.514
A41: W3Mix.D | B41: Sample | C41: Nonadecansäure | D41: 4.165 | E41: 27942 | F41: 38252679 | G41: 0.0007 | H41: 7017.0779
A42: Cip2.D | B42: Sample | C42: Nonadecansäure | D42: 4.193 | E42: 3058 | F42: 39706672 | G42: 0.0001 | H42: 6674.0167
A43: Cip3.D | B43: Sample | C43: Nonadecansäure | D43: 4.185 | E43: 4349 | F43: 33890606 | G43: 0.0001 | H43: 6700.9608
A44: Cip4.D | B44: Sample | C44: Nonadecansäure | D44: 4.178 | E44: 18489 | F44: 32717868 | G44: 0.0006 | H44: 6930.2637
A45: Cip18.D | B45: Sample | C45: Nonadecansäure | D45: 4.178 | E45: 24311 | F45: 29935446 | G45: 0.0008 | H45: 7059.9457
A46: Cip6.D | B46: Sample | C46: Nonadecansäure | D46: 4.19 | E46: 4321 | F46: 33606591 | G46: 0.0001 | H46: 6701.084
A47: Cip7.D | B47: Sample | C47: Nonadecansäure | D47: 4.173 | E47: 5865 | F47: 33491506 | G47: 0.0002 | H47: 6725.5191
A48: Cip16.D | B48: Sample | C48: Nonadecansäure | D48: 4.165 | E48: 6076 | F48: 35580632 | G48: 0.0002 | H48: 6723.2432
A49: Cip19.D | B49: Sample | C49: Nonadecansäure | D49: 4.209 | E49: 14702 | F49: 31727925 | G49: 0.0005 | H49: 6876.8636
... A52: Blank1.D | B52: Sample | C52: Nonadecansäure | D52: 4.163 | E52: 4373 | F52: 31466182 | G52: 0.0001 | H52: 6706.5411
A53: Decansäure
A54: Data File | B54: Type | C54: ISTD | D54: RT | E54: Resp. | F54: ISTD Resp | G54: RR | H54: Final Conc. | I54: Exp. Conc. | J54: Accuracy
A55: blank230627.D | B55: Blank | C55: Nonadecansäure | D55: 5.409 | E55: 2090 | F55: 829 | G55: 2.521 | H55: 1723219.1
A56: MEGA-Mix_230627.D | B56: Sample | C56: Nonadecansäure | D56: 5.353 | E56: 34591597 | F56: 60224864 | G56: 0.5744 | H56: 391475.17
A57: W3Cip.D | B57: Sample | C57: Nonadecansäure | D57: 5.339 | E57: 301610 | F57: 36911952 | G57: 0.0082 | H57: 4124.7162
A58: W3Mix.D | B58: Sample | C58: Nonadecansäure | D58: 5.338 | E58: 45291 | F58: 38252679 | G58: 0.0012 | H58: 0
A59: Cip2.D | B59: Sample | C59: Nonadecansäure | D59: 5.333 | E59: 23719 | F59: 39706672 | G59: 0.0006 | H59: 0
...
