Workbook

Sheet aufgeräumt
A1: FAME (µg/sample) | B1: FAME (µg/sample) | C1: Pro8.D | D1: Pro9.D | E1: Pro18.D | F1: Pro20D.D | G1: Pro21.D | H1: Pro23.D | I1: Pro24.D | J1: Pro26.D | K1: Mix4.D | L1: Mix7.D | M1: Mix9.D | N1: Mix10.D
A2: Octansäure | B2: C08:0 | C2: 6.884514 | D2: 7.0170779 | E2: 6.6740167 | F2: 6.7009608 | G2: 6.9302637 | H2: 7.0599457 | I2: 6.701084 | J2: 6.7255191 | K2: 6.7232432 | L2: 6.8768636 | M2: 6.7338295 | N2: 6.8677396
A3: Decansäure | B3: C10:0 | C3: 4.1247162 | D3: 0 | E3: 0 | F3: 0 | G3: 0 | H3: 0 | I3: 0 | J3: 0 | K3: 0 | L3: 0 | M3: 1.5662897 | N3: 1.0888094
A4: Undecansäure | B4: C11:0 | C4: ND | D4: ND | E4: ND | F4: ND | G4: ND | H4: ND | I4: ND | J4: ND | K4: ND | L4: ND | M4: ND | N4: ND
A5: Dodecansäure | B5: C12:0 | C5: 14.241061 | D5: 14.062033 | E5: 3.9211512 | F5: 1.8041423 | G5: 0 | H5: 2.4583841 | I5: 1.1361461 | J5: 16.954508 | K5: 7.192426 | L5: 5.7644689 | M5: 15.172462 | N5: 16.68453
A6: Tridecansäure | B6: C13:0 | C6: 116.72914 | D6: 104.66005 | E6: 76.050123 | F6: 71.632268 | G6: 58.130237 | H6: 74.712325 | I6: 71.046942 | J6: 98.337983 | K6: 89.01608 | L6: 80.76472 | M6: 96.950538 | N6: 100.95884
A7: Tetradecansäure | B7: C14:0 | C7: 307.14897 | D7: 228.45541 | E7: 79.314416 | F7: 44.227004 | G7: 66.694819 | H7: 54.893558 | I7: 66.590007 | J7: 111.37035 | K7: 56.979878 | L7: 76.653051 | M7: 90.80816 | N7: 84.719422
A8: 9-Tetradecensäure | B8: C14:1 | C8: 0 | D8: 0 | E8: 0 | F8: 0 | G8: 0 | H8: 0 | I8: 1.2378943 | J8: 0 | K8: 0 | L8: 0 | M8: 0 | N8: 0
A9: Pentadecansäure | B9: C15:0 | C9: 15.876937 | D9: 18.218657 | E9: 14.399843 | F9: 11.750371 | G9: 12.735333 | H9: 6.449668 | I9: 10.521298 | J9: 19.481495 | K9: 9.3105071 | L9: 13.141642 | M9: 11.251206 | N9: 14.583758
A10: Cis-10-Pentadecensäure | B10: C15:1 | C10: 0 | D10: 3.6164395 | E10: 0 | F10: 0 | G10: 0 | H10: 0 | I10: 0 | J10: 0 | K10: 0 | L10: 0 | M10: 0 | N10: 0
A11: Hexadecansäure | B11: C16:0 | C11: 5408.4227 | D11: 7135.8009 | E11: 2314.9184 | F11: 1889.5194 | G11: 2400.2797 | H11: 2264.3087 | I11: 2176.9347 | J11: 2738.568 | K11: 1936.7175 | L11: 2267.1542 | M11: 2681.835 | N11: 2450.7074
A12: Cis-9-Hexadecensäure | B12: C16:1 | C12: 949.72925 | D12: 672.07827 | E12: 267.76593 | F12: 76.218546 | G12: 235.98604 | H12: 264.58079 | I12: 206.18112 | J12: 347.50974 | K12: 159.33959 | L12: 292.75304 | M12: 418.1409 | N12: 323.61404
A13: Heptadecansäure | B13: C17:0 | C13: 17.226616 | D13: 34.639677 | E13: 20.27114 | F13: 14.551685 | G13: 19.930199 | H13: 15.71155 | I13: 16.219138 | J13: 25.551999 | K13: 12.34731 | L13: 15.849215 | M13: 16.984159 | N13: 18.090706
A14: Cis-10-Heptadecensäure | B14: C17:1 | C14: 20.971489 | D14: 35.866235 | E14: 0 | F14: 0 | G14: 0 | H14: 0 | I14: ND | J14: 0 | K14: 0 | L14: 0.539097 | M14: 0 | N14: ND
A15: Octadecansäure | B15: C18:0 | C15: 543.79472 | D15: 645.73957 | E15: 479.3803 | F15: 426.28469 | G15: 508.78927 | H15: 466.2344 | I15: 464.62921 | J15: 549.42977 | K15: 442.89498 | L15: 466.5122 | M15: 510.02375 | N15: 501.55448
A16: Cis-9-Octadecensäure | B16: C18:1 | C16: 1955.7333 | D16: 2472.5267 | E16: 410.53134 | F16: 285.97257 | G16: 398.91752 | H16: 323.44557 | I16: 393.18045 | J16: 477.99272 | K16: 335.34007 | L16: 336.10576 | M16: 433.00921 | N16: 484.74814
A17: Octadeca-9,12-diensäure (trans) | B17: C18:2(n-6t) | C17: 0 | D17: 3.7790925 | E17: 1.4892816 | F17: 0.3485468 | G17: 0.3485753 | H17: 0.2441129 | I17: 0.5552832 | J17: 1.9112914 | K17: 0.3407386 | L17: 0.2944635 | M17: 2.2944055 | N17: 0.1108309
A18: Octadeca-9,12-diensäure (cis) | B18: C18:2(n-6c) | C18: 1913.5384 | D18: 2318.1243 | E18: 196.64122 | F18: 112.63554 | G18: 201.41717 | H18: 174.77679 | I18: 147.41456 | J18: 286.14592 | K18: 117.20801 | L18: 153.96691 | M18: 231.05648 | N18: 258.65551
A19: Gamma-Octadecatriensäure | B19: C18:3(n-6) | C19: 157.53268 | D19: 0 | E19: 0.4872043 | F19: 0.2493268 | G19: ND | H19: 0.2375764 | I19: 0.1009045 | J19: 0 | K19: 0.1309809 | L19: 0 | M19: 22.888522 | N19: 0
A20: Alpha-Octadecatriensäure | B20: C18:3(n-3) | C20: 3321.1106 | D20: 4662.239 | E20: 171.92456 | F20: 81.385994 | G20: 177.07674 | H20: 108.25915 | I20: 108.1641 | J20: 274.66328 | K20: 88.699407 | L20: 117.57209 | M20: 225.5953 | N20: 264.73479
A21: 6,9,12,15-Octadecatetraensäure | B21: C18:4(n-3) | C21: 322.1213 | D21: 435.78198 | E21: 7.9447387 | F21: 0.4786554 | G21: 9.7597838 | H21: 0.2971872 | I21: 0.6644373 | J21: 16.514242 | K21: 0.7501133 | L21: 10.186508 | M21: 18.420323 | N21: 12.528589
A22: Eicosansäure | B22: C20:0 | C22: 28.789515 | D22: 27.809502 | E22: 1.3960406 | F22: 1.8113054 | G22: 6.3919607 | H22: 1.6299003 | I22: 1.6217752 | J22: 1.69143 | K22: 1.6099726 | L22: 2.4318781 | M22: 1.6016769 | N22: 1.7239437
A23: Cis-11-Eicosensäure | B23: C20:1 | C23: 29.800345 | D23: 40.924457 | E23: 10.101382 | F23: 7.4938227 | G23: 8.7549446 | H23: 0.0940871 | I23: 10.371822 | J23: 16.010991 | K23: 8.6810986 | L23: 0.2565368 | M23: 7.7440866 | N23: 15.196998
A24: Cis-11,14-Eicosadiensäure | B24: C20:2(n-6) | C24: 19.851863 | D24: 11.014298 | E24: 29.199633 | F24: 14.909966 | G24: 26.735095 | H24: 33.724539 | I24: 13.381612 | J24: 38.918844 | K24: 13.280418 | L24: 16.474373 | M24: 29.200895 | N24: 36.381874
A25: Cis-8,11,14-Eisocatriensäure | B25: C20:3(n-6) | C25: 4.6745024 | D25: 0.4264854 | E25: 0.6535427 | F25: 0.4315314 | G25: ND | H25: 0.4193009 | I25: 0.4120068 | J25: 0.915577 | K25: 14.096273 | L25: 0.4255577 | M25: 1.2008975 | N25: 0.2907852
A26: Cis-5,8,11,14-Eicosatetraensäure | B26: C20:4(n-6) | C26: 112.97919 | D26: 70.75697 | E26: 205.33235 | F26: 114.39899 | G26: 201.34779 | H26: 210.16844 | I26: 101.86173 | J26: 263.19871 | K26: 91.994642 | L26: 140.12785 | M26: 252.48779 | N26: 216.86235
A27: Cis-11,14,17-Eicosatriensäure | B27: C20:3(n-3) | C27: ND | D27: 3.9305622 | E27: ND | F27: ND | G27: ND | H27: ND | I27: ND | J27: 9.8058728 | K27: ND | L27: ND | M27: 8.6348212 | N27: ND
A28: Heneicosansäure | B28: C21:0 | C28: 0 | D28: 0 | E28: 0 | F28: 0 | G28: 0 | H28: 0 | I28: 0 | J28: 0 | K28: 0 | L28: 0 | M28: 0 | N28: 0
A29: Cis-5,8,11,14,17-Eicosapentaensäure | B29: C20:5(n-3) | C29: 294.62663 | D29: 245.77713 | E29: 176.33223 | F29: 102.39941 | G29: 178.77904 | H29: 175.02228 | I29: 109.08123 | J29: 213.88311 | K29: 98.28417 | L29: 155.76381 | M29: 240.54605 | N29: 190.06238
A30: Docosansäure | B30: C22:0 | C30: 1.5882031 | D30: 8.0548824 | E30: 0 | F30: 0 | G30: 0 | H30: 0 | I30: 0 | J30: 0 | K30: 0 | L30: 0 | M30: 0 | N30: 0
A31: 13-Docosensäure | B31: C22:1 | C31: 94.49607 | D31: 156.7944 | E31: 121.65281 | F31: 109.03916 | G31: 122.68979 | H31: 99.914846 | I31: 117.46671 | J31: 116.80064 | K31: 119.90831 | L31: 118.86794 | M31: 107.96056 | N31: 120.52015
A32: Cis-13,16-Docosadiensäure | B32: C22:2 | C32: 1.9322348 | D32: 1.9360178 | E32: 1.9353707 | F32: 1.9337981 | G32: 1.9588975 | H32: 1.9156862 | I32: 1.875428 | J32: 1.9571567 | K32: 1.972998 | L32: 1.9537872 | M32: 7.4573211 | N32: 1.9489389
A33: Cis-7,10,13,16,19-Docosapentaensäure | B33: C22:5(n-3) | C33: 0.7963374 | D33: 0.1548988 | E33: 6.9613173 | F33: 2.340826 | G33: 5.0671295 | H33: 5.3807233 | I33: 2.654284 | J33: 7.7411357 | K33: 2.6072953 | L33: 4.3420641 | M33: 7.6749007 | N33: 6.7048836
A34: Cis-4,7,10,13,16,19-Docosahexaensäure | B34: C22:6(n-3) | C34: 17.029595 | D34: 12.651214 | E34: 6.4502671 | F34: 1.0731942 | G34: 4.9528833 | H34: 5.8417789 | I34: 1.7200402 | J34: 8.2331139 | K34: 0.4985818 | L34: 2.4813516 | M34: 6.7180199 | N34: 4.7687079
A35: Tetracosansäure | B35: C24:0 | C35: 108.88773 | D35: 151.09801 | E35: 12.646934 | F35: 9.0722939 | G35: 13.239547 | H35: 0 | I35: 0 | J35: 0 | K35: 0 | L35: 14.399121 | M35: 10.869473 | N35: 13.146673
A36: Cis-15-Tetracosensäure | B36: C24:1 | C36: 0 | D36: 0 | E36: 0 | F36: 0 | G36: 0 | H36: 0 | I36: 0 | J36: 0 | K36: 0 | L36: 0 | M36: 0 | N36: 0

Sheet µg statt ng
A1: FAME | B1: Data File | C1: blank230704.D | D1: MEGA-Mix_230704.D | E1: Pro8.D | F1: Pro9.D | G1: Pro18.D | H1: Pro20D.D | I1: Pro21.D | J1: Pro23.D | K1: Pro24.D | L1: Pro26.D | M1: Mix4.D | N1: Mix7.D | O1: Mix9.D | P1: Mix10.D | R1: ISD( µ/ml)
A2: Octansäure | B2: Final Conc. | C2: ='data processing'!C2/1000 -> 1948.686 | D2: ='data processing'!D2/1000 -> 389.50208 | E2: ='data processing'!E2/1000 -> 6.7400191 | F2: ='data processing'!F2/1000 -> 6.6790025 | G2: ='data processing'!G2/1000 -> 6.653162 | H2: ='data processing'!H2/1000 -> 6.7039619 | I2: ='data processing'!I2/1000 -> 6.6724949 | J2: ='data processing'!J2/1000 -> 6.7317057 | ... P2: ='data processing'!P2/1000 -> 6.6966999 | R2: 400
A3: Decansäure | B3: Final Conc. | C3: ='data processing'!C3/1000 -> 494.6857 | D3: ='data processing'!D3/1000 -> 392.1382 | E3: ='data processing'!E3/1000 -> 0 | F3: ='data processing'!F3/1000 -> 0 | G3: ='data processing'!G3/1000 -> 0 | H3: ='data processing'!H3/1000 -> 0 | I3: ='data processing'!I3/1000 -> 0 | J3: ='data processing'!J3/1000 -> 0 | ... P3: ='data processing'!P3/1000 -> 0 | R3: 400
A4: Undecansäure | B4: Final Conc. | C4: ='data processing'!C4/1000 -> 473.09964 | D4: ='data processing'!D4/1000 -> 191.15799 | E4: ='data processing'!E4/1000 -> 0 | F4: ='data processing'!F4/1000 -> 0 | G4: ='data processing'!G4/1000 -> 0 | H4: ='data processing'!H4/1000 -> 0 | I4: ='data processing'!I4/1000 -> 0 | J4: ='data processing'!J4/1000 -> 0 | ... P4: ='data processing'!P4/1000 -> 0 | R4: 200
A5: Dodecansäure | B5: Final Conc. | C5: ='data processing'!C5/1000 -> 60.663514 | D5: ='data processing'!D5/1000 -> 263.34695 | E5: ='data processing'!E5/1000 -> 0 | F5: ='data processing'!F5/1000 -> 0 | G5: ='data processing'!G5/1000 -> 0 | H5: ='data processing'!H5/1000 -> 0 | I5: ='data processing'!I5/1000 -> 0 | J5: ='data processing'!J5/1000 -> 0 | ... P5: ='data processing'!P5/1000 -> 0 | R5: 400
A6: Tridecansäure | B6: Final Conc. | C6: ='data processing'!C6/1000 -> 578.7078 | D6: ='data processing'!D6/1000 -> 111.84234 | E6: ='data processing'!E6/1000 -> 0 | F6: ='data processing'!F6/1000 -> 0 | G6: ='data processing'!G6/1000 -> 0 | H6: ='data processing'!H6/1000 -> 0 | I6: ='data processing'!I6/1000 -> 0 | J6: ='data processing'!J6/1000 -> 0 | ... P6: ='data processing'!P6/1000 -> 0 | R6: 200
A7: Tetradecansäure | B7: Final Conc. | C7: ='data processing'!C7/1000 -> 51.86062 | D7: ='data processing'!D7/1000 -> 296.02996 | E7: ='data processing'!E7/1000 -> 0 | F7: ='data processing'!F7/1000 -> 0.5064356 | G7: ='data processing'!G7/1000 -> 0 | H7: ='data processing'!H7/1000 -> 0 | I7: ='data processing'!I7/1000 -> 0 | J7: ='data processing'!J7/1000 -> 0.0248369 | ... P7: ='data processing'!P7/1000 -> 0 | R7: 400
A8: 9-Tetradecensäure | B8: Final Conc. | C8: ='data processing'!C8/1000 -> 491.61146 | D8: ='data processing'!D8/1000 -> 166.6294 | E8: ND | F8: ='data processing'!F8/1000 -> 0 | G8: ='data processing'!G8/1000 -> 0 | H8: ='data processing'!H8/1000 -> 0 | I8: ='data processing'!I8/1000 -> 0 | J8: ='data processing'!J8/1000 -> 0 | K8: ='data processing'!K8/1000 -> 0 | L8: ='data processing'!L8/1000 -> 0 | M8: ='data processing'!M8/1000 -> 0 | ... P8: ='data processing'!P8/1000 -> 0 | R8: 200
A9: Pentadecansäure | B9: Final Conc. | C9: ='data processing'!C9/1000 -> 2580.1325 | D9: ='data processing'!D9/1000 -> 125.00205 | E9: ='data processing'!E9/1000 -> 0 | F9: ='data processing'!F9/1000 -> 1.6517376 | G9: ='data processing'!G9/1000 -> 0 | H9: ='data processing'!H9/1000 -> 0 | I9: ='data processing'!I9/1000 -> 1.8206234 | J9: ='data processing'!J9/1000 -> 2.9667627 | ... P9: ='data processing'!P9/1000 -> 0 | R9: 200
A10: Cis-10-Pentadecensäure | B10: Final Conc. | C10: ='data processing'!C10/1000 -> 254.79395 | D10: ='data processing'!D10/1000 -> 160.77209 | E10: ='data processing'!E10/1000 -> 0 | F10: ='data processing'!F10/1000 -> 0 | G10: ='data processing'!G10/1000 -> 0 | H10: ='data processing'!H10/1000 -> 0 | I10: ='data processing'!I10/1000 -> 0 | J10: ='data processing'!J10/1000 -> 1.0662697 | ... P10: ='data processing'!P10/1000 -> 0 | R10: 200
A11: Hexadecansäure | B11: Final Conc. | C11: ='data processing'!C11/1000 -> 237.35054 | D11: ='data processing'!D11/1000 -> 1856.2646 | E11: ='data processing'!E11/1000 -> 1648.1313 | F11: ='data processing'!F11/1000 -> 1827.8274 | G11: ='data processing'!G11/1000 -> 1273.9483 | H11: ='data processing'!H11/1000 -> 872.07461 | I11: ='data processing'!I11/1000 -> 1721.257 | J11: ='data processing'!J11/1000 -> 2278.4863 | ... P11: ='data processing'!P11/1000 -> 1068.9664 | R11: 600
A12: Cis-9-Hexadecensäure | B12: Final Conc. | C12: ='data processing'!C12/1000 -> 326.10468 | D12: ='data processing'!D12/1000 -> 164.72018 | E12: ='data processing'!E12/1000 -> 113.68672 | F12: ='data processing'!F12/1000 -> 277.20792 | G12: ='data processing'!G12/1000 -> 104.40764 | H12: ='data processing'!H12/1000 -> 18.949193 | I12: ='data processing'!I12/1000 -> 232.15132 | J12: ='data processing'!J12/1000 -> 365.00561 | ... P12: ='data processing'!P12/1000 -> 75.519233 | R12: 200
A13: Heptadecansäure | B13: Final Conc. | C13: ='data processing'!C13/1000 -> 13.201698 | D13: ='data processing'!D13/1000 -> 154.2235 | E13: ='data processing'!E13/1000 -> 12.215631 | F13: ='data processing'!F13/1000 -> 11.231103 | G13: ='data processing'!G13/1000 -> 12.699737 | H13: ='data processing'!H13/1000 -> 8.622144 | I13: ='data processing'!I13/1000 -> 12.726906 | J13: ='data processing'!J13/1000 -> 20.946637 | ... P13: ='data processing'!P13/1000 -> 8.2512096 | R13: 200
A14: Cis-10-Heptadecensäure | B14: Final Conc. | C14: ='data processing'!C14/1000 -> 634.26226 | D14: ='data processing'!D14/1000 -> 222.81121 | E14: ='data processing'!E14/1000 -> 0 | F14: ='data processing'!F14/1000 -> 0 | G14: ='data processing'!G14/1000 -> 0 | H14: ='data processing'!H14/1000 -> 0 | I14: ='data processing'!I14/1000 -> 0 | J14: ='data processing'!J14/1000 -> 0 | ... P14: ='data processing'!P14/1000 -> 0 | R14: 200
A15: Octadecansäure | B15: Final Conc. | C15: ='data processing'!C15/1000 -> 120.1516 | D15: ='data processing'!D15/1000 -> 418.72526 | E15: ='data processing'!E15/1000 -> 452.60678 | F15: ='data processing'!F15/1000 -> 380.28959 | G15: ='data processing'!G15/1000 -> 391.03193 | H15: ='data processing'!H15/1000 -> 312.44281 | I15: ='data processing'!I15/1000 -> 362.59808 | J15: ='data processing'!J15/1000 -> 446.84393 | ... P15: ='data processing'!P15/1000 -> 304.74207 | R15: 400
A16: Cis-9-Octadecensäure | B16: Final Conc. | C16: ='data processing'!C16/1000 -> 1274.2613 | D16: ='data processing'!D16/1000 -> 476.28834 | E16: ='data processing'!E16/1000 -> 97.155765 | F16: ='data processing'!F16/1000 -> 461.27457 | G16: ='data processing'!G16/1000 -> 122.14428 | H16: ='data processing'!H16/1000 -> 32.458587 | I16: ='data processing'!I16/1000 -> 506.49061 | J16: ='data processing'!J16/1000 -> 560.31324 | ... P16: ='data processing'!P16/1000 -> 186.02261 | R16: 400
A17: Octadeca-9,12-diensäure (trans) | B17: Final Conc. | C17: ='data processing'!C17/1000 -> 382.31183 | D17: ='data processing'!D17/1000 -> 71.494128 | E17: ='data processing'!E17/1000 -> 0.3450925 | F17: ='data processing'!F17/1000 -> 0.3456901 | G17: ='data processing'!G17/1000 -> 0.5320104 | H17: ='data processing'!H17/1000 -> 0.3509915 | I17: ='data processing'!I17/1000 -> 0.3445315 | J17: ='data processing'!J17/1000 -> 0.3553177 | ... P17: ='data processing'!P17/1000 -> 0.3765374 | R17: 200
A18: Octadeca-9,12-diensäure (cis) | B18: Final Conc. | C18: ='data processing'!C18/1000 -> 45.013387 | D18: ='data processing'!D18/1000 -> 192.17804 | E18: ='data processing'!E18/1000 -> 164.28777 | F18: ='data processing'!F18/1000 -> 147.44757 | G18: ='data processing'!G18/1000 -> 116.93534 | H18: ='data processing'!H18/1000 -> 91.481604 | I18: ='data processing'!I18/1000 -> 202.51821 | J18: ='data processing'!J18/1000 -> 288.68339 | ... P18: ='data processing'!P18/1000 -> 83.153325 | R18: 200
A19: Gamma-Octadecatriensäure | B19: Final Conc. | C19: ='data processing'!C19/1000 -> 305.84903 | D19: ='data processing'!D19/1000 -> 196.0604 | E19: ='data processing'!E19/1000 -> 0.136559 | F19: ='data processing'!F19/1000 -> 0.3357648 | G19: ='data processing'!G19/1000 -> 0.4308686 | H19: ='data processing'!H19/1000 -> 0 | I19: ='data processing'!I19/1000 -> 0 | J19: ='data processing'!J19/1000 -> 0 | ... P19: ='data processing'!P19/1000 -> 0.2877425 | R19: 200
A20: Alpha-Octadecatriensäure | B20: Final Conc. | C20: ='data processing'!C20/1000 -> 2176.6076 | D20: ='data processing'!D20/1000 -> 585.32523 | E20: ='data processing'!E20/1000 -> 133.34796 | F20: ='data processing'!F20/1000 -> 104.08387 | G20: ='data processing'!G20/1000 -> 99.081575 | H20: ='data processing'!H20/1000 -> 47.159155 | I20: ='data processing'!I20/1000 -> 166.60551 | J20: ='data processing'!J20/1000 -> 287.09124 | ... P20: ='data processing'!P20/1000 -> 58.885053 | R20: 200
A21: 6,9,12,15-Octadecatetraensäure | B21: Final Conc. | C21: ='data processing'!C21/1000 -> 622.93196 | D21: ='data processing'!D21/1000 -> 111.42746 | E21: ='data processing'!E21/1000 -> 0.292095 | F21: ='data processing'!F21/1000 -> 7.3226683 | G21: ='data processing'!G21/1000 -> 5.2815358 | H21: ='data processing'!H21/1000 -> 0.3006912 | I21: ='data processing'!I21/1000 -> 7.7271551 | J21: ='data processing'!J21/1000 -> 15.249481 | ... P21: ='data processing'!P21/1000 -> 0.2210108
A22: Eicosansäure | B22: Final Conc. | C22: ='data processing'!C22/1000 -> 183.32479 | D22: ='data processing'!D22/1000 -> 282.96403 | E22: ='data processing'!E22/1000 -> 1.6474803 | F22: ='data processing'!F22/1000 -> 4.0706527 | G22: ='data processing'!G22/1000 -> 4.5533488 | H22: ='data processing'!H22/1000 -> 4.3721038 | I22: ='data processing'!I22/1000 -> 1.6190281 | J22: ='data processing'!J22/1000 -> 1.878904 | ... P22: ='data processing'!P22/1000 -> 1.667225 | R22: 400
A23: Cis-11-Eicosensäure | B23: Final Conc. | C23: ='data processing'!C23/1000 -> 42.933051 | D23: ='data processing'!D23/1000 -> 52.272809 | E23: ='data processing'!E23/1000 -> 10.710388 | F23: ='data processing'!F23/1000 -> 21.279575 | G23: ='data processing'!G23/1000 -> 17.802877 | H23: ='data processing'!H23/1000 -> 11.019554 | I23: ='data processing'!I23/1000 -> 20.491605 | J23: ='data processing'!J23/1000 -> 29.647236 | ... P23: ='data processing'!P23/1000 -> 8.6941005 | R23: 200
A24: Cis-11,14-Eicosadiensäure | B24: Final Conc. | C24: ='data processing'!C24/1000 -> 180.91098 | D24: ='data processing'!D24/1000 -> 114.46691 | E24: ='data processing'!E24/1000 -> 24.53345 | F24: ='data processing'!F24/1000 -> 24.929061 | G24: ='data processing'!G24/1000 -> 21.818282 | H24: ='data processing'!H24/1000 -> 24.662934 | I24: ='data processing'!I24/1000 -> 33.882981 | J24: ='data processing'!J24/1000 -> 63.398295 | ... P24: ='data processing'!P24/1000 -> 13.882108 | R24: 200
A25: Cis-8,11,14-Eisocatriensäure | B25: Final Conc. | C25: ='data processing'!C25/1000 -> 439.24658 | D25: ='data processing'!D25/1000 -> 75.327796 | E25: ='data processing'!E25/1000 -> 0.4183594 | F25: ='data processing'!F25/1000 -> 13.354016 | G25: ='data processing'!G25/1000 -> 23.216803 | H25: ='data processing'!H25/1000 -> 0.4180562 | I25: ='data processing'!I25/1000 -> 0.4095625 | J25: ='data processing'!J25/1000 -> 13.192751 | ... P25: ='data processing'!P25/1000 -> 0.3783318 | R25: 200
A26: Cis-5,8,11,14-Eicosatetraensäure | B26: Final Conc. | C26: ='data processing'!C26/1000 -> 299.165 | D26: ='data processing'!D26/1000 -> 267.83357 | E26: ='data processing'!E26/1000 -> 195.64501 | F26: ='data processing'!F26/1000 -> 98.921193 | G26: ='data processing'!G26/1000 -> 160.35486 | H26: ='data processing'!H26/1000 -> 149.44635 | I26: ='data processing'!I26/1000 -> 157.60362 | J26: ='data processing'!J26/1000 -> 367.91714 | ... P26: ='data processing'!P26/1000 -> 131.80892 | R26: 200
A27: Cis-11,14,17-Eicosatriensäure | B27: Final Conc. | C27: ='data processing'!C27/1000 -> 129.35909 | D27: ='data processing'!D27/1000 -> 81.066609 | E27: ND | F27: ND | G27: ND | H27: ND | I27: ND | J27: ND | K27: ND | L27: ND | M27: ND | N27: ND | O27: ND | P27: ND | R27: 200
A28: Heneicosansäure | B28: Final Conc. | C28: ='data processing'!C28/1000 -> 48.894417 | D28: ='data processing'!D28/1000 -> 126.84634 | E28: ='data processing'!E28/1000 -> 0 | F28: ='data processing'!F28/1000 -> 0 | G28: ='data processing'!G28/1000 -> 0 | H28: ='data processing'!H28/1000 -> 0 | I28: ='data processing'!I28/1000 -> 0 | J28: ='data processing'!J28/1000 -> 0 | ... O28: ='data processing'!O28/1000 -> 0 | P28: ND | R28: 200
A29: Cis-5,8,11,14,17-Eicosapentaensäure | B29: Final Conc. | C29: ='data processing'!C29/1000 -> 522.40696 | D29: ='data processing'!D29/1000 -> 178.97492 | E29: ='data processing'!E29/1000 -> 157.84263 | F29: ='data processing'!F29/1000 -> 114.14139 | G29: ='data processing'!G29/1000 -> 139.50635 | H29: ='data processing'!H29/1000 -> 126.52346 | I29: ='data processing'!I29/1000 -> 143.94917 | J29: ='data processing'!J29/1000 -> 251.23453 | ... P29: ='data processing'!P29/1000 -> 123.66643 | R29: 200
A30: Docosansäure | B30: Final Conc. | C30: ='data processing'!C30/1000 -> 688.97135 | D30: ='data processing'!D30/1000 -> 170.57678 | E30: ='data processing'!E30/1000 -> 0 | F30: ='data processing'!F30/1000 -> 0 | G30: ='data processing'!G30/1000 -> 0 | H30: ='data processing'!H30/1000 -> 0 | I30: ='data processing'!I30/1000 -> 0 | J30: ='data processing'!J30/1000 -> 0 | ... P30: ='data processing'!P30/1000 -> 0 | R30: 200
A31: 13-Docosensäure | B31: Final Conc. | C31: ='data processing'!C31/1000 -> 280.58921 | D31: ='data processing'!D31/1000 -> 113.99086 | E31: ='data processing'!E31/1000 -> 107.58593 | F31: ='data processing'!F31/1000 -> 94.65723 | G31: ='data processing'!G31/1000 -> 87.345972 | H31: ='data processing'!H31/1000 -> 91.903609 | I31: ='data processing'!I31/1000 -> 90.412011 | J31: ='data processing'!J31/1000 -> 91.465663 | ... P31: ='data processing'!P31/1000 -> 64.393456 | R31: 400
A32: Cis-13,16-Docosadiensäure | B32: Final Conc. | C32: ='data processing'!C32/1000 -> 591.56431 | D32: ='data processing'!D32/1000 -> 100.51727 | E32: ='data processing'!E32/1000 -> 1.9889567 | F32: ='data processing'!F32/1000 -> 1.8106107 | G32: ='data processing'!G32/1000 -> 1.9278414 | H32: ='data processing'!H32/1000 -> 1.8321543 | I32: ='data processing'!I32/1000 -> 1.9176789 | J32: ='data processing'!J32/1000 -> 1.9278394 | ... P32: ='data processing'!P32/1000 -> 6.6324365 | R32: 200
A33: Cis-7,10,13,16,19-Docosapentaensäure | B33: Final Conc. | C33: ='data processing'!C33/1000 -> 765.21282 | D33: ='data processing'!D33/1000 -> 33.518709 | E33: ='data processing'!E33/1000 -> 4.0482913 | F33: ='data processing'!F33/1000 -> 3.0131136 | G33: ='data processing'!G33/1000 -> 4.9184707 | H33: ='data processing'!H33/1000 -> 4.4184021 | I33: ='data processing'!I33/1000 -> 3.7375247 | J33: ='data processing'!J33/1000 -> 13.474855 | ... P33: ='data processing'!P33/1000 -> 3.986333
A34: Cis-4,7,10,13,16,19-Docosahexaensäure | B34: Final Conc. | C34: ='data processing'!C34/1000 -> 982.1714 | D34: ='data processing'!D34/1000 -> 87.544902 | E34: ='data processing'!E34/1000 -> 3.1930093 | F34: ='data processing'!F34/1000 -> 1.1864359 | G34: ='data processing'!G34/1000 -> 3.9590977 | H34: ='data processing'!H34/1000 -> 4.6642734 | I34: ='data processing'!I34/1000 -> 2.8398957 | J34: ='data processing'!J34/1000 -> 16.621491 | ... P34: ='data processing'!P34/1000 -> 2.52481 | R34: 200
A35: Tetracosansäure | B35: Final Conc. | C35: ='data processing'!C35/1000 -> 1166.2768 | D35: ='data processing'!D35/1000 -> 650.40448 | E35: ='data processing'!E35/1000 -> 4.4918995 | F35: ='data processing'!F35/1000 -> 0 | G35: ='data processing'!G35/1000 -> 7.215856 | H35: ='data processing'!H35/1000 -> 0 | I35: ='data processing'!I35/1000 -> 6.684108 | J35: ='data processing'!J35/1000 -> 11.363155 | ... P35: ='data processing'!P35/1000 -> 0 | R35: 400
A36: Cis-15-Tetracosensäure | B36: Final Conc. | C36: ='data processing'!C36/1000 -> 203.05869 | D36: ='data processing'!D36/1000 -> 12.422542 | E36: ='data processing'!E36/1000 -> 0 | F36: ='data processing'!F36/1000 -> 0 | G36: ='data processing'!G36/1000 -> 0 | H36: ='data processing'!H36/1000 -> 0 | I36: ='data processing'!I36/1000 -> 0 | J36: ='data processing'!J36/1000 -> 0 | ... P36: ='data processing'!P36/1000 -> 0 | R36: 200

Sheet data processing
A1: FAME | B1: Data File | C1: blank230704.D | D1: MEGA-Mix_230704.D | E1: Pro8.D | F1: Pro9.D | G1: Pro18.D | H1: Pro20D.D | I1: Pro21.D | J1: Pro23.D | K1: Pro24.D | L1: Pro26.D | M1: Mix4.D | N1: Mix7.D | O1: Mix9.D | P1: Mix10.D | R1: ISD( µ/ml)
A2: Octansäure | B2: Final Conc. | C2: 1948686 | D2: 389502.08 | E2: 6740.0191 | F2: 6679.0025 | G2: 6653.162 | H2: 6703.9619 | I2: 6672.4949 | J2: 6731.7057 | K2: 6686.0376 | L2: 6693.537 | M2: 6691.2444 | N2: 6593.3497 | O2: 6681.6577 | P2: 6696.6999 | R2: 400
A3: Decansäure | B3: Final Conc. | C3: 494685.7 | D3: 392138.2 | E3: 0 | F3: 0 | G3: 0 | H3: 0 | I3: 0 | J3: 0 | K3: 0 | L3: 0 | M3: 0 | N3: 0 | O3: 0 | P3: 0 | R3: 400
A4: Undecansäure | B4: Final Conc. | C4: 473099.64 | D4: 191157.99 | E4: 0 | F4: 0 | G4: 0 | H4: 0 | I4: 0 | J4: 0 | K4: 0 | L4: 0 | M4: 0 | N4: 0 | O4: 0 | P4: 0 | R4: 200
A5: Dodecansäure | B5: Final Conc. | C5: 60663.514 | D5: 263346.95 | E5: 0 | F5: 0 | G5: 0 | H5: 0 | I5: 0 | J5: 0 | K5: 0 | L5: 0 | M5: 0 | N5: 0 | O5: 0 | P5: 0 | R5: 400
A6: Tridecansäure | B6: Final Conc. | C6: 578707.8 | D6: 111842.34 | E6: 0 | F6: 0 | G6: 0 | H6: 0 | I6: 0 | J6: 0 | K6: 0 | L6: 0 | M6: 0 | N6: 0 | O6: 0 | P6: 0 | R6: 200
A7: Tetradecansäure | B7: Final Conc. | C7: 51860.62 | D7: 296029.96 | E7: 0 | F7: 506.4356 | G7: 0 | H7: 0 | I7: 0 | J7: 24.8369 | K7: 419.525 | L7: 0 | M7: 0 | N7: 6197.3529 | O7: 0 | P7: 0 | R7: 400
A8: 9-Tetradecensäure | B8: Final Conc. | C8: 491611.46 | D8: 166629.4 | E8: ND | F8: 0 | G8: 0 | H8: 0 | I8: 0 | J8: 0 | K8: 0 | L8: 0 | M8: 0 | N8: 0 | O8: 0 | P8: 0 | R8: 200
A9: Pentadecansäure | B9: Final Conc. | C9: 2580132.5 | D9: 125002.05 | E9: 0 | F9: 1651.7376 | G9: 0 | H9: 0 | I9: 1820.6234 | J9: 2966.7627 | K9: 1500.6907 | L9: 1090.0266 | M9: 0 | N9: 1657.4317 | O9: 0 | P9: 0 | R9: 200
A10: Cis-10-Pentadecensäure | B10: Final Conc. | C10: 254793.95 | D10: 160772.09 | E10: 0 | F10: 0 | G10: 0 | H10: 0 | I10: 0 | J10: 1066.2697 | K10: 0 | L10: 0 | M10: 0 | N10: 0 | O10: 0 | P10: 0 | R10: 200
A11: Hexadecansäure | B11: Final Conc. | C11: 237350.54 | D11: 1856264.6 | E11: 1648131.3 | F11: 1827827.4 | G11: 1273948.3 | H11: 872074.61 | I11: 1721257 | J11: 2278486.3 | K11: 1960617.7 | L11: 1710161 | M11: 1110628.4 | N11: 1687498.1 | O11: 1279913.8 | P11: 1068966.4 | R11: 600
A12: Cis-9-Hexadecensäure | B12: Final Conc. | C12: 326104.68 | D12: 164720.18 | E12: 113686.72 | F12: 277207.92 | G12: 104407.64 | H12: 18949.193 | I12: 232151.32 | J12: 365005.61 | K12: 252239.01 | L12: 150109.76 | M12: 37103.08 | N12: 224296.16 | O12: 95966.261 | P12: 75519.233 | R12: 200
A13: Heptadecansäure | B13: Final Conc. | C13: 13201.698 | D13: 154223.5 | E13: 12215.631 | F13: 11231.103 | G13: 12699.737 | H13: 8622.144 | I13: 12726.906 | J13: 20946.637 | K13: 16220.191 | L13: 13230.699 | M13: 10003.223 | N13: 10630.903 | O13: 8038.9314 | P13: 8251.2096 | R13: 200
A14: Cis-10-Heptadecensäure | B14: Final Conc. | C14: 634262.26 | D14: 222811.2 | E14: 0 | F14: 0 | G14: 0 | H14: 0 | I14: 0 | J14: 0 | K14: 0 | L14: 0 | M14: 0 | N14: 0 | O14: 0 | P14: 0 | R14: 200
A15: Octadecansäure | B15: Final Conc. | C15: 120151.6 | D15: 418725.26 | E15: 452606.78 | F15: 380289.59 | G15: 391031.93 | H15: 312442.81 | I15: 362598.08 | J15: 446843.93 | K15: 411915.69 | L15: 377284.24 | M15: 337830.78 | N15: 346612.9 | O15: 329603.56 | P15: 304742.07 | R15: 400
A16: Cis-9-Octadecensäure | B16: Final Conc. | C16: 1274261.3 | D16: 476288.34 | E16: 97155.765 | F16: 461274.57 | G16: 122144.28 | H16: 32458.587 | I16: 506490.61 | J16: 560313.24 | K16: 466990.04 | L16: 438843.99 | M16: 136768.58 | N16: 291317.29 | O16: 211694.54 | P16: 186022.61 | R16: 400
A17: Octadeca-9,12-diensäure (trans) | B17: Final Conc. | C17: 382311.83 | D17: 71494.128 | E17: 345.0925 | F17: 345.6901 | G17: 532.0104 | H17: 350.9915 | I17: 344.5315 | J17: 355.3177 | K17: 333.3663 | L17: 372.8052 | M17: 1085.2927 | N17: 381.5171 | O17: 508.2623 | P17: 376.5374 | R17: 200
A18: Octadeca-9,12-diensäure (cis) | B18: Final Conc. | C18: 45013.387 | D18: 192178.04 | E18: 164287.77 | F18: 147447.57 | G18: 116935.34 | H18: 91481.604 | I18: 202518.21 | J18: 288683.39 | K18: 195887.55 | L18: 236212.1 | M18: 94392.74 | N18: 138782.68 | O18: 67669.773 | P18: 83153.325 | R18: 200
A19: Gamma-Octadecatriensäure | B19: Final Conc. | C19: 305849.03 | D19: 196060.4 | E19: 136.559 | F19: 335.7648 | G19: 430.8686 | H19: 0 | I19: 0 | J19: 0 | K19: 0 | L19: 0 | M19: 251.9983 | N19: 216.7068 | O19: 0 | P19: 287.7425 | R19: 200
A20: Alpha-Octadecatriensäure | B20: Final Conc. | C20: 2176607.6 | D20: 585325.23 | E20: 133347.96 | F20: 104083.87 | G20: 99081.575 | H20: 47159.155 | I20: 166605.51 | J20: 287091.24 | K20: 132598.77 | L20: 171019.5 | M20: 57832.197 | N20: 114662.43 | O20: 59032.133 | P20: 58885.052 | R20: 200
A21: 6,9,12,15-Octadecatetraensäure | B21: Final Conc. | C21: 622931.96 | D21: 111427.46 | E21: 292.095 | F21: 7322.6683 | G21: 5281.5358 | H21: 300.6912 | I21: 7727.1551 | J21: 15249.481 | K21: 6570.3067 | L21: 9464.0801 | M21: 211.0827 | N21: 5783.1597 | O21: 297.1855 | P21: 221.0108
A22: Eicosansäure | B22: Final Conc. | C22: 183324.79 | D22: 282964.03 | E22: 1647.4803 | F22: 4070.6527 | G22: 4553.3488 | H22: 4372.1038 | I22: 1619.0281 | J22: 1878.904 | K22: 5474.01 | L22: 1726.7209 | M22: 2071.5762 | N22: 1499.4907 | O22: 1643.5929 | P22: 1667.225 | R22: 400
A23: Cis-11-Eicosensäure | B23: Final Conc. | C23: 42933.051 | D23: 52272.809 | E23: 10710.388 | F23: 21279.575 | G23: 17802.877 | H23: 11019.553 | I23: 20491.605 | J23: 29647.236 | K23: 21444.904 | L23: 18148.003 | M23: 4555.5887 | N23: 6950.3088 | O23: 5938.5384 | P23: 8694.1005 | R23: 200
A24: Cis-11,14-Eicosadiensäure | B24: Final Conc. | C24: 180910.98 | D24: 114466.91 | E24: 24533.45 | F24: 24929.061 | G24: 21818.282 | H24: 24662.934 | I24: 33882.981 | J24: 63398.295 | K24: 30314.279 | L24: 23243.829 | M24: 16648.694 | N24: 23006.789 | O24: 10948.487 | P24: 13882.108 | R24: 200
A25: Cis-8,11,14-Eisocatriensäure | B25: Final Conc. | C25: 439246.58 | D25: 75327.796 | E25: 418.3594 | F25: 13354.016 | G25: 23216.803 | H25: 418.0562 | I25: 409.5625 | J25: 13192.751 | K25: 419.3208 | L25: 242.651 | M25: 413.0237 | N25: 425.7811 | O25: 521.4517 | P25: 378.3318 | R25: 200
A26: Cis-5,8,11,14-Eicosatetraensäure | B26: Final Conc. | C26: 299165 | D26: 267833.57 | E26: 195645.01 | F26: 98921.193 | G26: 160354.86 | H26: 149446.35 | I26: 157603.62 | J26: 367917.14 | K26: 202207.12 | L26: 173340.98 | M26: 187461.34 | N26: 160810.28 | O26: 118617.29 | P26: 131808.92 | R26: 200
A27: Cis-11,14,17-Eicosatriensäure | B27: Final Conc. | C27: 129359.09 | D27: 81066.609 | E27: ND | F27: ND | G27: ND | H27: ND | I27: ND | J27: ND | K27: ND | L27: ND | M27: ND | N27: ND | O27: ND | P27: ND | R27: 200
A28: Heneicosansäure | B28: Final Conc. | C28: 48894.417 | D28: 126846.34 | E28: 0 | F28: 0 | G28: 0 | H28: 0 | I28: 0 | J28: 0 | K28: 0 | L28: 0 | M28: 0 | N28: 0 | O28: 0 | P28: ND | R28: 200
A29: Cis-5,8,11,14,17-Eicosapentaensäure | B29: Final Conc. | C29: 522406.96 | D29: 178974.92 | E29: 157842.63 | F29: 114141.39 | G29: 139506.35 | H29: 126523.46 | I29: 143949.17 | J29: 251234.53 | K29: 162099.77 | L29: 164799.66 | M29: 141163.81 | N29: 146071.62 | O29: 102969.62 | P29: 123666.43 | R29: 200
A30: Docosansäure | B30: Final Conc. | C30: 688971.35 | D30: 170576.78 | E30: 0 | F30: 0 | G30: 0 | H30: 0 | I30: 0 | J30: 0 | K30: 0 | L30: 0 | M30: 0 | N30: 0 | O30: 0 | P30: 0 | R30: 200
A31: 13-Docosensäure | B31: Final Conc. | C31: 280589.21 | D31: 113990.86 | E31: 107585.93 | F31: 94657.23 | G31: 87345.972 | H31: 91903.609 | I31: 90412.011 | J31: 91465.663 | K31: 74956.481 | L31: 69208.523 | M31: 75827.078 | N31: 69840.765 | O31: 57916.578 | P31: 64393.456 | R31: 400
A32: Cis-13,16-Docosadiensäure | B32: Final Conc. | C32: 591564.31 | D32: 100517.27 | E32: 1988.9567 | F32: 1810.6107 | G32: 1927.8414 | H32: 1832.1543 | I32: 1917.6789 | J32: 1927.8394 | K32: 1952.8508 | L32: 1831.1798 | M32: 7360.196 | N32: 7966.8602 | O32: 5718.5781 | P32: 6632.4365 | R32: 200
A33: Cis-7,10,13,16,19-Docosapentaensäure | B33: Final Conc. | C33: 765212.82 | D33: 33518.709 | E33: 4048.2913 | F33: 3013.1136 | G33: 4918.4707 | H33: 4418.4021 | I33: 3737.5247 | J33: 13474.855 | K33: 5835.5874 | L33: 4613.6171 | M33: 4787.6171 | N33: 3708.5179 | O33: 2629.2755 | P33: 3986.333
A34: Cis-4,7,10,13,16,19-Docosahexaensäure | B34: Final Conc. | C34: 982171.4 | D34: 87544.902 | E34: 3193.0093 | F34: 1186.4359 | G34: 3959.0977 | H34: 4664.2734 | I34: 2839.8957 | J34: 16621.491 | K34: 6262.942 | L34: 4292.6268 | M34: 5797.3578 | N34: 2745.2621 | O34: 1612.0171 | P34: 2524.81 | R34: 200
A35: Tetracosansäure | B35: Final Conc. | C35: 1166276.8 | D35: 650404.48 | E35: 4491.8995 | F35: 0 | G35: 7215.856 | H35: 0 | I35: 6684.108 | J35: 11363.155 | K35: 8227.9948 | L35: 5959.2394 | M35: 0 | N35: 6042.8266 | O35: 0 | P35: 0 | R35: 400
A36: Cis-15-Tetracosensäure | B36: Final Conc. | C36: 203058.69 | D36: 12422.542 | E36: 0 | F36: 0 | G36: 0 | H36: 0 | I36: 0 | J36: 0 | K36: 0 | L36: 0 | M36: 0 | N36: 0 | O36: 0 | P36: 0 | R36: 200

Sheet raw data
A2: Octansäure | B2: Data File | C2: blank230704.D | D2: MEGA-Mix_230704.D | E2: Pro8.D | F2: Pro9.D | G2: Pro18.D | H2: Pro20D.D | I2: Pro21.D | J2: Pro23.D | K2: Pro24.D | L2: Pro26.D | M2: Mix4.D | N2: Mix7.D | O2: Mix9.D | P2: Mix10.D
B3: Type | C3: Blank | D3: Sample | E3: Sample | F3: Sample | G3: Sample | H3: Sample | I3: Sample | J3: Sample | K3: Sample | L3: Sample | M3: Sample | N3: Sample | O3: Sample | P3: Sample
B4: ISTD | C4: Nonadecansäure | D4: Nonadecansäure | E4: Nonadecansäure | F4: Nonadecansäure | G4: Nonadecansäure | H4: Nonadecansäure | I4: Nonadecansäure | J4: Nonadecansäure | K4: Nonadecansäure | L4: Nonadecansäure | M4: Nonadecansäure | N4: Nonadecansäure | O4: Nonadecansäure | P4: Nonadecansäure
B5: RT | C5: 4.201 | D5: 4.185 | E5: 4.17 | F5: 4.185 | G5: 4.196 | H5: 4.174 | I5: 4.192 | J5: 4.19 | K5: 4.176 | L5: 4.171 | M5: 4.173 | N5: 4.127 | O5: 4.201 | P5: 4.176
B6: Resp. | C6: 3744 | D6: 31791078 | E6: 2614 | F6: 2292 | G6: 967 | H6: 3236 | I6: 1875 | J6: 4759 | K6: 2371 | L6: 2298 | M6: 2609 | N6: -1639 | O6: 1357 | P6: 2569
B7: ISTD Resp | C7: 1012 | D7: 43592922 | E7: 12892209 | F7: 26499925 | G7: 25925002 | H7: 24140173 | I7: 25305784 | J7: 25464532 | K7: 23730137 | L7: 20123963 | M7: 23760706 | N7: 21389880 | O7: 14817197 | P7: 21371364
B8: RR | C8: 3.6991 | D8: 0.7293 | E8: 0.0002 | F8: 0.0001 | G8: 0 | H8: 0.0001 | I8: 0.0001 | J8: 0.0002 | K8: 0.0001 | L8: 0.0001 | M8: 0.0001 | N8: -0.0001 | O8: 0.0001 | P8: 0.0001
B9: Final Conc. | C9: 1948686 | D9: 389502.08 | E9: 6740.0191 | F9: 6679.0025 | G9: 6653.162 | H9: 6703.9619 | I9: 6672.4949 | J9: 6731.7057 | K9: 6686.0376 | L9: 6693.537 | M9: 6691.2444 | N9: 6593.3497 | O9: 6681.6577 | P9: 6696.6999
A10: Decansäure | B10: Data File | C10: blank230704.D | D10: MEGA-Mix_230704.D | E10: Pro8.D | F10: Pro9.D | G10: Pro18.D | H10: Pro20D.D | I10: Pro21.D | J10: Pro23.D | K10: Pro24.D | L10: Pro26.D | M10: Mix4.D | N10: Mix7.D | O10: Mix9.D | P10: Mix10.D
B11: Type | C11: Blank | D11: Sample | E11: Sample | F11: Sample | G11: Sample | H11: Sample | I11: Sample | J11: Sample | K11: Sample | L11: Sample | M11: Sample | N11: Sample | O11: Sample | P11: Sample
B12: ISTD | C12: Nonadecansäure | D12: Nonadecansäure | E12: Nonadecansäure | F12: Nonadecansäure | G12: Nonadecansäure | H12: Nonadecansäure | I12: Nonadecansäure | J12: Nonadecansäure | K12: Nonadecansäure | L12: Nonadecansäure | M12: Nonadecansäure | N12: Nonadecansäure | O12: Nonadecansäure | P12: Nonadecansäure
B13: RT | C13: 5.296 | D13: 5.35 | E13: 5.339 | F13: 5.336 | G13: 5.341 | H13: 4.543 | I13: 5.289 | J13: 5.364 | K13: 5.388 | L13: 5.366 | M13: 5.331 | N13: 5.359 | O13: 5.106 | P13: 5.372
B14: Resp. | C14: 734 | D14: 25080891 | E14: 2837 | F14: 2952 | G14: 6274 | H14: 2968 | I14: 3202 | J14: 2638 | K14: 3490 | L14: 1970 | M14: 8442 | N14: 1023 | O14: 634 | P14: 837
B15: ISTD Resp | C15: 1012 | D15: 43592922 | E15: 12892209 | F15: 26499925 | G15: 25925002 | H15: 24140173 | I15: 25305784 | J15: 25464532 | K15: 23730137 | L15: 20123963 | M15: 23760706 | N15: 21389880 | O15: 14817197 | P15: 21371364
B16: RR | C16: 0.7252 | D16: 0.5753 | E16: 0.0002 | F16: 0.0001 | G16: 0.0002 | H16: 0.0001 | I16: 0.0001 | J16: 0.0001 | K16: 0.0001 | L16: 0.0001 | M16: 0.0004 | N16: 0 | O16: 0 | P16: 0
B17: Final Conc. | C17: 494685.7 | D17: 392138.2 | E17: 0 | F17: 0 | G17: 0 | H17: 0 | I17: 0 | J17: 0 | K17: 0 | L17: 0 | M17: 0 | N17: 0 | O17: 0 | P17: 0
A18: Undecansäure | B18: Data File | C18: blank230704.D | D18: MEGA-Mix_230704.D | E18: Pro8.D | F18: Pro9.D | G18: Pro18.D | H18: Pro20D.D | I18: Pro21.D | J18: Pro23.D | K18: Pro24.D | L18: Pro26.D | M18: Mix4.D | N18: Mix7.D | O18: Mix9.D | P18: Mix10.D
B19: Type | C19: Blank | D19: Sample | E19: Sample | F19: Sample | G19: Sample | H19: Sample | I19: Sample | J19: Sample | K19: Sample | L19: Sample | M19: Sample | N19: Sample | O19: Sample | P19: Sample
B20: ISTD | C20: Nonadecansäure | D20: Nonadecansäure | E20: Nonadecansäure | F20: Nonadecansäure | G20: Nonadecansäure | H20: Nonadecansäure | I20: Nonadecansäure | J20: Nonadecansäure | K20: Nonadecansäure | L20: Nonadecansäure | M20: Nonadecansäure | N20: Nonadecansäure | O20: Nonadecansäure | P20: Nonadecansäure
B21: RT | C21: 6.167 | D21: 6.158 | E21: 6.187 | F21: 6.175 | G21: 6.168 | H21: 6.161 | I21: 6.146 | J21: 6.172 | K21: 6.181 | L21: 6.186 | M21: 6.187 | N21: 6.156 | O21: 6.181 | P21: 6.161
B22: Resp. | C22: 1393 | D22: 24352988 | E22: 2504 | F22: 3299 | G22: 3337 | H22: 2904 | I22: 3116 | J22: 958 | K22: 13515 | L22: 1265 | M22: 1657 | N22: 2865 | O22: 2056 | P22: 3064
B23: ISTD Resp | C23: 1012 | D23: 43592922 | E23: 12892209 | F23: 26499925 | G23: 25925002 | H23: 24140173 | I23: 25305784 | J23: 25464532 | K23: 23730137 | L23: 20123963 | M23: 23760706 | N23: 21389880 | O23: 14817197 | P23: 21371364
B24: RR | C24: 1.3765 | D24: 0.5586 | E24: 0.0002 | F24: 0.0001 | G24: 0.0001 | H24: 0.0001 | I24: 0.0001 | J24: 0 | K24: 0.0006 | L24: 0.0001 | M24: 0.0001 | N24: 0.0001 | O24: 0.0001 | P24: 0.0001
B25: Final Conc. | C25: 473099.64 | D25: 191157.99 | E25: 0 | F25: 0 | G25: 0 | H25: 0 | I25: 0 | J25: 0 | K25: 0 | L25: 0 | M25: 0 | N25: 0 | O25: 0 | P25: 0
A26: Dodecansäure | B26: Data File | C26: blank230704.D | D26: MEGA-Mix_230704.D | E26: Pro8.D | F26: Pro9.D | G26: Pro18.D | H26: Pro20D.D | I26: Pro21.D | J26: Pro23.D | K26: Pro24.D | L26: Pro26.D | M26: Mix4.D | N26: Mix7.D | O26: Mix9.D | P26: Mix10.D
B27: Type | C27: Blank | D27: Sample | E27: Sample | F27: Sample | G27: Sample | H27: Sample | I27: Sample | J27: Sample | K27: Sample | L27: Sample | M27: Sample | N27: Sample | O27: Sample | P27: Sample
B28: ISTD | C28: Nonadecansäure | D28: Nonadecansäure | E28: Nonadecansäure | F28: Nonadecansäure | G28: Nonadecansäure | H28: Nonadecansäure | I28: Nonadecansäure | J28: Nonadecansäure | K28: Nonadecansäure | L28: Nonadecansäure | M28: Nonadecansäure | N28: Nonadecansäure | O28: Nonadecansäure | P28: Nonadecansäure
B29: RT | C29: 7.478 | D29: 7.269 | E29: 7.487 | F29: 7.46 | G29: 7.482 | H29: 7.482 | I29: 7.499 | J29: 7.462 | K29: 7.488 | L29: 7.474 | M29: 7.272 | N29: 7.236 | O29: 7.482 | P29: 7.487
B30: Resp. | C30: 1146 | D30: 194786959 | E30: 2421 | F30: 925 | G30: 1007 | H30: 1997 | I30: 1428 | J30: 1125 | K30: 2363 | L30: 446 | M30: 214554 | N30: 142197 | O30: 668 | P30: 594
B31: ISTD Resp | C31: 1012 | D31: 43592922 | E31: 12892209 | F31: 26499925 | G31: 25925002 | H31: 24140173 | I31: 25305784 | J31: 25464532 | K31: 23730137 | L31: 20123963 | M31: 23760706 | N31: 21389880 | O31: 14817197 | P31: 21371364
B32: RR | C32: 1.1323 | D32: 4.4683 | E32: 0.0002 | F32: 0 | G32: 0 | H32: 0.0001 | I32: 0.0001 | J32: 0 | K32: 0.0001 | L32: 0 | M32: 0.009 | N32: 0.0066 | O32: 0 | P32: 0
B33: Final Conc. | C33: 60663.514 | D33: 263346.95 | E33: 0 | F33: 0 | G33: 0 | H33: 0 | I33: 0 | J33: 0 | K33: 0 | L33: 0 | M33: 0 | N33: 0 | O33: 0 | P33: 0
A34: Tridecansäure | B34: Data File | C34: blank230704.D | D34: MEGA-Mix_230704.D | E34: Pro8.D | F34: Pro9.D | G34: Pro18.D | H34: Pro20D.D | I34: Pro21.D | J34: Pro23.D | K34: Pro24.D | L34: Pro26.D | M34: Mix4.D | N34: Mix7.D | O34: Mix9.D | P34: Mix10.D
B35: Type | C35: Blank | D35: Sample | E35: Sample | F35: Sample | G35: Sample | H35: Sample | I35: Sample | J35: Sample | K35: Sample | L35: Sample | M35: Sample | N35: Sample | O35: Sample | P35: Sample
B36: ISTD | C36: Nonadecansäure | D36: Nonadecansäure | E36: Nonadecansäure | F36: Nonadecansäure | G36: Nonadecansäure | H36: Nonadecansäure | I36: Nonadecansäure | J36: Nonadecansäure | K36: Nonadecansäure | L36: Nonadecansäure | M36: Nonadecansäure | N36: Nonadecansäure | O36: Nonadecansäure | P36: Nonadecansäure
B37: RT | C37: 8.758 | D37: 8.772 | E37: 9.073 | F37: 9.044 | G37: 9.037 | H37: 9.046 | I37: 9.041 | J37: 9.021 | K37: 9.059 | L37: 9.046 | M37: 9.085 | N37: 9.051 | O37: 9.034 | P37: 9.013
B38: Resp. | C38: 3427 | D38: 28777394 | E38: 1676 | F38: 1631 | G38: 5078 | H38: 4104 | I38: 1235 | J38: 3132 | K38: 7174 | L38: 6090 | M38: 3423 | N38: 2193 | O38: 1813 | P38: 3056
B39: ISTD Resp | C39: 1012 | D39: 43592922 | E39: 12892209 | F39: 26499925 | G39: 25925002 | H39: 24140173 | I39: 25305784 | J39: 25464532 | K39: 23730137 | L39: 20123963 | M39: 23760706 | N39: 21389880 | O39: 14817197 | P39: 21371364
B40: RR | C40: 3.3857 | D40: 0.6601 | E40: 0.0001 | F40: 0.0001 | G40: 0.0002 | H40: 0.0002 | I40: 0 | J40: 0.0001 | K40: 0.0003 | L40: 0.0003 | M40: 0.0001 | N40: 0.0001 | O40: 0.0001 | P40: 0.0001
B41: Final Conc. | C41: 578707.8 | D41: 111842.34 | E41: 0 | F41: 0 | G41: 0 | H41: 0 | I41: 0 | J41: 0 | K41: 0 | L41: 0 | M41: 0 | N41: 0 | O41: 0 | P41: 0
...

Sheet 230704_FA-Quant-Report_ISTD
A1: Batch Data Path | B1: D:\MassHunter\GCMS\1\data\Sophie_Landau\230704\QuantResults\230704.batch.bin
A2: Analysis Time | B2: 45161.634 | C2: Analyst Name | D2: FLOEK026\install | E2: Report Generator Name | F2: FLOEK026\install
A3: Calibration Last Update | B3: 45154.569 | C3: Analyze Quant Version | D3: 10.1 | E3: Report Quant Version | F3: 10.2
A4: Sequence Table
A5: Data File | B5: Name | C5: Type | D5: Vial | E5: Vol. | F5: Level | G5: Acq. Method File
A6: blank230704.D | B6: blank | C6: Blank | D6: 1 | E6: 1 | G6: FAME_02_Insert
A8: MEGA-Mix_230704.D | B8: MEGA-Mix | C8: Sample | D8: 2 | E8: 1 | G8: FAME_02_Insert
A10: Pro8.D | B10: Pro8 | C10: Sample | D10: 3 | E10: 1 | G10: FAME_02_Insert
A12: Pro9.D | B12: Pro9 | C12: Sample | D12: 4 | E12: 1 | G12: FAME_02_Insert
A14: Pro18.D | B14: Pro18 | C14: Sample | D14: 5 | E14: 1 | G14: FAME_02_Insert
A16: Pro20D.D | B16: Pro20 | C16: Sample | D16: 6 | E16: 1 | G16: FAME_02_Insert
A18: Pro21.D | B18: Pro21 | C18: Sample | D18: 7 | E18: 1 | G18: FAME_02_Insert
A20: Pro23.D | B20: Pro23 | C20: Sample | D20: 8 | E20: 1 | G20: FAME_02_Insert
A22: Pro24.D | B22: Pro24 | C22: Sample | D22: 9 | E22: 1 | G22: FAME_02_Insert
A24: Pro26.D | B24: Pro26 | C24: Sample | D24: 10 | E24: 1 | G24: FAME_02_Insert
A26: Mix4.D | B26: Mix4 | C26: Sample | D26: 11 | E26: 1 | G26: FAME_02_Insert
A28: Mix7.D | B28: Mix7 | C28: Sample | D28: 12 | E28: 1 | G28: FAME_02_Insert
... A32: Mix10.D | B32: Mix10 | C32: Sample | D32: 14 | E32: 1 | G32: FAME_02_Insert
A34: Octansäure
A35: Data File | B35: Type | C35: ISTD | D35: RT | E35: Resp. | F35: ISTD Resp | G35: RR | H35: Final Conc. | I35: Exp. Conc. | J35: Accuracy
A36: blank230704.D | B36: Blank | C36: Nonadecansäure | D36: 4.201 | E36: 3744 | F36: 1012 | G36: 3.6991 | H36: 1948686
A37: MEGA-Mix_230704.D | B37: Sample | C37: Nonadecansäure | D37: 4.185 | E37: 31791078 | F37: 43592922 | G37: 0.7293 | H37: 389502.08
A38: Pro8.D | B38: Sample | C38: Nonadecansäure | D38: 4.17 | E38: 2614 | F38: 12892209 | G38: 0.0002 | H38: 6740.0191
A39: Pro9.D | B39: Sample | C39: Nonadecansäure | D39: 4.185 | E39: 2292 | F39: 26499925 | G39: 0.0001 | H39: 6679.0025
A40: Pro18.D | B40: Sample | C40: Nonadecansäure | D40: 4.196 | E40: 967 | F40: 25925002 | G40: 0 | H40: 6653.162
A41: Pro20D.D | B41: Sample | C41: Nonadecansäure | D41: 4.174 | E41: 3236 | F41: 24140173 | G41: 0.0001 | H41: 6703.9619
A42: Pro21.D | B42: Sample | C42: Nonadecansäure | D42: 4.192 | E42: 1875 | F42: 25305784 | G42: 0.0001 | H42: 6672.4949
A43: Pro23.D | B43: Sample | C43: Nonadecansäure | D43: 4.19 | E43: 4759 | F43: 25464532 | G43: 0.0002 | H43: 6731.7057
A44: Pro24.D | B44: Sample | C44: Nonadecansäure | D44: 4.176 | E44: 2371 | F44: 23730137 | G44: 0.0001 | H44: 6686.0376
A45: Pro26.D | B45: Sample | C45: Nonadecansäure | D45: 4.171 | E45: 2298 | F45: 20123963 | G45: 0.0001 | H45: 6693.537
A46: Mix4.D | B46: Sample | C46: Nonadecansäure | D46: 4.173 | E46: 2609 | F46: 23760706 | G46: 0.0001 | H46: 6691.2444
A47: Mix7.D | B47: Sample | C47: Nonadecansäure | D47: 4.127 | E47: -1639 | F47: 21389880 | G47: -0.0001 | H47: 6593.3497
... A49: Mix10.D | B49: Sample | C49: Nonadecansäure | D49: 4.176 | E49: 2569 | F49: 21371364 | G49: 0.0001 | H49: 6696.6999
A50: Decansäure
A51: Data File | B51: Type | C51: ISTD | D51: RT | E51: Resp. | F51: ISTD Resp | G51: RR | H51: Final Conc. | I51: Exp. Conc. | J51: Accuracy
A52: blank230704.D | B52: Blank | C52: Nonadecansäure | D52: 5.296 | E52: 734 | F52: 1012 | G52: 0.7252 | H52: 494685.7
A53: MEGA-Mix_230704.D | B53: Sample | C53: Nonadecansäure | D53: 5.35 | E53: 25080891 | F53: 43592922 | G53: 0.5753 | H53: 392138.2
A54: Pro8.D | B54: Sample | C54: Nonadecansäure | D54: 5.339 | E54: 2837 | F54: 12892209 | G54: 0.0002 | H54: 0
A55: Pro9.D | B55: Sample | C55: Nonadecansäure | D55: 5.336 | E55: 2952 | F55: 26499925 | G55: 0.0001 | H55: 0
A56: Pro18.D | B56: Sample | C56: Nonadecansäure | D56: 5.341 | E56: 6274 | F56: 25925002 | G56: 0.0002 | H56: 0
...
