Workbook

Sheet aufgeräumt
A1: FAME (µg/sample) | B1: FAME (µg/sample) | C1: S10.D | D1: S11.D | E1: WBPro1.D | F1: WBMix1.D | G1: WBPro2.D | H1: WBCip1.D | I1: WBMix2.D | J1: WBCip2.D | K1: Blank3.D
A2: Octansäure | B2: C08:0 | C2: 999.99712 | D2: 1677.0532 | E2: 355.12039 | F2: 1633.5655 | G2: 6.7620221 | H2: 6.6707279 | I2: 6.7047424 | J2: 6.7053478 | K2: 6.671278
A3: Decansäure | B3: C10:0 | C3: 785.18107 | D3: 750.86041 | E3: 794.76572 | F3: 6569.5086 | G3: 0 | H3: 0 | I3: ND | J3: 0 | K3: 0
A4: Undecansäure | B4: C11:0 | C4: 389.67763 | D4: 106.09962 | E4: 191.43178 | F4: 2004.9388 | G4: 0 | H4: 0 | I4: 0 | J4: 0 | K4: 0
A5: Dodecansäure | B5: C12:0 | C5: 74.603001 | D5: 1363.1961 | E5: 16.849257 | F5: 362.56932 | G5: 0 | H5: 0 | I5: 0 | J5: 0 | K5: 0
A6: Tridecansäure | B6: C13:0 | C6: 132.16665 | D6: 479.87861 | E6: 81.650103 | F6: 653.78862 | G6: 0 | H6: 0 | I6: 0 | J6: 0 | K6: 0
A7: Tetradecansäure | B7: C14:0 | C7: 28.280875 | D7: 46.617074 | E7: 269.15254 | F7: 119.25906 | G7: 7.2460668 | H7: 3.8908927 | I7: 0 | J7: 0 | K7: 0
A8: 9-Tetradecensäure | B8: C14:1 | C8: 102.55082 | D8: 66.026806 | E8: 25.418991 | F8: 504.88357 | G8: 2.1530712 | H8: 0 | I8: 0 | J8: 0 | K8: 0
A9: Pentadecansäure | B9: C15:0 | C9: 165.97198 | D9: 255.96202 | E9: 522.19903 | F9: 10613.568 | G9: 0 | H9: 0 | I9: 2.6967021 | J9: 0 | K9: 0
A10: Cis-10-Pentadecensäure | B10: C15:1 | C10: 163.5183 | D10: 136.16662 | E10: 189.89571 | F10: 717.38895 | G10: 0 | H10: 0 | I10: 0 | J10: 0 | K10: 0
A11: Hexadecansäure | B11: C16:0 | C11: 140.72816 | D11: 144.91283 | E11: 40.819096 | F11: 1606.6215 | G11: 1559.8596 | H11: 1357.4774 | I11: 984.67821 | J11: 1183.7139 | K11: 805.21669
A12: Cis-9-Hexadecensäure | B12: C16:1 | C12: 82.321367 | D12: 224.68902 | E12: 71.102224 | F12: 934.44564 | G12: 28.24261 | H12: 29.040412 | I12: 5.2233678 | J12: 9.3249853 | K12: 0
A13: Heptadecansäure | B13: C17:0 | C13: 11.877235 | D13: 9.7137046 | E13: 2.3504436 | F13: 82.19447 | G13: 11.384158 | H13: 11.511274 | I13: 6.3222615 | J13: 9.6450863 | K13: 0.8527135
A14: Cis-10-Heptadecensäure | B14: C17:1 | C14: 104.84753 | D14: 249.70114 | E14: 34.346812 | F14: 550.92311 | G14: 8.2494604 | H14: 0 | I14: 0 | J14: 0 | K14: 0
A15: Octadecansäure | B15: C18:0 | C15: 112.9411 | D15: 287.57468 | E15: 75.220625 | F15: 1346.7474 | G15: 245.30662 | H15: 256.75293 | I15: 222.38213 | J15: 252.44936 | K15: 268.6234
... A22: Eicosansäure | B22: C20:0 | C22: 105.8134 | D22: 135.2059 | E22: 230.69497 | F22: 829.06345 | G22: 2.1239129 | H22: 1.5846005 | I22: 1.634746 | J22: 4.1356598 | K22: 1.5947214
A23: Cis-11-Eicosensäure | B23: C20:1 | C23: 48.24559 | D23: 45.899627 | E23: 29.123577 | F23: 600.86933 | G23: 2.7619609 | H23: ND | I23: 0 | J23: 18.810504 | K23: 0.113223
A24: Cis-11,14-Eicosadiensäure | B24: C20:2(n-6) | C24: 401.89061 | D24: 70.784648 | E24: 71.876715 | F24: 369.38615 | G24: 4.1040791 | H24: 31.81121 | I24: 8.8022318 | J24: 21.227138 | K24: 0.272421
A25: Cis-8,11,14-Eisocatriensäure | B25: C20:3(n-6) | C25: 40.990187 | D25: 85.510205 | E25: 12.111099 | F25: 569.4732 | G25: 31.327736 | H25: 0.2061804 | I25: 0.4168924 | J25: 0.4154288 | K25: 0.4722408
A26: Cis-5,8,11,14-Eicosatetraensäure | B26: C20:4(n-6) | C26: 333.59119 | D26: 127.37523 | E26: 60.873054 | F26: 1805.8957 | G26: 146.30437 | H26: 207.9591 | I26: 134.56991 | J26: 220.39471 | K26: 0.5551678
A27: Cis-11,14,17-Eicosatriensäure | B27: C20:3(n-3) | C27: 49.465142 | D27: 64.368114 | E27: 35.022439 | F27: 194.9959 | G27: 32.247193 | H27: ND | I27: ND | J27: ND | K27: ND
A28: Heneicosansäure | B28: C21:0 | C28: 3.0212252 | D28: 26.257147 | E28: 17.763306 | F28: 94.414819 | G28: 0.3229982 | H28: 0 | I28: 0 | J28: 0 | K28: 0
A29: Cis-5,8,11,14,17-Eicosapentaensäure | B29: C20:5(n-3) | C29: 232.30122 | D29: 290.95257 | E29: 142.51884 | F29: 464.15108 | G29: 98.202708 | H29: 138.33426 | I29: 81.596109 | J29: 139.31305 | K29: 0.611621
A30: Docosansäure | B30: C22:0 | C30: 430.36435 | D30: 2962.5291 | E30: 192.30261 | F30: 5083.3647 | G30: 2.4229315 | H30: 0 | I30: 0 | J30: 0 | K30: 0
A31: 13-Docosensäure | B31: C22:1 | C31: 27.326137 | D31: 77.875611 | E31: 96.219251 | F31: 1356.3207 | G31: 14.90068 | H31: 32.909543 | I31: 30.142904 | J31: 25.474299 | K31: 47.341217
A32: Cis-13,16-Docosadiensäure | B32: C22:2 | C32: 69.288155 | D32: 85.370156 | E32: 59.28945 | F32: 512.13351 | G32: 1.9741491 | H32: 7.6568611 | I32: 1.9568238 | J32: 8.3154807 | K32: 1.9275685
A33: Cis-7,10,13,16,19-Docosapentaensäure | B33: C22:5(n-3) | C33: 91.573691 | D33: 96.615077 | E33: 149.81326 | F33: 2118.6202 | G33: 0.5242096 | H33: 4.1783335 | I33: 1.7470162 | J33: 4.0932411 | K33: 0
A34: Cis-4,7,10,13,16,19-Docosahexaensäure | B34: C22:6(n-3) | C34: 202.9113 | D34: 320.52067 | E34: 101.85354 | F34: 4562.5232 | G34: 2.7345747 | H34: 7.3196243 | I34: 0.4792708 | J34: 4.6130578 | K34: 0
A35: Tetracosansäure | B35: C24:0 | C35: 498.16925 | D35: 1532.0028 | E35: 842.16194 | F35: 18259.707 | G35: 0 | H35: 0 | I35: 0 | J35: 0 | K35: 0
A36: Cis-15-Tetracosensäure | B36: C24:1 | C36: 23.232825 | D36: 66.879493 | E36: 34.211179 | F36: 374.12417 | G36: 0 | H36: 0 | I36: 0 | J36: 0 | K36: 0

Sheet µg statt ng
A1: FAME | B1: Data File | C1: blank230717.D | D1: MEGA-Mix_230717.D | E1: S10.D | F1: S11.D | G1: WBPro1.D | H1: WBMix1.D | I1: WBPro2.D | J1: WBCip1.D | K1: WBMix2.D | L1: WBCip2.D | M1: Blank3.D | O1: ISD( µ/ml)
A2: Octansäure | B2: Final Conc. | C2: ='data processing'!C2/1000 -> 3014.2117 | D2: ='data processing'!D2/1000 -> 411.96419 | E2: ='data processing'!E2/1000 -> 999.99712 | F2: ='data processing'!F2/1000 -> 1677.0532 | G2: ='data processing'!G2/1000 -> 355.12039 | H2: ='data processing'!H2/1000 -> 1633.5655 | I2: ='data processing'!I2/1000 -> 6.7620221 | J2: ='data processing'!J2/1000 -> 6.6707279 | ... M2: ='data processing'!M2/1000 -> 6.671278 | O2: 400
A3: Decansäure | B3: Final Conc. | C3: ='data processing'!C3/1000 -> 616.36054 | D3: ='data processing'!D3/1000 -> 409.49751 | E3: ='data processing'!E3/1000 -> 785.18107 | F3: ='data processing'!F3/1000 -> 750.86041 | G3: ='data processing'!G3/1000 -> 794.76572 | H3: ='data processing'!H3/1000 -> 6569.5086 | I3: ='data processing'!I3/1000 -> 0 | J3: ='data processing'!J3/1000 -> 0 | K3: ND | L3: ='data processing'!L3/1000 -> 0 | M3: ='data processing'!M3/1000 -> 0 | O3: 400
A4: Undecansäure | B4: Final Conc. | C4: ='data processing'!C4/1000 -> 697.3512 | D4: ='data processing'!D4/1000 -> 196.41709 | E4: ='data processing'!E4/1000 -> 389.67763 | F4: ='data processing'!F4/1000 -> 106.09962 | G4: ='data processing'!G4/1000 -> 191.43178 | H4: ='data processing'!H4/1000 -> 2004.9388 | I4: ='data processing'!I4/1000 -> 0 | J4: ='data processing'!J4/1000 -> 0 | ... M4: ='data processing'!M4/1000 -> 0 | O4: 200
A5: Dodecansäure | B5: Final Conc. | C5: ='data processing'!C5/1000 -> 321.53051 | D5: ='data processing'!D5/1000 -> 273.1925 | E5: ='data processing'!E5/1000 -> 74.603001 | F5: ='data processing'!F5/1000 -> 1363.1961 | G5: ='data processing'!G5/1000 -> 16.849257 | H5: ='data processing'!H5/1000 -> 362.56932 | I5: ='data processing'!I5/1000 -> 0 | J5: ='data processing'!J5/1000 -> 0 | ... M5: ='data processing'!M5/1000 -> 0 | O5: 400
A6: Tridecansäure | B6: Final Conc. | C6: ='data processing'!C6/1000 -> 226.86136 | D6: ='data processing'!D6/1000 -> 114.65313 | E6: ='data processing'!E6/1000 -> 132.16665 | F6: ='data processing'!F6/1000 -> 479.87861 | G6: ='data processing'!G6/1000 -> 81.650103 | H6: ='data processing'!H6/1000 -> 653.78862 | I6: ='data processing'!I6/1000 -> 0 | J6: ='data processing'!J6/1000 -> 0 | ... M6: ='data processing'!M6/1000 -> 0 | O6: 200
A7: Tetradecansäure | B7: Final Conc. | C7: ='data processing'!C7/1000 -> 378.80403 | D7: ='data processing'!D7/1000 -> 297.92478 | E7: ='data processing'!E7/1000 -> 28.280875 | F7: ='data processing'!F7/1000 -> 46.617074 | G7: ='data processing'!G7/1000 -> 269.15254 | H7: ='data processing'!H7/1000 -> 119.25906 | I7: ='data processing'!I7/1000 -> 7.2460668 | J7: ='data processing'!J7/1000 -> 3.8908927 | ... M7: ='data processing'!M7/1000 -> 0 | O7: 400
A8: 9-Tetradecensäure | B8: Final Conc. | C8: ='data processing'!C8/1000 -> 1614.0015 | D8: ='data processing'!D8/1000 -> 167.59826 | E8: ='data processing'!E8/1000 -> 102.55082 | F8: ='data processing'!F8/1000 -> 66.026806 | G8: ='data processing'!G8/1000 -> 25.418991 | H8: ='data processing'!H8/1000 -> 504.88357 | I8: ='data processing'!I8/1000 -> 2.1530712 | J8: ='data processing'!J8/1000 -> 0 | ... M8: ='data processing'!M8/1000 -> 0 | O8: 200
A9: Pentadecansäure | B9: Final Conc. | C9: ='data processing'!C9/1000 -> 932.57293 | D9: ='data processing'!D9/1000 -> 125.86149 | E9: ='data processing'!E9/1000 -> 165.97198 | F9: ='data processing'!F9/1000 -> 255.96202 | G9: ='data processing'!G9/1000 -> 522.19903 | H9: ='data processing'!H9/1000 -> 10613.568 | I9: ='data processing'!I9/1000 -> 0 | J9: ='data processing'!J9/1000 -> 0 | ... M9: ='data processing'!M9/1000 -> 0 | O9: 200
A10: Cis-10-Pentadecensäure | B10: Final Conc. | C10: ='data processing'!C10/1000 -> 695.33354 | D10: ='data processing'!D10/1000 -> 159.86487 | E10: ='data processing'!E10/1000 -> 163.5183 | F10: ='data processing'!F10/1000 -> 136.16662 | G10: ='data processing'!G10/1000 -> 189.89571 | H10: ='data processing'!H10/1000 -> 717.38895 | I10: ='data processing'!I10/1000 -> 0 | J10: ='data processing'!J10/1000 -> 0 | ... M10: ='data processing'!M10/1000 -> 0 | O10: 200
A11: Hexadecansäure | B11: Final Conc. | C11: ='data processing'!C11/1000 -> 800.6011 | D11: ='data processing'!D11/1000 -> 1866.5355 | E11: ='data processing'!E11/1000 -> 140.72816 | F11: ='data processing'!F11/1000 -> 144.91283 | G11: ='data processing'!G11/1000 -> 40.819096 | H11: ='data processing'!H11/1000 -> 1606.6215 | I11: ='data processing'!I11/1000 -> 1559.8596 | J11: ='data processing'!J11/1000 -> 1357.4774 | ... M11: ='data processing'!M11/1000 -> 805.21669 | O11: 600
A12: Cis-9-Hexadecensäure | B12: Final Conc. | C12: ='data processing'!C12/1000 -> 576.75652 | D12: ='data processing'!D12/1000 -> 166.51416 | E12: ='data processing'!E12/1000 -> 82.321367 | F12: ='data processing'!F12/1000 -> 224.68902 | G12: ='data processing'!G12/1000 -> 71.102224 | H12: ='data processing'!H12/1000 -> 934.44564 | I12: ='data processing'!I12/1000 -> 28.24261 | J12: ='data processing'!J12/1000 -> 29.040412 | ... M12: ='data processing'!M12/1000 -> 0 | O12: 200
A13: Heptadecansäure | B13: Final Conc. | C13: ='data processing'!C13/1000 -> 50.904931 | D13: ='data processing'!D13/1000 -> 154.215 | E13: ='data processing'!E13/1000 -> 11.877235 | F13: ='data processing'!F13/1000 -> 9.7137046 | G13: ='data processing'!G13/1000 -> 2.3504436 | H13: ='data processing'!H13/1000 -> 82.19447 | I13: ='data processing'!I13/1000 -> 11.384158 | J13: ='data processing'!J13/1000 -> 11.511274 | ... M13: ='data processing'!M13/1000 -> 0.8527135 | O13: 200
A14: Cis-10-Heptadecensäure | B14: Final Conc. | C14: ='data processing'!C14/1000 -> 833.29136 | D14: ='data processing'!D14/1000 -> 220.19119 | E14: ='data processing'!E14/1000 -> 104.84753 | F14: ='data processing'!F14/1000 -> 249.70114 | G14: ='data processing'!G14/1000 -> 34.346812 | H14: ='data processing'!H14/1000 -> 550.92311 | I14: ='data processing'!I14/1000 -> 8.2494604 | J14: ='data processing'!J14/1000 -> 0 | ... M14: ='data processing'!M14/1000 -> 0 | O14: 200
A15: Octadecansäure | B15: Final Conc. | C15: ='data processing'!C15/1000 -> 756.45192 | D15: ='data processing'!D15/1000 -> 414.35686 | E15: ='data processing'!E15/1000 -> 112.9411 | F15: ='data processing'!F15/1000 -> 287.57468 | G15: ='data processing'!G15/1000 -> 75.220625 | H15: ='data processing'!H15/1000 -> 1346.7474 | I15: ='data processing'!I15/1000 -> 245.30662 | J15: ='data processing'!J15/1000 -> 256.75293 | ... M15: ='data processing'!M15/1000 -> 268.6234 | O15: 400
... A20: Alpha-Octadecatriensäure | B20: Final Conc. | C20: ='data processing'!C20/1000 -> 1099.4725 | D20: ='data processing'!D20/1000 -> 578.7478 | E20: ='data processing'!E20/1000 -> 264.64959 | F20: ='data processing'!F20/1000 -> 492.47828 | G20: ='data processing'!G20/1000 -> 324.86211 | H20: ='data processing'!H20/1000 -> 1173.8078 | I20: ='data processing'!I20/1000 -> 59.575627 | J20: ='data processing'!J20/1000 -> 113.39655 | ... M20: ='data processing'!M20/1000 -> 1.9239939 | O20: 200
A21: 6,9,12,15-Octadecatetraensäure | B21: Final Conc. | C21: ='data processing'!C21/1000 -> 1326.5842 | D21: ='data processing'!D21/1000 -> 109.04479 | E21: ='data processing'!E21/1000 -> 150.83892 | F21: ='data processing'!F21/1000 -> 505.64725 | G21: ='data processing'!G21/1000 -> 45.833785 | H21: ='data processing'!H21/1000 -> 913.5503 | I21: ='data processing'!I21/1000 -> 0.2683554 | J21: ='data processing'!J21/1000 -> 0.5445648 | ... M21: ='data processing'!M21/1000 -> 0.1878403
A22: Eicosansäure | B22: Final Conc. | C22: ='data processing'!C22/1000 -> 1031.2909 | D22: ='data processing'!D22/1000 -> 277.06629 | E22: ='data processing'!E22/1000 -> 105.8134 | F22: ='data processing'!F22/1000 -> 135.2059 | G22: ='data processing'!G22/1000 -> 230.69497 | H22: ='data processing'!H22/1000 -> 829.06345 | I22: ='data processing'!I22/1000 -> 2.1239129 | J22: ='data processing'!J22/1000 -> 1.5846005 | ... M22: ='data processing'!M22/1000 -> 1.5947214 | O22: 400
A23: Cis-11-Eicosensäure | B23: Final Conc. | C23: ='data processing'!C23/1000 -> 87.107756 | D23: ='data processing'!D23/1000 -> 50.590762 | E23: ='data processing'!E23/1000 -> 48.24559 | F23: ='data processing'!F23/1000 -> 45.899627 | G23: ='data processing'!G23/1000 -> 29.123577 | H23: ='data processing'!H23/1000 -> 600.86933 | I23: ='data processing'!I23/1000 -> 2.7619609 | J23: ND | K23: ='data processing'!K23/1000 -> 0 | L23: ='data processing'!L23/1000 -> 18.810504 | M23: ='data processing'!M23/1000 -> 0.113223 | O23: 200
A24: Cis-11,14-Eicosadiensäure | B24: Final Conc. | C24: ='data processing'!C24/1000 -> 472.69271 | D24: ='data processing'!D24/1000 -> 108.7257 | E24: ='data processing'!E24/1000 -> 401.89061 | F24: ='data processing'!F24/1000 -> 70.784648 | G24: ='data processing'!G24/1000 -> 71.876715 | H24: ='data processing'!H24/1000 -> 369.38615 | I24: ='data processing'!I24/1000 -> 4.1040791 | J24: ='data processing'!J24/1000 -> 31.81121 | ... M24: ='data processing'!M24/1000 -> 0.272421 | O24: 200
A25: Cis-8,11,14-Eisocatriensäure | B25: Final Conc. | C25: ='data processing'!C25/1000 -> 205.39397 | D25: ='data processing'!D25/1000 -> 70.959859 | E25: ='data processing'!E25/1000 -> 40.990187 | F25: ='data processing'!F25/1000 -> 85.510205 | G25: ='data processing'!G25/1000 -> 12.111099 | H25: ='data processing'!H25/1000 -> 569.4732 | I25: ='data processing'!I25/1000 -> 31.327736 | J25: ='data processing'!J25/1000 -> 0.2061804 | ... M25: ='data processing'!M25/1000 -> 0.4722408 | O25: 200
A26: Cis-5,8,11,14-Eicosatetraensäure | B26: Final Conc. | C26: ='data processing'!C26/1000 -> 654.70943 | D26: ='data processing'!D26/1000 -> 255.83358 | E26: ='data processing'!E26/1000 -> 333.59119 | F26: ='data processing'!F26/1000 -> 127.37523 | G26: ='data processing'!G26/1000 -> 60.873054 | H26: ='data processing'!H26/1000 -> 1805.8957 | I26: ='data processing'!I26/1000 -> 146.30437 | J26: ='data processing'!J26/1000 -> 207.9591 | ... M26: ='data processing'!M26/1000 -> 0.5551678 | O26: 200
A27: Cis-11,14,17-Eicosatriensäure | B27: Final Conc. | C27: ='data processing'!C27/1000 -> 90.182919 | D27: ='data processing'!D27/1000 -> 79.404541 | E27: ='data processing'!E27/1000 -> 49.465142 | F27: ='data processing'!F27/1000 -> 64.368114 | G27: ='data processing'!G27/1000 -> 35.022439 | H27: ='data processing'!H27/1000 -> 194.9959 | I27: ='data processing'!I27/1000 -> 32.247193 | J27: ND | K27: ND | L27: ND | M27: ND | O27: 200
A28: Heneicosansäure | B28: Final Conc. | C28: ='data processing'!C28/1000 -> 19.160971 | D28: ='data processing'!D28/1000 -> 120.35372 | E28: ='data processing'!E28/1000 -> 3.0212252 | F28: ='data processing'!F28/1000 -> 26.257147 | G28: ='data processing'!G28/1000 -> 17.763306 | H28: ='data processing'!H28/1000 -> 94.414819 | I28: ='data processing'!I28/1000 -> 0.3229982 | J28: ='data processing'!J28/1000 -> 0 | ... M28: ='data processing'!M28/1000 -> 0 | O28: 200
A29: Cis-5,8,11,14,17-Eicosapentaensäure | B29: Final Conc. | C29: ='data processing'!C29/1000 -> 568.66049 | D29: ='data processing'!D29/1000 -> 172.61318 | E29: ='data processing'!E29/1000 -> 232.30122 | F29: ='data processing'!F29/1000 -> 290.95257 | G29: ='data processing'!G29/1000 -> 142.51884 | H29: ='data processing'!H29/1000 -> 464.15108 | I29: ='data processing'!I29/1000 -> 98.202708 | J29: ='data processing'!J29/1000 -> 138.33426 | ... M29: ='data processing'!M29/1000 -> 0.611621 | O29: 200
A30: Docosansäure | B30: Final Conc. | C30: ='data processing'!C30/1000 -> 4050.2515 | D30: ='data processing'!D30/1000 -> 161.08566 | E30: ='data processing'!E30/1000 -> 430.36435 | F30: ='data processing'!F30/1000 -> 2962.5291 | G30: ='data processing'!G30/1000 -> 192.30261 | H30: ='data processing'!H30/1000 -> 5083.3647 | I30: ='data processing'!I30/1000 -> 2.4229315 | J30: ='data processing'!J30/1000 -> 0 | ... M30: ='data processing'!M30/1000 -> 0 | O30: 200
A31: 13-Docosensäure | B31: Final Conc. | C31: ='data processing'!C31/1000 -> 279.13584 | D31: ='data processing'!D31/1000 -> 105.83619 | E31: ='data processing'!E31/1000 -> 27.326137 | F31: ='data processing'!F31/1000 -> 77.875611 | G31: ='data processing'!G31/1000 -> 96.219251 | H31: ='data processing'!H31/1000 -> 1356.3207 | I31: ='data processing'!I31/1000 -> 14.90068 | J31: ='data processing'!J31/1000 -> 32.909543 | ... M31: ='data processing'!M31/1000 -> 47.341217 | O31: 400
A32: Cis-13,16-Docosadiensäure | B32: Final Conc. | C32: ='data processing'!C32/1000 -> 168.04247 | D32: ='data processing'!D32/1000 -> 92.426353 | E32: ='data processing'!E32/1000 -> 69.288155 | F32: ='data processing'!F32/1000 -> 85.370156 | G32: ='data processing'!G32/1000 -> 59.28945 | H32: ='data processing'!H32/1000 -> 512.13351 | I32: ='data processing'!I32/1000 -> 1.9741491 | J32: ='data processing'!J32/1000 -> 7.6568611 | ... M32: ='data processing'!M32/1000 -> 1.9275685 | O32: 200
A33: Cis-7,10,13,16,19-Docosapentaensäure | B33: Final Conc. | C33: ='data processing'!C33/1000 -> 1357.0144 | D33: ='data processing'!D33/1000 -> 30.345026 | E33: ='data processing'!E33/1000 -> 91.573691 | F33: ='data processing'!F33/1000 -> 96.615077 | G33: ='data processing'!G33/1000 -> 149.81326 | H33: ='data processing'!H33/1000 -> 2118.6202 | I33: ='data processing'!I33/1000 -> 0.5242096 | J33: ='data processing'!J33/1000 -> 4.1783335 | ... M33: ='data processing'!M33/1000 -> 0
A34: Cis-4,7,10,13,16,19-Docosahexaensäure | B34: Final Conc. | C34: ='data processing'!C34/1000 -> 2163.3103 | D34: ='data processing'!D34/1000 -> 81.064242 | E34: ='data processing'!E34/1000 -> 202.9113 | F34: ='data processing'!F34/1000 -> 320.52067 | G34: ='data processing'!G34/1000 -> 101.85354 | H34: ='data processing'!H34/1000 -> 4562.5232 | I34: ='data processing'!I34/1000 -> 2.7345747 | J34: ='data processing'!J34/1000 -> 7.3196243 | ... M34: ='data processing'!M34/1000 -> 0 | O34: 200
A35: Tetracosansäure | B35: Final Conc. | C35: ='data processing'!C35/1000 -> 1312.3258 | D35: ='data processing'!D35/1000 -> 619.98945 | E35: ='data processing'!E35/1000 -> 498.16925 | F35: ='data processing'!F35/1000 -> 1532.0028 | G35: ='data processing'!G35/1000 -> 842.16194 | H35: ='data processing'!H35/1000 -> 18259.707 | I35: ='data processing'!I35/1000 -> 0 | J35: ='data processing'!J35/1000 -> 0 | ... M35: ='data processing'!M35/1000 -> 0 | O35: 400
A36: Cis-15-Tetracosensäure | B36: Final Conc. | C36: ='data processing'!C36/1000 -> 478.33456 | D36: ='data processing'!D36/1000 -> 11.860512 | E36: ='data processing'!E36/1000 -> 23.232825 | F36: ='data processing'!F36/1000 -> 66.879493 | G36: ='data processing'!G36/1000 -> 34.211179 | H36: ='data processing'!H36/1000 -> 374.12417 | I36: ='data processing'!I36/1000 -> 0 | J36: ='data processing'!J36/1000 -> 0 | ... M36: ='data processing'!M36/1000 -> 0 | O36: 200
E38: kein ISTD | F38: kein ISTD | G38: kein ISTD | H38: kein ISTD

Sheet data processing
A1: FAME | B1: Data File | C1: blank230717.D | D1: MEGA-Mix_230717.D | E1: S10.D | F1: S11.D | G1: WBPro1.D | H1: WBMix1.D | I1: WBPro2.D | J1: WBCip1.D | K1: WBMix2.D | L1: WBCip2.D | M1: Blank3.D | O1: ISD( µ/ml)
A2: Octansäure | B2: Final Conc. | C2: 3014211.7 | D2: 411964.19 | E2: 999997.12 | F2: 1677053.2 | G2: 355120.39 | H2: 1633565.5 | I2: 6762.0221 | J2: 6670.7279 | K2: 6704.7424 | L2: 6705.3478 | M2: 6671.278 | O2: 400
A3: Decansäure | B3: Final Conc. | C3: 616360.54 | D3: 409497.51 | E3: 785181.07 | F3: 750860.41 | G3: 794765.72 | H3: 6569508.6 | I3: 0 | J3: 0 | K3: ND | L3: 0 | M3: 0 | O3: 400
A4: Undecansäure | B4: Final Conc. | C4: 697351.2 | D4: 196417.09 | E4: 389677.63 | F4: 106099.62 | G4: 191431.78 | H4: 2004938.8 | I4: 0 | J4: 0 | K4: 0 | L4: 0 | M4: 0 | O4: 200
A5: Dodecansäure | B5: Final Conc. | C5: 321530.51 | D5: 273192.5 | E5: 74603.001 | F5: 1363196.1 | G5: 16849.257 | H5: 362569.32 | I5: 0 | J5: 0 | K5: 0 | L5: 0 | M5: 0 | O5: 400
A6: Tridecansäure | B6: Final Conc. | C6: 226861.36 | D6: 114653.13 | E6: 132166.65 | F6: 479878.61 | G6: 81650.103 | H6: 653788.62 | I6: 0 | J6: 0 | K6: 0 | L6: 0 | M6: 0 | O6: 200
A7: Tetradecansäure | B7: Final Conc. | C7: 378804.03 | D7: 297924.78 | E7: 28280.875 | F7: 46617.074 | G7: 269152.54 | H7: 119259.06 | I7: 7246.0668 | J7: 3890.8927 | K7: 0 | L7: 0 | M7: 0 | O7: 400
A8: 9-Tetradecensäure | B8: Final Conc. | C8: 1614001.5 | D8: 167598.26 | E8: 102550.82 | F8: 66026.806 | G8: 25418.991 | H8: 504883.57 | I8: 2153.0712 | J8: 0 | K8: 0 | L8: 0 | M8: 0 | O8: 200
A9: Pentadecansäure | B9: Final Conc. | C9: 932572.93 | D9: 125861.49 | E9: 165971.98 | F9: 255962.02 | G9: 522199.03 | H9: 10613568 | I9: 0 | J9: 0 | K9: 2696.7021 | L9: 0 | M9: 0 | O9: 200
A10: Cis-10-Pentadecensäure | B10: Final Conc. | C10: 695333.54 | D10: 159864.87 | E10: 163518.3 | F10: 136166.62 | G10: 189895.71 | H10: 717388.95 | I10: 0 | J10: 0 | K10: 0 | L10: 0 | M10: 0 | O10: 200
A11: Hexadecansäure | B11: Final Conc. | C11: 800601.1 | D11: 1866535.5 | E11: 140728.16 | F11: 144912.83 | G11: 40819.096 | H11: 1606621.5 | I11: 1559859.6 | J11: 1357477.4 | K11: 984678.21 | L11: 1183713.9 | M11: 805216.69 | O11: 600
A12: Cis-9-Hexadecensäure | B12: Final Conc. | C12: 576756.52 | D12: 166514.16 | E12: 82321.367 | F12: 224689.02 | G12: 71102.224 | H12: 934445.64 | I12: 28242.609 | J12: 29040.412 | K12: 5223.3678 | L12: 9324.9853 | M12: 0 | O12: 200
A13: Heptadecansäure | B13: Final Conc. | C13: 50904.931 | D13: 154215 | E13: 11877.235 | F13: 9713.7046 | G13: 2350.4436 | H13: 82194.47 | I13: 11384.158 | J13: 11511.274 | K13: 6322.2615 | L13: 9645.0863 | M13: 852.7135 | O13: 200
A14: Cis-10-Heptadecensäure | B14: Final Conc. | C14: 833291.36 | D14: 220191.19 | E14: 104847.53 | F14: 249701.14 | G14: 34346.812 | H14: 550923.11 | I14: 8249.4604 | J14: 0 | K14: 0 | L14: 0 | M14: 0 | O14: 200
A15: Octadecansäure | B15: Final Conc. | C15: 756451.92 | D15: 414356.86 | E15: 112941.1 | F15: 287574.68 | G15: 75220.625 | H15: 1346747.4 | I15: 245306.62 | J15: 256752.93 | K15: 222382.13 | L15: 252449.36 | M15: 268623.4 | O15: 400
... A20: Alpha-Octadecatriensäure | B20: Final Conc. | C20: 1099472.5 | D20: 578747.8 | E20: 264649.59 | F20: 492478.28 | G20: 324862.11 | H20: 1173807.8 | I20: 59575.627 | J20: 113396.55 | K20: 51747.863 | L20: 63409.074 | M20: 1923.9939 | O20: 200
A21: 6,9,12,15-Octadecatetraensäure | B21: Final Conc. | C21: 1326584.2 | D21: 109044.79 | E21: 150838.92 | F21: 505647.25 | G21: 45833.785 | H21: 913550.3 | I21: 268.3554 | J21: 544.5648 | K21: 277.0617 | L21: 225.1592 | M21: 187.8403
A22: Eicosansäure | B22: Final Conc. | C22: 1031290.9 | D22: 277066.29 | E22: 105813.4 | F22: 135205.9 | G22: 230694.97 | H22: 829063.45 | I22: 2123.9129 | J22: 1584.6005 | K22: 1634.746 | L22: 4135.6598 | M22: 1594.7214 | O22: 400
A23: Cis-11-Eicosensäure | B23: Final Conc. | C23: 87107.756 | D23: 50590.762 | E23: 48245.59 | F23: 45899.627 | G23: 29123.577 | H23: 600869.33 | I23: 2761.9609 | J23: ND | K23: 0 | L23: 18810.504 | M23: 113.223 | O23: 200
A24: Cis-11,14-Eicosadiensäure | B24: Final Conc. | C24: 472692.71 | D24: 108725.7 | E24: 401890.61 | F24: 70784.648 | G24: 71876.715 | H24: 369386.15 | I24: 4104.0791 | J24: 31811.21 | K24: 8802.2318 | L24: 21227.138 | M24: 272.421 | O24: 200
A25: Cis-8,11,14-Eisocatriensäure | B25: Final Conc. | C25: 205393.97 | D25: 70959.859 | E25: 40990.187 | F25: 85510.205 | G25: 12111.099 | H25: 569473.2 | I25: 31327.736 | J25: 206.1804 | K25: 416.8924 | L25: 415.4288 | M25: 472.2408 | O25: 200
A26: Cis-5,8,11,14-Eicosatetraensäure | B26: Final Conc. | C26: 654709.43 | D26: 255833.58 | E26: 333591.19 | F26: 127375.23 | G26: 60873.054 | H26: 1805895.7 | I26: 146304.37 | J26: 207959.1 | K26: 134569.91 | L26: 220394.71 | M26: 555.1678 | O26: 200
A27: Cis-11,14,17-Eicosatriensäure | B27: Final Conc. | C27: 90182.919 | D27: 79404.541 | E27: 49465.142 | F27: 64368.114 | G27: 35022.439 | H27: 194995.9 | I27: 32247.193 | J27: ND | K27: ND | L27: ND | M27: ND | O27: 200
A28: Heneicosansäure | B28: Final Conc. | C28: 19160.971 | D28: 120353.72 | E28: 3021.2252 | F28: 26257.147 | G28: 17763.306 | H28: 94414.819 | I28: 322.9982 | J28: 0 | K28: 0 | L28: 0 | M28: 0 | O28: 200
A29: Cis-5,8,11,14,17-Eicosapentaensäure | B29: Final Conc. | C29: 568660.49 | D29: 172613.18 | E29: 232301.22 | F29: 290952.57 | G29: 142518.84 | H29: 464151.08 | I29: 98202.708 | J29: 138334.26 | K29: 81596.109 | L29: 139313.05 | M29: 611.621 | O29: 200
A30: Docosansäure | B30: Final Conc. | C30: 4050251.5 | D30: 161085.66 | E30: 430364.35 | F30: 2962529.1 | G30: 192302.61 | H30: 5083364.7 | I30: 2422.9315 | J30: 0 | K30: 0 | L30: 0 | M30: 0 | O30: 200
A31: 13-Docosensäure | B31: Final Conc. | C31: 279135.84 | D31: 105836.19 | E31: 27326.137 | F31: 77875.611 | G31: 96219.25 | H31: 1356320.7 | I31: 14900.68 | J31: 32909.543 | K31: 30142.904 | L31: 25474.299 | M31: 47341.217 | O31: 400
A32: Cis-13,16-Docosadiensäure | B32: Final Conc. | C32: 168042.47 | D32: 92426.353 | E32: 69288.155 | F32: 85370.156 | G32: 59289.45 | H32: 512133.51 | I32: 1974.1491 | J32: 7656.8611 | K32: 1956.8238 | L32: 8315.4807 | M32: 1927.5685 | O32: 200
A33: Cis-7,10,13,16,19-Docosapentaensäure | B33: Final Conc. | C33: 1357014.4 | D33: 30345.026 | E33: 91573.691 | F33: 96615.077 | G33: 149813.26 | H33: 2118620.2 | I33: 524.2096 | J33: 4178.3335 | K33: 1747.0162 | L33: 4093.2411 | M33: 0
A34: Cis-4,7,10,13,16,19-Docosahexaensäure | B34: Final Conc. | C34: 2163310.3 | D34: 81064.242 | E34: 202911.3 | F34: 320520.67 | G34: 101853.54 | H34: 4562523.2 | I34: 2734.5747 | J34: 7319.6243 | K34: 479.2708 | L34: 4613.0578 | M34: 0 | O34: 200
A35: Tetracosansäure | B35: Final Conc. | C35: 1312325.8 | D35: 619989.45 | E35: 498169.25 | F35: 1532002.8 | G35: 842161.94 | H35: 18259707 | I35: 0 | J35: 0 | K35: 0 | L35: 0 | M35: 0 | O35: 400
A36: Cis-15-Tetracosensäure | B36: Final Conc. | C36: 478334.56 | D36: 11860.512 | E36: 23232.825 | F36: 66879.493 | G36: 34211.179 | H36: 374124.17 | I36: 0 | J36: 0 | K36: 0 | L36: 0 | M36: 0 | O36: 200

Sheet raw data
A2: Octansäure | B2: Data File | C2: blank230717.D | D2: MEGA-Mix_230717.D | E2: S10.D | F2: S11.D | G2: WBPro1.D | H2: WBMix1.D | I2: WBPro2.D | J2: WBCip1.D | K2: WBMix2.D | L2: WBCip2.D | M2: Blank3.D
B3: Type | C3: Blank | D3: Sample | E3: Sample | F3: Sample | G3: Sample | H3: Sample | I3: Sample | J3: Sample | K3: Sample | L3: Sample | M3: Sample
B4: ISTD | C4: Nonadecansäure | D4: Nonadecansäure | E4: Nonadecansäure | F4: Nonadecansäure | G4: Nonadecansäure | H4: Nonadecansäure | I4: Nonadecansäure | J4: Nonadecansäure | K4: Nonadecansäure | L4: Nonadecansäure | M4: Nonadecansäure
B5: RT | C5: 4.202 | D5: 4.185 | E5: 4.223 | F5: 4.181 | G5: 4.112 | H5: 4.153 | I5: 4.209 | J5: 4.184 | K5: 4.182 | L5: 4.171 | M5: 4.179
B6: Resp. | C6: 2152 | D6: 28739917 | E6: 5353 | F6: 5634 | G6: 2678 | H6: 1124 | I6: 3632 | J6: 1471 | K6: 2871 | L6: 2748 | M6: 1337
B7: ISTD Resp | C7: 376 | D7: 37225151 | E7: 2829 | F7: 1771 | G7: 4034 | H7: 363 | I7: 14848336 | J7: 20796389 | K7: 21179334 | L7: 20101666 | M7: 18626997
B8: RR | C8: 5.7287 | D8: 0.7721 | E8: 1.8921 | F8: 3.1817 | G8: 0.6638 | H8: 3.0989 | I8: 0.0002 | J8: 0.0001 | K8: 0.0001 | L8: 0.0001 | M8: 0.0001
B9: Final Conc. | C9: 3014211.7 | D9: 411964.19 | E9: 999997.12 | F9: 1677053.2 | G9: 355120.39 | H9: 1633565.5 | I9: 6762.0221 | J9: 6670.7279 | K9: 6704.7424 | L9: 6705.3478 | M9: 6671.278
A10: Decansäure | B10: Data File | C10: blank230717.D | D10: MEGA-Mix_230717.D | E10: S10.D | F10: S11.D | G10: WBPro1.D | H10: WBMix1.D | I10: WBPro2.D | J10: WBCip1.D | K10: WBMix2.D | L10: WBCip2.D | M10: Blank3.D
B11: Type | C11: Blank | D11: Sample | E11: Sample | F11: Sample | G11: Sample | H11: Sample | I11: Sample | J11: Sample | K11: Sample | L11: Sample | M11: Sample
B12: ISTD | C12: Nonadecansäure | D12: Nonadecansäure | E12: Nonadecansäure | F12: Nonadecansäure | G12: Nonadecansäure | H12: Nonadecansäure | I12: Nonadecansäure | J12: Nonadecansäure | K12: Nonadecansäure | L12: Nonadecansäure | M12: Nonadecansäure
B13: RT | C13: 5.329 | D13: 5.346 | E13: 5.315 | F13: 5.403 | G13: 5.422 | H13: 5.4 | I13: 5.336 | J13: 5.192 | L13: 5.364 | M13: 5.458
B14: Resp. | C14: 339 | D14: 22361814 | E14: 3253 | F14: 1947 | G14: 4695 | H14: 3482 | I14: 4416 | J14: 3110 | L14: 4575 | M14: 1257
B15: ISTD Resp | C15: 376 | D15: 37225151 | E15: 2829 | F15: 1771 | G15: 4034 | H15: 363 | I15: 14848336 | J15: 20796389 | K15: 21179334 | L15: 20101666 | M15: 18626997
B16: RR | C16: 0.9031 | D16: 0.6007 | E16: 1.1499 | F16: 1.0997 | G16: 1.1639 | H16: 9.605 | I16: 0.0003 | J16: 0.0001 | L16: 0.0002 | M16: 0.0001
B17: Final Conc. | C17: 616360.54 | D17: 409497.51 | E17: 785181.07 | F17: 750860.41 | G17: 794765.72 | H17: 6569508.6 | I17: 0 | J17: 0 | K17: ND | L17: 0 | M17: 0
A18: Undecansäure | B18: Data File | C18: blank230717.D | D18: MEGA-Mix_230717.D | E18: S10.D | F18: S11.D | G18: WBPro1.D | H18: WBMix1.D | I18: WBPro2.D | J18: WBCip1.D | K18: WBMix2.D | L18: WBCip2.D | M18: Blank3.D
B19: Type | C19: Blank | D19: Sample | E19: Sample | F19: Sample | G19: Sample | H19: Sample | I19: Sample | J19: Sample | K19: Sample | L19: Sample | M19: Sample
B20: ISTD | C20: Nonadecansäure | D20: Nonadecansäure | E20: Nonadecansäure | F20: Nonadecansäure | G20: Nonadecansäure | H20: Nonadecansäure | I20: Nonadecansäure | J20: Nonadecansäure | K20: Nonadecansäure | L20: Nonadecansäure | M20: Nonadecansäure
B21: RT | C21: 6.19 | D21: 6.155 | E21: 6.286 | F21: 6.174 | G21: 6.163 | H21: 6.175 | I21: 6.188 | J21: 6.187 | K21: 6.149 | L21: 6.19 | M21: 6.162
B22: Resp. | C22: 761 | D22: 21363548 | E22: 3210 | F22: 552 | G22: 2257 | H22: 2110 | I22: 2958 | J22: 1076 | K22: 1910 | L22: 4128 | M22: 4995
B23: ISTD Resp | C23: 376 | D23: 37225151 | E23: 2829 | F23: 1771 | G23: 4034 | H23: 363 | I23: 14848336 | J23: 20796389 | K23: 21179334 | L23: 20101666 | M23: 18626997
B24: RR | C24: 2.027 | D24: 0.5739 | E24: 1.1345 | F24: 0.3119 | G24: 0.5594 | H24: 5.82 | I24: 0.0002 | J24: 0.0001 | K24: 0.0001 | L24: 0.0002 | M24: 0.0003
B25: Final Conc. | C25: 697351.2 | D25: 196417.09 | E25: 389677.63 | F25: 106099.62 | G25: 191431.78 | H25: 2004938.8 | I25: 0 | J25: 0 | K25: 0 | L25: 0 | M25: 0
A26: Dodecansäure | B26: Data File | C26: blank230717.D | D26: MEGA-Mix_230717.D | E26: S10.D | F26: S11.D | G26: WBPro1.D | H26: WBMix1.D | I26: WBPro2.D | J26: WBCip1.D | K26: WBMix2.D | L26: WBCip2.D | M26: Blank3.D
B27: Type | C27: Blank | D27: Sample | E27: Sample | F27: Sample | G27: Sample | H27: Sample | I27: Sample | J27: Sample | K27: Sample | L27: Sample | M27: Sample
B28: ISTD | C28: Nonadecansäure | D28: Nonadecansäure | E28: Nonadecansäure | F28: Nonadecansäure | G28: Nonadecansäure | H28: Nonadecansäure | I28: Nonadecansäure | J28: Nonadecansäure | K28: Nonadecansäure | L28: Nonadecansäure | M28: Nonadecansäure
B29: RT | C29: 7.49 | D29: 7.265 | E29: 7.461 | F29: 7.579 | G29: 7.491 | H29: 7.493 | I29: 7.239 | J29: 7.497 | K29: 7.496 | L29: 7.492 | M29: 7.449
B30: Resp. | C30: 2038 | D30: 172366047 | E30: 3853 | F30: 39966 | G30: 1659 | H30: 2212 | I30: 433815 | J30: 1928 | K30: 2340 | L30: 1310 | M30: 843
B31: ISTD Resp | C31: 376 | D31: 37225151 | E31: 2829 | F31: 1771 | G31: 4034 | H31: 363 | I31: 14848336 | J31: 20796389 | K31: 21179334 | L31: 20101666 | M31: 18626997
B32: RR | C32: 5.426 | D32: 4.6304 | E32: 1.3618 | F32: 22.5709 | G32: 0.4112 | H32: 6.1014 | I32: 0.0292 | J32: 0.0001 | K32: 0.0001 | L32: 0.0001 | M32: 0
B33: Final Conc. | C33: 321530.51 | D33: 273192.5 | E33: 74603.001 | F33: 1363196.1 | G33: 16849.257 | H33: 362569.32 | I33: 0 | J33: 0 | K33: 0 | L33: 0 | M33: 0
A34: Tridecansäure | B34: Data File | C34: blank230717.D | D34: MEGA-Mix_230717.D | E34: S10.D | F34: S11.D | G34: WBPro1.D | H34: WBMix1.D | I34: WBPro2.D | J34: WBCip1.D | K34: WBMix2.D | L34: WBCip2.D | M34: Blank3.D
B35: Type | C35: Blank | D35: Sample | E35: Sample | F35: Sample | G35: Sample | H35: Sample | I35: Sample | J35: Sample | K35: Sample | L35: Sample | M35: Sample
B36: ISTD | C36: Nonadecansäure | D36: Nonadecansäure | E36: Nonadecansäure | F36: Nonadecansäure | G36: Nonadecansäure | H36: Nonadecansäure | I36: Nonadecansäure | J36: Nonadecansäure | K36: Nonadecansäure | L36: Nonadecansäure | M36: Nonadecansäure
B37: RT | C37: 9.029 | D37: 8.764 | E37: 9.035 | F37: 9.089 | G37: 9.356 | H37: 9.035 | I37: 8.949 | J37: 9.007 | K37: 9.061 | L37: 9.058 | M37: 9.041
B38: Resp. | C38: 500 | D38: 25184615 | E38: 2203 | F38: 4973 | G38: 1952 | H38: 1386 | I38: 5300 | J38: 2014 | K38: 2059 | L38: 1699 | M38: 550
B39: ISTD Resp | C39: 376 | D39: 37225151 | E39: 2829 | F39: 1771 | G39: 4034 | H39: 363 | I39: 14848336 | J39: 20796389 | K39: 21179334 | L39: 20101666 | M39: 18626997
B40: RR | C40: 1.3316 | D40: 0.6765 | E40: 0.7788 | F40: 2.8087 | G40: 0.4839 | H40: 3.824 | I40: 0.0004 | J40: 0.0001 | K40: 0.0001 | L40: 0.0001 | M40: 0
B41: Final Conc. | C41: 226861.36 | D41: 114653.13 | E41: 132166.65 | F41: 479878.61 | G41: 81650.103 | H41: 653788.62 | I41: 0 | J41: 0 | K41: 0 | L41: 0 | M41: 0
...

Sheet 230717_FA-Quant-Report_ISTD
A1: Batch Data Path | B1: D:\MassHunter\GCMS\1\data\Sophie_Landau\230717\QuantResults\23017.batch.bin
A2: Analysis Time | B2: 45162.433 | C2: Analyst Name | D2: FLOEK026\install | E2: Report Generator Name | F2: FLOEK026\install
A3: Calibration Last Update | B3: 45154.569 | C3: Analyze Quant Version | D3: 10.1 | E3: Report Quant Version | F3: 10.2
A4: Sequence Table
A5: Data File | B5: Name | C5: Type | D5: Vial | E5: Vol. | F5: Level | G5: Acq. Method File
A6: blank230717.D | B6: blank | C6: Blank | D6: 1 | E6: 1 | G6: FAME_02_Insert
A8: MEGA-Mix_230717.D | B8: MEGA-Mix | C8: Sample | D8: 2 | E8: 1 | G8: FAME_02_Insert
A10: S10.D | B10: S10 | C10: Sample | D10: 3 | E10: 1 | G10: FAME_02_Insert
A12: S11.D | B12: S11 | C12: Sample | D12: 4 | E12: 1 | G12: FAME_02_Insert
A14: WBPro1.D | B14: WBPro1 | C14: Sample | D14: 5 | E14: 1 | G14: FAME_02_Insert
A16: WBMix1.D | B16: WBMix1 | C16: Sample | D16: 6 | E16: 1 | G16: FAME_02_Insert
A18: WBPro2.D | B18: WBPro2 | C18: Sample | D18: 7 | E18: 1 | G18: FAME_02_Insert
A20: WBCip1.D | B20: WBCip1 | C20: Sample | D20: 8 | E20: 1 | G20: FAME_02_Insert
A22: WBMix2.D | B22: WBMix2 | C22: Sample | D22: 9 | E22: 1 | G22: FAME_02_Insert
A24: WBCip2.D | B24: WBCip2 | C24: Sample | D24: 10 | E24: 1 | G24: FAME_02_Insert
A26: Blank3.D | B26: Blank3 | C26: Sample | D26: 11 | E26: 1 | G26: FAME_02_Insert
A28: Octansäure
A29: Data File | B29: Type | C29: ISTD | D29: RT | E29: Resp. | F29: ISTD Resp | G29: RR | H29: Final Conc. | I29: Exp. Conc. | J29: Accuracy
A30: blank230717.D | B30: Blank | C30: Nonadecansäure | D30: 4.202 | E30: 2152 | F30: 376 | G30: 5.7287 | H30: 3014211.7
A31: MEGA-Mix_230717.D | B31: Sample | C31: Nonadecansäure | D31: 4.185 | E31: 28739917 | F31: 37225151 | G31: 0.7721 | H31: 411964.19
A32: S10.D | B32: Sample | C32: Nonadecansäure | D32: 4.223 | E32: 5353 | F32: 2829 | G32: 1.8921 | H32: 999997.12
A33: S11.D | B33: Sample | C33: Nonadecansäure | D33: 4.181 | E33: 5634 | F33: 1771 | G33: 3.1817 | H33: 1677053.2
A34: WBPro1.D | B34: Sample | C34: Nonadecansäure | D34: 4.112 | E34: 2678 | F34: 4034 | G34: 0.6638 | H34: 355120.39
A35: WBMix1.D | B35: Sample | C35: Nonadecansäure | D35: 4.153 | E35: 1124 | F35: 363 | G35: 3.0989 | H35: 1633565.5
A36: WBPro2.D | B36: Sample | C36: Nonadecansäure | D36: 4.209 | E36: 3632 | F36: 14848336 | G36: 0.0002 | H36: 6762.0221
A37: WBCip1.D | B37: Sample | C37: Nonadecansäure | D37: 4.184 | E37: 1471 | F37: 20796389 | G37: 0.0001 | H37: 6670.7279
A38: WBMix2.D | B38: Sample | C38: Nonadecansäure | D38: 4.182 | E38: 2871 | F38: 21179334 | G38: 0.0001 | H38: 6704.7424
A39: WBCip2.D | B39: Sample | C39: Nonadecansäure | D39: 4.171 | E39: 2748 | F39: 20101666 | G39: 0.0001 | H39: 6705.3478
A40: Blank3.D | B40: Sample | C40: Nonadecansäure | D40: 4.179 | E40: 1337 | F40: 18626997 | G40: 0.0001 | H40: 6671.278
A41: Decansäure
A42: Data File | B42: Type | C42: ISTD | D42: RT | E42: Resp. | F42: ISTD Resp | G42: RR | H42: Final Conc. | I42: Exp. Conc. | J42: Accuracy
A43: blank230717.D | B43: Blank | C43: Nonadecansäure | D43: 5.329 | E43: 339 | F43: 376 | G43: 0.9031 | H43: 616360.54
A44: MEGA-Mix_230717.D | B44: Sample | C44: Nonadecansäure | D44: 5.346 | E44: 22361814 | F44: 37225151 | G44: 0.6007 | H44: 409497.51
A45: S10.D | B45: Sample | C45: Nonadecansäure | D45: 5.315 | E45: 3253 | F45: 2829 | G45: 1.1499 | H45: 785181.07
A46: S11.D | B46: Sample | C46: Nonadecansäure | D46: 5.403 | E46: 1947 | F46: 1771 | G46: 1.0997 | H46: 750860.41
A47: WBPro1.D | B47: Sample | C47: Nonadecansäure | D47: 5.422 | E47: 4695 | F47: 4034 | G47: 1.1639 | H47: 794765.72
A48: WBMix1.D | B48: Sample | C48: Nonadecansäure | D48: 5.4 | E48: 3482 | F48: 363 | G48: 9.605 | H48: 6569508.6
A49: WBPro2.D | B49: Sample | C49: Nonadecansäure | D49: 5.336 | E49: 4416 | F49: 14848336 | G49: 0.0003 | H49: 0
A50: WBCip1.D | B50: Sample | C50: Nonadecansäure | D50: 5.192 | E50: 3110 | F50: 20796389 | G50: 0.0001 | H50: 0
A51: WBMix2.D | B51: Sample | C51: Nonadecansäure | F51: 21179334 | H51: ND
...
