Workbook

Sheet aufgeräumt
A1: FAME (µg/sample) | B1: FAME (µg/sample) | C1: WB3Pro.D
A2: Octansäure | B2: C08:0 | C2: 7.0501939
A3: Decansäure | B3: C10:0 | C3: 4.0526835
A4: Undecansäure | B4: C11:0 | C4: 0
A5: Dodecansäure | B5: C12:0 | C5: 21.264584
A6: Tridecansäure | B6: C13:0 | C6: 131.61412
A7: Tetradecansäure | B7: C14:0 | C7: 398.01738
A8: 9-Tetradecensäure | B8: C14:1 | C8: 0
A9: Pentadecansäure | B9: C15:0 | C9: 25.339976
A10: Cis-10-Pentadecensäure | B10: C15:1 | C10: 0
A11: Hexadecansäure | B11: C16:0 | C11: 7138.6246
A12: Cis-9-Hexadecensäure | B12: C16:1 | C12: 1252.4399
A13: Heptadecansäure | B13: C17:0 | C13: 21.140595
... A36: Cis-15-Tetracosensäure | B36: C24:1 | C36: 0

Sheet µg statt ng
A1: FAME | B1: Data File | C1: blank231129.D | D1: MEGA-Mix_231129.D | E1: WB3Pro.D | F1: blank231129b.D | H1: ISD( µ/ml)
A2: Octansäure | B2: Final Conc. | C2: ='data processing'!C2/1000 -> 5629.903 | D2: ='data processing'!D2/1000 -> 506.76566 | E2: ='data processing'!E2/1000 -> 7.0501939 | F2: ='data processing'!F2/1000 -> 899.79473 | H2: 400
A3: Decansäure | B3: Final Conc. | C3: ='data processing'!C3/1000 -> 2613.0715 | D3: ='data processing'!D3/1000 -> 506.76611 | E3: ='data processing'!E3/1000 -> 4.0526835 | F3: ='data processing'!F3/1000 -> 133.61284 | H3: 400
A4: Undecansäure | B4: Final Conc. | C4: ='data processing'!C4/1000 -> 759.65153 | D4: ='data processing'!D4/1000 -> 243.76539 | E4: ='data processing'!E4/1000 -> 0 | F4: ='data processing'!F4/1000 -> 188.31048 | H4: 200
A5: Dodecansäure | B5: Final Conc. | C5: ='data processing'!C5/1000 -> 256.51922 | D5: ='data processing'!D5/1000 -> 332.74727 | E5: ='data processing'!E5/1000 -> 21.264584 | F5: ='data processing'!F5/1000 -> 27.872244 | H5: 400
A6: Tridecansäure | B6: Final Conc. | C6: ='data processing'!C6/1000 -> 541.96101 | D6: ='data processing'!D6/1000 -> 161.13565 | E6: ='data processing'!E6/1000 -> 131.61412 | F6: ='data processing'!F6/1000 -> 22.2325 | H6: 200
A7: Tetradecansäure | B7: Final Conc. | C7: ='data processing'!C7/1000 -> 235.30463 | D7: ='data processing'!D7/1000 -> 384.07964 | E7: ='data processing'!E7/1000 -> 398.01738 | F7: ='data processing'!F7/1000 -> 20.596956 | H7: 400
A8: 9-Tetradecensäure | B8: Final Conc. | C8: ='data processing'!C8/1000 -> 2917.1072 | D8: ='data processing'!D8/1000 -> 223.30295 | E8: ='data processing'!E8/1000 -> 0 | F8: ='data processing'!F8/1000 -> 122.07736 | H8: 200
A9: Pentadecansäure | B9: Final Conc. | C9: ='data processing'!C9/1000 -> 1069.7125 | D9: ='data processing'!D9/1000 -> 205.37114 | E9: ='data processing'!E9/1000 -> 25.339976 | F9: ='data processing'!F9/1000 -> 336.46612 | H9: 200
A10: Cis-10-Pentadecensäure | B10: Final Conc. | C10: ='data processing'!C10/1000 -> 939.25172 | D10: ='data processing'!D10/1000 -> 220.62954 | E10: ='data processing'!E10/1000 -> 0 | F10: ='data processing'!F10/1000 -> 129.1175 | H10: 200
A11: Hexadecansäure | B11: Final Conc. | C11: ='data processing'!C11/1000 -> 309.83038 | D11: ='data processing'!D11/1000 -> 2534.2269 | E11: ='data processing'!E11/1000 -> 7138.6246 | F11: ='data processing'!F11/1000 -> 120.20106 | H11: 600
A12: Cis-9-Hexadecensäure | B12: Final Conc. | C12: ='data processing'!C12/1000 -> 142.99871 | D12: ='data processing'!D12/1000 -> 223.10696 | E12: ='data processing'!E12/1000 -> 1252.4399 | F12: ='data processing'!F12/1000 -> 28.11593 | H12: 200
A13: Heptadecansäure | B13: Final Conc. | C13: ='data processing'!C13/1000 -> 68.505445 | D13: ='data processing'!D13/1000 -> 193.91992 | E13: ='data processing'!E13/1000 -> 21.140595 | F13: ='data processing'!F13/1000 -> 14.793909 | H13: 200
... A20: Alpha-Octadecatriensäure | B20: Final Conc. | C20: ='data processing'!C20/1000 -> 1470.9157 | D20: ='data processing'!D20/1000 -> 710.45204 | E20: ='data processing'!E20/1000 -> 4129.4039 | F20: ='data processing'!F20/1000 -> 266.07677 | H20: 200
A21: 6,9,12,15-Octadecatetraensäure | B21: Final Conc. | C21: ='data processing'!C21/1000 -> 1492.4096 | D21: ='data processing'!D21/1000 -> 137.22617 | E21: ='data processing'!E21/1000 -> 381.21438 | F21: ='data processing'!F21/1000 -> 140.14681
A22: Eicosansäure | B22: Final Conc. | C22: ='data processing'!C22/1000 -> 735.968 | D22: ='data processing'!D22/1000 -> 327.55411 | E22: ='data processing'!E22/1000 -> 23.186993 | F22: ='data processing'!F22/1000 -> 368.76418 | H22: 400
A23: Cis-11-Eicosensäure | B23: Final Conc. | C23: ='data processing'!C23/1000 -> 507.40417 | D23: ='data processing'!D23/1000 -> 62.352752 | E23: ='data processing'!E23/1000 -> 38.964143 | F23: ='data processing'!F23/1000 -> 187.71493 | H23: 200
A24: Cis-11,14-Eicosadiensäure | B24: Final Conc. | C24: ='data processing'!C24/1000 -> 111.63369 | D24: ='data processing'!D24/1000 -> 143.17166 | E24: ='data processing'!E24/1000 -> 24.454633 | F24: ='data processing'!F24/1000 -> 137.93711 | H24: 200
A25: Cis-8,11,14-Eisocatriensäure | B25: Final Conc. | C25: ='data processing'!C25/1000 -> 71.6833 | D25: ='data processing'!D25/1000 -> 90.050367 | E25: ='data processing'!E25/1000 -> 5.5145531 | F25: ='data processing'!F25/1000 -> 15.48561 | H25: 200
A26: Cis-5,8,11,14-Eicosatetraensäure | B26: Final Conc. | C26: ='data processing'!C26/1000 -> 2413.0367 | D26: ='data processing'!D26/1000 -> 328.23372 | E26: ='data processing'!E26/1000 -> 144.33782 | F26: ='data processing'!F26/1000 -> 231.14043 | H26: 200
A27: Cis-11,14,17-Eicosatriensäure | B27: Final Conc. | C27: ='data processing'!C27/1000 -> 149.59766 | D27: ='data processing'!D27/1000 -> 88.57554 | E27: ='data processing'!E27/1000 -> 3.5786523 | F27: ='data processing'!F27/1000 -> 91.419676 | H27: 200
A28: Heneicosansäure | B28: Final Conc. | C28: ='data processing'!C28/1000 -> 105.54759 | D28: ='data processing'!D28/1000 -> 155.97072 | E28: ='data processing'!E28/1000 -> 0 | F28: ='data processing'!F28/1000 -> 30.560642 | H28: 200
A29: Cis-5,8,11,14,17-Eicosapentaensäure | B29: Final Conc. | C29: ='data processing'!C29/1000 -> 370.19341 | D29: ='data processing'!D29/1000 -> 195.23362 | E29: ='data processing'!E29/1000 -> 318.05392 | F29: ='data processing'!F29/1000 -> 172.85499 | H29: 200
A30: Docosansäure | B30: Final Conc. | C30: ='data processing'!C30/1000 -> 3428.4964 | D30: ='data processing'!D30/1000 -> 275.54442 | E30: ='data processing'!E30/1000 -> 12.035405 | F30: ='data processing'!F30/1000 -> 1429.6962 | H30: 200
A31: 13-Docosensäure | B31: Final Conc. | C31: ='data processing'!C31/1000 -> 896.318 | D31: ='data processing'!D31/1000 -> 140.67657 | E31: ='data processing'!E31/1000 -> 117.98646 | F31: ='data processing'!F31/1000 -> 161.20567 | H31: 400
A32: Cis-13,16-Docosadiensäure | B32: Final Conc. | C32: ='data processing'!C32/1000 -> 128.79941 | D32: ='data processing'!D32/1000 -> 114.94898 | E32: ='data processing'!E32/1000 -> 1.9374972 | F32: ='data processing'!F32/1000 -> 90.054535 | H32: 200
A33: Cis-7,10,13,16,19-Docosapentaensäure | B33: Final Conc. | C33: ='data processing'!C33/1000 -> 579.81388 | D33: ='data processing'!D33/1000 -> 36.847272 | E33: ='data processing'!E33/1000 -> 0.8371749 | F33: ='data processing'!F33/1000 -> 167.66513
A34: Cis-4,7,10,13,16,19-Docosahexaensäure | B34: Final Conc. | C34: ='data processing'!C34/1000 -> 4429.8287 | D34: ='data processing'!D34/1000 -> 98.995628 | E34: ='data processing'!E34/1000 -> 18.683949 | F34: ='data processing'!F34/1000 -> 537.72969 | H34: 200
A35: Tetracosansäure | B35: Final Conc. | C35: ='data processing'!C35/1000 -> 5911.5634 | D35: ='data processing'!D35/1000 -> 23.629413 | E35: ='data processing'!E35/1000 -> 136.32513 | F35: ='data processing'!F35/1000 -> 174.94109 | H35: 400
A36: Cis-15-Tetracosensäure | B36: Final Conc. | C36: ='data processing'!C36/1000 -> 270.37143 | D36: ='data processing'!D36/1000 -> 17.920515 | E36: ='data processing'!E36/1000 -> 0 | F36: ='data processing'!F36/1000 -> 60.148751 | H36: 200

Sheet data processing
A1: FAME | B1: Data File | C1: blank231129.D | D1: MEGA-Mix_231129.D | E1: WB3Pro.D | F1: blank231129b.D | H1: ISD( µ/ml)
A2: Octansäure | B2: Final Conc. | C2: 5629903 | D2: 506765.66 | E2: 7050.1939 | F2: 899794.73 | H2: 400
A3: Decansäure | B3: Final Conc. | C3: 2613071.5 | D3: 506766.11 | E3: 4052.6835 | F3: 133612.84 | H3: 400
A4: Undecansäure | B4: Final Conc. | C4: 759651.53 | D4: 243765.39 | E4: 0 | F4: 188310.48 | H4: 200
A5: Dodecansäure | B5: Final Conc. | C5: 256519.22 | D5: 332747.27 | E5: 21264.584 | F5: 27872.244 | H5: 400
A6: Tridecansäure | B6: Final Conc. | C6: 541961.01 | D6: 161135.65 | E6: 131614.12 | F6: 22232.5 | H6: 200
A7: Tetradecansäure | B7: Final Conc. | C7: 235304.63 | D7: 384079.64 | E7: 398017.38 | F7: 20596.956 | H7: 400
A8: 9-Tetradecensäure | B8: Final Conc. | C8: 2917107.2 | D8: 223302.95 | E8: 0 | F8: 122077.36 | H8: 200
A9: Pentadecansäure | B9: Final Conc. | C9: 1069712.5 | D9: 205371.14 | E9: 25339.976 | F9: 336466.12 | H9: 200
A10: Cis-10-Pentadecensäure | B10: Final Conc. | C10: 939251.72 | D10: 220629.54 | E10: 0 | F10: 129117.5 | H10: 200
A11: Hexadecansäure | B11: Final Conc. | C11: 309830.38 | D11: 2534226.9 | E11: 7138624.6 | F11: 120201.06 | H11: 600
A12: Cis-9-Hexadecensäure | B12: Final Conc. | C12: 142998.71 | D12: 223106.96 | E12: 1252439.9 | F12: 28115.93 | H12: 200
A13: Heptadecansäure | B13: Final Conc. | C13: 68505.445 | D13: 193919.92 | E13: 21140.595 | F13: 14793.909 | H13: 200
... A20: Alpha-Octadecatriensäure | B20: Final Conc. | C20: 1470915.7 | D20: 710452.04 | E20: 4129403.9 | F20: 266076.77 | H20: 200
A21: 6,9,12,15-Octadecatetraensäure | B21: Final Conc. | C21: 1492409.6 | D21: 137226.17 | E21: 381214.38 | F21: 140146.81
A22: Eicosansäure | B22: Final Conc. | C22: 735968 | D22: 327554.11 | E22: 23186.993 | F22: 368764.18 | H22: 400
A23: Cis-11-Eicosensäure | B23: Final Conc. | C23: 507404.17 | D23: 62352.752 | E23: 38964.143 | F23: 187714.93 | H23: 200
A24: Cis-11,14-Eicosadiensäure | B24: Final Conc. | C24: 111633.69 | D24: 143171.66 | E24: 24454.633 | F24: 137937.11 | H24: 200
A25: Cis-8,11,14-Eisocatriensäure | B25: Final Conc. | C25: 71683.3 | D25: 90050.367 | E25: 5514.5531 | F25: 15485.61 | H25: 200
A26: Cis-5,8,11,14-Eicosatetraensäure | B26: Final Conc. | C26: 2413036.7 | D26: 328233.72 | E26: 144337.82 | F26: 231140.43 | H26: 200
A27: Cis-11,14,17-Eicosatriensäure | B27: Final Conc. | C27: 149597.66 | D27: 88575.54 | E27: 3578.6523 | F27: 91419.676 | H27: 200
A28: Heneicosansäure | B28: Final Conc. | C28: 105547.59 | D28: 155970.72 | E28: 0 | F28: 30560.642 | H28: 200
A29: Cis-5,8,11,14,17-Eicosapentaensäure | B29: Final Conc. | C29: 370193.41 | D29: 195233.62 | E29: 318053.92 | F29: 172854.99 | H29: 200
A30: Docosansäure | B30: Final Conc. | C30: 3428496.4 | D30: 275544.42 | E30: 12035.405 | F30: 1429696.2 | H30: 200
A31: 13-Docosensäure | B31: Final Conc. | C31: 896318 | D31: 140676.57 | E31: 117986.46 | F31: 161205.67 | H31: 400
A32: Cis-13,16-Docosadiensäure | B32: Final Conc. | C32: 128799.41 | D32: 114948.98 | E32: 1937.4972 | F32: 90054.535 | H32: 200
A33: Cis-7,10,13,16,19-Docosapentaensäure | B33: Final Conc. | C33: 579813.88 | D33: 36847.272 | E33: 837.1749 | F33: 167665.13
A34: Cis-4,7,10,13,16,19-Docosahexaensäure | B34: Final Conc. | C34: 4429828.7 | D34: 98995.628 | E34: 18683.949 | F34: 537729.69 | H34: 200
A35: Tetracosansäure | B35: Final Conc. | C35: 5911563.4 | D35: 23629.413 | E35: 136325.13 | F35: 174941.09 | H35: 400
A36: Cis-15-Tetracosensäure | B36: Final Conc. | C36: 270371.43 | D36: 17920.515 | E36: 0 | F36: 60148.751 | H36: 200

Sheet raw data
A5: Octansäure | B5: Data File | C5: blank231129.D | D5: MEGA-Mix_231129.D | E5: WB3Pro.D | F5: blank231129b.D
B6: Type | C6: Blank | D6: Sample | E6: Sample | F6: Blank
B7: ISTD | C7: Nonadecansäure | D7: Nonadecansäure | E7: Nonadecansäure | F7: Nonadecansäure
B8: RT | C8: 4.201 | D8: 4.182 | E8: 4.38 | F8: 4.192
B9: Resp. | C9: 11794 | D9: 68205443 | E9: 35393 | F9: 13286
B10: ISTD Resp | C10: 1101 | D10: 71596977 | E10: 44601880 | F10: 7809
B11: RR | C11: 10.711 | D11: 0.9526 | E11: 0.0008 | F11: 1.7013
B12: Final Conc. | C12: 5629903 | D12: 506765.66 | E12: 7050.1939 | F12: 899794.73
A13: Decansäure | B13: Data File | C13: blank231129.D | D13: MEGA-Mix_231129.D | E13: WB3Pro.D | F13: blank231129b.D
B14: Type | C14: Blank | D14: Sample | E14: Sample | F14: Blank
B15: ISTD | C15: Nonadecansäure | D15: Nonadecansäure | E15: Nonadecansäure | F15: Nonadecansäure
B16: RT | C16: 5.337 | D16: 5.347 | E16: 5.33 | F16: 5.354
B17: Resp. | C17: 4208 | D17: 53189293 | E17: 359749 | F17: 1542
B18: ISTD Resp | C18: 1101 | D18: 71596977 | E18: 44601880 | F18: 7809
B19: RR | C19: 3.8218 | D19: 0.7429 | E19: 0.0081 | F19: 0.1974
B20: Final Conc. | C20: 2613071.5 | D20: 506766.11 | E20: 4052.6835 | F20: 133612.84
A21: Undecansäure | B21: Data File | C21: blank231129.D | D21: MEGA-Mix_231129.D | E21: WB3Pro.D | F21: blank231129b.D
B22: Type | C22: Blank | D22: Sample | E22: Sample | F22: Blank
B23: ISTD | C23: Nonadecansäure | D23: Nonadecansäure | E23: Nonadecansäure | F23: Nonadecansäure
B24: RT | C24: 6.159 | D24: 6.155 | E24: 6.154 | F24: 6.169
B25: Resp. | C25: 2431 | D25: 50923149 | E25: 37720 | F25: 4298
B26: ISTD Resp | C26: 1101 | D26: 71596977 | E26: 44601880 | F26: 7809
B27: RR | C27: 2.2077 | D27: 0.7112 | E27: 0.0008 | F27: 0.5504
B28: Final Conc. | C28: 759651.53 | D28: 243765.39 | E28: 0 | F28: 188310.48
A29: Dodecansäure | B29: Data File | C29: blank231129.D | D29: MEGA-Mix_231129.D | E29: WB3Pro.D | F29: blank231129b.D
B30: Type | C30: Blank | D30: Sample | E30: Sample | F30: Blank
B31: ISTD | C31: Nonadecansäure | D31: Nonadecansäure | E31: Nonadecansäure | F31: Nonadecansäure
B32: RT | C32: 7.475 | D32: 7.265 | E32: 7.236 | F32: 7.459
B33: Resp. | C33: 4797 | D33: 401700846 | E33: 21580865 | F33: 4628
B34: ISTD Resp | C34: 1101 | D34: 71596977 | E34: 44601880 | F34: 7809
B35: RR | C35: 4.3559 | D35: 5.6106 | E35: 0.4839 | F35: 0.5926
B36: Final Conc. | C36: 256519.22 | D36: 332747.27 | E36: 21264.584 | F36: 27872.244
A37: Tridecansäure | B37: Data File | C37: blank231129.D | D37: MEGA-Mix_231129.D | E37: WB3Pro.D | F37: blank231129b.D
B38: Type | C38: Blank | D38: Sample | E38: Sample | F38: Blank
B39: ISTD | C39: Nonadecansäure | D39: Nonadecansäure | E39: Nonadecansäure | F39: Nonadecansäure
B40: RT | C40: 9.015 | D40: 8.767 | E40: 8.737 | F40: 9.038
B41: Resp. | C41: 3492 | D41: 67867534 | E41: 34591687 | F41: 1070
B42: ISTD Resp | C42: 1101 | D42: 71596977 | E42: 44601880 | F42: 7809
B43: RR | C43: 3.1711 | D43: 0.9479 | E43: 0.7756 | F43: 0.137
B44: Final Conc. | C44: 541961.01 | D44: 161135.65 | E44: 131614.12 | F44: 22232.5
...

Sheet 231129_FA-Quant-Report_ISTD
A1: Batch Data Path | B1: D:\MassHunter\GCMS\1\data\Sophie_Landau\231129\QuantResults\231129.batch.bin
A2: Analysis Time | B2: 45267.616 | C2: Analyst Name | D2: FLOEK026\install | E2: Report Generator Name | F2: FLOEK026\install
A3: Calibration Last Update | B3: 45154.569 | C3: Analyze Quant Version | D3: 10.1 | E3: Report Quant Version | F3: 10.2
A4: Sequence Table
A5: Data File | B5: Name | C5: Type | D5: Vial | E5: Vol. | F5: Level | G5: Acq. Method File
A6: blank231129.D | B6: blank | C6: Blank | D6: 1 | E6: 1 | G6: FAME_02_Insert
A8: MEGA-Mix_231129.D | B8: MEGA-Mix | C8: Sample | D8: 2 | E8: 1 | G8: FAME_02_Insert
A10: WB3Pro.D | B10: WB3Pro | C10: Sample | D10: 3 | E10: 1 | G10: FAME_02_Insert
A12: blank231129b.D | B12: blank | C12: Blank | D12: 1 | E12: 1 | G12: FAME_02_Insert
A14: Octansäure
A15: Data File | B15: Type | C15: ISTD | D15: RT | E15: Resp. | F15: ISTD Resp | G15: RR | H15: Final Conc. | I15: Exp. Conc. | J15: Accuracy
A16: blank231129.D | B16: Blank | C16: Nonadecansäure | D16: 4.201 | E16: 11794 | F16: 1101 | G16: 10.711 | H16: 5629903
A17: MEGA-Mix_231129.D | B17: Sample | C17: Nonadecansäure | D17: 4.182 | E17: 68205443 | F17: 71596977 | G17: 0.9526 | H17: 506765.66
A18: WB3Pro.D | B18: Sample | C18: Nonadecansäure | D18: 4.38 | E18: 35393 | F18: 44601880 | G18: 0.0008 | H18: 7050.1939
A19: blank231129b.D | B19: Blank | C19: Nonadecansäure | D19: 4.192 | E19: 13286 | F19: 7809 | G19: 1.7013 | H19: 899794.73
A20: Decansäure
A21: Data File | B21: Type | C21: ISTD | D21: RT | E21: Resp. | F21: ISTD Resp | G21: RR | H21: Final Conc. | I21: Exp. Conc. | J21: Accuracy
A22: blank231129.D | B22: Blank | C22: Nonadecansäure | D22: 5.337 | E22: 4208 | F22: 1101 | G22: 3.8218 | H22: 2613071.5
A23: MEGA-Mix_231129.D | B23: Sample | C23: Nonadecansäure | D23: 5.347 | E23: 53189293 | F23: 71596977 | G23: 0.7429 | H23: 506766.11
A24: WB3Pro.D | B24: Sample | C24: Nonadecansäure | D24: 5.33 | E24: 359749 | F24: 44601880 | G24: 0.0081 | H24: 4052.6835
A25: blank231129b.D | B25: Blank | C25: Nonadecansäure | D25: 5.354 | E25: 1542 | F25: 7809 | G25: 0.1974 | H25: 133612.84
A26: Undecansäure
A27: Data File | B27: Type | C27: ISTD | D27: RT | E27: Resp. | F27: ISTD Resp | G27: RR | H27: Final Conc. | I27: Exp. Conc. | J27: Accuracy
A28: blank231129.D | B28: Blank | C28: Nonadecansäure | D28: 6.159 | E28: 2431 | F28: 1101 | G28: 2.2077 | H28: 759651.53
A29: MEGA-Mix_231129.D | B29: Sample | C29: Nonadecansäure | D29: 6.155 | E29: 50923149 | F29: 71596977 | G29: 0.7112 | H29: 243765.39
A30: WB3Pro.D | B30: Sample | C30: Nonadecansäure | D30: 6.154 | E30: 37720 | F30: 44601880 | G30: 0.0008 | H30: 0
A31: blank231129b.D | B31: Blank | C31: Nonadecansäure | D31: 6.169 | E31: 4298 | F31: 7809 | G31: 0.5504 | H31: 188310.48
A32: Dodecansäure
A33: Data File | B33: Type | C33: ISTD | D33: RT | E33: Resp. | F33: ISTD Resp | G33: RR | H33: Final Conc. | I33: Exp. Conc. | J33: Accuracy
A34: blank231129.D | B34: Blank | C34: Nonadecansäure | D34: 7.475 | E34: 4797 | F34: 1101 | G34: 4.3559 | H34: 256519.22
A35: MEGA-Mix_231129.D | B35: Sample | C35: Nonadecansäure | D35: 7.265 | E35: 401700846 | F35: 71596977 | G35: 5.6106 | H35: 332747.27
A36: WB3Pro.D | B36: Sample | C36: Nonadecansäure | D36: 7.236 | E36: 21580865 | F36: 44601880 | G36: 0.4839 | H36: 21264.584
A37: blank231129b.D | B37: Blank | C37: Nonadecansäure | D37: 7.459 | E37: 4628 | F37: 7809 | G37: 0.5926 | H37: 27872.244
A38: Tridecansäure
A39: Data File | B39: Type | C39: ISTD | D39: RT | E39: Resp. | F39: ISTD Resp | G39: RR | H39: Final Conc. | I39: Exp. Conc. | J39: Accuracy
A40: blank231129.D | B40: Blank | C40: Nonadecansäure | D40: 9.015 | E40: 3492 | F40: 1101 | G40: 3.1711 | H40: 541961.01
A41: MEGA-Mix_231129.D | B41: Sample | C41: Nonadecansäure | D41: 8.767 | E41: 67867534 | F41: 71596977 | G41: 0.9479 | H41: 161135.65
A42: WB3Pro.D | B42: Sample | C42: Nonadecansäure | D42: 8.737 | E42: 34591687 | F42: 44601880 | G42: 0.7756 | H42: 131614.12
A43: blank231129b.D | B43: Blank | C43: Nonadecansäure | D43: 9.038 | E43: 1070 | F43: 7809 | G43: 0.137 | H43: 22232.5
A44: Tetradecansäure
...
