Workbook

Sheet all FA
A1: Oldname | B1: RUNINFO | C1: Name | D1: Treatment | E1: Week | F1: FA_µg_sample | G1: blank deduction | H1: negative values? | I1: µg_FA_per_mg | L1: a) in Spalte FA_ug_sample, bei #NV Angabe stand in Patricks aufgeräumter Liste "ND"
A2: W1NC | B2: B_1 | C2: C08:0 | D2: NC | E2: 1 | F2: 8.4897928 | G2: =IFERROR(F2-'Alt Blanks'!$I$2,F2) -> 1.7832517 | H2: =IF(G2<0,0,G2) -> 1.7832517 | I2: =H2/2 -> 0.89162585 | L2: b) negative values set to 0 (as there was a data, but the blank median was higher)
A3: W1NC | B3: B_1 | C3: C10:0 | D3: NC | E3: 1 | F3: 3.5278461 | G3: =IFERROR(F3-'Alt Blanks'!$I$3,F3) -> 3.5278461 | H3: =IF(G3<0,0,G3) -> 3.5278461 | I3: =H3/2 -> 1.7639231
A4: W1NC | B4: B_1 | C4: C11:0 | D4: NC | E4: 1 | F4: 0.2621582 | G4: =IFERROR(F4-'Alt Blanks'!$I$4,F4) -> 0.2621582 | H4: =IF(G4<0,0,G4) -> 0.2621582 | I4: =H4/2 -> 0.1310791
A5: W1NC | B5: B_1 | C5: C12:0 | D5: NC | E5: 1 | F5: 17.347754 | G5: =IFERROR(F5-'Alt Blanks'!$I$5,F5) -> 17.347754 | H5: =IF(G5<0,0,G5) -> 17.347754 | I5: =H5/2 -> 8.673877
A6: W1NC | B6: B_1 | C6: C13:0 | D6: NC | E6: 1 | F6: 89.994023 | G6: =IFERROR(F6-'Alt Blanks'!$I$6,F6) -> 89.994023 | H6: =IF(G6<0,0,G6) -> 89.994023 | I6: =H6/2 -> 44.997012
A7: W1NC | B7: B_1 | C7: C14:0 | D7: NC | E7: 1 | F7: 260.69208 | G7: =IFERROR(F7-'Alt Blanks'!$I$7,F7) -> 260.69208 | H7: =IF(G7<0,0,G7) -> 260.69208 | I7: =H7/2 -> 130.34604
A8: W1NC | B8: B_1 | C8: C14:1 | D8: NC | E8: 1 | F8: 0 | G8: =IFERROR(F8-'Alt Blanks'!$I$8,F8) -> 0 | H8: =IF(G8<0,0,G8) -> 0 | I8: =H8/2 -> 0
A9: W1NC | B9: B_1 | C9: C15:0 | D9: NC | E9: 1 | F9: 11.053502 | G9: =IFERROR(F9-'Alt Blanks'!$I$9,F9) -> 11.053502 | H9: =IF(G9<0,0,G9) -> 11.053502 | I9: =H9/2 -> 5.526751
A10: W1NC | B10: B_1 | C10: C15:1 | D10: NC | E10: 1 | F10: 0 | G10: =IFERROR(F10-'Alt Blanks'!$I$10,F10) -> 0 | H10: =IF(G10<0,0,G10) -> 0 | I10: =H10/2 -> 0
A11: W1NC | B11: B_1 | C11: C16:0 | D11: NC | E11: 1 | F11: 3439.147 | G11: =IFERROR(F11-'Alt Blanks'!$I$11,F11) -> 2633.9303 | H11: =IF(G11<0,0,G11) -> 2633.9303 | I11: =H11/2 -> 1316.9652
A12: W1NC | B12: B_1 | C12: C16:1 | D12: NC | E12: 1 | F12: 412.95174 | G12: =IFERROR(F12-'Alt Blanks'!$I$12,F12) -> 412.95174 | H12: =IF(G12<0,0,G12) -> 412.95174 | I12: =H12/2 -> 206.47587
A13: W1NC | B13: B_1 | C13: C17:0 | D13: NC | E13: 1 | F13: 12.402884 | G13: =IFERROR(F13-'Alt Blanks'!$I$13,F13) -> 11.55017 | H13: =IF(G13<0,0,G13) -> 11.55017 | I13: =H13/2 -> 5.7750851
A14: W1NC | B14: B_1 | C14: C17:1 | D14: NC | E14: 1 | F14: 13.942528 | G14: =IFERROR(F14-'Alt Blanks'!$I$14,F14) -> 13.942528 | H14: =IF(G14<0,0,G14) -> 13.942528 | I14: =H14/2 -> 6.9712641
A15: W1NC | B15: B_1 | C15: C18:0 | D15: NC | E15: 1 | F15: 546.45375 | G15: =IFERROR(F15-'Alt Blanks'!$I$15,F15) -> 277.83035 | H15: =IF(G15<0,0,G15) -> 277.83035 | I15: =H15/2 -> 138.91518
A16: W1NC | B16: B_1 | C16: C18:1 | D16: NC | E16: 1 | F16: 1231.4862 | G16: =IFERROR(F16-'Alt Blanks'!$I$16,F16) -> 1213.0203 | H16: =IF(G16<0,0,G16) -> 1213.0203 | I16: =H16/2 -> 606.51014
A17: W1NC | B17: B_1 | C17: C18:2(n-6t) | D17: NC | E17: 1 | F17: 0.2679868 | G17: =IFERROR(F17-'Alt Blanks'!$I$17,F17) -> -0.0639666 | H17: =IF(G17<0,0,G17) -> 0 | I17: =H17/2 -> 0
A18: W1NC | B18: B_1 | C18: C18:2(n-6c) | D18: NC | E18: 1 | F18: 1203.1442 | G18: =IFERROR(F18-'Alt Blanks'!$I$18,F18) -> 1197.1408 | H18: =IF(G18<0,0,G18) -> 1197.1408 | I18: =H18/2 -> 598.57039
A19: W1NC | B19: B_1 | C19: C18:3(n-6) | D19: NC | E19: 1 | F19: 104.46111 | G19: =IFERROR(F19-'Alt Blanks'!$I$19,F19) -> 104.46111 | H19: =IF(G19<0,0,G19) -> 104.46111 | I19: =H19/2 -> 52.230553
A20: W1NC | B20: B_1 | C20: C18:3(n-3) | D20: NC | E20: 1 | F20: 1589.8427 | G20: =IFERROR(F20-'Alt Blanks'!$I$20,F20) -> 1587.9048 | H20: =IF(G20<0,0,G20) -> 1587.9048 | I20: =H20/2 -> 793.95239
A21: W1NC | B21: B_1 | C21: C18:4(n-3) | D21: NC | E21: 1 | F21: 119.44329 | G21: =IFERROR(F21-'Alt Blanks'!$I$21,F21) -> 119.22878 | H21: =IF(G21<0,0,G21) -> 119.22878 | I21: =H21/2 -> 59.614392
A22: W1NC | B22: B_1 | C22: C20:0 | D22: NC | E22: 1 | F22: 38.12247 | G22: =IFERROR(F22-'Alt Blanks'!$I$22,F22) -> 36.527748 | H22: =IF(G22<0,0,G22) -> 36.527748 | I22: =H22/2 -> 18.263874
A23: W1NC | B23: B_1 | C23: C20:1 | D23: NC | E23: 1 | F23: 25.829834 | G23: =IFERROR(F23-'Alt Blanks'!$I$23,F23) -> 25.709096 | H23: =IF(G23<0,0,G23) -> 25.709096 | I23: =H23/2 -> 12.854548
A24: W1NC | B24: B_1 | C24: C20:2(n-6) | D24: NC | E24: 1 | F24: 17.306898 | G24: =IFERROR(F24-'Alt Blanks'!$I$24,F24) -> 17.059728 | H24: =IF(G24<0,0,G24) -> 17.059728 | I24: =H24/2 -> 8.5298642
A25: W1NC | B25: B_1 | C25: C20:3(n-6) | D25: NC | E25: 1 | F25: 4.9322325 | G25: =IFERROR(F25-'Alt Blanks'!$I$25,F25) -> 4.4599917 | H25: =IF(G25<0,0,G25) -> 4.4599917 | I25: =H25/2 -> 2.2299959
A26: W1NC | B26: B_1 | C26: C20:4(n-6) | D26: NC | E26: 1 | F26: 34.410478 | G26: =IFERROR(F26-'Alt Blanks'!$I$26,F26) -> 33.830302 | H26: =IF(G26<0,0,G26) -> 33.830302 | I26: =H26/2 -> 16.915151
A27: W1NC | B27: B_1 | C27: C20:3(n-3) | D27: NC | E27: 1 | F27: 0 | G27: =IFERROR(F27-'Alt Blanks'!$I$27,F27) -> 0 | H27: =IF(G27<0,0,G27) -> 0 | I27: =H27/2 -> 0
A28: W1NC | B28: B_1 | C28: C21:0 | D28: NC | E28: 1 | F28: 0 | G28: =IFERROR(F28-'Alt Blanks'!$I$28,F28) -> 0 | H28: =IF(G28<0,0,G28) -> 0 | I28: =H28/2 -> 0
A29: W1NC | B29: B_1 | C29: C20:5(n-3) | D29: NC | E29: 1 | F29: 93.22772 | G29: =IFERROR(F29-'Alt Blanks'!$I$29,F29) -> 92.616099 | H29: =IF(G29<0,0,G29) -> 92.616099 | I29: =H29/2 -> 46.30805
A30: W1NC | B30: B_1 | C30: C22:0 | D30: NC | E30: 1 | F30: 7.7498568 | G30: =IFERROR(F30-'Alt Blanks'!$I$30,F30) -> 7.7498568 | H30: =IF(G30<0,0,G30) -> 7.7498568 | I30: =H30/2 -> 3.8749284
A31: W1NC | B31: B_1 | C31: C22:1 | D31: NC | E31: 1 | F31: 72.88725 | G31: =IFERROR(F31-'Alt Blanks'!$I$31,F31) -> -29.567383 | H31: =IF(G31<0,0,G31) -> 0 | I31: =H31/2 -> 0
A32: W1NC | B32: B_1 | C32: C22:2 | D32: NC | E32: 1 | F32: 1.9283764 | G32: =IFERROR(F32-'Alt Blanks'!$I$32,F32) -> 0.0008079 | H32: =IF(G32<0,0,G32) -> 0.0008079 | I32: =H32/2 -> 0.00040395
A33: W1NC | B33: B_1 | C33: C22:5(n-3) | D33: NC | E33: 1 | F33: 0 | G33: =IFERROR(F33-'Alt Blanks'!$I$33,F33) -> 0 | H33: =IF(G33<0,0,G33) -> 0 | I33: =H33/2 -> 0
A34: W1NC | B34: B_1 | C34: C22:6(n-3) | D34: NC | E34: 1 | F34: 5.6614434 | G34: =IFERROR(F34-'Alt Blanks'!$I$34,F34) -> 5.6614434 | H34: =IF(G34<0,0,G34) -> 5.6614434 | I34: =H34/2 -> 2.8307217
A35: W1NC | B35: B_1 | C35: C24:0 | D35: NC | E35: 1 | F35: 64.036196 | G35: =IFERROR(F35-'Alt Blanks'!$I$35,F35) -> 64.036196 | H35: =IF(G35<0,0,G35) -> 64.036196 | I35: =H35/2 -> 32.018098
A36: W1NC | B36: B_1 | C36: C24:1 | D36: NC | E36: 1 | F36: 0 | G36: =IFERROR(F36-'Alt Blanks'!$I$36,F36) -> 0 | H36: =IF(G36<0,0,G36) -> 0 | I36: =H36/2 -> 0
A37: W1Cip | B37: B_2 | C37: C08:0 | D37: Cip | E37: 1 | F37: 6.7110905 | G37: =IFERROR(F37-'Alt Blanks'!$I$2,F37) -> 0.0045494 | H37: =IF(G37<0,0,G37) -> 0.0045494 | I37: =H37/2 -> 0.0022747
A38: W1Cip | B38: B_2 | C38: C10:0 | D38: Cip | E38: 1 | F38: 0 | G38: =IFERROR(F38-'Alt Blanks'!$I$3,F38) -> 0 | H38: =IF(G38<0,0,G38) -> 0 | I38: =H38/2 -> 0
A39: W1Cip | B39: B_2 | C39: C11:0 | D39: Cip | E39: 1 | F39: 0 | G39: =IFERROR(F39-'Alt Blanks'!$I$4,F39) -> 0 | H39: =IF(G39<0,0,G39) -> 0 | I39: =H39/2 -> 0
A40: W1Cip | B40: B_2 | C40: C12:0 | D40: Cip | E40: 1 | F40: 3.4789967 | G40: =IFERROR(F40-'Alt Blanks'!$I$5,F40) -> 3.4789967 | H40: =IF(G40<0,0,G40) -> 3.4789967 | I40: =H40/2 -> 1.7394984
...

Sheet Alt Blanks
A1: Oldname | B1: RUNINFO | C1: Name | D1: Treatment | E1: Replicate | F1: FA_µg_sample | I1: median
A2: Blank1 | C2: C08:0 | F2: 6.7065411 | H2: C08:0 | I2: 6.7065411
A3: Blank1 | C3: C10:0 | F3: 4.5137455 | H3: C10:0 | I3: 0
A4: Blank1 | C4: C11:0 | F4: 0.5605737 | H4: C11:0 | I4: 0
A5: Blank1 | C5: C12:0 | F5: 16.079607 | H5: C12:0 | I5: 0
A6: Blank1 | C6: C13:0 | F6: 104.06352 | H6: C13:0 | I6: 0
A7: Blank1 | C7: C14:0 | F7: 28.730075 | H7: C14:0 | I7: 0
A8: Blank1 | C8: C14:1 | F8: 0 | H8: C14:1 | I8: 0
A9: Blank1 | C9: C15:0 | F9: 6.547856 | H9: C15:0 | I9: 0
A10: Blank1 | C10: C15:1 | F10: 0 | H10: C15:1 | I10: 0
A11: Blank1 | C11: C16:0 | F11: 1489.3189 | H11: C16:0 | I11: 805.21669
A12: Blank1 | C12: C16:1 | F12: 0 | H12: C16:1 | I12: 0
A13: Blank1 | C13: C17:0 | F13: 3.3850266 | H13: C17:0 | I13: 0.8527135
A14: Blank1 | C14: C17:1 | F14: NA | H14: C17:1 | I14: 0
A15: Blank1 | C15: C18:0 | F15: 448.63464 | H15: C18:0 | I15: 268.6234
A16: Blank1 | C16: C18:1 | F16: 16.423912 | H16: C18:1 | I16: 18.465913
A17: Blank1 | C17: C18:2(n-6t) | F17: 0.3319534 | H17: C18:2(n-6t) | I17: 0.3319534
A18: Blank1 | C18: C18:2(n-6c) | F18: 6.0034596 | H18: C18:2(n-6c) | I18: 6.0034596
A19: Blank1 | C19: C18:3(n-6) | F19: 0 | H19: C18:3(n-6) | I19: 0
A20: Blank1 | C20: C18:3(n-3) | F20: 1.9379754 | H20: C18:3(n-3) | I20: 1.9379754
A21: Blank1 | C21: C18:4(n-3) | F21: 0.2145091 | H21: C18:4(n-3) | I21: 0.2145091
A22: Blank1 | C22: C20:0 | F22: 8.752849 | H22: C20:0 | I22: 1.5947214
A23: Blank1 | C23: C20:1 | F23: 0.1493779 | H23: C20:1 | I23: 0.1207374
A24: Blank1 | C24: C20:2(n-6) | F24: 0.2437476 | H24: C20:2(n-6) | I24: 0.2471696
A25: Blank1 | C25: C20:3(n-6) | F25: 0.4401581 | H25: C20:3(n-6) | I25: 0.4722408
A26: Blank1 | C26: C20:4(n-6) | F26: 0.5801763 | H26: C20:4(n-6) | I26: 0.5801763
A27: Blank1 | C27: C20:3(n-3) | F27: NA | H27: C20:3(n-3) | I27: #N/A
A28: Blank1 | C28: C21:0 | F28: 0.0007524 | H28: C21:0 | I28: 0
A29: Blank1 | C29: C20:5(n-3) | F29: 0.535825 | H29: C20:5(n-3) | I29: 0.611621
A30: Blank1 | C30: C22:0 | F30: 0 | H30: C22:0 | I30: 0
A31: Blank1 | C31: C22:1 | F31: 165.91263 | H31: C22:1 | I31: 102.45463
A32: Blank1 | C32: C22:2 | F32: 1.9244387 | H32: C22:2 | I32: 1.9275685
A33: Blank1 | C33: C22:5(n-3) | F33: 0 | H33: C22:5(n-3) | I33: 0
A34: Blank1 | C34: C22:6(n-3) | F34: 0 | H34: C22:6(n-3) | I34: 0
A35: Blank1 | C35: C24:0 | F35: 6.9332251 | H35: C24:0 | I35: 0
A36: Blank1 | C36: C24:1 | F36: 0 | H36: C24:1 | I36: 0
A37: Blank2 | C37: C08:0 | F37: 6.7179712
A38: Blank2 | C38: C10:0 | F38: 0
A39: Blank2 | C39: C11:0 | F39: 0
A40: Blank2 | C40: C12:0 | F40: 0
...

Sheet 22.10.2024 alles neu
A1: Oldname | B1: RUNINFO | C1: Name | D1: Treatment | E1: Week | F1: Alt FA_µg_sample | G1: Neu FA_µg_sample | H1: Neu FA_µg_sample | I1: negative values? | J1: µg_FA_per_mg
A2: W1NC | B2: B_1 | C2: C08:0 | D2: NC | E2: 1 | F2: 8.4897928 | G2: 0.76282936 | H2: 0.76282936 | I2: =IF(G2<0,0,G2) -> 0.76282936 | J2: =I2/2 -> 0.38141468
A3: W1NC | B3: B_1 | C3: C10:0 | D3: NC | E3: 1 | F3: 3.5278461 | G3: -0.094178237 | H3: -0.094178237 | I3: =IF(G3<0,0,G3) -> 0 | J3: =I3/2 -> 0 | M3: a) in Spalte FA_ug_sample, bei #NV Angabe stand in Patricks aufgeräumter Liste "ND"
A4: W1NC | B4: B_1 | C4: C11:0 | D4: NC | E4: 1 | F4: 0.2621582 | G4: 0.039129578 | H4: 0.039129578 | I4: =IF(G4<0,0,G4) -> 0.039129578 | J4: =I4/2 -> 0.019564789 | M4: b) negative values set to 0 (as there was a data, but the blank median was higher)
A5: W1NC | B5: B_1 | C5: C12:0 | D5: NC | E5: 1 | F5: 17.347754 | G5: 7.5664663 | H5: 7.5664663 | I5: =IF(G5<0,0,G5) -> 7.5664663 | J5: =I5/2 -> 3.7832332
A6: W1NC | B6: B_1 | C6: C13:0 | D6: NC | E6: 1 | F6: 89.994023 | G6: 7.2420249 | H6: 7.2420249 | I6: =IF(G6<0,0,G6) -> 7.2420249 | J6: =I6/2 -> 3.6210124
A7: W1NC | B7: B_1 | C7: C14:0 | D7: NC | E7: 1 | F7: 260.69208 | G7: 68.378216 | H7: 68.378216 | I7: =IF(G7<0,0,G7) -> 68.378216 | J7: =I7/2 -> 34.189108
A8: W1NC | B8: B_1 | C8: C14:1 | D8: NC | E8: 1 | F8: 0 | G8: -0.021516307 | H8: -0.021516307 | I8: =IF(G8<0,0,G8) -> 0 | J8: =I8/2 -> 0
A9: W1NC | B9: B_1 | C9: C15:0 | D9: NC | E9: 1 | F9: 11.053502 | G9: 0.19931254 | H9: 0.19931254 | I9: =IF(G9<0,0,G9) -> 0.19931254 | J9: =I9/2 -> 0.099656271
A10: W1NC | B10: B_1 | C10: C15:1 | D10: NC | E10: 1 | F10: 0 | G10: 0.90598315 | H10: 0.90598315 | I10: =IF(G10<0,0,G10) -> 0.90598315 | J10: =I10/2 -> 0.45299158
A11: W1NC | B11: B_1 | C11: C16:0 | D11: NC | E11: 1 | F11: 3439.147 | G11: 250.68685 | H11: 250.68685 | I11: =IF(G11<0,0,G11) -> 250.68685 | J11: =I11/2 -> 125.34343
A12: W1NC | B12: B_1 | C12: C16:1 | D12: NC | E12: 1 | F12: 412.95174 | G12: 103.78202 | H12: 103.78202 | I12: =IF(G12<0,0,G12) -> 103.78202 | J12: =I12/2 -> 51.891008
A13: W1NC | B13: B_1 | C13: C17:1 | D13: NC | E13: 1 | F13: 13.942528 | G13: 2.9522131 | H13: 2.9522131 | I13: =IF(G13<0,0,G13) -> 2.9522131 | J13: =I13/2 -> 1.4761066
A14: W1NC | B14: B_1 | C14: C18:0 | D14: NC | E14: 1 | F14: 546.45375 | G14: 44.748065 | H14: 44.748065 | I14: =IF(G14<0,0,G14) -> 44.748065 | J14: =I14/2 -> 22.374032
A15: W1NC | B15: B_1 | C15: C18:1 | D15: NC | E15: 1 | F15: 1231.4862 | G15: 14.15372 | H15: 14.15372 | I15: =IF(G15<0,0,G15) -> 14.15372 | J15: =I15/2 -> 7.0768598
A16: W1NC | B16: B_1 | C16: C18:2(n-6t) | D16: NC | E16: 1 | F16: 0.2679868 | G16: 109.55238 | H16: 109.55238 | I16: =IF(G16<0,0,G16) -> 109.55238 | J16: =I16/2 -> 54.776192
... A309: W3Cip | B309: B_10 | C309: C10:0 | D309: Cip | E309: 3 | F309: 4.1247162 | G309: 0.089866979 | H309: 0.089866979 | I309: =IF(G309<0,0,G309) -> 0.089866979 | J309: =I309/2 -> 0.04493349
A310: W3Cip | B310: B_10 | C310: C11:0 | D310: Cip | E310: 3 | F310: #N/A | G310: 0.016703509 | H310: 0.016703509 | I310: =IF(G310<0,0,G310) -> 0.016703509 | J310: =I310/2 -> 0.0083517545
A311: W3Cip | B311: B_10 | C311: C12:0 | D311: Cip | E311: 3 | F311: 14.241061 | G311: 6.5955487 | H311: 6.5955487 | I311: =IF(G311<0,0,G311) -> 6.5955487 | J311: =I311/2 -> 3.2977743
A312: W3Cip | B312: B_10 | C312: C13:0 | D312: Cip | E312: 3 | F312: 116.72914 | G312: 9.3926011 | H312: 9.3926011 | I312: =IF(G312<0,0,G312) -> 9.3926011 | J312: =I312/2 -> 4.6963005
A313: W3Cip | B313: B_10 | C313: C14:0 | D313: Cip | E313: 3 | F313: 307.14897 | G313: 80.308787 | H313: 80.308787 | I313: =IF(G313<0,0,G313) -> 80.308787 | J313: =I313/2 -> 40.154393
A314: W3Cip | B314: B_10 | C314: C14:1 | D314: Cip | E314: 3 | F314: 0 | G314: 0.055098335 | H314: 0.055098335 | I314: =IF(G314<0,0,G314) -> 0.055098335 | J314: =I314/2 -> 0.027549168
A315: W3Cip | B315: B_10 | C315: C15:0 | D315: Cip | E315: 3 | F315: 15.876937 | G315: 0.76946538 | H315: 0.76946538 | I315: =IF(G315<0,0,G315) -> 0.76946538 | J315: =I315/2 -> 0.38473269
A316: W3Cip | B316: B_10 | C316: C15:1 | D316: Cip | E316: 3 | F316: 0 | G316: -0.053555463 | H316: -0.053555463 | I316: =IF(G316<0,0,G316) -> 0 | J316: =I316/2 -> 0
A317: W3Cip | B317: B_10 | C317: C16:0 | D317: Cip | E317: 3 | F317: 5408.4227 | G317: 394.31126 | H317: 394.31126 | I317: =IF(G317<0,0,G317) -> 394.31126 | J317: =I317/2 -> 197.15563
A318: W3Cip | B318: B_10 | C318: C16:1 | D318: Cip | E318: 3 | F318: 949.72925 | G318: 238.09212 | H318: 238.09212 | I318: =IF(G318<0,0,G318) -> 238.09212 | J318: =I318/2 -> 119.04606
A319: W3Cip | B319: B_10 | C319: C17:1 | D319: Cip | E319: 3 | F319: 20.971489 | G319: 4.3637172 | H319: 4.3637172 | I319: =IF(G319<0,0,G319) -> 4.3637172 | J319: =I319/2 -> 2.1818586
A320: W3Cip | B320: B_10 | C320: C18:0 | D320: Cip | E320: 3 | F320: 543.79472 | G320: 44.531956 | H320: 44.531956 | I320: =IF(G320<0,0,G320) -> 44.531956 | J320: =I320/2 -> 22.265978
A321: W3Cip | B321: B_10 | C321: C18:1 | D321: Cip | E321: 3 | F321: 1955.7333 | G321: 477.69422 | H321: 477.69422 | I321: =IF(G321<0,0,G321) -> 477.69422 | J321: =I321/2 -> 238.84711
A322: W3Cip | B322: B_10 | C322: C18:2(n-6t) | D322: Cip | E322: 3 | F322: 0 | G322: -0.17181211 | H322: -0.17181211 | I322: =IF(G322<0,0,G322) -> 0 | J322: =I322/2 -> 0
... A331: W3Cip | B331: B_10 | C331: C20:4(n-6) | D331: Cip | E331: 3 | F331: 112.97919 | G331: 13.985073 | H331: 13.985073 | I331: =IF(G331<0,0,G331) -> 13.985073 | J331: =I331/2 -> 6.9925363
A332: W3Cip | B332: B_10 | C332: C20:3(n-3) | D332: Cip | E332: 3 | F332: #N/A | G332: 0.066317454 | H332: 0.066317454 | I332: =IF(G332<0,0,G332) -> 0.066317454 | J332: =I332/2 -> 0.033158727
A333: W3Cip | B333: B_10 | C333: C21:0 | D333: Cip | E333: 3 | F333: 0 | G333: 0.034190319 | H333: 0.034190319 | I333: =IF(G333<0,0,G333) -> 0.034190319 | J333: =I333/2 -> 0.01709516
A334: W3Cip | B334: B_10 | C334: C20:5(n-3) | D334: Cip | E334: 3 | F334: 294.62663 | G334: 28.262679 | H334: 28.262679 | I334: =IF(G334<0,0,G334) -> 28.262679 | J334: =I334/2 -> 14.13134
A335: W3Cip | B335: B_10 | C335: C22:0 | D335: Cip | E335: 3 | F335: 1.5882031 | G335: 0.083489708 | H335: 0.083489708 | I335: =IF(G335<0,0,G335) -> 0.083489708 | J335: =I335/2 -> 0.041744854
A336: W3Cip | B336: B_10 | C336: C22:1 | D336: Cip | E336: 3 | F336: 94.49607 | G336: 29.326342 | H336: 29.326342 | I336: =IF(G336<0,0,G336) -> 29.326342 | J336: =I336/2 -> 14.663171
A337: W3Cip | B337: B_10 | C337: C22:2 | D337: Cip | E337: 3 | F337: 1.9322348 | G337: 0.17318383 | H337: 0.17318383 | I337: =IF(G337<0,0,G337) -> 0.17318383 | J337: =I337/2 -> 0.086591915
A338: W3Cip | B338: B_10 | C338: C22:5(n-3) | D338: Cip | E338: 3 | F338: 0.7963374 | G338: 0.47800243 | H338: 0.47800243 | I338: =IF(G338<0,0,G338) -> 0.47800243 | J338: =I338/2 -> 0.23900122
A339: W3Cip | B339: B_10 | C339: C22:6(n-3) | D339: Cip | E339: 3 | F339: 17.029595 | G339: 2.1000833 | H339: 2.1000833 | I339: =IF(G339<0,0,G339) -> 2.1000833 | J339: =I339/2 -> 1.0500416
A340: W3Cip | B340: B_10 | C340: C24:0 | D340: Cip | E340: 3 | F340: 108.88773 | G340: 4.3603965 | H340: 4.3603965 | I340: =IF(G340<0,0,G340) -> 4.3603965 | J340: =I340/2 -> 2.1801982
...

Sheet 09.03.2025 alles neu
A1: Oldname | B1: RUNINFO | C1: Name | D1: Treatment | E1: Week | F1: Alt FA_µg_sample | G1: Neu FA_µg_sample | H1: Neu FA_µg_sample | I1: negative values? | J1: µg_FA_per_mg
A2: W1NC | B2: B_1 | C2: C08:0 | D2: NC | E2: 1 | F2: 8.4897928 | G2: #N/A | H2: 0.76282936 | I2: =IF(G2<0,0,G2) -> #N/A | J2: =I2/2 -> #N/A
A3: W1NC | B3: B_1 | C3: C10:0 | D3: NC | E3: 1 | F3: 3.5278461 | G3: #N/A | H3: -0.094178237 | I3: =IF(G3<0,0,G3) -> #N/A | J3: =I3/2 -> #N/A | M3: a) in Spalte FA_ug_sample, bei #NV Angabe stand in Patricks aufgeräumter Liste "ND"
A4: W1NC | B4: B_1 | C4: C11:0 | D4: NC | E4: 1 | F4: 0.2621582 | G4: #N/A | H4: 0.039129578 | I4: =IF(G4<0,0,G4) -> #N/A | J4: =I4/2 -> #N/A | M4: b) negative values set to 0 (as there was a data, but the blank median was higher)
A5: W1NC | B5: B_1 | C5: C12:0 | D5: NC | E5: 1 | F5: 17.347754 | G5: 2.1392032 | H5: 7.5664663 | I5: =IF(G5<0,0,G5) -> 2.1392032 | J5: =I5/2 -> 1.0696016
A6: W1NC | B6: B_1 | C6: C13:0 | D6: NC | E6: 1 | F6: 89.994023 | G6: 8.6586979 | H6: 7.2420249 | I6: =IF(G6<0,0,G6) -> 8.6586979 | J6: =I6/2 -> 4.3293489
A7: W1NC | B7: B_1 | C7: C14:0 | D7: NC | E7: 1 | F7: 260.69208 | G7: 25.746439 | H7: 68.378216 | I7: =IF(G7<0,0,G7) -> 25.746439 | J7: =I7/2 -> 12.87322
A8: W1NC | B8: B_1 | C8: C14:1 | D8: NC | E8: 1 | F8: 0 | G8: #N/A | H8: -0.021516307 | I8: =IF(G8<0,0,G8) -> #N/A | J8: =I8/2 -> #N/A
A9: W1NC | B9: B_1 | C9: C15:0 | D9: NC | E9: 1 | F9: 11.053502 | G9: 1.5609963 | H9: 0.19931254 | I9: =IF(G9<0,0,G9) -> 1.5609963 | J9: =I9/2 -> 0.78049817
A10: W1NC | B10: B_1 | C10: C15:1 | D10: NC | E10: 1 | F10: 0 | G10: #N/A | H10: 0.90598315 | I10: =IF(G10<0,0,G10) -> #N/A | J10: =I10/2 -> #N/A
A11: W1NC | B11: B_1 | C11: C16:0 | D11: NC | E11: 1 | F11: 3439.147 | G11: 79.550237 | H11: 250.68685 | I11: =IF(G11<0,0,G11) -> 79.550237 | J11: =I11/2 -> 39.775118
A12: W1NC | B12: B_1 | C12: C16:1 | D12: NC | E12: 1 | F12: 412.95174 | G12: 34.756348 | H12: 103.78202 | I12: =IF(G12<0,0,G12) -> 34.756348 | J12: =I12/2 -> 17.378174
A13: W1NC | B13: B_1 | C13: C17:1 | D13: NC | E13: 1 | F13: 13.942528 | G13: 0.91435954 | H13: 2.9522131 | I13: =IF(G13<0,0,G13) -> 0.91435954 | J13: =I13/2 -> 0.45717977
A14: W1NC | B14: B_1 | C14: C18:0 | D14: NC | E14: 1 | F14: 546.45375 | G14: 43.94766 | H14: 44.748065 | I14: =IF(G14<0,0,G14) -> 43.94766 | J14: =I14/2 -> 21.97383
A15: W1NC | B15: B_1 | C15: C18:1 | D15: NC | E15: 1 | F15: 1231.4862 | G15: 156.19025 | H15: 14.15372 | I15: =IF(G15<0,0,G15) -> 156.19025 | J15: =I15/2 -> 78.095124
A16: W1NC | B16: B_1 | C16: C18:2(n-6t) | D16: NC | E16: 1 | F16: 0.2679868 | G16: #N/A | H16: 109.55238 | I16: =IF(G16<0,0,G16) -> #N/A | J16: =I16/2 -> #N/A
A17: W1NC | B17: B_1 | C17: C18:2(n-6c) | D17: NC | E17: 1 | F17: 1203.1442 | G17: 87.091349 | H17: 211.00127 | I17: =IF(G17<0,0,G17) -> 87.091349 | J17: =I17/2 -> 43.545675
A18: W1NC | B18: B_1 | C18: C18:3(n-6) | D18: NC | E18: 1 | F18: 104.46111 | G18: 6.472962 | H18: 15.620748 | I18: =IF(G18<0,0,G18) -> 6.472962 | J18: =I18/2 -> 3.236481
A19: W1NC | B19: B_1 | C19: C18:3(n-3) | D19: NC | E19: 1 | F19: 1589.8427 | G19: 32.312425 | H19: 45.501107 | I19: =IF(G19<0,0,G19) -> 32.312425 | J19: =I19/2 -> 16.156213
A20: W1NC | B20: B_1 | C20: C18:4(n-3) | D20: NC | E20: 1 | F20: 119.44329 | G20: 12.470841 | H20: 10.816488 | I20: =IF(G20<0,0,G20) -> 12.470841 | J20: =I20/2 -> 6.2354205
A21: W1NC | B21: B_1 | C21: C20:0 | D21: NC | E21: 1 | F21: 38.12247 | G21: 3.7749747 | H21: 1.0584745 | I21: =IF(G21<0,0,G21) -> 3.7749747 | J21: =I21/2 -> 1.8874874
A22: W1NC | B22: B_1 | C22: C20:1 | D22: NC | E22: 1 | F22: 25.829834 | G22: 5.7257133 | H22: 0.16806924 | I22: =IF(G22<0,0,G22) -> 5.7257133 | J22: =I22/2 -> 2.8628567
A23: W1NC | B23: B_1 | C23: C20:2(n-6) | D23: NC | E23: 1 | F23: 17.306898 | G23: 1.8324287 | H23: 5.0858632 | I23: =IF(G23<0,0,G23) -> 1.8324287 | J23: =I23/2 -> 0.91621436
A24: W1NC | B24: B_1 | C24: C20:3(n-6) | D24: NC | E24: 1 | F24: 4.9322325 | G24: 0.65366118 | H24: 0.77664578 | I24: =IF(G24<0,0,G24) -> 0.65366118 | J24: =I24/2 -> 0.32683059
A25: W1NC | B25: B_1 | C25: C20:4(n-6) | D25: NC | E25: 1 | F25: 34.410478 | G25: 1.2757594 | H25: 4.2546496 | I25: =IF(G25<0,0,G25) -> 1.2757594 | J25: =I25/2 -> 0.6378797
A26: W1NC | B26: B_1 | C26: C20:3(n-3) | D26: NC | E26: 1 | F26: 0 | G26: #N/A | H26: 2.6544927 | I26: =IF(G26<0,0,G26) -> #N/A | J26: =I26/2 -> #N/A
A27: W1NC | B27: B_1 | C27: C21:0 | D27: NC | E27: 1 | F27: 0 | G27: #N/A | H27: 0.042837186 | I27: =IF(G27<0,0,G27) -> #N/A | J27: =I27/2 -> #N/A
A28: W1NC | B28: B_1 | C28: C20:5(n-3) | D28: NC | E28: 1 | F28: 93.22772 | G28: 3.5899642 | H28: 4.547054 | I28: =IF(G28<0,0,G28) -> 3.5899642 | J28: =I28/2 -> 1.7949821
A29: W1NC | B29: B_1 | C29: C22:0 | D29: NC | E29: 1 | F29: 7.7498568 | G29: 1.5776484 | H29: 0.19184441 | I29: =IF(G29<0,0,G29) -> 1.5776484 | J29: =I29/2 -> 0.7888242
A30: W1NC | B30: B_1 | C30: C22:1 | D30: NC | E30: 1 | F30: 72.88725 | G30: 7.0346462 | H30: 22.483049 | I30: =IF(G30<0,0,G30) -> 7.0346462 | J30: =I30/2 -> 3.5173231
A31: W1NC | B31: B_1 | C31: C22:2 | D31: NC | E31: 1 | F31: 1.9283764 | G31: #N/A | H31: 0.17220419 | I31: =IF(G31<0,0,G31) -> #N/A | J31: =I31/2 -> #N/A
A32: W1NC | B32: B_1 | C32: C22:5(n-3) | D32: NC | E32: 1 | F32: 0 | G32: #N/A | H32: 0.13750299 | I32: =IF(G32<0,0,G32) -> #N/A | J32: =I32/2 -> #N/A
A33: W1NC | B33: B_1 | C33: C22:6(n-3) | D33: NC | E33: 1 | F33: 5.6614434 | G33: 0.63953228 | H33: 0.74847597 | I33: =IF(G33<0,0,G33) -> 0.63953228 | J33: =I33/2 -> 0.31976614
A34: W1NC | B34: B_1 | C34: C24:0 | D34: NC | E34: 1 | F34: 64.036196 | G34: 1.7327895 | H34: -0.10656165 | I34: =IF(G34<0,0,G34) -> 1.7327895 | J34: =I34/2 -> 0.86639477
A35: W1NC | B35: B_1 | C35: C24:1 | D35: NC | E35: 1 | F35: 0 | G35: #N/A | H35: 0.49007247 | I35: =IF(G35<0,0,G35) -> #N/A | J35: =I35/2 -> #N/A
A36: W1Cip | B36: B_2 | C36: C08:0 | D36: Cip | E36: 1 | F36: 6.7110905 | G36: #N/A | H36: 0.75030683 | I36: =IF(G36<0,0,G36) -> #N/A | J36: =I36/2 -> #N/A
A37: W1Cip | B37: B_2 | C37: C10:0 | D37: Cip | E37: 1 | F37: 0 | G37: #N/A | H37: -0.09978084 | I37: =IF(G37<0,0,G37) -> #N/A | J37: =I37/2 -> #N/A
A38: W1Cip | B38: B_2 | C38: C11:0 | D38: Cip | E38: 1 | F38: 0 | G38: #N/A | H38: -0.035037025 | I38: =IF(G38<0,0,G38) -> #N/A | J38: =I38/2 -> #N/A
A39: W1Cip | B39: B_2 | C39: C12:0 | D39: Cip | E39: 1 | F39: 3.4789967 | G39: 0.82426176 | H39: 3.2321375 | I39: =IF(G39<0,0,G39) -> 0.82426176 | J39: =I39/2 -> 0.41213088
A40: W1Cip | B40: B_2 | C40: C13:0 | D40: Cip | E40: 1 | F40: 76.516699 | G40: 7.7609377 | H40: 6.1579074 | I40: =IF(G40<0,0,G40) -> 7.7609377 | J40: =I40/2 -> 3.8804688
...

Sheet Tabelle1
A1: replicate | B1: fa | C1: week | D1: treatment | E1: fa_conc
A2: B_1 | B2: C08:0 | C2: 1 | D2: NC | E2: 0
A3: B_1 | B3: C10:0 | C3: 1 | D3: NC | E3: 0
A4: B_1 | B4: C11:0 | C4: 1 | D4: NC | E4: 0
A5: B_1 | B5: C12:0 | C5: 1 | D5: NC | E5: 1.0696016
A6: B_1 | B6: C13:0 | C6: 1 | D6: NC | E6: 4.3293489
A7: B_1 | B7: C14:0 | C7: 1 | D7: NC | E7: 12.87322
A8: B_1 | B8: C14:1 | C8: 1 | D8: NC | E8: 0
A9: B_1 | B9: C15:0 | C9: 1 | D9: NC | E9: 0.78049817
A10: B_1 | B10: C15:1 | C10: 1 | D10: NC | E10: 0
A11: B_1 | B11: C16:0 | C11: 1 | D11: NC | E11: 39.775118
A12: B_1 | B12: C16:1 | C12: 1 | D12: NC | E12: 17.378174
A13: B_1 | B13: C17:1 | C13: 1 | D13: NC | E13: 0.45717977
... A409: B_12 | B409: C24:1 | C409: 3 | D409: Mix | E409: 0
