Workbook

Sheet !alt_all FA
A1: Oldname | B1: RUNINFO | C1: Name | D1: FA | E1: Treatment | F1: FA_µg_sample | G1: blank deduction | H1: negative values to 0 | I1: µg_FA_per_mg dryweight | L1: Infos: | M1: a) in Spalte FA_ug_sample, bei #NV Angabe stand in Patricks aufgeräumter Liste "ND"
A2: NC25 | B2: S_1 | C2: C08:0 | D2: SAFA | E2: NC | F2: 6.9195217 | G2: =IFERROR(F2-alt_Blanks!$I$2,F2) -> 0.2129806 | H2: =IF(G2<0,0,G2) -> 0.2129806 | I2: =H2/0.4108 -> 0.51845326 | M2: b) negative values set to 0 (as there was a data, but the blank average was higher)
A3: NC25 | B3: S_1 | C3: C10:0 | D3: SAFA | E3: NC | F3: 0 | G3: =IFERROR(F3-alt_Blanks!$I$3,F3) -> 0 | H3: =IF(G3<0,0,G3) -> 0 | I3: =H3/0.4108 -> 0
A4: NC25 | B4: S_1 | C4: C11:0 | D4: SAFA | E4: NC | F4: 0 | G4: =IFERROR(F4-alt_Blanks!$I$4,F4) -> 0 | H4: =IF(G4<0,0,G4) -> 0 | I4: =H4/0.4108 -> 0
A5: NC25 | B5: S_1 | C5: C12:0 | D5: SAFA | E5: NC | F5: 3.9083869 | G5: =IFERROR(F5-alt_Blanks!$I$5,F5) -> 3.9083869 | H5: =IF(G5<0,0,G5) -> 3.9083869 | I5: =H5/0.4108 -> 9.5140869
A6: NC25 | B6: S_1 | C6: C13:0 | D6: SAFA | E6: NC | F6: 89.102143 | G6: =IFERROR(F6-alt_Blanks!$I$6,F6) -> 89.102143 | H6: =IF(G6<0,0,G6) -> 89.102143 | I6: =H6/0.4108 -> 216.89908
A7: NC25 | B7: S_1 | C7: C14:0 | D7: SAFA | E7: NC | F7: 82.495747 | G7: =IFERROR(F7-alt_Blanks!$I$7,F7) -> 82.495747 | H7: =IF(G7<0,0,G7) -> 82.495747 | I7: =H7/0.4108 -> 200.8173
A8: NC25 | B8: S_1 | C8: C14:1 | D8: MUFA | E8: NC | F8: 0 | G8: =IFERROR(F8-alt_Blanks!$I$8,F8) -> 0 | H8: =IF(G8<0,0,G8) -> 0 | I8: =H8/0.4108 -> 0
A9: NC25 | B9: S_1 | C9: C15:0 | D9: SAFA | E9: NC | F9: 12.380672 | G9: =IFERROR(F9-alt_Blanks!$I$9,F9) -> 12.380672 | H9: =IF(G9<0,0,G9) -> 12.380672 | I9: =H9/0.4108 -> 30.137956
A10: NC25 | B10: S_1 | C10: C15:1 | D10: MUFA | E10: NC | F10: 0 | G10: =IFERROR(F10-alt_Blanks!$I$10,F10) -> 0 | H10: =IF(G10<0,0,G10) -> 0 | I10: =H10/0.4108 -> 0
A11: NC25 | B11: S_1 | C11: C16:0 | D11: SAFA | E11: NC | F11: 2493.7801 | G11: =IFERROR(F11-alt_Blanks!$I$11,F11) -> 1688.5634 | H11: =IF(G11<0,0,G11) -> 1688.5634 | I11: =H11/0.4108 -> 4110.427
A12: NC25 | B12: S_1 | C12: C16:1 | D12: MUFA | E12: NC | F12: 349.68088 | G12: =IFERROR(F12-alt_Blanks!$I$12,F12) -> 349.68088 | H12: =IF(G12<0,0,G12) -> 349.68088 | I12: =H12/0.4108 -> 851.21927
A13: NC25 | B13: S_1 | C13: C17:0 | D13: SAFA | E13: NC | F13: 19.372227 | G13: =IFERROR(F13-alt_Blanks!$I$13,F13) -> 18.519513 | H13: =IF(G13<0,0,G13) -> 18.519513 | I13: =H13/0.4108 -> 45.08158
A14: NC25 | B14: S_1 | C14: C17:1 | D14: MUFA | E14: NC | F14: 0 | G14: =IFERROR(F14-alt_Blanks!$I$14,F14) -> 0 | H14: =IF(G14<0,0,G14) -> 0 | I14: =H14/0.4108 -> 0
A15: NC25 | B15: S_1 | C15: C18:0 | D15: SAFA | E15: NC | F15: 465.12035 | G15: =IFERROR(F15-alt_Blanks!$I$15,F15) -> 196.49695 | H15: =IF(G15<0,0,G15) -> 196.49695 | I15: =H15/0.4108 -> 478.32754
A16: NC25 | B16: S_1 | C16: C18:1 | D16: MUFA | E16: NC | F16: 393.7337 | G16: =IFERROR(F16-alt_Blanks!$I$16,F16) -> 375.26778 | H16: =IF(G16<0,0,G16) -> 375.26778 | I16: =H16/0.4108 -> 913.50483
A17: NC25 | B17: S_1 | C17: C18:2(n-6t) | D17: PUFA | E17: NC | F17: 0.3628882 | G17: =IFERROR(F17-alt_Blanks!$I$17,F17) -> 0.0309348 | H17: =IF(G17<0,0,G17) -> 0.0309348 | I17: =H17/0.4108 -> 0.075303797
A18: NC25 | B18: S_1 | C18: C18:2(n-6c) | D18: PUFA | E18: NC | F18: 217.57505 | G18: =IFERROR(F18-alt_Blanks!$I$18,F18) -> 211.5716 | H18: =IF(G18<0,0,G18) -> 211.5716 | I18: =H18/0.4108 -> 515.02336
A19: NC25 | B19: S_1 | C19: C18:3(n-6) | D19: PUFA | E19: NC | F19: 0 | G19: =IFERROR(F19-alt_Blanks!$I$19,F19) -> 0 | H19: =IF(G19<0,0,G19) -> 0 | I19: =H19/0.4108 -> 0
A20: NC25 | B20: S_1 | C20: C18:3(n-3) | D20: PUFA | E20: NC | F20: 181.89141 | G20: =IFERROR(F20-alt_Blanks!$I$20,F20) -> 179.95344 | H20: =IF(G20<0,0,G20) -> 179.95344 | I20: =H20/0.4108 -> 438.05608
A21: NC25 | B21: S_1 | C21: C18:4(n-3) | D21: PUFA | E21: NC | F21: 8.8877941 | G21: =IFERROR(F21-alt_Blanks!$I$21,F21) -> 8.673285 | H21: =IF(G21<0,0,G21) -> 8.673285 | I21: =H21/0.4108 -> 21.113157
A22: NC25 | B22: S_1 | C22: C20:0 | D22: SAFA | E22: NC | F22: 4.7820946 | G22: =IFERROR(F22-alt_Blanks!$I$22,F22) -> 3.1873732 | H22: =IF(G22<0,0,G22) -> 3.1873732 | I22: =H22/0.4108 -> 7.7589416
A23: NC25 | B23: S_1 | C23: C20:1 | D23: MUFA | E23: NC | F23: 9.3887077 | G23: =IFERROR(F23-alt_Blanks!$I$23,F23) -> 9.2679703 | H23: =IF(G23<0,0,G23) -> 9.2679703 | I23: =H23/0.4108 -> 22.560785
A24: NC25 | B24: S_1 | C24: C20:2(n-6) | D24: PUFA | E24: NC | F24: 22.894911 | G24: =IFERROR(F24-alt_Blanks!$I$24,F24) -> 22.647741 | H24: =IF(G24<0,0,G24) -> 22.647741 | I24: =H24/0.4108 -> 55.130821
A25: NC25 | B25: S_1 | C25: C20:3(n-6) | D25: PUFA | E25: NC | F25: 0.4021034 | G25: =IFERROR(F25-alt_Blanks!$I$25,F25) -> -0.0701374 | H25: =IF(G25<0,0,G25) -> 0 | I25: =H25/0.4108 -> 0
A26: NC25 | B26: S_1 | C26: C20:4(n-6) | D26: PUFA | E26: NC | F26: 214.76229 | G26: =IFERROR(F26-alt_Blanks!$I$26,F26) -> 214.18212 | H26: =IF(G26<0,0,G26) -> 214.18212 | I26: =H26/0.4108 -> 521.37808
A27: NC25 | B27: S_1 | C27: C20:3(n-3) | D27: PUFA | E27: NC | F27: #N/A | G27: =IFERROR(F27-alt_Blanks!$I$27,F27) -> #N/A | H27: =IF(G27<0,0,G27) -> #N/A | I27: =H27/0.4108 -> #N/A
A28: NC25 | B28: S_1 | C28: C21:0 | D28: SAFA | E28: NC | F28: 0 | G28: =IFERROR(F28-alt_Blanks!$I$28,F28) -> 0 | H28: =IF(G28<0,0,G28) -> 0 | I28: =H28/0.4108 -> 0
A29: NC25 | B29: S_1 | C29: C20:5(n-3) | D29: PUFA | E29: NC | F29: 187.38594 | G29: =IFERROR(F29-alt_Blanks!$I$29,F29) -> 186.77432 | H29: =IF(G29<0,0,G29) -> 186.77432 | I29: =H29/0.4108 -> 454.65999
A30: NC25 | B30: S_1 | C30: C22:0 | D30: SAFA | E30: NC | F30: 0 | G30: =IFERROR(F30-alt_Blanks!$I$30,F30) -> 0 | H30: =IF(G30<0,0,G30) -> 0 | I30: =H30/0.4108 -> 0
A31: NC25 | B31: S_1 | C31: C22:1 | D31: MUFA | E31: NC | F31: 94.303771 | G31: =IFERROR(F31-alt_Blanks!$I$31,F31) -> -8.1508628 | H31: =IF(G31<0,0,G31) -> 0 | I31: =H31/0.4108 -> 0
A32: NC25 | B32: S_1 | C32: C22:2 | D32: PUFA | E32: NC | F32: 1.9159594 | G32: =IFERROR(F32-alt_Blanks!$I$32,F32) -> -0.0116091 | H32: =IF(G32<0,0,G32) -> 0 | I32: =H32/0.4108 -> 0
A33: NC25 | B33: S_1 | C33: C22:5(n-3) | D33: PUFA | E33: NC | F33: 5.5423441 | G33: =IFERROR(F33-alt_Blanks!$I$33,F33) -> 5.5423441 | H33: =IF(G33<0,0,G33) -> 5.5423441 | I33: =H33/0.4108 -> 13.491587
A34: NC25 | B34: S_1 | C34: C22:6(n-3) | D34: PUFA | E34: NC | F34: 6.4709817 | G34: =IFERROR(F34-alt_Blanks!$I$34,F34) -> 6.4709817 | H34: =IF(G34<0,0,G34) -> 6.4709817 | I34: =H34/0.4108 -> 15.752146
A35: NC25 | B35: S_1 | C35: C24:0 | D35: SAFA | E35: NC | F35: 6.612612 | G35: =IFERROR(F35-alt_Blanks!$I$35,F35) -> 6.612612 | H35: =IF(G35<0,0,G35) -> 6.612612 | I35: =H35/0.4108 -> 16.096913
A36: NC25 | B36: S_1 | C36: C24:1 | D36: MUFA | E36: NC | F36: 0 | G36: =IFERROR(F36-alt_Blanks!$I$36,F36) -> 0 | H36: =IF(G36<0,0,G36) -> 0 | I36: =H36/0.4108 -> 0
A37: NC26 | B37: S_2 | C37: C08:0 | D37: SAFA | E37: NC | F37: 6.7014393 | G37: =IFERROR(F37-alt_Blanks!$I$2,F37) -> -0.0051018 | H37: =IF(G37<0,0,G37) -> 0 | I37: =H37/0.6072 -> 0
A38: NC26 | B38: S_2 | C38: C10:0 | D38: SAFA | E38: NC | F38: 0 | G38: =IFERROR(F38-alt_Blanks!$I$3,F38) -> 0 | H38: =IF(G38<0,0,G38) -> 0 | I38: =H38/0.6072 -> 0
A39: NC26 | B39: S_2 | C39: C11:0 | D39: SAFA | E39: NC | F39: 0 | G39: =IFERROR(F39-alt_Blanks!$I$4,F39) -> 0 | H39: =IF(G39<0,0,G39) -> 0 | I39: =H39/0.6072 -> 0
A40: NC26 | B40: S_2 | C40: C12:0 | D40: SAFA | E40: NC | F40: 8.8682996 | G40: =IFERROR(F40-alt_Blanks!$I$5,F40) -> 8.8682996 | H40: =IF(G40<0,0,G40) -> 8.8682996 | I40: =H40/0.6072 -> 14.605236
...

Sheet from culture Day 0_baseline
A1: Oldname | B1: RUNINFO | C1: Name | D1: Treatment | E1: Replicate | F1: FA_µg_sample | G1: µg_FA_per_mg
A2: S3 | C2: C08:0 | F2: 0.74884669
A3: S3 | C3: C10:0 | F3: -0.10552341 | I3: jetzt noch werte durch mg einwaage teilen
A4: S3 | C4: C11:0 | F4: -0.042365544
A5: S3 | C5: C12:0 | F5: -0.39463838
A6: S3 | C6: C13:0 | F6: -0.094757783
A7: S3 | C7: C14:0 | F7: 1.2538965
A8: S3 | C8: C14:1 | F8: -0.054083705
A9: S3 | C9: C15:0 | F9: -0.05234687
A10: S3 | C10: C15:1 | F10: -0.039897742
A11: S3 | C11: C16:0 | F11: 107.8288
A12: S3 | C12: C16:1 | F12: 8.3030493
A13: S3 | C13: C17:1 | F13: -0.038329393
A14: S3 | C14: C18:0 | F14: 34.195856
A15: S3 | C15: C18:1 | F15: 32.642109
... A171: S6 | C171: C24:1 | F171: -0.1521661

Sheet alt_Blanks
A1: Oldname | B1: RUNINFO | C1: Name | D1: Treatment | E1: Replicate | F1: FA_µg_sample | I1: median
A2: Blank1 | C2: C08:0 | F2: 6.7065411 | H2: C08:0 | I2: =MEDIAN(F2,F37,F72) -> 6.7065411 | K2: Wieso median? Eher mittelwert nehmen
A3: Blank1 | C3: C10:0 | F3: 4.5137455 | H3: C10:0 | I3: =MEDIAN(F3,F38,F73) -> 0
A4: Blank1 | C4: C11:0 | F4: 0.5605737 | H4: C11:0 | I4: =MEDIAN(F4,F39,F74) -> 0
A5: Blank1 | C5: C12:0 | F5: 16.079607 | H5: C12:0 | I5: =MEDIAN(F5,F40,F75) -> 0
A6: Blank1 | C6: C13:0 | F6: 104.06352 | H6: C13:0 | I6: =MEDIAN(F6,F41,F76) -> 0
A7: Blank1 | C7: C14:0 | F7: 28.730075 | H7: C14:0 | I7: =MEDIAN(F7,F42,F77) -> 0
A8: Blank1 | C8: C14:1 | F8: 0 | H8: C14:1 | I8: =MEDIAN(F8,F43,F78) -> 0
A9: Blank1 | C9: C15:0 | F9: 6.547856 | H9: C15:0 | I9: =MEDIAN(F9,F44,F79) -> 0
A10: Blank1 | C10: C15:1 | F10: 0 | H10: C15:1 | I10: =MEDIAN(F10,F45,F80) -> 0
A11: Blank1 | C11: C16:0 | F11: 1489.3189 | H11: C16:0 | I11: =MEDIAN(F11,F46,F81) -> 805.21669
A12: Blank1 | C12: C16:1 | F12: 0 | H12: C16:1 | I12: =MEDIAN(F12,F47,F82) -> 0
A13: Blank1 | C13: C17:0 | F13: 3.3850266 | H13: C17:0 | I13: =MEDIAN(F13,F48,F83) -> 0.8527135
A14: Blank1 | C14: C17:1 | F14: NA | H14: C17:1 | I14: =MEDIAN(F14,F49,F84) -> 0
A15: Blank1 | C15: C18:0 | F15: 448.63464 | H15: C18:0 | I15: =MEDIAN(F15,F50,F85) -> 268.6234
A16: Blank1 | C16: C18:1 | F16: 16.423912 | H16: C18:1 | I16: =MEDIAN(F16,F51,F86) -> 18.465913
A17: Blank1 | C17: C18:2(n-6t) | F17: 0.3319534 | H17: C18:2(n-6t) | I17: =MEDIAN(F17,F52,F87) -> 0.3319534
A18: Blank1 | C18: C18:2(n-6c) | F18: 6.0034596 | H18: C18:2(n-6c) | I18: =MEDIAN(F18,F53,F88) -> 6.0034596
A19: Blank1 | C19: C18:3(n-6) | F19: 0 | H19: C18:3(n-6) | I19: =MEDIAN(F19,F54,F89) -> 0
A20: Blank1 | C20: C18:3(n-3) | F20: 1.9379754 | H20: C18:3(n-3) | I20: =MEDIAN(F20,F55,F90) -> 1.9379754
A21: Blank1 | C21: C18:4(n-3) | F21: 0.2145091 | H21: C18:4(n-3) | I21: =MEDIAN(F21,F56,F91) -> 0.2145091
A22: Blank1 | C22: C20:0 | F22: 8.752849 | H22: C20:0 | I22: =MEDIAN(F22,F57,F92) -> 1.5947214
A23: Blank1 | C23: C20:1 | F23: 0.1493779 | H23: C20:1 | I23: =MEDIAN(F23,F58,F93) -> 0.1207374
A24: Blank1 | C24: C20:2(n-6) | F24: 0.2437476 | H24: C20:2(n-6) | I24: =MEDIAN(F24,F59,F94) -> 0.2471696
A25: Blank1 | C25: C20:3(n-6) | F25: 0.4401581 | H25: C20:3(n-6) | I25: =MEDIAN(F25,F60,F95) -> 0.4722408
A26: Blank1 | C26: C20:4(n-6) | F26: 0.5801763 | H26: C20:4(n-6) | I26: =MEDIAN(F26,F61,F96) -> 0.5801763
A27: Blank1 | C27: C20:3(n-3) | F27: NA | H27: C20:3(n-3) | I27: #N/A
A28: Blank1 | C28: C21:0 | F28: 0.0007524 | H28: C21:0 | I28: =MEDIAN(F28,F63,F98) -> 0
A29: Blank1 | C29: C20:5(n-3) | F29: 0.535825 | H29: C20:5(n-3) | I29: =MEDIAN(F29,F64,F99) -> 0.611621
A30: Blank1 | C30: C22:0 | F30: 0 | H30: C22:0 | I30: =MEDIAN(F30,F65,F100) -> 0
A31: Blank1 | C31: C22:1 | F31: 165.91263 | H31: C22:1 | I31: =MEDIAN(F31,F66,F101) -> 102.45463
A32: Blank1 | C32: C22:2 | F32: 1.9244387 | H32: C22:2 | I32: =MEDIAN(F32,F67,F102) -> 1.9275685
A33: Blank1 | C33: C22:5(n-3) | F33: 0 | H33: C22:5(n-3) | I33: =MEDIAN(F33,F68,F103) -> 0
A34: Blank1 | C34: C22:6(n-3) | F34: 0 | H34: C22:6(n-3) | I34: =MEDIAN(F34,F69,F104) -> 0
A35: Blank1 | C35: C24:0 | F35: 6.9332251 | H35: C24:0 | I35: =MEDIAN(F35,F70,F105) -> 0
A36: Blank1 | C36: C24:1 | F36: 0 | H36: C24:1 | I36: =MEDIAN(F36,F71,F106) -> 0
A37: Blank2 | C37: C08:0 | F37: 6.7179712
A38: Blank2 | C38: C10:0 | F38: 0
A39: Blank2 | C39: C11:0 | F39: 0
A40: Blank2 | C40: C12:0 | F40: 0
...

Sheet Neu_all FA
A1: Oldname | B1: RUNINFO | C1: Name | D1: FA | E1: Treatment | F1: Alt FA_µg_sample | G1: Neu FA_µg_sample | H1: Neu FA_µg_sample | I1: negative values to 0 | J1: µg_FA_per_mg dryweight
A2: NC25 | B2: S_1 | C2: C08:0 | D2: SAFA | E2: NC | F2: 6.9195217 | G2: #N/A | H2: 0.75908155 | I2: =IF(G2<0,0,G2) -> #N/A | J2: =I2/0.4108 -> #N/A | M2: Infos: | N2: a) in Spalte FA_ug_sample, bei #NV Angabe stand in Patricks aufgeräumter Liste "ND"
A3: NC25 | B3: S_1 | C3: C10:0 | D3: SAFA | E3: NC | F3: 0 | G3: #N/A | H3: -0.10339415 | I3: =IF(G3<0,0,G3) -> #N/A | J3: =I3/0.4108 -> #N/A | N3: b) negative values set to 0 (as there was a data, but the blank average was higher)
A4: NC25 | B4: S_1 | C4: C11:0 | D4: SAFA | E4: NC | F4: 0 | G4: #N/A | H4: -0.021110198 | I4: =IF(G4<0,0,G4) -> #N/A | J4: =I4/0.4108 -> #N/A
A5: NC25 | B5: S_1 | C5: C12:0 | D5: SAFA | E5: NC | F5: 3.9083869 | G5: 0.8450394 | H5: 3.3663328 | I5: =IF(G5<0,0,G5) -> 0.8450394 | J5: =I5/0.4108 -> 2.0570579
A6: NC25 | B6: S_1 | C6: C13:0 | D6: SAFA | E6: NC | F6: 89.102143 | G6: 9.2403641 | H6: 7.1702823 | I6: =IF(G6<0,0,G6) -> 9.2403641 | J6: =I6/0.4108 -> 22.493584
A7: NC25 | B7: S_1 | C7: C14:0 | D7: SAFA | E7: NC | F7: 82.495747 | G7: 9.4333098 | H7: 22.615715 | I7: =IF(G7<0,0,G7) -> 9.4333098 | J7: =I7/0.4108 -> 22.963266
A8: NC25 | B8: S_1 | C8: C14:1 | D8: MUFA | E8: NC | F8: 0 | G8: #N/A | H8: -0.063471318 | I8: =IF(G8<0,0,G8) -> #N/A | J8: =I8/0.4108 -> #N/A
A9: NC25 | B9: S_1 | C9: C15:0 | D9: SAFA | E9: NC | F9: 12.380672 | G9: 1.6266302 | H9: 0.60201098 | I9: =IF(G9<0,0,G9) -> 1.6266302 | J9: =I9/0.4108 -> 3.9596645
A10: NC25 | B10: S_1 | C10: C15:1 | D10: MUFA | E10: NC | F10: 0 | G10: #N/A | H10: 0.036666508 | I10: =IF(G10<0,0,G10) -> #N/A | J10: =I10/0.4108 -> #N/A
A11: NC25 | B11: S_1 | C11: C16:0 | D11: SAFA | E11: NC | F11: 2493.7801 | G11: 59.714345 | H11: 181.73879 | I11: =IF(G11<0,0,G11) -> 59.714345 | J11: =I11/0.4108 -> 145.36111
A12: NC25 | B12: S_1 | C12: C16:1 | D12: MUFA | E12: NC | F12: 349.68088 | G12: 31.686628 | H12: 87.950659 | I12: =IF(G12<0,0,G12) -> 31.686628 | J12: =I12/0.4108 -> 77.133954
A13: NC25 | B13: S_1 | C13: C17:1 | D13: MUFA | E13: NC | F13: 0 | G13: #N/A | H13: 43.753674 | I13: =IF(G13<0,0,G13) -> #N/A | J13: =I13/0.4108 -> #N/A
A14: NC25 | B14: S_1 | C14: C18:0 | D14: SAFA | E14: NC | F14: 465.12035 | G14: 35.853295 | H14: 32.855584 | I14: =IF(G14<0,0,G14) -> 35.853295 | J14: =I14/0.4108 -> 87.276765
A15: NC25 | B15: S_1 | C15: C18:1 | D15: MUFA | E15: NC | F15: 393.7337 | G15: 37.4635 | H15: 114.92268 | I15: =IF(G15<0,0,G15) -> 37.4635 | J15: =I15/0.4108 -> 91.196446
A16: NC25 | B16: S_1 | C16: C18:2(n-6t) | D16: PUFA | E16: NC | F16: 0.3628882 | G16: #N/A | H16: 17.624163 | I16: =IF(G16<0,0,G16) -> #N/A | J16: =I16/0.4108 -> #N/A
A17: NC25 | B17: S_1 | C17: C18:2(n-6c) | D17: PUFA | E17: NC | F17: 217.57505 | G17: 16.592306 | H17: 32.199884 | I17: =IF(G17<0,0,G17) -> 16.592306 | J17: =I17/0.4108 -> 40.390229
A18: NC25 | B18: S_1 | C18: C18:3(n-6) | D18: PUFA | E18: NC | F18: 0 | G18: 0.96402894 | H18: 28.579172 | I18: =IF(G18<0,0,G18) -> 0.96402894 | J18: =I18/0.4108 -> 2.3467111
A19: NC25 | B19: S_1 | C19: C18:3(n-3) | D19: PUFA | E19: NC | F19: 181.89141 | G19: 4.024122 | H19: 16.250554 | I19: =IF(G19<0,0,G19) -> 4.024122 | J19: =I19/0.4108 -> 9.795818
A20: NC25 | B20: S_1 | C20: C18:4(n-3) | D20: PUFA | E20: NC | F20: 8.8877941 | G20: 1.0491493 | H20: 10.142542 | I20: =IF(G20<0,0,G20) -> 1.0491493 | J20: =I20/0.4108 -> 2.5539174
A21: NC25 | B21: S_1 | C21: C20:0 | D21: SAFA | E21: NC | F21: 4.7820946 | G21: 1.287298 | H21: 8.1985001 | I21: =IF(G21<0,0,G21) -> 1.287298 | J21: =I21/0.4108 -> 3.1336367
A22: NC25 | B22: S_1 | C22: C20:1 | D22: MUFA | E22: NC | F22: 9.3887077 | G22: 4.0511194 | H22: 13.624564 | I22: =IF(G22<0,0,G22) -> 4.0511194 | J22: =I22/0.4108 -> 9.8615371
A23: NC25 | B23: S_1 | C23: C20:2(n-6) | D23: PUFA | E23: NC | F23: 22.894911 | G23: 3.0265876 | H23: 31.746355 | I23: =IF(G23<0,0,G23) -> 3.0265876 | J23: =I23/0.4108 -> 7.3675452
A24: NC25 | B24: S_1 | C24: C20:3(n-6) | D24: PUFA | E24: NC | F24: 0.4021034 | G24: 0.34635517 | H24: 21.442089 | I24: =IF(G24<0,0,G24) -> 0.34635517 | J24: =I24/0.4108 -> 0.84312359
A25: NC25 | B25: S_1 | C25: C20:4(n-6) | D25: PUFA | E25: NC | F25: 214.76229 | G25: 8.6957298 | H25: 31.882429 | I25: =IF(G25<0,0,G25) -> 8.6957298 | J25: =I25/0.4108 -> 21.167794
A26: NC25 | B26: S_1 | C26: C20:3(n-3) | D26: PUFA | E26: NC | F26: #N/A | G26: #N/A | H26: 17.186008 | I26: =IF(G26<0,0,G26) -> #N/A | J26: =I26/0.4108 -> #N/A
A27: NC25 | B27: S_1 | C27: C21:0 | D27: SAFA | E27: NC | F27: 0 | G27: #N/A | H27: 36.733727 | I27: =IF(G27<0,0,G27) -> #N/A | J27: =I27/0.4108 -> #N/A
A28: NC25 | B28: S_1 | C28: C20:5(n-3) | D28: PUFA | E28: NC | F28: 187.38594 | G28: 10.781184 | H28: 11.666827 | I28: =IF(G28<0,0,G28) -> 10.781184 | J28: =I28/0.4108 -> 26.244361
A29: NC25 | B29: S_1 | C29: C22:0 | D29: SAFA | E29: NC | F29: 0 | G29: #N/A | H29: 13.785033 | I29: =IF(G29<0,0,G29) -> #N/A | J29: =I29/0.4108 -> #N/A
A30: NC25 | B30: S_1 | C30: C22:1 | D30: MUFA | E30: NC | F30: 94.303771 | G30: 4.6407941 | H30: 32.832154 | I30: =IF(G30<0,0,G30) -> 4.6407941 | J30: =I30/0.4108 -> 11.296967
A31: NC25 | B31: S_1 | C31: C22:2 | D31: PUFA | E31: NC | F31: 1.9159594 | G31: #N/A | H31: 23.642877 | I31: =IF(G31<0,0,G31) -> #N/A | J31: =I31/0.4108 -> #N/A
A32: NC25 | B32: S_1 | C32: C22:5(n-3) | D32: PUFA | E32: NC | F32: 5.5423441 | G32: 1.7717347 | H32: 10.286512 | I32: =IF(G32<0,0,G32) -> 1.7717347 | J32: =I32/0.4108 -> 4.3128887
A33: NC25 | B33: S_1 | C33: C22:6(n-3) | D33: PUFA | E33: NC | F33: 6.4709817 | G33: 0.76990417 | H33: 9.8843817 | I33: =IF(G33<0,0,G33) -> 0.76990417 | J33: =I33/0.4108 -> 1.8741582
A34: NC25 | B34: S_1 | C34: C24:0 | D34: SAFA | E34: NC | F34: 6.612612 | G34: #N/A | H34: 26.141296 | I34: =IF(G34<0,0,G34) -> #N/A | J34: =I34/0.4108 -> #N/A
A35: NC25 | B35: S_1 | C35: C24:1 | D35: MUFA | E35: NC | F35: 0 | G35: #N/A | H35: 25.934878 | I35: =IF(G35<0,0,G35) -> #N/A | J35: =I35/0.4108 -> #N/A
A36: NC26 | B36: S_2 | C36: C08:0 | D36: SAFA | E36: NC | F36: 6.7014393 | G36: #N/A | H36: 0.7499002 | I36: =IF(G36<0,0,G36) -> #N/A | J36: =I36/0.6072 -> #N/A
A37: NC26 | B37: S_2 | C37: C10:0 | D37: SAFA | E37: NC | F37: 0 | G37: #N/A | H37: -0.089316841 | I37: =IF(G37<0,0,G37) -> #N/A | J37: =I37/0.6072 -> #N/A
A38: NC26 | B38: S_2 | C38: C11:0 | D38: SAFA | E38: NC | F38: 0 | G38: #N/A | H38: -0.0096652026 | I38: =IF(G38<0,0,G38) -> #N/A | J38: =I38/0.6072 -> #N/A
A39: NC26 | B39: S_2 | C39: C12:0 | D39: SAFA | E39: NC | F39: 8.8682996 | G39: 1.3552616 | H39: 4.9164279 | I39: =IF(G39<0,0,G39) -> 1.3552616 | J39: =I39/0.6072 -> 2.2319855
A40: NC26 | B40: S_2 | C40: C13:0 | D40: SAFA | E40: NC | F40: 96.253499 | G40: 9.8489304 | H40: 7.7455378 | I40: =IF(G40<0,0,G40) -> 9.8489304 | J40: =I40/0.6072 -> 16.220241
...

Sheet Tabelle2
A1: replicate | B1: fa | C1: treatment | D1: fa_conc
A2: S_1 | B2: C08:0 | C2: NC | D2: 0
A3: S_1 | B3: C10:0 | C3: NC | D3: 0
A4: S_1 | B4: C11:0 | C4: NC | D4: 0
A5: S_1 | B5: C12:0 | C5: NC | D5: 2.0570579
A6: S_1 | B6: C13:0 | C6: NC | D6: 22.493584
A7: S_1 | B7: C14:0 | C7: NC | D7: 22.963266
A8: S_1 | B8: C14:1 | C8: NC | D8: 0
A9: S_1 | B9: C15:0 | C9: NC | D9: 3.9596645
A10: S_1 | B10: C15:1 | C10: NC | D10: 0
A11: S_1 | B11: C16:0 | C11: NC | D11: 145.36111
A12: S_1 | B12: C16:1 | C12: NC | D12: 77.133954
A13: S_1 | B13: C17:1 | C13: NC | D13: 0
... A1327: S_40 | B1327: C24:1 | C1327: Cip | D1327: 0
