Workbook

Sheet Rohdaten
A1: Pigment analysis snail experiment | AA1: Chl a in 300 uL | AB1: Chl b in 300 uL | AC1: Chl c1+2 in 300 uL | AD1: 5000/300 | AE1: Chl a in 5000 uL | AF1: Chl b in 5000 uL | AG1: Chl c1+2 in 5000 uL | AH1: Jetzt noch auf die Fläche normieren | AI1: Chl a in ug/cm² | AJ1: Chl b in ug/cm² | AK1: Chl c in ug/cm²
W2: negativer Messwert | Z2: nach Jeffrey & Humphrey | AA2: 11,93xE(664nm) - 1,93xE(647nm) | AB2: 20,36xE(647nm) - 5,5xE(664nm) | AC2: 24,36xE(630nm) - 3,73xE(664nm) | AD2: =5000/300 -> 16.666667
B3: Wavelenght | Z3: modifiziert, da bei 650 die Extinktion immer höher als bei 645 | AA3: 11,93xE(665nm) - 1,93xE(650nm) | AB3: 20,36xE(650nm) - 5,5xE(665nm) | AC3: 24,36xE(630nm) - 3,73xE(665nm)
A4: Sample | B4: 600 | C4: 605 | D4: 610 | E4: 615 | F4: 620 | G4: 625 | H4: 630 | I4: 635 | J4: 640 | K4: 645 | L4: 650 | M4: 655 | N4: 660 | O4: 665 | P4: 670 | Q4: 675 | R4: 680 | S4: 685 | T4: 690 | U4: 695 | V4: 700 | W4: 665 bereinigt mit Acteon-Blank | X4: 645 bereinigt | Y4: 650 bereinigt | Z4: 630 bereinigt | AH4: 44.18
A5: Week 1 NC 1 | B5: 0.0528 | C5: 0.053399999 | D5: 0.0539 | E5: 0.0539 | F5: 0.053800002 | G5: 0.0535 | H5: 0.053300001 | I5: 0.052900001 | J5: 0.0528 | K5: 0.053199999 | L5: 0.055599999 | M5: 0.059999999 | N5: 0.0669 | O5: 0.069700003 | P5: 0.066100001 | Q5: 0.0583 | R5: 0.052200001 | S5: 0.048799999 | T5: 0.047899999 | U5: 0.047200002 | V5: 0.0469 | W5: =(O5-$O$131) -> 0.029483337 | X5: =(K5-$K$131) -> 0.012649999 | Y5: =(L5-$L$131) -> 0.015199998 | Z5: =(H5-$H$131) -> 0.012416668 | AA5: =11.93*W5-1.93*Y5 -> 0.32240021 | AB5: =20.36*Y5-5.5*W5 -> 0.14731361 | AC5: =24.36*Z5-3.73*W5 -> 0.19249718 | AE5: =AA5*$AD$2 -> 5.3733369 | AF5: =AB5*$AD$2 -> 2.4552269 | AG5: =AC5*$AD$2 -> 3.2082863 | AI5: =AE5/$AH$4 -> 0.12162374 | AJ5: =AF5/$AH$4 -> 0.055573266 | AK5: =AG5/$AH$4 -> 0.072618521
B6: 0.050500002 | C6: 0.050900001 | D6: 0.0515 | E6: 0.0515 | F6: 0.0513 | G6: 0.0513 | H6: 0.050999999 | I6: 0.0506 | J6: 0.050500002 | K6: 0.050900001 | L6: 0.0535 | M6: 0.057700001 | N6: 0.064599998 | O6: 0.067400001 | P6: 0.063900001 | Q6: 0.056000002 | R6: 0.049800001 | S6: 0.046500001 | T6: 0.045400001 | U6: 0.0449 | V6: 0.0447 | W6: =(O6-$O$131) -> 0.027183335 | X6: =(K6-$K$131) -> 0.010350001 | Y6: =(L6-$L$131) -> 0.0131 | Z6: =(H6-$H$131) -> 0.010116666 | AA6: =11.93*W6-1.93*Y6 -> 0.29901419 | AB6: =20.36*Y6-5.5*W6 -> 0.11720766 | AC6: =24.36*Z6-3.73*W6 -> 0.14504814 | AE6: =AA6*$AD$2 -> 4.9835698 | AF6: =AB6*$AD$2 -> 1.953461 | AG6: =AC6*$AD$2 -> 2.417469 | AI6: =AE6/$AH$4 -> 0.11280149 | AJ6: =AF6/$AH$4 -> 0.044215957 | AK6: =AG6/$AH$4 -> 0.054718629
B7: 0.050099999 | C7: 0.050700001 | D7: 0.051199999 | E7: 0.0513 | F7: 0.050900001 | G7: 0.050700001 | H7: 0.050500002 | I7: 0.0502 | J7: 0.050000001 | K7: 0.050500002 | L7: 0.053100001 | M7: 0.0572 | N7: 0.064199999 | O7: 0.067100003 | P7: 0.063299999 | Q7: 0.055500001 | R7: 0.049400002 | S7: 0.046100002 | T7: 0.0451 | U7: 0.044199999 | V7: 0.044100001 | W7: =(O7-$O$131) -> 0.026883338 | X7: =(K7-$K$131) -> 0.0099500014 | Y7: =(L7-$L$131) -> 0.012700001 | Z7: =(H7-$H$131) -> 0.0096166686 | AA7: =11.93*W7-1.93*Y7 -> 0.29620722 | AB7: =20.36*Y7-5.5*W7 -> 0.11071366 | AC7: =24.36*Z7-3.73*W7 -> 0.1339872 | AE7: =AA7*$AD$2 -> 4.9367869 | AF7: =AB7*$AD$2 -> 1.8452276 | AG7: =AC7*$AD$2 -> 2.23312 | AI7: =AE7/$AH$4 -> 0.11174257 | AJ7: =AF7/$AH$4 -> 0.041766131 | AK7: =AG7/$AH$4 -> 0.050545948
A8: Week 1 NC 2 | B8: 0.0539 | C8: 0.055399999 | D8: 0.056499999 | E8: 0.056499999 | F8: 0.0559 | G8: 0.055799998 | H8: 0.055399999 | I8: 0.055100001 | J8: 0.055199999 | K8: 0.056699999 | L8: 0.062399998 | M8: 0.072400004 | N8: 0.088100001 | O8: 0.094700001 | P8: 0.086499996 | Q8: 0.0691 | R8: 0.056200001 | S8: 0.049199998 | T8: 0.046799999 | U8: 0.045499999 | V8: 0.045200001 | W8: =(O8-$O$131) -> 0.054483335 | X8: =(K8-$K$131) -> 0.016149998 | Y8: =(L8-$L$131) -> 0.021999998 | Z8: =(H8-$H$131) -> 0.014516666 | AA8: =11.93*W8-1.93*Y8 -> 0.6075262 | AB8: =20.36*Y8-5.5*W8 -> 0.14826161 | AC8: =24.36*Z8-3.73*W8 -> 0.15040314 | AE8: =AA8*$AD$2 -> 10.125437 | AF8: =AB8*$AD$2 -> 2.4710269 | AG8: =AC8*$AD$2 -> 2.506719 | AI8: =AE8/$AH$4 -> 0.22918598 | AJ8: =AF8/$AH$4 -> 0.055930894 | AK8: =AG8/$AH$4 -> 0.056738773
B9: 0.053599998 | C9: 0.055 | D9: 0.0561 | E9: 0.056299999 | F9: 0.055599999 | G9: 0.055100001 | H9: 0.055199999 | I9: 0.0548 | J9: 0.054699998 | K9: 0.056200001 | L9: 0.062399998 | M9: 0.072899997 | N9: 0.089400001 | O9: 0.096000001 | P9: 0.087800004 | Q9: 0.069600001 | R9: 0.055799998 | S9: 0.048500001 | T9: 0.0462 | U9: 0.044799998 | V9: 0.044500001 | W9: =(O9-$O$131) -> 0.055783335 | X9: =(K9-$K$131) -> 0.015650001 | Y9: =(L9-$L$131) -> 0.021999998 | Z9: =(H9-$H$131) -> 0.014316666 | AA9: =11.93*W9-1.93*Y9 -> 0.62303519 | AB9: =20.36*Y9-5.5*W9 -> 0.14111162 | AC9: =24.36*Z9-3.73*W9 -> 0.14068215 | AE9: =AA9*$AD$2 -> 10.38392 | AF9: =AB9*$AD$2 -> 2.3518603 | AG9: =AC9*$AD$2 -> 2.3447025 | AI9: =AE9/$AH$4 -> 0.23503667 | AJ9: =AF9/$AH$4 -> 0.053233596 | AK9: =AG9/$AH$4 -> 0.053071582
B10: 0.053399999 | C10: 0.055199999 | D10: 0.056499999 | E10: 0.056499999 | F10: 0.056000002 | G10: 0.0557 | H10: 0.055300001 | I10: 0.054900002 | J10: 0.054900002 | K10: 0.056699999 | L10: 0.063100003 | M10: 0.072999999 | N10: 0.089699998 | O10: 0.096100003 | P10: 0.087499999 | Q10: 0.069600001 | R10: 0.055799998 | S10: 0.048500001 | T10: 0.046100002 | U10: 0.044799998 | V10: 0.044599999 | W10: =(O10-$O$131) -> 0.055883337 | X10: =(K10-$K$131) -> 0.016149998 | Y10: =(L10-$L$131) -> 0.022700002 | Z10: =(H10-$H$131) -> 0.014416668 | AA10: =11.93*W10-1.93*Y10 -> 0.6228772 | AB10: =20.36*Y10-5.5*W10 -> 0.1548137 | AC10: =24.36*Z10-3.73*W10 -> 0.14274518 | AE10: =AA10*$AD$2 -> 10.381287 | AF10: =AB10*$AD$2 -> 2.5802283 | AG10: =AC10*$AD$2 -> 2.3790864 | AI10: =AE10/$AH$4 -> 0.23497706 | AJ10: =AF10/$AH$4 -> 0.058402632 | AK10: =AG10/$AH$4 -> 0.053849851
A11: Week 1 NC 3 | B11: 0.047400001 | C11: 0.048300002 | D11: 0.048799999 | E11: 0.048900001 | F11: 0.048599999 | G11: 0.048500001 | H11: 0.048500001 | I11: 0.0484 | J11: 0.048500001 | K11: 0.049199998 | L11: 0.052099999 | M11: 0.056600001 | N11: 0.064199999 | O11: 0.067599997 | P11: 0.064199999 | Q11: 0.056000002 | R11: 0.0495 | S11: 0.046 | T11: 0.0449 | U11: 0.044399999 | V11: 0.044100001 | W11: =(O11-$O$131) -> 0.027383331 | X11: =(K11-$K$131) -> 0.008649998 | Y11: =(L11-$L$131) -> 0.011699999 | Z11: =(H11-$H$131) -> 0.0076166683 | AA11: =11.93*W11-1.93*Y11 -> 0.30410214 | AB11: =20.36*Y11-5.5*W11 -> 0.087603653 | AC11: =24.36*Z11-3.73*W11 -> 0.083402215 | AE11: =AA11*$AD$2 -> 5.0683691 | AF11: =AB11*$AD$2 -> 1.4600609 | AG11: =AC11*$AD$2 -> 1.3900369 | AI11: =AE11/$AH$4 -> 0.11472089 | AJ11: =AF11/$AH$4 -> 0.033048005 | AK11: =AG11/$AH$4 -> 0.031463036
B12: 0.047400001 | C12: 0.0482 | D12: 0.048799999 | E12: 0.048799999 | F12: 0.048500001 | G12: 0.0482 | H12: 0.0484 | I12: 0.0482 | J12: 0.048300002 | K12: 0.0491 | L12: 0.0526 | M12: 0.0572 | N12: 0.065300003 | O12: 0.068999998 | P12: 0.065300003 | Q12: 0.056699999 | R12: 0.049899999 | S12: 0.046300001 | T12: 0.045200001 | U12: 0.044599999 | V12: 0.044500001 | W12: =(O12-$O$131) -> 0.028783333 | X12: =(K12-$K$131) -> 0.0085500001 | Y12: =(L12-$L$131) -> 0.0122 | Z12: =(H12-$H$131) -> 0.0075166666 | AA12: =11.93*W12-1.93*Y12 -> 0.31983916 | AB12: =20.36*Y12-5.5*W12 -> 0.090083666 | AC12: =24.36*Z12-3.73*W12 -> 0.075744169 | AE12: =AA12*$AD$2 -> 5.3306526 | AF12: =AB12*$AD$2 -> 1.5013944 | AG12: =AC12*$AD$2 -> 1.2624028 | AI12: =AE12/$AH$4 -> 0.1206576 | AJ12: =AF12/$AH$4 -> 0.033983577 | AK12: =AG12/$AH$4 -> 0.028574079
B13: 0.046799999 | C13: 0.047499999 | D13: 0.048099998 | E13: 0.048 | F13: 0.047499999 | G13: 0.047200002 | H13: 0.046999998 | I13: 0.046799999 | J13: 0.046700001 | K13: 0.047400001 | L13: 0.050299998 | M13: 0.0548 | N13: 0.062600002 | O13: 0.066 | P13: 0.0625 | Q13: 0.0539 | R13: 0.046999998 | S13: 0.043299999 | T13: 0.042199999 | U13: 0.041499998 | V13: 0.0414 | W13: =(O13-$O$131) -> 0.025783334 | X13: =(K13-$K$131) -> 0.0068500011 | Y13: =(L13-$L$131) -> 0.0098999981 | Z13: =(H13-$H$131) -> 0.0061166653 | AA13: =11.93*W13-1.93*Y13 -> 0.28848818 | AB13: =20.36*Y13-5.5*W13 -> 0.059755624 | AC13: =24.36*Z13-3.73*W13 -> 0.052830131 | AE13: =AA13*$AD$2 -> 4.8081363 | AF13: =AB13*$AD$2 -> 0.99592707 | AG13: =AC13*$AD$2 -> 0.88050218 | AI13: =AE13/$AH$4 -> 0.10883061 | AJ13: =AF13/$AH$4 -> 0.022542487 | AK13: =AG13/$AH$4 -> 0.019929882
W14: =(O14-$O$131) -> -0.040216666 | X14: =(K14-$K$131) -> -0.04055 | Y14: =(L14-$L$131) -> -0.0404 | Z14: =(H14-$H$131) -> -0.040883333 | AA14: =11.93*W14-1.93*Y14 -> -0.40181282 | AB14: =20.36*Y14-5.5*W14 -> -0.60135234 | AC14: =24.36*Z14-3.73*W14 -> -0.84590983 | AE14: =AA14*$AD$2 -> -6.6968804 | AF14: =AB14*$AD$2 -> -10.022539 | AG14: =AC14*$AD$2 -> -14.098497 | AI14: =AE14/$AH$4 -> -0.15158172 | AJ14: =AF14/$AH$4 -> -0.22685693 | AK14: =AG14/$AH$4 -> -0.31911492
A15: Week 1 Pro 1 | B15: 0.054299999 | C15: 0.0557 | D15: 0.056899998 | E15: 0.057300001 | F15: 0.057 | G15: 0.056600001 | H15: 0.0561 | I15: 0.055399999 | J15: 0.055199999 | K15: 0.056499999 | L15: 0.062799998 | M15: 0.072300002 | N15: 0.088500001 | O15: 0.095200002 | P15: 0.086900003 | Q15: 0.0691 | R15: 0.055599999 | S15: 0.0484 | T15: 0.046 | U15: 0.044799998 | V15: 0.044300001 | W15: =(O15-$O$131) -> 0.054983336 | X15: =(K15-$K$131) -> 0.015949999 | Y15: =(L15-$L$131) -> 0.022399997 | Z15: =(H15-$H$131) -> 0.015216667 | AA15: =11.93*W15-1.93*Y15 -> 0.61271921 | AB15: =20.36*Y15-5.5*W15 -> 0.1536556 | AC15: =24.36*Z15-3.73*W15 -> 0.16559015 | AE15: =AA15*$AD$2 -> 10.211987 | AF15: =AB15*$AD$2 -> 2.5609266 | AG15: =AC15*$AD$2 -> 2.7598359 | AI15: =AE15/$AH$4 -> 0.23114502 | AJ15: =AF15/$AH$4 -> 0.057965744 | AK15: =AG15/$AH$4 -> 0.062467992
B16: 0.054699998 | C16: 0.056200001 | D16: 0.057500001 | E16: 0.057799999 | F16: 0.057399999 | G16: 0.057100002 | H16: 0.056699999 | I16: 0.0559 | J16: 0.055399999 | K16: 0.056899998 | L16: 0.063299999 | M16: 0.072899997 | N16: 0.089500003 | O16: 0.096199997 | P16: 0.087499999 | Q16: 0.069399998 | R16: 0.055599999 | S16: 0.048300002 | T16: 0.0458 | U16: 0.044500001 | V16: 0.044199999 | W16: =(O16-$O$131) -> 0.055983331 | X16: =(K16-$K$131) -> 0.016349998 | Y16: =(L16-$L$131) -> 0.022899998 | Z16: =(H16-$H$131) -> 0.015816666 | AA16: =11.93*W16-1.93*Y16 -> 0.62368414 | AB16: =20.36*Y16-5.5*W16 -> 0.15833565 | AC16: =24.36*Z16-3.73*W16 -> 0.17647615 | AE16: =AA16*$AD$2 -> 10.394736 | AF16: =AB16*$AD$2 -> 2.6389274 | AG16: =AC16*$AD$2 -> 2.9412691 | AI16: =AE16/$AH$4 -> 0.23528148 | AJ16: =AF16/$AH$4 -> 0.059731268 | AK16: =AG16/$AH$4 -> 0.066574675
B17: 0.054099999 | C17: 0.055399999 | D17: 0.056600001 | E17: 0.057 | F17: 0.057 | G17: 0.056699999 | H17: 0.056400001 | I17: 0.056000002 | J17: 0.055599999 | K17: 0.057 | L17: 0.063500002 | M17: 0.073100001 | N17: 0.089599997 | O17: 0.096500002 | P17: 0.088100001 | Q17: 0.070200004 | R17: 0.0568 | S17: 0.0495 | T17: 0.0471 | U17: 0.046 | V17: 0.045600001 | W17: =(O17-$O$131) -> 0.056283336 | X17: =(K17-$K$131) -> 0.01645 | Y17: =(L17-$L$131) -> 0.023100002 | Z17: =(H17-$H$131) -> 0.015516668 | AA17: =11.93*W17-1.93*Y17 -> 0.6268772 | AB17: =20.36*Y17-5.5*W17 -> 0.16075769 | AC17: =24.36*Z17-3.73*W17 -> 0.16804919 | AE17: =AA17*$AD$2 -> 10.447953 | AF17: =AB17*$AD$2 -> 2.6792948 | AG17: =AC17*$AD$2 -> 2.8008198 | AI17: =AE17/$AH$4 -> 0.23648604 | AJ17: =AF17/$AH$4 -> 0.06064497 | AK17: =AG17/$AH$4 -> 0.063395649
A18: Week 1 Pro 2 | B18: 0.0484 | C18: 0.048999999 | D18: 0.0495 | E18: 0.049899999 | F18: 0.049400002 | G18: 0.049199998 | H18: 0.048999999 | I18: 0.048599999 | J18: 0.048500001 | K18: 0.049199998 | L18: 0.052000001 | M18: 0.056299999 | N18: 0.063600004 | O18: 0.066600002 | P18: 0.063000001 | Q18: 0.054900002 | R18: 0.048799999 | S18: 0.045299999 | T18: 0.044300001 | U18: 0.0436 | V18: 0.043400001 | W18: =(O18-$O$131) -> 0.026383337 | X18: =(K18-$K$131) -> 0.008649998 | Y18: =(L18-$L$131) -> 0.011600001 | Z18: =(H18-$H$131) -> 0.0081166656 | AA18: =11.93*W18-1.93*Y18 -> 0.2923652 | AB18: =20.36*Y18-5.5*W18 -> 0.091067664 | AC18: =24.36*Z18-3.73*W18 -> 0.099312129 | AE18: =AA18*$AD$2 -> 4.8727534 | AF18: =AB18*$AD$2 -> 1.5177944 | AG18: =AC18*$AD$2 -> 1.6552021 | AI18: =AE18/$AH$4 -> 0.1102932 | AJ18: =AF18/$AH$4 -> 0.034354785 | AK18: =AG18/$AH$4 -> 0.037464965
B19: 0.047200002 | C19: 0.047699999 | D19: 0.0482 | E19: 0.0482 | F19: 0.048099998 | G19: 0.047699999 | H19: 0.0473 | I19: 0.046999998 | J19: 0.046799999 | K19: 0.047400001 | L19: 0.050500002 | M19: 0.055100001 | N19: 0.063000001 | O19: 0.066200003 | P19: 0.0623 | Q19: 0.053599998 | R19: 0.046799999 | S19: 0.043099999 | T19: 0.042100001 | U19: 0.0414 | V19: 0.0414 | W19: =(O19-$O$131) -> 0.025983337 | X19: =(K19-$K$131) -> 0.0068500011 | Y19: =(L19-$L$131) -> 0.010100001 | Z19: =(H19-$H$131) -> 0.0064166666 | AA19: =11.93*W19-1.93*Y19 -> 0.29048821 | AB19: =20.36*Y19-5.5*W19 -> 0.062727675 | AC19: =24.36*Z19-3.73*W19 -> 0.059392151 | AE19: =AA19*$AD$2 -> 4.8414702 | AF19: =AB19*$AD$2 -> 1.0454612 | AG19: =AC19*$AD$2 -> 0.98986918 | AI19: =AE19/$AH$4 -> 0.10958511 | AJ19: =AF19/$AH$4 -> 0.023663677 | AK19: =AG19/$AH$4 -> 0.022405369
B20: 0.047400001 | C20: 0.047899999 | D20: 0.048500001 | E20: 0.048700001 | F20: 0.048599999 | G20: 0.0482 | H20: 0.048 | I20: 0.047699999 | J20: 0.047499999 | K20: 0.048300002 | L20: 0.0513 | M20: 0.055599999 | N20: 0.0634 | O20: 0.066600002 | P20: 0.062600002 | Q20: 0.054099999 | R20: 0.047499999 | S20: 0.044 | T20: 0.042800002 | U20: 0.042300001 | V20: 0.041999999 | W20: =(O20-$O$131) -> 0.026383337 | X20: =(K20-$K$131) -> 0.0077500014 | Y20: =(L20-$L$131) -> 0.0109 | Z20: =(H20-$H$131) -> 0.0071166673 | AA20: =11.93*W20-1.93*Y20 -> 0.29371621 | AB20: =20.36*Y20-5.5*W20 -> 0.076815651 | AC20: =24.36*Z20-3.73*W20 -> 0.07495217 | AE20: =AA20*$AD$2 -> 4.8952701 | AF20: =AB20*$AD$2 -> 1.2802608 | AG20: =AC20*$AD$2 -> 1.2492028 | AI20: =AE20/$AH$4 -> 0.11080285 | AJ20: =AF20/$AH$4 -> 0.02897829 | AK20: =AG20/$AH$4 -> 0.028275302
A21: Week 1 Pro 3 | B21: 0.053199999 | C21: 0.0546 | D21: 0.055500001 | E21: 0.055500001 | F21: 0.055 | G21: 0.054499999 | H21: 0.054000001 | I21: 0.053599998 | J21: 0.053399999 | K21: 0.0546 | L21: 0.060199998 | M21: 0.068899997 | N21: 0.084299996 | O21: 0.090999998 | P21: 0.083899997 | Q21: 0.067199998 | R21: 0.054200001 | S21: 0.046999998 | T21: 0.0447 | U21: 0.0436 | V21: 0.043099999 | W21: =(O21-$O$131) -> 0.050783332 | X21: =(K21-$K$131) -> 0.01405 | Y21: =(L21-$L$131) -> 0.019799998 | Z21: =(H21-$H$131) -> 0.013116668 | AA21: =11.93*W21-1.93*Y21 -> 0.56763116 | AB21: =20.36*Y21-5.5*W21 -> 0.12381963 | AC21: =24.36*Z21-3.73*W21 -> 0.13010021 | AE21: =AA21*$AD$2 -> 9.4605193 | AF21: =AB21*$AD$2 -> 2.0636605 | AG21: =AC21*$AD$2 -> 2.1683368 | AI21: =AE21/$AH$4 -> 0.21413579 | AJ21: =AF21/$AH$4 -> 0.046710288 | AK21: =AG21/$AH$4 -> 0.049079602
B22: 0.0568 | C22: 0.0581 | D22: 0.059 | E22: 0.0592 | F22: 0.058699999 | G22: 0.058200002 | H22: 0.057700001 | I22: 0.057300001 | J22: 0.057 | K22: 0.058400001 | L22: 0.064199999 | M22: 0.073299997 | N22: 0.089199997 | O22: 0.096199997 | P22: 0.088699996 | Q22: 0.071500003 | R22: 0.058200002 | S22: 0.050799999 | T22: 0.048500001 | U22: 0.0471 | V22: 0.046799999 | W22: =(O22-$O$131) -> 0.055983331 | X22: =(K22-$K$131) -> 0.017850001 | Y22: =(L22-$L$131) -> 0.023799999 | Z22: =(H22-$H$131) -> 0.016816668 | AA22: =11.93*W22-1.93*Y22 -> 0.62194714 | AB22: =20.36*Y22-5.5*W22 -> 0.17665965 | AC22: =24.36*Z22-3.73*W22 -> 0.2008362 | AE22: =AA22*$AD$2 -> 10.365786 | AF22: =AB22*$AD$2 -> 2.9443275 | AG22: =AC22*$AD$2 -> 3.34727 | AI22: =AE22/$AH$4 -> 0.2346262 | AJ22: =AF22/$AH$4 -> 0.066643901 | AK22: =AG22/$AH$4 -> 0.075764372
B23: 0.055599999 | C23: 0.057 | D23: 0.057999998 | E23: 0.057999998 | F23: 0.057500001 | G23: 0.057 | H23: 0.056400001 | I23: 0.0559 | J23: 0.055599999 | K23: 0.057100002 | L23: 0.063100003 | M23: 0.072300002 | N23: 0.088399999 | O23: 0.095600002 | P23: 0.088100001 | Q23: 0.070799999 | R23: 0.057 | S23: 0.0493 | T23: 0.0469 | U23: 0.045699999 | V23: 0.045299999 | W23: =(O23-$O$131) -> 0.055383336 | X23: =(K23-$K$131) -> 0.016550001 | Y23: =(L23-$L$131) -> 0.022700002 | Z23: =(H23-$H$131) -> 0.015516668 | AA23: =11.93*W23-1.93*Y23 -> 0.61691219 | AB23: =20.36*Y23-5.5*W23 -> 0.1575637 | AC23: =24.36*Z23-3.73*W23 -> 0.17140619 | AE23: =AA23*$AD$2 -> 10.28187 | AF23: =AB23*$AD$2 -> 2.6260617 | AG23: =AC23*$AD$2 -> 2.8567698 | AI23: =AE23/$AH$4 -> 0.2327268 | AJ23: =AF23/$AH$4 -> 0.059440057 | AK23: =AG23/$AH$4 -> 0.06466206
W24: =(O24-$O$131) -> -0.040216666 | X24: =(K24-$K$131) -> -0.04055 | Y24: =(L24-$L$131) -> -0.0404 | Z24: =(H24-$H$131) -> -0.040883333 | AA24: =11.93*W24-1.93*Y24 -> -0.40181282 | AB24: =20.36*Y24-5.5*W24 -> -0.60135234 | AC24: =24.36*Z24-3.73*W24 -> -0.84590983 | AE24: =AA24*$AD$2 -> -6.6968804 | AF24: =AB24*$AD$2 -> -10.022539 | AG24: =AC24*$AD$2 -> -14.098497 | AI24: =AE24/$AH$4 -> -0.15158172 | AJ24: =AF24/$AH$4 -> -0.22685693 | AK24: =AG24/$AH$4 -> -0.31911492
A25: Week 1 Cip 1 | B25: 0.052900001 | C25: 0.0535 | D25: 0.054299999 | E25: 0.054299999 | F25: 0.054000001 | G25: 0.053800002 | H25: 0.053300001 | I25: 0.052700002 | J25: 0.052900001 | K25: 0.053300001 | L25: 0.056699999 | M25: 0.063299999 | N25: 0.073299997 | O25: 0.077500001 | P25: 0.0722 | Q25: 0.061000001 | R25: 0.052099999 | S25: 0.047400001 | T25: 0.045699999 | U25: 0.0449 | V25: 0.0447 | W25: =(O25-$O$131) -> 0.037283335 | X25: =(K25-$K$131) -> 0.01275 | Y25: =(L25-$L$131) -> 0.016299998 | Z25: =(H25-$H$131) -> 0.012416668 | AA25: =11.93*W25-1.93*Y25 -> 0.41333119 | AB25: =20.36*Y25-5.5*W25 -> 0.12680963 | AC25: =24.36*Z25-3.73*W25 -> 0.16340318 | AE25: =AA25*$AD$2 -> 6.8888531 | AF25: =AB25*$AD$2 -> 2.1134938 | AG25: =AC25*$AD$2 -> 2.7233864 | AI25: =AE25/$AH$4 -> 0.15592696 | AJ25: =AF25/$AH$4 -> 0.047838247 | AK25: =AG25/$AH$4 -> 0.06164297
B26: 0.055199999 | C26: 0.055799998 | D26: 0.056400001 | E26: 0.0568 | F26: 0.056499999 | G26: 0.056299999 | H26: 0.056000002 | I26: 0.0557 | J26: 0.055199999 | K26: 0.056000002 | L26: 0.060400002 | M26: 0.066600002 | N26: 0.077699997 | O26: 0.082599998 | P26: 0.077799998 | Q26: 0.066600002 | R26: 0.057599999 | S26: 0.052700002 | T26: 0.050900001 | U26: 0.0502 | V26: 0.049899999 | W26: =(O26-$O$131) -> 0.042383332 | X26: =(K26-$K$131) -> 0.015450001 | Y26: =(L26-$L$131) -> 0.020000001 | Z26: =(H26-$H$131) -> 0.015116669 | AA26: =11.93*W26-1.93*Y26 -> 0.46703315 | AB26: =20.36*Y26-5.5*W26 -> 0.1740917 | AC26: =24.36*Z26-3.73*W26 -> 0.21015222 | AE26: =AA26*$AD$2 -> 7.7838858 | AF26: =AB26*$AD$2 -> 2.9015284 | AG26: =AC26*$AD$2 -> 3.502537 | AI26: =AE26/$AH$4 -> 0.17618573 | AJ26: =AF26/$AH$4 -> 0.065675156 | AK26: =AG26/$AH$4 -> 0.079278791
B27: 0.057 | C27: 0.057799999 | D27: 0.058400001 | E27: 0.0583 | F27: 0.057799999 | G27: 0.057700001 | H27: 0.057700001 | I27: 0.057 | J27: 0.056899998 | K27: 0.057700001 | L27: 0.061500002 | M27: 0.0678 | N27: 0.0788 | O27: 0.083899997 | P27: 0.078299999 | Q27: 0.066500001 | R27: 0.056899998 | S27: 0.052200001 | T27: 0.0502 | U27: 0.049199998 | V27: 0.048999999 | W27: =(O27-$O$131) -> 0.043683331 | X27: =(K27-$K$131) -> 0.01715 | Y27: =(L27-$L$131) -> 0.021100001 | Z27: =(H27-$H$131) -> 0.016816668 | AA27: =11.93*W27-1.93*Y27 -> 0.48041914 | AB27: =20.36*Y27-5.5*W27 -> 0.18933771 | AC27: =24.36*Z27-3.73*W27 -> 0.2467152 | AE27: =AA27*$AD$2 -> 8.0069857 | AF27: =AB27*$AD$2 -> 3.1556284 | AG27: =AC27*$AD$2 -> 4.1119199 | AI27: =AE27/$AH$4 -> 0.18123553 | AJ27: =AF27/$AH$4 -> 0.071426628 | AK27: =AG27/$AH$4 -> 0.093071977
A28: Week 1 Cip 2 | B28: 0.045600001 | C28: 0.045899998 | D28: 0.046300001 | E28: 0.0462 | F28: 0.045899998 | G28: 0.0458 | H28: 0.045699999 | I28: 0.045600001 | J28: 0.045400001 | K28: 0.045600001 | L28: 0.0471 | M28: 0.0495 | N28: 0.053399999 | O28: 0.055100001 | P28: 0.053199999 | Q28: 0.048500001 | R28: 0.0451 | S28: 0.043200001 | T28: 0.0425 | U28: 0.041999999 | V28: 0.0418 | W28: =(O28-$O$131) -> 0.014883336 | X28: =(K28-$K$131) -> 0.0050500004 | Y28: =(L28-$L$131) -> 0.0066999998 | Z28: =(H28-$H$131) -> 0.0048166656 | AA28: =11.93*W28-1.93*Y28 -> 0.1646272 | AB28: =20.36*Y28-5.5*W28 -> 0.05455365 | AC28: =24.36*Z28-3.73*W28 -> 0.061819133 | AE28: =AA28*$AD$2 -> 2.7437866 | AF28: =AB28*$AD$2 -> 0.90922749 | AG28: =AC28*$AD$2 -> 1.0303189 | AI28: =AE28/$AH$4 -> 0.062104721 | AJ28: =AF28/$AH$4 -> 0.02058007 | AK28: =AG28/$AH$4 -> 0.023320934
B29: 0.046700001 | C29: 0.0471 | D29: 0.047600001 | E29: 0.047699999 | F29: 0.047400001 | G29: 0.0471 | H29: 0.046999998 | I29: 0.046700001 | J29: 0.046700001 | K29: 0.0473 | L29: 0.0491 | M29: 0.051399998 | N29: 0.055399999 | O29: 0.056899998 | P29: 0.054499999 | Q29: 0.050099999 | R29: 0.0469 | S29: 0.0451 | T29: 0.044199999 | U29: 0.0438 | V29: 0.043400001 | W29: =(O29-$O$131) -> 0.016683333 | X29: =(K29-$K$131) -> 0.0067499994 | Y29: =(L29-$L$131) -> 0.0087000001 | Z29: =(H29-$H$131) -> 0.0061166653 | AA29: =11.93*W29-1.93*Y29 -> 0.18224116 | AB29: =20.36*Y29-5.5*W29 -> 0.085373673 | AC29: =24.36*Z29-3.73*W29 -> 0.086773136 | AE29: =AA29*$AD$2 -> 3.0373526 | AF29: =AB29*$AD$2 -> 1.4228946 | AG29: =AC29*$AD$2 -> 1.4462189 | AI29: =AE29/$AH$4 -> 0.068749494 | AJ29: =AF29/$AH$4 -> 0.032206758 | AK29: =AG29/$AH$4 -> 0.032734697
B30: 0.0462 | C30: 0.046500001 | D30: 0.0471 | E30: 0.047200002 | F30: 0.0471 | G30: 0.046700001 | H30: 0.046599999 | I30: 0.046100002 | J30: 0.046 | K30: 0.046500001 | L30: 0.048300002 | M30: 0.050799999 | N30: 0.054900002 | O30: 0.056299999 | P30: 0.054099999 | Q30: 0.049600001 | R30: 0.046300001 | S30: 0.044399999 | T30: 0.044 | U30: 0.043400001 | V30: 0.043200001 | W30: =(O30-$O$131) -> 0.016083334 | X30: =(K30-$K$131) -> 0.0059500008 | Y30: =(L30-$L$131) -> 0.0079000015 | Z30: =(H30-$H$131) -> 0.005716666 | AA30: =11.93*W30-1.93*Y30 -> 0.17662717 | AB30: =20.36*Y30-5.5*W30 -> 0.072385695 | AC30: =24.36*Z30-3.73*W30 -> 0.079267148 | AE30: =AA30*$AD$2 -> 2.9437861 | AF30: =AB30*$AD$2 -> 1.2064283 | AG30: =AC30*$AD$2 -> 1.3211191 | AI30: =AE30/$AH$4 -> 0.066631646 | AJ30: =AF30/$AH$4 -> 0.027307113 | AK30: =AG30/$AH$4 -> 0.029903104
A31: Week 1 Cip 3 | B31: 0.050799999 | C31: 0.052299999 | D31: 0.053399999 | E31: 0.053800002 | F31: 0.053399999 | G31: 0.052700002 | H31: 0.052200001 | I31: 0.051600002 | J31: 0.0513 | K31: 0.052700002 | L31: 0.0594 | M31: 0.069300003 | N31: 0.086000003 | O31: 0.092699997 | P31: 0.084399998 | Q31: 0.066699997 | R31: 0.053100001 | S31: 0.045899998 | T31: 0.043900002 | U31: 0.042599998 | V31: 0.042300001 | W31: =(O31-$O$131) -> 0.052483331 | X31: =(K31-$K$131) -> 0.012150001 | Y31: =(L31-$L$131) -> 0.018999999 | Z31: =(H31-$H$131) -> 0.011316668 | AA31: =11.93*W31-1.93*Y31 -> 0.58945614 | AB31: =20.36*Y31-5.5*W31 -> 0.098181665 | AC31: =24.36*Z31-3.73*W31 -> 0.079911197 | AE31: =AA31*$AD$2 -> 9.8242691 | AF31: =AB31*$AD$2 -> 1.6363611 | AG31: =AC31*$AD$2 -> 1.3318533 | AI31: =AE31/$AH$4 -> 0.22236915 | AJ31: =AF31/$AH$4 -> 0.037038503 | AK31: =AG31/$AH$4 -> 0.030146068
B32: 0.0517 | C32: 0.053199999 | D32: 0.054099999 | E32: 0.054299999 | F32: 0.054099999 | G32: 0.0539 | H32: 0.053399999 | I32: 0.0528 | J32: 0.052200001 | K32: 0.053599998 | L32: 0.060600001 | M32: 0.070900001 | N32: 0.088399999 | O32: 0.0955 | P32: 0.086999997 | Q32: 0.068300001 | R32: 0.054099999 | S32: 0.046799999 | T32: 0.0447 | U32: 0.043699998 | V32: 0.0436 | W32: =(O32-$O$131) -> 0.055283334 | X32: =(K32-$K$131) -> 0.013049998 | Y32: =(L32-$L$131) -> 0.020200001 | Z32: =(H32-$H$131) -> 0.012516666 | AA32: =11.93*W32-1.93*Y32 -> 0.62054417 | AB32: =20.36*Y32-5.5*W32 -> 0.10721368 | AC32: =24.36*Z32-3.73*W32 -> 0.098699137 | AE32: =AA32*$AD$2 -> 10.342403 | AF32: =AB32*$AD$2 -> 1.7868947 | AG32: =AC32*$AD$2 -> 1.6449856 | AI32: =AE32/$AH$4 -> 0.23409694 | AJ32: =AF32/$AH$4 -> 0.040445784 | AK32: =AG32/$AH$4 -> 0.037233717
B33: 0.052900001 | C33: 0.054400001 | D33: 0.055500001 | E33: 0.0557 | F33: 0.0557 | G33: 0.055199999 | H33: 0.054699998 | I33: 0.054200001 | J33: 0.053800002 | K33: 0.055300001 | L33: 0.0623 | M33: 0.0726 | N33: 0.090599999 | O33: 0.097999997 | P33: 0.089199997 | Q33: 0.0704 | R33: 0.0557 | S33: 0.0482 | T33: 0.046 | U33: 0.0449 | V33: 0.0447 | W33: =(O33-$O$131) -> 0.057783332 | X33: =(K33-$K$131) -> 0.014750001 | Y33: =(L33-$L$131) -> 0.0219 | Z33: =(H33-$H$131) -> 0.013816665 | AA33: =11.93*W33-1.93*Y33 -> 0.64708815 | AB33: =20.36*Y33-5.5*W33 -> 0.12807568 | AC33: =24.36*Z33-3.73*W33 -> 0.12104214 | AE33: =AA33*$AD$2 -> 10.784802 | AF33: =AB33*$AD$2 -> 2.1345946 | AG33: =AC33*$AD$2 -> 2.017369 | AI33: =AE33/$AH$4 -> 0.24411051 | AJ33: =AF33/$AH$4 -> 0.048315858 | AK33: =AG33/$AH$4 -> 0.045662494
W34: =(O34-$O$131) -> -0.040216666 | X34: =(K34-$K$131) -> -0.04055 | Y34: =(L34-$L$131) -> -0.0404 | Z34: =(H34-$H$131) -> -0.040883333 | AA34: =11.93*W34-1.93*Y34 -> -0.40181282 | AB34: =20.36*Y34-5.5*W34 -> -0.60135234 | AC34: =24.36*Z34-3.73*W34 -> -0.84590983 | AE34: =AA34*$AD$2 -> -6.6968804 | AF34: =AB34*$AD$2 -> -10.022539 | AG34: =AC34*$AD$2 -> -14.098497 | AI34: =AE34/$AH$4 -> -0.15158172 | AJ34: =AF34/$AH$4 -> -0.22685693 | AK34: =AG34/$AH$4 -> -0.31911492
A35: Week 1 Mix 1 | B35: 0.0515 | C35: 0.051800001 | D35: 0.052099999 | E35: 0.052299999 | F35: 0.0517 | G35: 0.0515 | H35: 0.050900001 | I35: 0.050700001 | J35: 0.0506 | K35: 0.051100001 | L35: 0.054499999 | M35: 0.0592 | N35: 0.066699997 | O35: 0.069600001 | P35: 0.0656 | Q35: 0.057300001 | R35: 0.050799999 | S35: 0.047800001 | T35: 0.046599999 | U35: 0.045899998 | V35: 0.045499999 | W35: =(O35-$O$131) -> 0.029383335 | X35: =(K35-$K$131) -> 0.01055 | Y35: =(L35-$L$131) -> 0.014099998 | Z35: =(H35-$H$131) -> 0.010016668 | AA35: =11.93*W35-1.93*Y35 -> 0.32333019 | AB35: =20.36*Y35-5.5*W35 -> 0.12546762 | AC35: =24.36*Z35-3.73*W35 -> 0.13440619 | AE35: =AA35*$AD$2 -> 5.3888365 | AF35: =AB35*$AD$2 -> 2.0911271 | AG35: =AC35*$AD$2 -> 2.2401032 | AI35: =AE35/$AH$4 -> 0.12197457 | AJ35: =AF35/$AH$4 -> 0.047331984 | AK35: =AG35/$AH$4 -> 0.050704011
B36: 0.054200001 | C36: 0.054900002 | D36: 0.055300001 | E36: 0.055399999 | F36: 0.0548 | G36: 0.054699998 | H36: 0.054099999 | I36: 0.0537 | J36: 0.052999999 | K36: 0.0537 | L36: 0.057 | M36: 0.061500002 | N36: 0.069300003 | O36: 0.0722 | P36: 0.068099998 | Q36: 0.059700001 | R36: 0.053100001 | S36: 0.049600001 | T36: 0.048300002 | U36: 0.0473 | V36: 0.046799999 | W36: =(O36-$O$131) -> 0.031983335 | X36: =(K36-$K$131) -> 0.01315 | Y36: =(L36-$L$131) -> 0.0166 | Z36: =(H36-$H$131) -> 0.013216666 | AA36: =11.93*W36-1.93*Y36 -> 0.34952318 | AB36: =20.36*Y36-5.5*W36 -> 0.16206765 | AC36: =24.36*Z36-3.73*W36 -> 0.20266015 | AE36: =AA36*$AD$2 -> 5.8253864 | AF36: =AB36*$AD$2 -> 2.7011276 | AG36: =AC36*$AD$2 -> 3.3776692 | AI36: =AE36/$AH$4 -> 0.13185573 | AJ36: =AF36/$AH$4 -> 0.061139148 | AK36: =AG36/$AH$4 -> 0.076452449
B37: 0.061900001 | C37: 0.062600002 | D37: 0.065300003 | E37: 0.0678 | F37: 0.0682 | G37: 0.068099998 | H37: 0.067299999 | I37: 0.067599997 | J37: 0.066500001 | K37: 0.067000002 | L37: 0.069899999 | M37: 0.0744 | N37: 0.082199998 | O37: 0.084799998 | P37: 0.080200002 | Q37: 0.070299998 | R37: 0.063299999 | S37: 0.059599999 | T37: 0.059 | U37: 0.0581 | V37: 0.058200002 | W37: =(O37-$O$131) -> 0.044583332 | X37: =(K37-$K$131) -> 0.026450001 | Y37: =(L37-$L$131) -> 0.029499998 | Z37: =(H37-$H$131) -> 0.026416666 | AA37: =11.93*W37-1.93*Y37 -> 0.47494415 | AB37: =20.36*Y37-5.5*W37 -> 0.35541164 | AC37: =24.36*Z37-3.73*W37 -> 0.47721416 | AE37: =AA37*$AD$2 -> 7.9157359 | AF37: =AB37*$AD$2 -> 5.9235273 | AG37: =AC37*$AD$2 -> 7.9535693 | AI37: =AE37/$AH$4 -> 0.17917012 | AJ37: =AF37/$AH$4 -> 0.13407712 | AK37: =AG37/$AH$4 -> 0.18002647
A38: Week 1 Mix 2 | B38: 0.0592 | C38: 0.060199998 | D38: 0.060899999 | E38: 0.060899999 | F38: 0.061000001 | G38: 0.0605 | H38: 0.060899999 | I38: 0.060199998 | J38: 0.0601 | K38: 0.061299998 | L38: 0.066299997 | M38: 0.075800002 | N38: 0.090599999 | O38: 0.096699998 | P38: 0.0889 | Q38: 0.072800003 | R38: 0.061299998 | S38: 0.0546 | T38: 0.052200001 | U38: 0.051600002 | V38: 0.050999999 | W38: =(O38-$O$131) -> 0.056483332 | X38: =(K38-$K$131) -> 0.020749998 | Y38: =(L38-$L$131) -> 0.025899997 | Z38: =(H38-$H$131) -> 0.020016666 | AA38: =11.93*W38-1.93*Y38 -> 0.62385916 | AB38: =20.36*Y38-5.5*W38 -> 0.21666561 | AC38: =24.36*Z38-3.73*W38 -> 0.27692315 | AE38: =AA38*$AD$2 -> 10.397653 | AF38: =AB38*$AD$2 -> 3.6110935 | AG38: =AC38*$AD$2 -> 4.6153859 | AI38: =AE38/$AH$4 -> 0.2353475 | AJ38: =AF38/$AH$4 -> 0.081735933 | AK38: =AG38/$AH$4 -> 0.10446777
B39: 0.059300002 | C39: 0.0605 | D39: 0.061700001 | E39: 0.061700001 | F39: 0.0616 | G39: 0.060800001 | H39: 0.0603 | I39: 0.059999999 | J39: 0.059599999 | K39: 0.060400002 | L39: 0.065200001 | M39: 0.075099997 | N39: 0.090099998 | O39: 0.096199997 | P39: 0.088399999 | Q39: 0.072499998 | R39: 0.059999999 | S39: 0.053300001 | T39: 0.051100001 | U39: 0.049899999 | V39: 0.0504 | W39: =(O39-$O$131) -> 0.055983331 | X39: =(K39-$K$131) -> 0.019850001 | Y39: =(L39-$L$131) -> 0.024800001 | Z39: =(H39-$H$131) -> 0.019416667 | AA39: =11.93*W39-1.93*Y39 -> 0.62001714 | AB39: =20.36*Y39-5.5*W39 -> 0.19701969 | AC39: =24.36*Z39-3.73*W39 -> 0.26417218 | AE39: =AA39*$AD$2 -> 10.333619 | AF39: =AB39*$AD$2 -> 3.2836616 | AG39: =AC39*$AD$2 -> 4.4028697 | AI39: =AE39/$AH$4 -> 0.23389812 | AJ39: =AF39/$AH$4 -> 0.074324617 | AK39: =AG39/$AH$4 -> 0.09965753
B40: 0.059799999 | C40: 0.0605 | D40: 0.0612 | E40: 0.061700001 | F40: 0.061299998 | G40: 0.060600001 | H40: 0.0601 | I40: 0.059900001 | J40: 0.059500001 | K40: 0.0612 | L40: 0.067400001 | M40: 0.076099999 | N40: 0.090899996 | O40: 0.097400002 | P40: 0.089599997 | Q40: 0.072999999 | R40: 0.0603 | S40: 0.0539 | T40: 0.051399998 | U40: 0.050299998 | V40: 0.050299998 | W40: =(O40-$O$131) -> 0.057183336 | X40: =(K40-$K$131) -> 0.02065 | Y40: =(L40-$L$131) -> 0.027000001 | Z40: =(H40-$H$131) -> 0.019216667 | AA40: =11.93*W40-1.93*Y40 -> 0.6300872 | AB40: =20.36*Y40-5.5*W40 -> 0.23521166 | AC40: =24.36*Z40-3.73*W40 -> 0.25482417 | AE40: =AA40*$AD$2 -> 10.501453 | AF40: =AB40*$AD$2 -> 3.9201944 | AG40: =AC40*$AD$2 -> 4.2470695 | AI40: =AE40/$AH$4 -> 0.237697 | AJ40: =AF40/$AH$4 -> 0.088732331 | AK40: =AG40/$AH$4 -> 0.096131043
...

Sheet für R 
A1: sample | B1: treatment | C1: week | D1: chla | E1: chlb | F1: chlc | G1: afdw_after_colonisation
A2: 1 | B2: NC | C2: 1 | D2: =AVERAGE(Rohdaten!AI5:AI7) -> 0.11538927 | E2: =AVERAGE(Rohdaten!AJ5:AJ7) -> 0.047185118 | F2: =AVERAGE(Rohdaten!AK5:AK7) -> 0.059294366 | G2: 0.073336351
A3: 2 | B3: NC | C3: 1 | D3: =AVERAGE(Rohdaten!AI8:AI10) -> 0.23306657 | E3: =AVERAGE(Rohdaten!AJ8:AJ10) -> 0.055855707 | F3: =AVERAGE(Rohdaten!AK8:AK10) -> 0.054553402 | G3: 0.07831598
A4: 3 | B4: NC | C4: 1 | D4: =AVERAGE(Rohdaten!AI11:AI13) -> 0.11473637 | E4: =AVERAGE(Rohdaten!AJ11:AJ13) -> 0.029858023 | F4: =AVERAGE(Rohdaten!AK11:AK13) -> 0.026655665 | G4: 0.099366229
A5: 4 | B5: Cip | C5: 1 | D5: =AVERAGE(Rohdaten!AI25:AI27) -> 0.17111608 | E5: =AVERAGE(Rohdaten!AJ25:AJ27) -> 0.061646677 | F5: =AVERAGE(Rohdaten!AK25:AK27) -> 0.077997913 | G5: 0.067224989
A6: 5 | B6: Cip | C6: 1 | D6: =AVERAGE(Rohdaten!AI28:AI30) -> 0.06582862 | E6: =AVERAGE(Rohdaten!AJ28:AJ30) -> 0.02669798 | F6: =AVERAGE(Rohdaten!AK28:AK30) -> 0.028652912 | G6: 0.098913536
A7: 6 | B7: Cip | C7: 1 | D7: =AVERAGE(Rohdaten!AI31:AI33) -> 0.23352554 | E7: =AVERAGE(Rohdaten!AJ31:AJ33) -> 0.041933382 | F7: =AVERAGE(Rohdaten!AK31:AK33) -> 0.03768076 | G7: 0.06926211
A8: 7 | B8: Pro | C8: 1 | D8: =AVERAGE(Rohdaten!AI15:AI17) -> 0.23430418 | E8: =AVERAGE(Rohdaten!AJ15:AJ17) -> 0.059447328 | F8: =AVERAGE(Rohdaten!AK15:AK17) -> 0.064146105 | G8: 0.095971028
A9: 8 | B9: Pro | C9: 1 | D9: =AVERAGE(Rohdaten!AI18:AI20) -> 0.11022705 | E9: =AVERAGE(Rohdaten!AJ18:AJ20) -> 0.028998917 | F9: =AVERAGE(Rohdaten!AK18:AK20) -> 0.029381878 | G9: 0.12698053
A10: 9 | B10: Pro | C10: 1 | D10: =AVERAGE(Rohdaten!AI21:AI23) -> 0.22716293 | E10: =AVERAGE(Rohdaten!AJ21:AJ23) -> 0.057598082 | F10: =AVERAGE(Rohdaten!AK21:AK23) -> 0.063168678 | G10: 0.18220914
A11: 10 | B11: Mix | C11: 1 | D11: =AVERAGE(Rohdaten!AI35:AI37) -> 0.14433347 | E11: =AVERAGE(Rohdaten!AJ35:AJ37) -> 0.080849419 | F11: =AVERAGE(Rohdaten!AK35:AK37) -> 0.10239431 | G11: 0.066093255
A12: 11 | B12: Mix | C12: 1 | D12: =AVERAGE(Rohdaten!AI38:AI40) -> 0.23564754 | E12: =AVERAGE(Rohdaten!AJ38:AJ40) -> 0.081597627 | F12: =AVERAGE(Rohdaten!AK38:AK40) -> 0.10008545 | G12: 0.070393843
A13: 12 | B13: Mix | C13: 1 | D13: =AVERAGE(Rohdaten!AI41:AI43) -> 0.18786499 | E13: =AVERAGE(Rohdaten!AJ41:AJ43) -> 0.069594454 | F13: =AVERAGE(Rohdaten!AK41:AK43) -> 0.084834824 | G13: 0.063377094
A14: 13 | B14: NC | C14: 2 | D14: =AVERAGE(Rohdaten!AI45:AI47) -> 0.12160851 | E14: =AVERAGE(Rohdaten!AJ45:AJ47) -> 0.025465644 | F14: =AVERAGE(Rohdaten!AK45:AK47) -> 0.019337511 | G14: 0.32571299
A15: 14 | B15: NC | C15: 2 | D15: =AVERAGE(Rohdaten!AI48:AI50) -> 0.18514507 | E15: =AVERAGE(Rohdaten!AJ48:AJ50) -> 0.03926474 | F15: =AVERAGE(Rohdaten!AK48:AK50) -> 0.036427175 | G15: 0.20574921
A16: 15 | B16: NC | C16: 2 | D16: =AVERAGE(Rohdaten!AI51:AI53) -> 0.23499039 | E16: =AVERAGE(Rohdaten!AJ51:AJ53) -> 0.046154735 | F16: =AVERAGE(Rohdaten!AK51:AK53) -> 0.046567017 | G16: 0.11204165
A17: 16 | B17: Cip | C17: 2 | D17: =AVERAGE(Rohdaten!AI65:AI67) -> 0.024529896 | E17: =AVERAGE(Rohdaten!AJ65:AJ67) -> 0.014398797 | F17: =AVERAGE(Rohdaten!AK65:AK67) -> 0.01986866 | G17: 0.15436849
A18: 17 | B18: Cip | C18: 2 | D18: =AVERAGE(Rohdaten!AI68:AI70) -> 0.17635111 | E18: =AVERAGE(Rohdaten!AJ68:AJ70) -> 0.079064799 | F18: =AVERAGE(Rohdaten!AK68:AK70) -> 0.095657467 | G18: 0.093254866
A19: 18 | B19: Cip | C19: 2 | D19: =AVERAGE(Rohdaten!AI71:AI73) -> 0.085295451 | E19: =AVERAGE(Rohdaten!AJ71:AJ73) -> 0.039268766 | F19: =AVERAGE(Rohdaten!AK71:AK73) -> 0.044872932 | G19: 0.078768674
A20: 19 | B20: Pro | C20: 2 | D20: =AVERAGE(Rohdaten!AI55:AI57) -> 0.0574167 | E20: =AVERAGE(Rohdaten!AJ55:AJ57) -> 0.018579168 | F20: =AVERAGE(Rohdaten!AK55:AK57) -> 0.023077753 | G20: 0.06926211
A21: 20 | B21: Pro | C21: 2 | D21: =AVERAGE(Rohdaten!AI58:AI60) -> 0.1443316 | E21: =AVERAGE(Rohdaten!AJ58:AJ60) -> 0.038493904 | F21: =AVERAGE(Rohdaten!AK58:AK60) -> 0.043668387 | G21: 0.063829787
A22: 21 | B22: Pro | C22: 2 | D22: =AVERAGE(Rohdaten!AI61:AI63) -> 0.074207355 | E22: =AVERAGE(Rohdaten!AJ61:AJ63) -> 0.048787662 | F22: =AVERAGE(Rohdaten!AK61:AK63) -> 0.065357181 | G22: 0.076731553
A23: 22 | B23: Mix | C23: 2 | D23: =AVERAGE(Rohdaten!AI75:AI77) -> 0.029875201 | E23: =AVERAGE(Rohdaten!AJ75:AJ77) -> 0.035193779 | F23: =AVERAGE(Rohdaten!AK75:AK77) -> 0.049027768 | G23: 0.079221367
A24: 23 | B24: Mix | C24: 2 | D24: =AVERAGE(Rohdaten!AI78:AI80) -> 0.031858627 | E24: =AVERAGE(Rohdaten!AJ78:AJ80) -> 0.020323804 | F24: =AVERAGE(Rohdaten!AK78:AK80) -> 0.027091255 | G24: 0.057039384
A25: 24 | B25: Mix | C25: 2 | D25: =AVERAGE(Rohdaten!AI81:AI83) -> 0.03330146 | E25: =AVERAGE(Rohdaten!AJ81:AJ83) -> 0.017210274 | F25: =AVERAGE(Rohdaten!AK81:AK83) -> 0.019670609 | G25: 0.099366229
A26: 25 | B26: NC | C26: 3 | D26: =AVERAGE(Rohdaten!AI85:AI87) -> 0.21934455 | E26: =AVERAGE(Rohdaten!AJ85:AJ87) -> 0.038677744 | F26: =AVERAGE(Rohdaten!AK85:AK87) -> 0.026489307 | G26: 0.64259846
A27: 26 | B27: NC | C27: 3 | D27: =AVERAGE(Rohdaten!AI88:AI90) -> 1.0636792 | E27: =AVERAGE(Rohdaten!AJ88:AJ90) -> 0.19540151 | F27: =AVERAGE(Rohdaten!AK88:AK90) -> 0.17872094 | G27: 0.32254414
A28: 27 | B28: NC | C28: 3 | D28: =AVERAGE(Rohdaten!AI91:AI93) -> 0.47517851 | E28: =AVERAGE(Rohdaten!AJ91:AJ93) -> 0.080609502 | F28: =AVERAGE(Rohdaten!AK91:AK93) -> 0.058867582 | G28: 0.59483929
A29: 28 | B29: Cip | C29: 3 | D29: =AVERAGE(Rohdaten!AI105:AI107) -> 0.36968342 | E29: =AVERAGE(Rohdaten!AJ105:AJ107) -> 0.076605672 | F29: =AVERAGE(Rohdaten!AK105:AK107) -> 0.051822913 | G29: 0.20982345
A30: 29 | B30: Cip | C30: 3 | D30: =AVERAGE(Rohdaten!AI108:AI110) -> 0.22908437 | E30: =AVERAGE(Rohdaten!AJ108:AJ110) -> 0.072136823 | F30: =AVERAGE(Rohdaten!AK108:AK110) -> 0.052593881 | G30: 0.17768221
A31: 30 | B31: Cip | C31: 3 | D31: =AVERAGE(Rohdaten!AI111:AI113) -> 0.15175073 | E31: =AVERAGE(Rohdaten!AJ111:AJ113) -> 0.049518753 | F31: =AVERAGE(Rohdaten!AK111:AK113) -> 0.039369432 | G31: 0.17677682
A32: 31 | B32: Pro | C32: 3 | D32: =AVERAGE(Rohdaten!AI95:AI97) -> 0.75896642 | E32: =AVERAGE(Rohdaten!AJ95:AJ97) -> 0.11822304 | F32: =AVERAGE(Rohdaten!AK95:AK97) -> 0.10613344 | G32: 0.53078316
A33: 32 | B33: Pro | C33: 3 | D33: =AVERAGE(Rohdaten!AI98:AI100) -> 0.77222758 | E33: =AVERAGE(Rohdaten!AJ98:AJ100) -> 0.10696782 | F33: =AVERAGE(Rohdaten!AK98:AK100) -> 0.089893678 | G33: 0.54368493
A34: 33 | B34: Pro | C34: 3 | D34: =AVERAGE(Rohdaten!AI101:AI103) -> 0.35595035 | E34: =AVERAGE(Rohdaten!AJ101:AJ103) -> 0.064084675 | F34: =AVERAGE(Rohdaten!AK101:AK103) -> 0.061295769 | G34: 0.34766863
A35: 34 | B35: Mix | C35: 3 | D35: =AVERAGE(Rohdaten!AI115:AI117) -> 0.87529344 | E35: =AVERAGE(Rohdaten!AJ115:AJ117) -> 0.14416489 | F35: =AVERAGE(Rohdaten!AK115:AK117) -> 0.101605 | G35: 0.11837936
A36: 35 | B36: Mix | C36: 3 | D36: =AVERAGE(Rohdaten!AI118:AI120) -> 0.73129463 | E36: =AVERAGE(Rohdaten!AJ118:AJ120) -> 0.14983264 | F36: =AVERAGE(Rohdaten!AK118:AK120) -> 0.12737281 | G36: 0.41376188
A37: 36 | B37: Mix | C37: 3 | D37: =AVERAGE(Rohdaten!AI121:AI123) -> 0.43303249 | E37: =AVERAGE(Rohdaten!AJ121:AJ123) -> 0.086329038 | F37: =AVERAGE(Rohdaten!AK121:AK123) -> 0.062667434 | G37: 0.30692621
